{"topic":"orderbook.50.BTCUSDT","type":"delta","ts":1704258145632,"data":{"s":"BTCUSDT","b":[["45170.20","3.613"]],"a":[["45172.60","0"],["45173.70","0"],["45176.20","0.014"],["45178.00","0.380"],["45178.10","1.946"]],"u":20458946,"seq":114533092125},"cts":1704258145630}
{"topic":"orderbook.50.BTCUSDT","type":"delta","ts":1704258145651,"data":{"s":"BTCUSDT","b":[["45163.90","0.064"]],"a":[["45170.30","6.679"],["45171.10","0.003"],["45172.70","0.002"],["45176.20","0.003"],["45177.60","0"]],"u":20458947,"seq":114533092185},"cts":1704258145650}
{"topic":"orderbook.50.BTCUSDT","type":"delta","ts":1704258145672,"data":{"s":"BTCUSDT","b":[["45164.10","0.055"]],"a":[["45173.70","0.011"],["45176.20","0.040"],["45178.10","0"]],"u":20458948,"seq":114533092220},"cts":1704258145669}
{"topic":"orderbook.50.BTCUSDT","type":"delta","ts":1704258145691,"data":{"s":"BTCUSDT","b":[["45164.10","0.018"]],"a":[["45176.20","0.003"],["45177.30","0.144"]],"u":20458949,"seq":114533092258},"cts":1704258145689}
{"topic":"orderbook.50.BTCUSDT","type":"delta","ts":1704258145732,"data":{"s":"BTCUSDT","b":[["45170.20","1.111"],["45170.00","0.108"],["45169.90","0"],["45168.60","0.090"],["45167.30","0.006"],["45167.20","0"],["45165.90","0"],["45165.80","0"],["45165.70","0"],["45165.60","0.078"],["45165.50","0.046"],["45164.90","0.100"],["45164.80","0"],["45164.50","0"],["45164.10","0"],["45163.50","0"],["45162.90","0"],["45162.80","0"],["45162.50","0.080"],["45162.30","1.994"],["45162.10","0"],["45162.00","0.114"],["45161.30","0.666"],["45161.10","3.758"],["45160.90","0.447"],["45160.80","0.428"],["45160.40","1.560"],["45160.30","0.611"],["45160.20","0.447"],["45160.10","0.708"],["45160.00","0.647"],["45159.90","0.897"],["45159.80","0.266"],["45159.70","0.963"],["45159.50","2.105"],["45159.40","0.270"]],"a":[["45170.30","6.707"],["45172.70","0"],["45173.30","0"],["45173.60","0.112"],["45173.70","3.762"],["45174.00","1.771"],["45174.30","2.418"],["45174.50","0.004"],["45175.00","0.022"],["45175.80","0.004"],["45176.60","1.200"],["45176.70","0.122"],["45176.80","0"],["45176.90","0"],["45177.10","0.803"],["45178.10","1.946"],["45178.20","1.129"],["45178.30","0.996"]],"u":20458950,"seq":114533092478},"cts":1704258145730}
{"topic":"orderbook.50.BTCUSDT","type":"delta","ts":1704258145751,"data":{"s":"BTCUSDT","b":[["45166.30","0.075"],["45163.30","0"],["45159.20","0.553"]],"a":[["45170.30","6.775"],["45171.50","0.112"],["45172.60","1.200"],["45172.70","0.011"],["45173.00","0.081"],["45173.70","0"],["45174.90","0.078"],["45176.70","0.343"],["45177.30","3.906"],["45178.20","0"],["45178.30","0"]],"u":20458951,"seq":114533092638},"cts":1704258145750}
{"topic":"orderbook.50.BTCUSDT","type":"delta","ts":1704258145771,"data":{"s":"BTCUSDT","b":[["45164.30","0.073"],["45163.40","0"]],"a":[["45177.30","0.133"],["45177.60","3.762"],["45177.80","2.102"],["45178.10","0"]],"u":20458952,"seq":114533092774},"cts":1704258145769}
{"topic":"orderbook.50.BTCUSDT","type":"delta","ts":1704258145791,"data":{"s":"BTCUSDT","b":[["45163.50","0.163"],["45162.20","0.147"],["45159.20","0"]],"a":[["45174.30","2.455"],["45177.20","3.983"],["45177.60","0"],["45177.70","1.992"],["45177.80","0.155"],["45178.10","1.968"]],"u":20458953,"seq":114533092880},"cts":1704258145789}
{"topic":"orderbook.50.BTCUSDT","type":"delta","ts":1704258145811,"data":{"s":"BTCUSDT","b":[["45162.40","0.160"],["45162.20","0.110"],["45160.30","1.014"],["45159.40","0"]],"a":[["45170.30","7.975"],["45171.70","0.012"],["45172.50","1.600"],["45172.70","0"],["45174.30","2.418"],["45176.10","3.762"],["45177.20","0.221"],["45178.10","0"]],"u":20458954,"seq":114533092968},"cts":1704258145809}
{"topic":"orderbook.50.BTCUSDT","type":"delta","ts":1704258145832,"data":{"s":"BTCUSDT","b":[["45167.30","0.005"],["45167.10","0"],["45162.90","0.111"],["45162.70","1.616"],["45160.40","1.671"],["45159.90","3.110"],["45159.50","0"]],"a":[["45171.00","0.112"],["45171.50","0.312"],["45171.70","0.001"],["45171.80","0.300"],["45171.90","0.187"],["45172.20","0.111"],["45172.70","0.011"],["45173.80","0.241"],["45175.00","0.133"],["45176.10","0"],["45177.90","0"],["45178.00","0"]],"u":20458955,"seq":114533093082},"cts":1704258145830}
{"topic":"orderbook.50.BTCUSDT","type":"delta","ts":1704258145852,"data":{"s":"BTCUSDT","b":[["45167.20","0.002"],["45160.00","0.868"],["45159.70","0"]],"a":[["45171.90","0.198"],["45172.50","0"],["45172.70","0"],["45176.90","3.762"],["45177.20","2.168"],["45177.90","0.110"]],"u":20458956,"seq":114533093166},"cts":1704258145850}
{"topic":"orderbook.50.BTCUSDT","type":"delta","ts":1704258145872,"data":{"s":"BTCUSDT","b":[["45164.40","0.078"],["45161.40","0.079"],["45159.90","0"],["45159.80","0"]],"a":[],"u":20458957,"seq":114533093233},"cts":1704258145870}
{"topic":"orderbook.50.BTCUSDT","type":"delta","ts":1704258145892,"data":{"s":"BTCUSDT","b":[["45162.60","0.037"],["45160.00","0"]],"a":[["45171.90","0.187"],["45172.50","0.011"],["45174.80","0.040"],["45177.20","0.221"],["45177.90","0"]],"u":20458958,"seq":114533093304},"cts":1704258145890}
{"topic":"orderbook.50.BTCUSDT","type":"delta","ts":1704258145911,"data":{"s":"BTCUSDT","b":[["45162.60","0"],["45160.00","0.868"]],"a":[["45172.50","0"],["45173.00","0.092"],["45174.80","0.003"],["45176.20","0.014"],["45176.90","0"],["45177.30","3.895"],["45177.90","0.110"],["45178.00","0.380"]],"u":20458959,"seq":114533093381},"cts":1704258145910}
{"topic":"orderbook.50.BTCUSDT","type":"delta","ts":1704258145931,"data":{"s":"BTCUSDT","b":[["45167.00","0.001"],["45160.00","0"]],"a":[["45173.00","0.081"],["45173.40","0.011"],["45176.60","1.211"],["45177.30","0.133"],["45177.90","2.057"],["45178.00","0"]],"u":20458960,"seq":114533093464},"cts":1704258145930}
{"topic":"orderbook.50.BTCUSDT","type":"delta","ts":1704258145952,"data":{"s":"BTCUSDT","b":[["45167.30","0.004"]],"a":[["45177.10","4.565"],["45177.90","0.110"]],"u":20458961,"seq":114533093538},"cts":1704258145951}
{"topic":"orderbook.50.BTCUSDT","type":"delta","ts":1704258145971,"data":{"s":"BTCUSDT","b":[],"a":[["45172.70","0.011"],["45173.40","0"]],"u":20458962,"seq":114533093602},"cts":1704258145970}
{"topic":"orderbook.50.BTCUSDT","type":"delta","ts":1704258145991,"data":{"s":"BTCUSDT","b":[["45162.60","0.037"],["45160.10","0"]],"a":[["45174.80","0.040"],["45177.10","0.803"],["45177.60","3.762"],["45177.90","0"]],"u":20458963,"seq":114533093669},"cts":1704258145990}
{"topic":"orderbook.50.BTCUSDT","type":"delta","ts":1704258146012,"data":{"s":"BTCUSDT","b":[["45167.30","0.002"],["45167.00","0.004"],["45164.50","0.078"],["45162.60","0"]],"a":[["45172.50","0.011"],["45172.70","0"],["45174.80","0.003"],["45176.60","1.200"],["45176.90","0.011"],["45177.00","3.873"],["45177.60","0"]],"u":20458964,"seq":114533093741},"cts":1704258146010}
{"topic":"orderbook.50.BTCUSDT","type":"delta","ts":1704258146032,"data":{"s":"BTCUSDT","b":[["45167.30","0.001"]],"a":[["45177.30","2.080"]],"u":20458965,"seq":114533093799},"cts":1704258146029}
{"topic":"orderbook.50.BTCUSDT","type":"delta","ts":1704258146051,"data":{"s":"BTCUSDT","b":[["45167.30","0"],["45167.00","0.005"],["45160.50","0.109"]],"a":[["45172.50","0"],["45172.70","0.011"],["45177.30","0.133"]],"u":20458966,"seq":114533093866},"cts":1704258146050}
{"topic":"orderbook.50.BTCUSDT","type":"delta","ts":1704258146091,"data":{"s":"BTCUSDT","b":[],"a":[["45176.90","0"],["45177.30","2.080"],["45177.90","0.110"]],"u":20458967,"seq":114533093983},"cts":1704258146090}
{"topic":"orderbook.50.BTCUSDT","type":"delta","ts":1704258146111,"data":{"s":"BTCUSDT","b":[],"a":[["45172.70","0"],["45172.90","0.088"],["45177.30","0.133"],["45178.00","2.327"]],"u":20458968,"seq":114533094041},"cts":1704258146110}
{"topic":"orderbook.50.BTCUSDT","type":"delta","ts":1704258146132,"data":{"s":"BTCUSDT","b":[["45167.20","0.001"],["45163.00","0.147"]],"a":[["45172.50","0.011"],["45172.90","0.077"],["45174.70","0.125"],["45178.00","0"]],"u":20458969,"seq":114533094108},"cts":1704258146129}
{"topic":"orderbook.50.BTCUSDT","type":"delta","ts":1704258146151,"data":{"s":"BTCUSDT","b":[["45167.20","0"],["45167.00","0.007"],["45160.10","0.708"]],"a":[["45172.50","0"],["45172.90","0.088"],["45178.00","2.327"]],"u":20458970,"seq":114533094165},"cts":1704258146150}
{"topic":"orderbook.50.BTCUSDT","type":"delta","ts":1704258146171,"data":{"s":"BTCUSDT","b":[],"a":[["45178.00","0.380"]],"u":20458971,"seq":114533094232},"cts":1704258146170}
{"topic":"orderbook.50.BTCUSDT","type":"delta","ts":1704258146212,"data":{"s":"BTCUSDT","b":[],"a":[["45172.10","1.200"],["45172.90","0.077"],["45173.00","0.092"],["45178.00","0"]],"u":20458972,"seq":114533094325},"cts":1704258146210}
{"topic":"orderbook.50.BTCUSDT","type":"delta","ts":1704258146231,"data":{"s":"BTCUSDT","b":[],"a":[["45172.70","0.111"],["45174.30","2.307"],["45176.60","1.211"],["45177.90","0"]],"u":20458973,"seq":114533094394},"cts":1704258146228}
{"topic":"orderbook.50.BTCUSDT","type":"delta","ts":1704258146251,"data":{"s":"BTCUSDT","b":[],"a":[["45172.10","0"],["45176.20","0.235"],["45177.90","0.110"]],"u":20458974,"seq":114533094454},"cts":1704258146250}
{"topic":"orderbook.50.BTCUSDT","type":"delta","ts":1704258146271,"data":{"s":"BTCUSDT","b":[["45163.00","0.110"],["45162.70","1.653"]],"a":[["45174.50","0.041"],["45174.70","0.088"]],"u":20458975,"seq":114533094530},"cts":1704258146270}
{"topic":"orderbook.50.BTCUSDT","type":"delta","ts":1704258146292,"data":{"s":"BTCUSDT","b":[["45162.70","1.616"]],"a":[["45174.50","0.004"]],"u":20458976,"seq":114533094590},"cts":1704258146287}
{"topic":"orderbook.50.BTCUSDT","type":"delta","ts":1704258146311,"data":{"s":"BTCUSDT","b":[],"a":[["45173.00","0.081"],["45173.40","0.011"],["45177.90","0"]],"u":20458977,"seq":114533094647},"cts":1704258146310}
{"topic":"orderbook.50.BTCUSDT","type":"delta","ts":1704258146331,"data":{"s":"BTCUSDT","b":[],"a":[["45177.00","0.111"],["45177.20","3.983"]],"u":20458978,"seq":114533094699},"cts":1704258146330}
{"topic":"orderbook.50.BTCUSDT","type":"delta","ts":1704258146351,"data":{"s":"BTCUSDT","b":[["45162.90","0.222"],["45162.30","2.105"],["45162.10","0.111"],["45160.10","0"]],"a":[["45171.30","0.111"],["45171.60","0.111"],["45172.10","0.111"],["45173.40","0"],["45173.50","0.088"],["45174.60","0.111"],["45177.00","3.873"],["45177.20","0.221"],["45177.40","0"],["45177.70","0"],["45177.80","0"]],"u":20458979,"seq":114533094796},"cts":1704258146350}
{"topic":"orderbook.50.BTCUSDT","type":"delta","ts":1704258146371,"data":{"s":"BTCUSDT","b":[["45164.30","0"],["45164.10","0.018"],["45163.60","0.140"],["45160.20","0"]],"a":[],"u":20458980,"seq":114533094856},"cts":1704258146370}
{"topic":"orderbook.50.BTCUSDT","type":"delta","ts":1704258146391,"data":{"s":"BTCUSDT","b":[["45170.20","1.083"],["45163.30","0.037"],["45162.70","0.111"],["45160.30","0"]],"a":[["45175.00","0.170"]],"u":20458981,"seq":114533094972},"cts":1704258146390}
{"topic":"orderbook.50.BTCUSDT","type":"delta","ts":1704258146412,"data":{"s":"BTCUSDT","b":[["45163.30","0"],["45160.30","1.014"]],"a":[["45175.00","0.133"],["45177.00","0.111"]],"u":20458982,"seq":114533095057},"cts":1704258146410}
{"topic":"orderbook.50.BTCUSDT","type":"delta","ts":1704258146432,"data":{"s":"BTCUSDT","b":[],"a":[["45170.30","6.775"],["45173.40","0.011"],["45173.50","0.077"],["45177.00","3.873"],["45177.30","0"]],"u":20458983,"seq":114533095123},"cts":1704258146430}
{"topic":"orderbook.50.BTCUSDT","type":"delta","ts":1704258146472,"data":{"s":"BTCUSDT","b":[["45161.30","0.166"]],"a":[],"u":20458984,"seq":114533095237},"cts":1704258146470}
{"topic":"orderbook.50.BTCUSDT","type":"delta","ts":1704258146492,"data":{"s":"BTCUSDT","b":[],"a":[["45177.00","0.111"]],"u":20458985,"seq":114533095296},"cts":1704258146489}
{"topic":"orderbook.50.BTCUSDT","type":"delta","ts":1704258146512,"data":{"s":"BTCUSDT","b":[["45163.50","0.201"]],"a":[["45173.00","0.092"],["45173.40","0"],["45174.30","2.345"],["45175.30","0.003"],["45177.30","0.133"]],"u":20458986,"seq":114533095365},"cts":1704258146510}
{"topic":"orderbook.50.BTCUSDT","type":"delta","ts":1704258146552,"data":{"s":"BTCUSDT","b":[],"a":[["45176.90","3.762"],["45177.30","0"]],"u":20458987,"seq":114533095476},"cts":1704258146549}
{"topic":"orderbook.50.BTCUSDT","type":"delta","ts":1704258146571,"data":{"s":"BTCUSDT","b":[["45170.20","1.082"],["45162.30","2.217"]],"a":[["45174.30","2.307"],["45177.10","0.804"]],"u":20458988,"seq":114533095540},"cts":1704258146570}
{"topic":"orderbook.50.BTCUSDT","type":"delta","ts":1704258146592,"data":{"s":"BTCUSDT","b":[],"a":[["45176.90","0"],["45177.30","0.133"]],"u":20458989,"seq":114533095606},"cts":1704258146590}
{"topic":"orderbook.50.BTCUSDT","type":"delta","ts":1704258146612,"data":{"s":"BTCUSDT","b":[],"a":[["45177.30","2.080"]],"u":20458990,"seq":114533095656},"cts":1704258146609}
{"topic":"orderbook.50.BTCUSDT","type":"delta","ts":1704258146651,"data":{"s":"BTCUSDT","b":[],"a":[["45175.50","0.038"],["45177.00","3.873"],["45177.30","0"]],"u":20458991,"seq":114533095770},"cts":1704258146649}
{"topic":"orderbook.50.BTCUSDT","type":"delta","ts":1704258146672,"data":{"s":"BTCUSDT","b":[],"a":[["45173.00","0.081"],["45173.40","0.011"],["45177.00","0.111"],["45177.20","0"]],"u":20458992,"seq":114533095832},"cts":1704258146670}
{"topic":"orderbook.50.BTCUSDT","type":"delta","ts":1704258146691,"data":{"s":"BTCUSDT","b":[],"a":[["45176.90","3.762"],["45177.10","0"]],"u":20458993,"seq":114533095890},"cts":1704258146690}
{"topic":"orderbook.50.BTCUSDT","type":"delta","ts":1704258146712,"data":{"s":"BTCUSDT","b":[],"a":[["45173.00","0.092"],["45173.40","0"],["45177.10","0.804"]],"u":20458994,"seq":114533095946},"cts":1704258146710}
{"topic":"orderbook.50.BTCUSDT","type":"delta","ts":1704258146732,"data":{"s":"BTCUSDT","b":[],"a":[["45173.00","0.081"],["45173.40","0.011"],["45176.60","1.200"],["45176.90","3.773"],["45177.10","0"]],"u":20458995,"seq":114533096010},"cts":1704258146729}
{"topic":"orderbook.50.BTCUSDT","type":"delta","ts":1704258146751,"data":{"s":"BTCUSDT","b":[],"a":[["45176.90","0.011"]],"u":20458996,"seq":114533096066},"cts":1704258146749}
{"topic":"orderbook.50.BTCUSDT","type":"delta","ts":1704258146772,"data":{"s":"BTCUSDT","b":[],"a":[["45176.90","3.773"]],"u":20458997,"seq":114533096120},"cts":1704258146769}
{"topic":"orderbook.50.BTCUSDT","type":"delta","ts":1704258146791,"data":{"s":"BTCUSDT","b":[["45163.10","0.207"]],"a":[],"u":20458998,"seq":114533096176},"cts":1704258146790}
{"topic":"orderbook.50.BTCUSDT","type":"delta","ts":1704258146812,"data":{"s":"BTCUSDT","b":[["45163.60","0.178"],["45163.50","0.163"]],"a":[["45172.30","0.102"],["45175.50","0"],["45175.70","0.149"],["45176.90","0"],["45177.00","3.873"],["45177.10","0.848"]],"u":20458999,"seq":114533096239},"cts":1704258146810}
{"topic":"orderbook.50.BTCUSDT","type":"delta","ts":1704258146891,"data":{"s":"BTCUSDT","b":[],"a":[["45177.00","0.111"]],"u":20459000,"seq":114533096440},"cts":1704258146889}
{"topic":"orderbook.50.BTCUSDT","type":"delta","ts":1704258146911,"data":{"s":"BTCUSDT","b":[],"a":[["45177.00","3.873"]],"u":20459001,"seq":114533096496},"cts":1704258146910}
{"topic":"orderbook.50.BTCUSDT","type":"delta","ts":1704258146932,"data":{"s":"BTCUSDT","b":[],"a":[["45175.60","0.038"],["45175.70","0.111"],["45177.10","0"]],"u":20459002,"seq":114533096548},"cts":1704258146929}
{"topic":"orderbook.50.BTCUSDT","type":"delta","ts":1704258146951,"data":{"s":"BTCUSDT","b":[["45168.00","0.115"]],"a":[["45176.80","0.011"],["45177.00","0"]],"u":20459003,"seq":114533096600},"cts":1704258146949}
{"topic":"orderbook.50.BTCUSDT","type":"delta","ts":1704258147032,"data":{"s":"BTCUSDT","b":[["45163.60","0.140"],["45163.50","0.201"]],"a":[["45175.60","0"],["45176.80","0"],["45176.90","3.773"],["45177.00","0.111"]],"u":20459004,"seq":114533096800},"cts":1704258147030}
{"topic":"orderbook.50.BTCUSDT","type":"delta","ts":1704258147052,"data":{"s":"BTCUSDT","b":[["45163.50","0.163"]],"a":[["45175.60","0.038"],["45176.70","0.365"],["45176.90","0.011"],["45177.00","0"]],"u":20459005,"seq":114533096854},"cts":1704258147049}
{"topic":"orderbook.50.BTCUSDT","type":"delta","ts":1704258147071,"data":{"s":"BTCUSDT","b":[],"a":[["45175.60","0"],["45176.90","3.773"],["45177.00","0.111"]],"u":20459006,"seq":114533096915},"cts":1704258147069}
{"topic":"orderbook.50.BTCUSDT","type":"delta","ts":1704258147111,"data":{"s":"BTCUSDT","b":[],"a":[["45176.90","3.762"]],"u":20459007,"seq":114533097023},"cts":1704258147110}
{"topic":"orderbook.50.BTCUSDT","type":"delta","ts":1704258147132,"data":{"s":"BTCUSDT","b":[],"a":[["45176.90","0"],["45177.10","0.848"]],"u":20459008,"seq":114533097088},"cts":1704258147129}
{"topic":"orderbook.50.BTCUSDT","type":"delta","ts":1704258147151,"data":{"s":"BTCUSDT","b":[["45170.20","1.080"],["45163.60","0.178"]],"a":[["45175.60","0.038"],["45176.10","0.011"],["45176.20","0.224"],["45177.00","0"],["45177.10","0"]],"u":20459009,"seq":114533097198},"cts":1704258147150}
{"topic":"orderbook.50.BTCUSDT","type":"delta","ts":1704258147252,"data":{"s":"BTCUSDT","b":[["45168.00","0.114"],["45164.10","0"],["45163.60","0.140"],["45162.30","2.105"],["45160.20","0.447"]],"a":[["45175.60","0"],["45176.60","1.211"],["45176.90","3.762"]],"u":20459010,"seq":114533097486},"cts":1704258147250}
{"topic":"orderbook.50.BTCUSDT","type":"delta","ts":1704258147272,"data":{"s":"BTCUSDT","b":[["45163.80","0.038"],["45160.20","0"]],"a":[["45175.80","0.042"]],"u":20459011,"seq":114533097557},"cts":1704258147270}
{"topic":"orderbook.50.BTCUSDT","type":"delta","ts":1704258147292,"data":{"s":"BTCUSDT","b":[],"a":[["45175.80","0.004"],["45176.90","0"],["45177.00","0.111"]],"u":20459012,"seq":114533097618},"cts":1704258147289}
{"topic":"orderbook.50.BTCUSDT","type":"delta","ts":1704258147332,"data":{"s":"BTCUSDT","b":[["45163.80","0"],["45160.20","0.447"]],"a":[["45176.90","3.762"],["45177.00","0"]],"u":20459013,"seq":114533097721},"cts":1704258147329}
{"topic":"orderbook.50.BTCUSDT","type":"delta","ts":1704258147391,"data":{"s":"BTCUSDT","b":[["45170.20","1.091"],["45170.00","0.221"]],"a":[["45171.00","0"],["45176.90","0"],["45177.00","0.111"],["45177.10","0.847"]],"u":20459014,"seq":114533097892},"cts":1704258147390}
{"topic":"orderbook.50.BTCUSDT","type":"delta","ts":1704258147432,"data":{"s":"BTCUSDT","b":[["45164.00","0.152"],["45163.90","0.004"]],"a":[["45175.90","0.038"],["45176.90","3.762"],["45177.00","0"],["45177.10","0"]],"u":20459015,"seq":114533098011},"cts":1704258147429}
{"topic":"orderbook.50.BTCUSDT","type":"delta","ts":1704258147451,"data":{"s":"BTCUSDT","b":[["45164.00","0.114"]],"a":[["45176.10","0"],["45176.20","0.235"],["45177.00","0.111"]],"u":20459016,"seq":114533098074},"cts":1704258147449}
{"topic":"orderbook.50.BTCUSDT","type":"delta","ts":1704258147472,"data":{"s":"BTCUSDT","b":[],"a":[["45176.90","0"],["45177.10","0.847"]],"u":20459017,"seq":114533098132},"cts":1704258147470}
{"topic":"orderbook.50.BTCUSDT","type":"delta","ts":1704258147492,"data":{"s":"BTCUSDT","b":[],"a":[["45176.90","3.762"],["45177.10","0"]],"u":20459018,"seq":114533098202},"cts":1704258147490}
{"topic":"orderbook.50.BTCUSDT","type":"delta","ts":1704258147511,"data":{"s":"BTCUSDT","b":[["45170.00","0.108"]],"a":[],"u":20459019,"seq":114533098257},"cts":1704258147510}
{"topic":"orderbook.50.BTCUSDT","type":"delta","ts":1704258147532,"data":{"s":"BTCUSDT","b":[],"a":[["45175.90","0"],["45177.10","0.847"]],"u":20459020,"seq":114533098318},"cts":1704258147528}
{"topic":"orderbook.50.BTCUSDT","type":"delta","ts":1704258147551,"data":{"s":"BTCUSDT","b":[["45163.70","0.038"],["45160.20","0"]],"a":[["45175.60","0.038"],["45177.10","0"]],"u":20459021,"seq":114533098387},"cts":1704258147550}
{"topic":"orderbook.50.BTCUSDT","type":"delta","ts":1704258147611,"data":{"s":"BTCUSDT","b":[],"a":[["45171.50","0.200"]],"u":20459022,"seq":114533098550},"cts":1704258147610}
{"topic":"orderbook.50.BTCUSDT","type":"delta","ts":1704258147632,"data":{"s":"BTCUSDT","b":[],"a":[["45175.60","0"],["45177.10","0.847"]],"u":20459023,"seq":114533098603},"cts":1704258147630}
{"topic":"orderbook.50.BTCUSDT","type":"delta","ts":1704258147672,"data":{"s":"BTCUSDT","b":[],"a":[["45175.50","0.038"],["45177.10","0"]],"u":20459024,"seq":114533098706},"cts":1704258147670}
{"topic":"orderbook.50.BTCUSDT","type":"delta","ts":1704258147751,"data":{"s":"BTCUSDT","b":[["45161.20","0.544"],["45160.30","0"]],"a":[],"u":20459025,"seq":114533098878},"cts":1704258147750}
{"topic":"orderbook.50.BTCUSDT","type":"delta","ts":1704258147811,"data":{"s":"BTCUSDT","b":[["45162.50","0.190"]],"a":[],"u":20459026,"seq":114533099020},"cts":1704258147809}
{"topic":"orderbook.50.BTCUSDT","type":"delta","ts":1704258147851,"data":{"s":"BTCUSDT","b":[["45160.50","0"],["45160.30","1.014"]],"a":[["45171.40","0.112"],["45172.10","0.223"],["45176.20","3.997"],["45176.90","0"]],"u":20459027,"seq":114533099137},"cts":1704258147850}
{"topic":"orderbook.50.BTCUSDT","type":"delta","ts":1704258147872,"data":{"s":"BTCUSDT","b":[["45168.00","0.001"],["45162.30","2.217"]],"a":[["45170.30","7.975"],["45176.10","3.762"],["45176.20","0.235"],["45177.00","0"]],"u":20459028,"seq":114533099208},"cts":1704258147870}
{"topic":"orderbook.50.BTCUSDT","type":"delta","ts":1704258147891,"data":{"s":"BTCUSDT","b":[["45168.60","0"],["45166.30","0.191"],["45162.30","2.105"],["45160.20","0.447"]],"a":[["45170.90","0.112"],["45171.40","0.312"],["45171.50","0"],["45175.80","0.026"],["45176.30","1.781"]],"u":20459029,"seq":114533099288},"cts":1704258147890}
{"topic":"orderbook.50.BTCUSDT","type":"delta","ts":1704258147912,"data":{"s":"BTCUSDT","b":[["45166.10","0"],["45163.70","0"],["45163.50","0.038"],["45160.10","0.708"],["45160.00","0.979"]],"a":[["45170.30","9.734"],["45173.40","1.947"],["45174.50","0"],["45175.30","0.041"],["45175.50","0"],["45176.10","0"],["45176.30","1.785"],["45176.80","0.022"],["45176.90","0.022"],["45177.00","0.111"]],"u":20459030,"seq":114533099395},"cts":1704258147910}
{"topic":"orderbook.50.BTCUSDT","type":"delta","ts":1704258147932,"data":{"s":"BTCUSDT","b":[["45163.50","0"],["45159.90","0.897"]],"a":[["45171.70","0.012"],["45172.90","3.839"],["45175.30","0.003"]],"u":20459031,"seq":114533099501},"cts":1704258147929}
{"topic":"orderbook.50.BTCUSDT","type":"delta","ts":1704258147951,"data":{"s":"BTCUSDT","b":[],"a":[["45171.20","0.011"],["45171.70","0.001"],["45172.50","3.762"],["45172.90","0.077"],["45173.40","0"],["45177.00","0"]],"u":20459032,"seq":114533099592},"cts":1704258147949}
{"topic":"orderbook.50.BTCUSDT","type":"delta","ts":1704258147972,"data":{"s":"BTCUSDT","b":[["45162.90","0.333"],["45161.20","0"],["45159.80","0.266"]],"a":[["45171.20","0"],["45173.40","1.947"]],"u":20459033,"seq":114533099658},"cts":1704258147969}
{"topic":"orderbook.50.BTCUSDT","type":"delta","ts":1704258147992,"data":{"s":"BTCUSDT","b":[],"a":[["45171.70","0.012"],["45172.50","0"],["45177.00","0.111"]],"u":20459034,"seq":114533099729},"cts":1704258147990}
{"topic":"orderbook.50.BTCUSDT","type":"delta","ts":1704258148011,"data":{"s":"BTCUSDT","b":[["45162.50","0.227"]],"a":[["45171.70","0.001"],["45173.00","0.092"],["45173.40","0"],["45174.90","0.115"],["45176.10","5.720"],["45176.20","0.224"]],"u":20459035,"seq":114533099795},"cts":1704258148010}
{"topic":"orderbook.50.BTCUSDT","type":"delta","ts":1704258148031,"data":{"s":"BTCUSDT","b":[["45162.50","0.190"]],"a":[["45173.00","0.081"],["45174.90","0.078"],["45175.60","0.011"],["45176.10","0.011"],["45176.70","4.127"],["45177.00","0"]],"u":20459036,"seq":114533099871},"cts":1704258148029}
{"topic":"orderbook.50.BTCUSDT","type":"delta","ts":1704258148051,"data":{"s":"BTCUSDT","b":[],"a":[["45175.30","0.014"],["45175.60","0"],["45175.90","3.762"],["45176.70","0.365"],["45176.80","1.969"]],"u":20459037,"seq":114533099936},"cts":1704258148049}
{"topic":"orderbook.50.BTCUSDT","type":"delta","ts":1704258148072,"data":{"s":"BTCUSDT","b":[["45164.30","0.018"],["45159.80","0"]],"a":[["45175.30","0.003"],["45175.60","0.011"],["45175.90","0"],["45176.80","0.022"],["45176.90","1.969"]],"u":20459038,"seq":114533099997},"cts":1704258148069}
{"topic":"orderbook.50.BTCUSDT","type":"delta","ts":1704258148091,"data":{"s":"BTCUSDT","b":[["45169.70","0.001"],["45169.60","0.001"],["45169.50","0.001"],["45168.50","0.026"],["45168.40","0.001"],["45168.30","0.001"],["45164.30","0.097"],["45160.30","0"],["45160.20","0"],["45160.10","0"],["45160.00","0"],["45159.90","0"]],"a":[["45173.00","0.092"],["45175.60","0"],["45176.10","3.762"],["45176.70","2.312"],["45176.90","0.022"],["45177.00","0.111"]],"u":20459039,"seq":114533100077},"cts":1704258148089}
{"topic":"orderbook.50.BTCUSDT","type":"delta","ts":1704258148112,"data":{"s":"BTCUSDT","b":[],"a":[["45173.00","0.081"],["45173.40","0.011"],["45176.70","0.365"],["45177.00","0"]],"u":20459040,"seq":114533100144},"cts":1704258148110}
{"topic":"orderbook.50.BTCUSDT","type":"delta","ts":1704258148131,"data":{"s":"BTCUSDT","b":[["45169.70","0"],["45169.50","0"],["45168.50","0.025"],["45168.40","0"],["45168.30","0"],["45162.70","0.148"],["45160.30","1.014"],["45160.20","0.447"],["45160.10","0.708"],["45160.00","0.979"]],"a":[["45170.30","9.733"],["45175.10","0.585"],["45175.90","3.762"],["45176.10","0"],["45176.20","2.171"]],"u":20459041,"seq":114533100220},"cts":1704258148130}
{"topic":"orderbook.50.BTCUSDT","type":"delta","ts":1704258148152,"data":{"s":"BTCUSDT","b":[["45169.60","0"],["45168.70","0"],["45168.60","0.001"],["45159.90","0.897"]],"a":[["45176.20","0.224"]],"u":20459042,"seq":114533100308},"cts":1704258148148}
{"topic":"orderbook.50.BTCUSDT","type":"delta","ts":1704258148171,"data":{"s":"BTCUSDT","b":[],"a":[["45175.30","0.025"],["45176.70","0.343"]],"u":20459043,"seq":114533100359},"cts":1704258148169}
{"topic":"orderbook.50.BTCUSDT","type":"delta","ts":1704258148192,"data":{"s":"BTCUSDT","b":[["45166.80","0.131"],["45166.30","0"],["45165.60","0"],["45163.80","0.078"]],"a":[["45172.50","0.078"],["45174.20","0"],["45175.90","0"],["45176.00","3.876"],["45177.00","0.111"]],"u":20459044,"seq":114533100424},"cts":1704258148190}
{"topic":"orderbook.50.BTCUSDT","type":"delta","ts":1704258148212,"data":{"s":"BTCUSDT","b":[["45162.70","0.111"]],"a":[["45175.10","0.548"],["45177.00","2.058"]],"u":20459045,"seq":114533100488},"cts":1704258148210}
{"topic":"orderbook.50.BTCUSDT","type":"delta","ts":1704258148232,"data":{"s":"BTCUSDT","b":[["45162.50","0.227"]],"a":[["45175.30","0.062"],["45176.10","0.011"],["45177.00","0"]],"u":20459046,"seq":114533100550},"cts":1704258148229}
{"topic":"orderbook.50.BTCUSDT","type":"delta","ts":1704258148251,"data":{"s":"BTCUSDT","b":[["45162.50","0.190"]],"a":[["45175.30","0.025"],["45176.00","0.114"],["45176.10","3.773"]],"u":20459047,"seq":114533100613},"cts":1704258148250}
{"topic":"orderbook.50.BTCUSDT","type":"delta","ts":1704258148272,"data":{"s":"BTCUSDT","b":[],"a":[["45176.10","0.011"]],"u":20459048,"seq":114533100676},"cts":1704258148270}
{"topic":"orderbook.50.BTCUSDT","type":"delta","ts":1704258148292,"data":{"s":"BTCUSDT","b":[["45170.20","0.684"],["45168.00","0.114"]],"a":[["45173.40","0"],["45173.50","0.088"],["45176.10","3.773"],["45177.00","0.111"]],"u":20459049,"seq":114533100737},"cts":1704258148290}
{"topic":"orderbook.50.BTCUSDT","type":"delta","ts":1704258148312,"data":{"s":"BTCUSDT","b":[["45170.20","1.104"],["45168.60","0.086"],["45166.80","0.071"]],"a":[["45173.50","0.077"],["45173.70","0.011"],["45176.10","0.011"],["45176.20","3.986"],["45177.00","0"]],"u":20459050,"seq":114533100874},"cts":1704258148309}
{"topic":"orderbook.50.BTCUSDT","type":"delta","ts":1704258148332,"data":{"s":"BTCUSDT","b":[],"a":[["45176.20","0.224"]],"u":20459051,"seq":114533100948},"cts":1704258148330}
{"topic":"orderbook.50.BTCUSDT","type":"delta","ts":1704258148352,"data":{"s":"BTCUSDT","b":[["45163.00","0.147"]],"a":[["45175.80","0.063"],["45176.70","4.105"]],"u":20459052,"seq":114533101005},"cts":1704258148349}
{"topic":"orderbook.50.BTCUSDT","type":"delta","ts":1704258148372,"data":{"s":"BTCUSDT","b":[["45170.20","1.106"]],"a":[["45176.70","0.343"]],"u":20459053,"seq":114533101071},"cts":1704258148370}
{"topic":"orderbook.50.BTCUSDT","type":"delta","ts":1704258148391,"data":{"s":"BTCUSDT","b":[["45168.60","0.001"],["45168.10","0.073"],["45159.90","0"]],"a":[],"u":20459054,"seq":114533101139},"cts":1704258148390}
{"topic":"orderbook.50.BTCUSDT","type":"delta","ts":1704258148411,"data":{"s":"BTCUSDT","b":[["45170.20","1.109"]],"a":[["45170.30","9.660"]],"u":20459055,"seq":114533101251},"cts":1704258148410}
{"topic":"orderbook.50.BTCUSDT","type":"delta","ts":1704258148431,"data":{"s":"BTCUSDT","b":[["45163.00","0.110"]],"a":[["45175.80","0.026"],["45176.70","4.105"]],"u":20459056,"seq":114533101335},"cts":1704258148430}
{"topic":"orderbook.50.BTCUSDT","type":"delta","ts":1704258148451,"data":{"s":"BTCUSDT","b":[],"a":[["45176.70","0.343"]],"u":20459057,"seq":114533101400},"cts":1704258148450}
{"topic":"orderbook.50.BTCUSDT","type":"delta","ts":1704258148471,"data":{"s":"BTCUSDT","b":[["45162.80","0.037"],["45160.00","0"]],"a":[["45173.50","0.088"],["45173.70","0"],["45175.60","0.037"],["45176.20","3.986"]],"u":20459058,"seq":114533101470},"cts":1704258148469}
{"topic":"orderbook.50.BTCUSDT","type":"delta","ts":1704258148512,"data":{"s":"BTCUSDT","b":[],"a":[["45176.90","1.969"]],"u":20459059,"seq":114533101574},"cts":1704258148509}
{"topic":"orderbook.50.BTCUSDT","type":"delta","ts":1704258148531,"data":{"s":"BTCUSDT","b":[["45162.80","0"],["45160.00","0.979"]],"a":[["45173.50","0.077"],["45173.70","0.011"],["45175.60","0"],["45176.90","0.022"]],"u":20459060,"seq":114533101644},"cts":1704258148530}
{"topic":"orderbook.50.BTCUSDT","type":"delta","ts":1704258148551,"data":{"s":"BTCUSDT","b":[],"a":[["45176.90","1.969"]],"u":20459061,"seq":114533101714},"cts":1704258148550}
{"topic":"orderbook.50.BTCUSDT","type":"delta","ts":1704258148571,"data":{"s":"BTCUSDT","b":[["45163.00","0.147"],["45162.30","2.217"]],"a":[["45175.90","0.037"],["45176.20","0.224"],["45176.70","4.105"],["45176.90","0"]],"u":20459062,"seq":114533101785},"cts":1704258148569}
{"topic":"orderbook.50.BTCUSDT","type":"delta","ts":1704258148632,"data":{"s":"BTCUSDT","b":[["45163.00","0.110"]],"a":[["45175.90","0"],["45176.90","0.022"]],"u":20459063,"seq":114533101947},"cts":1704258148630}
{"topic":"orderbook.50.BTCUSDT","type":"delta","ts":1704258148652,"data":{"s":"BTCUSDT","b":[["45169.70","0.001"],["45169.60","0.001"],["45169.50","0.001"],["45169.30","0.001"],["45168.40","0.001"],["45168.30","0.001"],["45168.20","0.001"],["45160.90","0"],["45160.80","0"],["45160.40","0"],["45160.30","0"],["45160.20","0"],["45160.10","0"],["45160.00","0"]],"a":[["45176.70","0.343"]],"u":20459064,"seq":114533102009},"cts":1704258148650}
{"topic":"orderbook.50.BTCUSDT","type":"delta","ts":1704258148672,"data":{"s":"BTCUSDT","b":[["45169.70","0"],["45169.60","0"],["45169.50","0"],["45168.40","0"],["45168.30","0"],["45160.90","0.447"],["45160.80","0.428"],["45160.40","1.671"],["45160.30","1.014"],["45160.20","0.447"]],"a":[["45176.70","4.105"]],"u":20459065,"seq":114533102077},"cts":1704258148670}
{"topic":"orderbook.50.BTCUSDT","type":"delta","ts":1704258148691,"data":{"s":"BTCUSDT","b":[["45169.30","0"],["45168.20","0"],["45163.00","0.147"],["45160.10","0.708"],["45160.00","0.979"]],"a":[["45175.80","0.063"]],"u":20459066,"seq":114533102133},"cts":1704258148690}
{"topic":"orderbook.50.BTCUSDT","type":"delta","ts":1704258148731,"data":{"s":"BTCUSDT","b":[["45163.00","0.110"]],"a":[["45175.80","0.026"],["45176.70","0.343"]],"u":20459067,"seq":114533102238},"cts":1704258148730}
{"topic":"orderbook.50.BTCUSDT","type":"delta","ts":1704258148752,"data":{"s":"BTCUSDT","b":[],"a":[["45176.80","3.784"]],"u":20459068,"seq":114533102295},"cts":1704258148750}
{"topic":"orderbook.50.BTCUSDT","type":"delta","ts":1704258148811,"data":{"s":"BTCUSDT","b":[["45162.90","0.370"]],"a":[["45175.70","0.148"],["45176.80","0.022"]],"u":20459069,"seq":114533102447},"cts":1704258148810}
{"topic":"orderbook.50.BTCUSDT","type":"delta","ts":1704258148831,"data":{"s":"BTCUSDT","b":[["45163.60","0.212"]],"a":[["45175.40","1.703"],["45176.80","3.784"]],"u":20459070,"seq":114533102514},"cts":1704258148829}
{"topic":"orderbook.50.BTCUSDT","type":"delta","ts":1704258148872,"data":{"s":"BTCUSDT","b":[["45168.10","0"],["45168.00","0.001"],["45166.90","0"],["45166.80","0"],["45166.70","0"],["45165.10","0"],["45164.90","0"],["45164.30","0"],["45164.20","0"],["45163.90","0"],["45163.00","0"],["45162.90","0.259"],["45162.50","0.124"],["45162.30","2.105"],["45162.20","0"],["45161.60","0"],["45161.40","0"],["45161.10","1.658"],["45161.00","1.768"],["45160.90","0"],["45160.40","1.675"],["45160.30","0"],["45160.20","0"],["45160.10","0.442"],["45160.00","0.492"],["45159.90","0.011"],["45159.50","2.158"],["45159.20","0.553"],["45159.10","0.221"],["45159.00","0.143"],["45158.90","0.044"],["45158.70","0.001"],["45158.60","0.840"],["45158.50","1.200"],["45158.40","0.706"],["45158.30","0.004"],["45158.10","0.111"],["45158.00","0.113"],["45157.90","1.148"],["45157.60","0.111"],["45157.50","0.122"]],"a":[["45170.30","11.318"],["45170.70","0.044"],["45171.80","1.900"],["45172.10","0.289"],["45172.80","0.628"],["45173.50","0.081"],["45173.70","0.015"],["45173.90","1.760"],["45174.70","0.044"],["45175.00","0.111"],["45175.10","0"],["45175.80","0.022"],["45176.30","1.781"],["45176.50","0"],["45177.00","0.111"]],"u":20459071,"seq":114533102727},"cts":1704258148870}
{"topic":"orderbook.50.BTCUSDT","type":"delta","ts":1704258148892,"data":{"s":"BTCUSDT","b":[["45166.00","0.001"],["45165.50","0"],["45162.60","1.271"],["45162.40","0"],["45161.80","0"],["45161.70","0.008"],["45158.50","0"],["45157.40","0.088"],["45157.20","2.153"],["45157.10","0.176"]],"a":[["45170.70","0"],["45171.90","0.231"],["45172.40","0.044"],["45173.20","0.022"],["45173.60","0.152"],["45173.90","1.738"],["45174.10","1.916"],["45175.70","0.037"],["45177.00","0"]],"u":20459072,"seq":114533102831},"cts":1704258148890}
{"topic":"orderbook.50.BTCUSDT","type":"delta","ts":1704258148912,"data":{"s":"BTCUSDT","b":[["45168.00","0.002"],["45167.00","0.005"],["45166.10","0.002"],["45166.00","0.114"],["45162.50","0.174"],["45159.30","1.658"],["45158.70","1.201"],["45157.20","0"],["45157.10","0"]],"a":[["45171.60","3.874"],["45171.70","0.605"],["45172.10","0.300"],["45172.70","0.155"],["45174.40","0"],["45174.70","0"],["45176.10","0.033"],["45176.30","1.803"],["45176.80","0.022"],["45177.00","0.111"],["45177.10","0.781"]],"u":20459073,"seq":114533102936},"cts":1704258148910}
{"topic":"orderbook.50.BTCUSDT","type":"delta","ts":1704258148931,"data":{"s":"BTCUSDT","b":[["45168.00","0.001"],["45166.10","0.082"],["45164.50","0"],["45163.80","0"],["45162.90","0.222"],["45161.00","1.658"],["45160.80","0"],["45160.60","0.421"],["45157.20","2.153"],["45157.10","0.176"]],"a":[["45170.30","11.766"],["45170.80","0.011"],["45171.50","3.763"],["45171.60","0.111"],["45171.70","0.001"],["45171.90","0.155"],["45172.10","0.289"],["45172.50","3.052"],["45175.70","0"],["45175.90","0.011"],["45177.00","0"],["45177.10","0"]],"u":20459074,"seq":114533103083},"cts":1704258148930}
{"topic":"orderbook.50.BTCUSDT","type":"delta","ts":1704258148952,"data":{"s":"BTCUSDT","b":[["45166.10","0.083"],["45163.60","0.140"],["45162.30","2.183"]],"a":[["45170.30","12.099"],["45171.50","0"],["45172.50","0.078"],["45173.40","1.947"],["45173.70","0.004"],["45175.20","0.011"],["45176.10","0.022"],["45176.90","0"]],"u":20459075,"seq":114533103210},"cts":1704258148950}
{"topic":"orderbook.50.BTCUSDT","type":"delta","ts":1704258148971,"data":{"s":"BTCUSDT","b":[["45168.50","0"],["45167.00","0.004"],["45159.00","0.111"],["45157.00","2.048"]],"a":[["45170.40","0.453"],["45170.80","0"],["45171.60","0.554"],["45173.10","0.974"],["45173.40","3.762"],["45173.70","1.951"],["45175.90","2.974"],["45176.20","0.235"],["45176.90","0.022"]],"u":20459076,"seq":114533103297},"cts":1704258148969}
{"topic":"orderbook.50.BTCUSDT","type":"delta","ts":1704258148992,"data":{"s":"BTCUSDT","b":[["45160.70","0.076"],["45158.70","0.001"],["45157.70","0.438"],["45157.10","0"],["45157.00","0"]],"a":[["45171.20","0.011"],["45172.50","3.840"],["45173.40","1.947"],["45173.70","0.004"],["45175.40","1.725"],["45175.70","1.947"],["45175.90","0"],["45176.20","0.224"],["45176.90","0"]],"u":20459077,"seq":114533103390},"cts":1704258148990}
{"topic":"orderbook.50.BTCUSDT","type":"delta","ts":1704258149012,"data":{"s":"BTCUSDT","b":[["45165.50","0.079"],["45164.40","0"],["45163.20","0.047"],["45158.80","0.081"],["45157.40","0"],["45157.20","0"]],"a":[["45170.30","12.199"],["45171.70","0.605"],["45172.50","0.078"],["45173.40","0"],["45175.20","0"],["45175.70","0"],["45176.10","2.996"],["45176.20","0.235"],["45176.60","1.200"],["45176.90","0.022"],["45177.00","0.111"],["45177.10","0.781"]],"u":20459078,"seq":114533103484},"cts":1704258149010}
{"topic":"orderbook.50.BTCUSDT","type":"delta","ts":1704258149032,"data":{"s":"BTCUSDT","b":[["45166.10","0.118"]],"a":[["45175.20","1.947"],["45176.10","0.022"],["45176.20","2.171"],["45176.80","0.033"],["45177.10","0"]],"u":20459079,"seq":114533103566},"cts":1704258149030}
{"topic":"orderbook.50.BTCUSDT","type":"delta","ts":1704258149051,"data":{"s":"BTCUSDT","b":[["45166.20","0.007"],["45163.10","0.126"],["45162.30","2.105"],["45162.20","0.079"],["45161.80","0.111"],["45160.60","0"],["45159.40","0.559"],["45159.10","0.111"],["45157.60","0"],["45157.50","0"]],"a":[["45170.30","18.371"],["45171.30","0"],["45171.60","0.443"],["45171.80","1.944"],["45171.90","0"],["45172.10","0.178"],["45172.20","0"],["45172.80","0.650"],["45173.20","0"],["45173.80","0.130"],["45174.50","0.111"],["45174.60","0"],["45174.70","3.762"],["45175.20","0"],["45175.70","1.947"],["45176.10","0.033"],["45176.20","0.224"],["45176.80","0.022"],["45177.00","0.593"],["45177.10","0.781"],["45177.20","0.478"],["45177.30","0.111"]],"u":20459080,"seq":114533103751},"cts":1704258149050}
{"topic":"orderbook.50.BTCUSDT","type":"delta","ts":1704258149072,"data":{"s":"BTCUSDT","b":[["45168.60","0"],["45167.00","0.002"],["45166.20","0.010"],["45157.90","0.451"],["45157.60","0.111"]],"a":[["45170.70","0.078"],["45170.80","0.011"],["45170.90","0.312"],["45171.00","0.111"],["45171.20","0"],["45171.40","0.112"],["45171.50","3.839"],["45171.70","0.649"],["45171.80","1.900"],["45172.30","2.049"],["45172.50","0"],["45172.70","0.044"],["45173.30","0.040"],["45173.60","0.112"],["45173.90","1.658"],["45174.70","0"],["45175.30","1.972"],["45175.70","0"],["45175.90","2.974"],["45176.10","0.022"],["45176.40","1.542"],["45177.20","0"],["45177.30","0"]],"u":20459081,"seq":114533103878},"cts":1704258149070}
{"topic":"orderbook.50.BTCUSDT","type":"delta","ts":1704258149092,"data":{"s":"BTCUSDT","b":[["45167.00","0"],["45166.20","0.011"],["45157.50","0.122"]],"a":[["45171.30","3.763"],["45171.50","0.076"],["45175.30","0.025"],["45175.90","0.011"],["45177.10","0"]],"u":20459082,"seq":114533103963},"cts":1704258149089}
{"topic":"orderbook.50.BTCUSDT","type":"delta","ts":1704258149112,"data":{"s":"BTCUSDT","b":[["45170.20","0"],["45170.10","0"],["45170.00","0"],["45169.80","0"],["45158.60","0.389"],["45157.40","0.088"],["45157.20","2.153"],["45157.10","0.066"],["45157.00","2.048"]],"a":[["45168.10","2.986"],["45169.20","0.300"],["45169.90","6.033"],["45170.00","0.100"],["45170.10","9.284"],["45170.20","27.859"],["45170.30","18.015"],["45172.30","0.102"],["45172.40","1.991"],["45173.70","1.951"],["45174.50","0.122"],["45175.20","2.985"],["45175.30","0.047"],["45175.90","0"],["45176.40","0"],["45176.60","0"],["45176.70","0"],["45176.80","0"],["45176.90","0"],["45177.00","0"]],"u":20459083,"seq":114533104203},"cts":1704258149109}
{"topic":"orderbook.50.BTCUSDT","type":"delta","ts":1704258149132,"data":{"s":"BTCUSDT","b":[["45168.00","0"],["45166.20","0"],["45166.10","0.306"],["45166.00","0.001"],["45163.00","0.076"],["45162.30","2.187"],["45161.10","1.734"],["45160.40","1.671"],["45159.10","0"],["45159.00","0"],["45158.80","0.004"],["45158.60","0.111"],["45158.30","0"],["45157.90","0"],["45157.60","0"],["45157.50","0.011"],["45157.10","0.044"],["45156.90","0.022"],["45156.80","1.681"],["45156.70","0.666"],["45156.60","0.487"],["45156.50","0.894"],["45156.40","0.161"]],"a":[["45166.20","19.008"],["45166.30","1.505"],["45168.00","6.111"],["45168.10","8.664"],["45169.20","0.344"],["45169.90","2.084"],["45170.00","0.313"],["45170.10","1.870"],["45170.20","9.603"],["45170.30","3.017"],["45170.40","0.443"],["45170.90","0.112"],["45171.20","3.763"],["45171.30","0"],["45171.50","2.023"],["45171.70","0.413"],["45171.80","0.344"],["45172.10","0.200"],["45172.40","0"],["45172.70","0.110"],["45172.80","0.628"],["45172.90","0.099"],["45173.10","0.966"],["45173.20","0.062"],["45173.30","0"],["45173.50","0.077"],["45173.80","1.635"],["45174.10","0.219"],["45174.20","0.177"],["45174.70","1.330"],["45175.00","0.232"],["45175.20","0"],["45175.30","0.069"],["45175.50","0.111"],["45175.80","0.278"],["45176.00","0"],["45176.10","0"],["45176.20","0"],["45176.30","0"]],"u":20459084,"seq":114533105058},"cts":1704258149129}
{"topic":"orderbook.50.BTCUSDT","type":"delta","ts":1704258149152,"data":{"s":"BTCUSDT","b":[["45165.50","0"],["45165.40","0"],["45163.20","1.647"],["45162.20","0"],["45161.10","1.658"],["45160.70","0.113"],["45159.70","0.127"],["45159.60","0.082"],["45158.90","0"],["45158.10","0"],["45157.30","1.299"],["45157.20","2.109"],["45157.00","0.001"],["45156.80","1.659"],["45156.70","0.444"],["45156.60","0.443"],["45156.50","0.938"],["45156.30","0.459"],["45156.20","0.004"]],"a":[["45166.20","16.819"],["45166.30","0.076"],["45167.90","0.604"],["45168.00","1.813"],["45168.10","5.649"],["45169.00","0.126"],["45169.90","2.028"],["45170.00","0.213"],["45170.10","2.649"],["45170.20","8.003"],["45170.30","2.972"],["45170.80","0"],["45171.00","0.022"],["45171.20","0"],["45171.50","0.076"],["45171.70","2.052"],["45171.90","0.022"],["45172.10","0.178"],["45172.20","0.011"],["45172.70","0.044"],["45172.80","0.783"],["45173.10","1.099"],["45173.40","3.762"],["45173.60","0.260"],["45173.70","0.026"],["45173.90","2.679"],["45174.20","0.066"],["45174.40","0.022"],["45174.50","0.344"],["45174.70","1.197"],["45174.90","0"],["45175.00","0.121"],["45175.10","0.111"],["45175.30","0"],["45175.40","0"],["45175.50","0"],["45175.80","0"]],"u":20459085,"seq":114533105476},"cts":1704258149150}
{"topic":"orderbook.50.BTCUSDT","type":"delta","ts":1704258149172,"data":{"s":"BTCUSDT","b":[["45163.60","0.975"],["45157.40","0.066"]],"a":[["45170.10","0.386"],["45170.20","3.431"],["45170.30","3.083"],["45171.00","0"],["45171.70","2.453"],["45171.90","0"],["45172.20","0"],["45173.10","1.077"],["45173.20","0.073"],["45173.40","0.011"],["45174.10","0.108"],["45174.70","1.219"],["45174.80","1.972"],["45175.30","0.680"],["45175.40","1.725"],["45175.70","0.243"]],"u":20459086,"seq":114533105639},"cts":1704258149170}
{"topic":"orderbook.50.BTCUSDT","type":"delta","ts":1704258149191,"data":{"s":"BTCUSDT","b":[["45166.10","0.003"],["45166.00","0.011"],["45160.70","0.076"],["45159.40","0"],["45159.30","2.278"],["45158.60","0.389"],["45157.20","1.658"],["45157.10","0"],["45156.10","0.443"],["45156.00","0.558"]],"a":[["45166.30","0.086"],["45167.90","0.804"],["45168.00","1.713"],["45169.80","0.166"],["45169.90","1.928"],["45170.10","0.186"],["45170.20","3.331"],["45170.30","2.972"],["45170.50","0.111"],["45170.80","0.111"],["45171.80","0.300"],["45171.90","0.066"],["45172.50","0.111"],["45172.60","1.311"],["45173.50","3.839"],["45173.60","0.223"],["45175.00","0"],["45175.10","0"],["45175.30","0"],["45175.40","0"],["45175.70","0"]],"u":20459087,"seq":114533105813},"cts":1704258149190}
{"topic":"orderbook.50.BTCUSDT","type":"delta","ts":1704258149211,"data":{"s":"BTCUSDT","b":[["45163.20","0.047"],["45160.10","0"],["45159.50","1.658"],["45157.70","0"],["45156.90","0"],["45156.50","0.487"],["45155.90","0.999"],["45155.80","1.204"],["45155.70","0.774"]],"a":[["45170.00","0.113"],["45170.10","0.152"],["45170.20","3.231"],["45173.20","0.022"],["45173.30","0.040"],["45173.50","0.077"],["45174.20","0.022"],["45174.80","0"]],"u":20459088,"seq":114533105995},"cts":1704258149210}
{"topic":"orderbook.50.BTCUSDT","type":"delta","ts":1704258149232,"data":{"s":"BTCUSDT","b":[["45164.00","0.001"],["45163.60","0.272"],["45163.10","0"],["45162.90","0"],["45162.70","0"],["45162.50","0.050"],["45162.30","2.076"],["45162.10","0"],["45161.80","0"],["45160.40","0.078"],["45160.10","1.375"],["45160.00","0.381"],["45159.30","1.658"],["45159.20","0.111"],["45158.60","0"],["45158.40","0"],["45157.00","0.542"],["45156.70","0.001"],["45156.60","0"],["45156.50","0.044"],["45156.40","0.051"],["45156.30","0.016"],["45156.20","0"],["45156.10","0"],["45156.00","0.115"],["45155.90","0.004"],["45155.80","0.731"],["45155.70","0"],["45155.60","0.567"],["45155.40","0.438"],["45155.20","0.088"],["45155.10","0.066"],["45155.00","1.469"],["45154.80","0.533"],["45154.70","0.109"],["45154.60","0.697"],["45154.50","0.173"],["45154.40","0.464"]],"a":[["45168.10","5.548"],["45169.20","0.422"],["45170.30","2.960"],["45170.70","0.004"],["45171.00","0.117"],["45171.50","0.044"],["45171.90","0.040"],["45172.90","0.022"],["45173.00","0"],["45173.30","0"],["45173.50","0"],["45173.70","0.022"],["45173.90","2.701"],["45174.50","0.222"],["45174.70","1.553"],["45174.80","0.025"],["45175.00","0.707"]],"u":20459089,"seq":114533106276},"cts":1704258149230}
{"topic":"orderbook.50.BTCUSDT","type":"delta","ts":1704258149252,"data":{"s":"BTCUSDT","b":[["45163.60","0.083"],["45163.20","0"],["45163.00","0"],["45160.10","0.995"],["45158.80","0.041"],["45158.60","0.111"],["45154.70","0"],["45154.60","0"],["45154.30","0.133"],["45154.10","1.869"],["45154.00","0.064"]],"a":[["45166.20","21.391"],["45167.70","0.078"],["45168.10","5.518"],["45169.20","0.344"],["45169.90","1.118"],["45170.10","0"],["45170.20","2.421"],["45170.40","0.487"],["45171.50","0"],["45171.70","2.490"],["45171.80","0.340"],["45171.90","0.115"],["45173.40","0"],["45173.60","0.931"],["45175.00","3.772"],["45175.10","0.111"],["45175.20","1.947"]],"u":20459090,"seq":114533106438},"cts":1704258149250}
{"topic":"orderbook.50.BTCUSDT","type":"delta","ts":1704258149272,"data":{"s":"BTCUSDT","b":[["45163.60","0"],["45162.60","0"],["45162.30","0.082"],["45161.40","2.136"],["45160.40","0"],["45160.10","0.069"],["45160.00","0.457"],["45159.80","0.079"],["45158.80","0.004"],["45155.70","0.022"],["45154.10","1.418"]],"a":[["45166.20","21.480"],["45173.60","0.920"],["45174.60","1.947"],["45175.00","0.010"],["45175.20","0"]],"u":20459091,"seq":114533106552},"cts":1704258149270}
{"topic":"orderbook.50.BTCUSDT","type":"delta","ts":1704258149291,"data":{"s":"BTCUSDT","b":[["45159.30","0"],["45158.60","0"],["45158.50","0.078"],["45155.40","2.432"],["45155.00","0.002"],["45154.60","0.856"]],"a":[["45168.60","0.044"],["45169.70","0.044"],["45170.20","2.498"],["45170.30","2.916"],["45170.40","0.443"],["45170.60","0.022"],["45170.70","0.098"],["45171.20","0.040"],["45171.70","2.453"],["45171.80","0.300"],["45172.80","0.739"],["45173.10","3.024"],["45173.80","1.505"],["45173.90","2.679"],["45174.00","1.793"],["45174.60","0"],["45174.80","0"],["45175.00","0"],["45175.10","0"]],"u":20459092,"seq":114533106680},"cts":1704258149290}
{"topic":"orderbook.50.BTCUSDT","type":"delta","ts":1704258149311,"data":{"s":"BTCUSDT","b":[["45155.90","1.463"],["45154.60","0"],["45153.90","0.855"]],"a":[["45172.70","0.055"],["45172.90","3.784"],["45173.00","1.947"],["45173.10","1.077"],["45174.70","0"]],"u":20459093,"seq":114533106774},"cts":1704258149310}
{"topic":"orderbook.50.BTCUSDT","type":"delta","ts":1704258149332,"data":{"s":"BTCUSDT","b":[["45158.60","0.111"],["45156.00","1.773"],["45153.90","0"]],"a":[["45171.50","0.080"],["45172.70","0.066"],["45172.90","0.022"],["45174.40","1.969"],["45174.50","0"]],"u":20459094,"seq":114533106861},"cts":1704258149330}
{"topic":"orderbook.50.BTCUSDT","type":"delta","ts":1704258149352,"data":{"s":"BTCUSDT","b":[["45162.30","0"],["45159.10","0.111"],["45158.90","0.111"],["45158.70","0.038"],["45156.80","1.770"],["45155.40","2.543"],["45154.00","0"]],"a":[["45166.20","22.608"],["45169.70","0.120"],["45170.50","0"],["45170.80","0"],["45171.40","0.223"],["45171.50","0.117"],["45172.50","0"],["45173.00","3.762"],["45173.50","1.947"],["45174.40","0.022"],["45174.50","0.222"],["45174.70","1.553"]],"u":20459095,"seq":114533106948},"cts":1704258149349}
{"topic":"orderbook.50.BTCUSDT","type":"delta","ts":1704258149371,"data":{"s":"BTCUSDT","b":[["45162.60","0.004"],["45160.20","0.047"],["45158.70","0.056"],["45155.30","0.266"],["45155.20","0.531"],["45155.10","0.775"],["45155.00","0.268"],["45154.50","0.439"],["45154.40","0"],["45154.30","0"],["45154.10","0"]],"a":[["45172.50","0.443"],["45172.70","0.044"],["45172.80","1.005"],["45173.20","0.288"],["45173.30","0.443"],["45173.40","0.709"],["45173.60","1.186"],["45174.40","0"],["45174.50","0"],["45174.70","0"]],"u":20459096,"seq":114533107040},"cts":1704258149370}
{"topic":"orderbook.50.BTCUSDT","type":"delta","ts":1704258149392,"data":{"s":"BTCUSDT","b":[["45162.60","0.005"],["45161.50","0.079"],["45161.00","0"],["45159.50","0"],["45159.40","0.500"],["45158.80","0"],["45158.70","0.019"],["45158.60","0"],["45158.10","0.033"],["45157.20","1.662"],["45155.80","0.113"],["45154.40","0.464"]],"a":[["45167.80","0.078"],["45168.50","0.080"],["45168.90","0.079"],["45169.10","0.124"],["45169.70","0.076"],["45169.90","1.140"],["45170.30","2.838"],["45170.60","0"],["45171.50","0"],["45171.60","0.454"],["45171.70","2.534"],["45173.00","0"],["45173.50","0"],["45174.20","0.067"],["45174.30","2.352"]],"u":20459097,"seq":114533107152},"cts":1704258149390}
{"topic":"orderbook.50.BTCUSDT","type":"delta","ts":1704258149411,"data":{"s":"BTCUSDT","b":[["45161.60","1.188"],["45161.40","0"],["45160.10","0.293"],["45159.90","0.087"],["45156.30","1.674"],["45155.10","2.433"]],"a":[["45166.20","22.622"],["45170.50","0.040"],["45171.20","0"],["45171.50","0.011"],["45172.80","6.714"],["45174.30","0"]],"u":20459098,"seq":114533107261},"cts":1704258149410}
{"topic":"orderbook.50.BTCUSDT","type":"delta","ts":1704258149432,"data":{"s":"BTCUSDT","b":[["45166.10","0.018"]],"a":[["45172.50","4.205"],["45172.80","1.005"],["45172.90","1.969"]],"u":20459099,"seq":114533107358},"cts":1704258149430}
{"topic":"orderbook.50.BTCUSDT","type":"delta","ts":1704258149451,"data":{"s":"BTCUSDT","b":[["45166.10","0"],["45166.00","0"],["45162.00","0.001"],["45159.40","0.630"],["45157.10","0.100"],["45155.90","1.459"],["45154.50","0.435"],["45154.30","0.133"]],"a":[["45164.10","15.078"],["45164.20","0.003"],["45165.40","0.271"],["45166.00","0.313"],["45166.10","8.126"],["45166.20","6.748"],["45166.30","0.054"],["45168.10","4.318"],["45169.20","0.300"],["45170.30","2.878"],["45170.50","0"],["45171.80","1.805"],["45172.30","0.172"],["45172.50","0.443"],["45172.80","0.877"],["45172.90","0.022"],["45173.50","1.947"],["45173.80","0"],["45173.90","0"],["45174.00","0"],["45174.10","0"],["45174.20","0"]],"u":20459100,"seq":114533107740},"cts":1704258149449}
{"topic":"orderbook.50.BTCUSDT","type":"delta","ts":1704258149472,"data":{"s":"BTCUSDT","b":[["45164.00","0"],["45162.60","0"],["45162.50","2.819"],["45160.70","0"],["45159.00","0.077"],["45158.40","0.037"],["45157.20","1.658"],["45157.10","0"],["45155.60","0.460"],["45155.20","0.487"],["45155.10","2.411"],["45154.80","0.267"],["45154.60","0.100"],["45154.30","0.111"],["45154.20","0.443"]],"a":[["45162.60","15.861"],["45162.70","1.878"],["45164.00","0.113"],["45164.10","4.068"],["45165.80","0.100"],["45166.00","0.113"],["45166.10","6.309"],["45166.20","3.577"],["45167.70","0.122"],["45167.80","0.122"],["45168.10","3.929"],["45168.40","0.115"],["45168.60","0"],["45169.00","0.170"],["45169.10","0.080"],["45169.50","0.022"],["45169.60","0.810"],["45169.80","0.188"],["45169.90","1.118"],["45170.10","0.111"],["45170.30","4.426"],["45170.70","0.205"],["45170.80","0.022"],["45171.00","0.272"],["45171.10","0.040"],["45171.40","0.245"],["45171.50","0.122"],["45171.70","2.667"],["45171.80","0.322"],["45172.10","0.200"],["45172.40","0.222"],["45172.60","1.200"],["45172.70","0.066"],["45172.80","0"],["45172.90","0"],["45173.10","0"],["45173.20","0"],["45173.30","0"],["45173.40","0"],["45173.50","0"],["45173.60","0"],["45173.70","0"]],"u":20459101,"seq":114533108343},"cts":1704258149469}
{"topic":"orderbook.50.BTCUSDT","type":"delta","ts":1704258149492,"data":{"s":"BTCUSDT","b":[["45162.50","1.219"],["45162.40","0.010"],["45161.60","0"],["45159.80","0"],["45159.40","0.130"],["45158.70","0.001"],["45158.60","0.110"],["45158.40","0"],["45155.80","0.002"],["45154.80","1.772"],["45154.60","0"],["45154.10","0.001"],["45154.00","0.062"]],"a":[["45162.60","10.968"],["45162.70","0.130"],["45164.00","0.513"],["45164.10","1.800"],["45165.80","0"],["45166.10","1.709"],["45166.20","2.853"],["45166.30","0.044"],["45167.90","0.604"],["45168.00","0.113"],["45168.10","2.741"],["45169.20","1.622"],["45169.50","0.121"],["45170.00","0.224"],["45170.30","4.474"],["45170.40","0.483"],["45170.60","0.022"],["45170.70","0.094"],["45170.80","0"],["45170.90","0.334"],["45171.00","0.139"],["45171.10","0.003"],["45171.30","0.111"],["45171.40","0.356"],["45171.50","0.022"],["45171.70","2.645"],["45171.80","0.300"],["45171.90","0.126"],["45172.10","0.178"],["45172.40","0"],["45172.80","0.766"]],"u":20459102,"seq":114533108769},"cts":1704258149490}
{"topic":"orderbook.50.BTCUSDT","type":"delta","ts":1704258149512,"data":{"s":"BTCUSDT","b":[["45161.60","0.854"],["45160.10","0.071"],["45158.10","0"],["45155.70","0"],["45154.00","0.061"],["45153.90","0.833"]],"a":[["45164.10","1.876"],["45164.70","0.112"],["45165.30","0.127"],["45166.10","1.509"],["45166.20","2.809"],["45168.10","4.787"],["45168.20","0.044"],["45168.50","0"],["45169.70","0"],["45170.30","5.092"],["45170.70","0.044"],["45171.20","0.022"],["45171.90","0.115"],["45172.20","3.762"],["45172.40","1.947"],["45172.50","0"],["45172.60","0"],["45172.70","0"],["45172.80","0"]],"u":20459103,"seq":114533108939},"cts":1704258149510}
{"topic":"orderbook.50.BTCUSDT","type":"delta","ts":1704258149531,"data":{"s":"BTCUSDT","b":[["45158.60","0.221"],["45157.00","0.001"],["45156.50","0.400"],["45153.90","0.612"]],"a":[["45162.60","10.099"],["45166.20","2.887"],["45167.70","0.044"],["45169.80","0.166"],["45170.30","5.132"],["45170.40","0.443"],["45171.30","0.122"],["45171.90","0.126"],["45172.00","3.875"],["45172.10","0.875"],["45172.20","0"],["45172.40","0"],["45172.50","0.443"],["45172.60","1.200"]],"u":20459104,"seq":114533109116},"cts":1704258149530}
{"topic":"orderbook.50.BTCUSDT","type":"delta","ts":1704258149552,"data":{"s":"BTCUSDT","b":[["45160.10","0.002"],["45160.00","0.381"],["45159.60","0"],["45159.50","0.139"]],"a":[["45162.70","0.140"],["45162.90","0.112"],["45164.00","0.313"],["45167.00","0.111"],["45167.30","0.111"],["45167.80","0.233"],["45170.30","5.243"],["45171.20","0.044"],["45171.50","1.680"],["45171.60","4.206"],["45172.00","0.113"],["45172.30","0"],["45172.50","0"],["45172.60","0"]],"u":20459105,"seq":114533109285},"cts":1704258149550}
{"topic":"orderbook.50.BTCUSDT","type":"delta","ts":1704258149572,"data":{"s":"BTCUSDT","b":[],"a":[["45166.10","1.475"],["45167.60","0.081"],["45171.60","0.443"],["45171.70","2.564"],["45172.10","0"]],"u":20459106,"seq":114533109394},"cts":1704258149570}
{"topic":"orderbook.50.BTCUSDT","type":"delta","ts":1704258149591,"data":{"s":"BTCUSDT","b":[["45157.60","0.076"],["45157.50","0.048"],["45153.90","0"]],"a":[["45166.10","0.559"],["45170.30","5.280"],["45171.20","3.807"],["45171.30","0.111"],["45171.40","2.303"],["45171.50","1.691"],["45171.90","0.115"]],"u":20459107,"seq":114533109495},"cts":1704258149590}
{"topic":"orderbook.50.BTCUSDT","type":"delta","ts":1704258149611,"data":{"s":"BTCUSDT","b":[["45157.70","0.079"],["45154.00","0"]],"a":[["45165.30","0.206"],["45165.90","0.080"],["45168.90","0"],["45169.10","0"],["45171.20","0.044"],["45171.40","0.356"],["45171.50","5.443"],["45171.90","2.062"],["45172.10","0.875"]],"u":20459108,"seq":114533109587},"cts":1704258149610}
{"topic":"orderbook.50.BTCUSDT","type":"delta","ts":1704258149632,"data":{"s":"BTCUSDT","b":[["45157.50","0.011"]],"a":[["45162.60","7.101"],["45162.90","0"],["45164.70","0"],["45165.90","0.156"],["45166.10","0"],["45166.20","2.328"],["45169.50","0.132"],["45170.20","2.421"],["45170.30","5.243"],["45171.40","4.119"],["45171.50","1.680"],["45171.60","2.390"],["45171.90","0.115"],["45172.30","0.172"],["45172.50","0.443"],["45172.60","1.200"]],"u":20459109,"seq":114533109682},"cts":1704258149630}
{"topic":"orderbook.50.BTCUSDT","type":"delta","ts":1704258149652,"data":{"s":"BTCUSDT","b":[["45162.00","0.114"],["45161.70","0"],["45160.10","0.001"],["45156.80","1.852"],["45156.10","0.076"]],"a":[["45162.60","7.486"],["45162.70","0.077"],["45170.30","3.738"],["45171.40","0.356"],["45171.60","0.443"],["45172.20","3.762"],["45172.40","1.947"],["45172.50","0"],["45172.60","0"]],"u":20459110,"seq":114533109801},"cts":1704258149650}
{"topic":"orderbook.50.BTCUSDT","type":"delta","ts":1704258149671,"data":{"s":"BTCUSDT","b":[["45161.20","0.001"],["45160.10","0.003"],["45157.70","0.116"],["45154.10","0"]],"a":[["45170.60","0.059"],["45172.00","2.060"],["45172.20","0"],["45172.40","0"],["45172.50","1.948"],["45172.60","1.200"]],"u":20459111,"seq":114533109932},"cts":1704258149670}
{"topic":"orderbook.50.BTCUSDT","type":"delta","ts":1704258149691,"data":{"s":"BTCUSDT","b":[["45160.10","0.004"]],"a":[["45162.60","8.629"],["45171.70","2.563"],["45171.90","3.877"],["45172.00","0.113"]],"u":20459112,"seq":114533110049},"cts":1704258149690}
{"topic":"orderbook.50.BTCUSDT","type":"delta","ts":1704258149711,"data":{"s":"BTCUSDT","b":[],"a":[["45170.30","3.749"],["45171.90","0.115"]],"u":20459113,"seq":114533110169},"cts":1704258149710}
{"topic":"orderbook.50.BTCUSDT","type":"delta","ts":1704258149732,"data":{"s":"BTCUSDT","b":[["45158.60","0.332"],["45158.00","0.224"],["45157.80","0.111"],["45157.70","0.079"],["45155.70","0.111"],["45154.30","0"],["45154.20","0"]],"a":[["45163.90","0.078"],["45167.80","0.155"],["45169.50","0.121"],["45169.80","3.929"],["45170.60","0.022"],["45171.20","1.991"],["45172.60","0"]],"u":20459114,"seq":114533110319},"cts":1704258149730}
{"topic":"orderbook.50.BTCUSDT","type":"delta","ts":1704258149752,"data":{"s":"BTCUSDT","b":[["45160.20","1.147"]],"a":[["45167.50","0.011"],["45169.80","0.166"],["45170.10","3.874"],["45170.80","0.011"],["45171.10","1.950"],["45171.20","0.044"],["45172.30","0"],["45172.50","0"]],"u":20459115,"seq":114533110428},"cts":1704258149750}
{"topic":"orderbook.50.BTCUSDT","type":"delta","ts":1704258149771,"data":{"s":"BTCUSDT","b":[["45160.20","0.047"],["45160.10","0.005"]],"a":[["45170.10","0.111"],["45170.30","3.738"],["45170.50","0.011"],["45171.00","3.902"],["45171.80","0.305"],["45172.10","0"]],"u":20459116,"seq":114533110552},"cts":1704258149769}
{"topic":"orderbook.50.BTCUSDT","type":"delta","ts":1704258149791,"data":{"s":"BTCUSDT","b":[],"a":[["45165.00","0.001"],["45167.50","0"],["45167.80","0.166"],["45171.00","0.139"],["45171.10","0.003"],["45171.20","1.991"]],"u":20459117,"seq":114533110668},"cts":1704258149790}
{"topic":"orderbook.50.BTCUSDT","type":"delta","ts":1704258149812,"data":{"s":"BTCUSDT","b":[["45162.50","4.600"],["45158.60","0.610"],["45157.60","0.113"]],"a":[["45162.60","8.429"],["45170.30","3.179"],["45170.40","1.985"],["45171.20","0.044"],["45171.30","5.821"]],"u":20459118,"seq":114533110795},"cts":1704258149809}
{"topic":"orderbook.50.BTCUSDT","type":"delta","ts":1704258149832,"data":{"s":"BTCUSDT","b":[["45159.50","0.353"],["45157.60","0.076"],["45155.00","0.301"],["45154.40","0.573"]],"a":[["45162.60","5.103"],["45164.20","0"],["45164.70","0.003"],["45166.20","2.250"],["45167.80","0.111"],["45167.90","0"],["45168.10","4.865"],["45168.90","0.011"],["45169.80","0"],["45170.40","1.948"],["45170.80","0"],["45171.20","0.055"],["45171.30","0.111"],["45172.10","0.178"],["45172.30","0.172"]],"u":20459119,"seq":114533110916},"cts":1704258149829}
{"topic":"orderbook.50.BTCUSDT","type":"delta","ts":1704258149851,"data":{"s":"BTCUSDT","b":[["45162.50","4.625"]],"a":[["45162.60","4.704"],["45168.20","0"],["45168.90","0"],["45169.70","0.011"],["45169.90","1.162"],["45170.20","1.862"],["45171.00","0.117"],["45171.50","1.658"],["45172.40","3.762"]],"u":20459120,"seq":114533111015},"cts":1704258149849}
{"topic":"orderbook.50.BTCUSDT","type":"delta","ts":1704258149871,"data":{"s":"BTCUSDT","b":[["45162.50","4.700"],["45158.60","0.500"],["45155.60","1.660"]],"a":[["45164.10","0.676"],["45169.70","0"],["45170.30","2.979"],["45170.50","0"],["45170.90","0.222"],["45172.40","0"],["45172.50","0.443"],["45172.60","1.200"],["45172.70","0.066"]],"u":20459121,"seq":114533111101},"cts":1704258149870}
{"topic":"orderbook.50.BTCUSDT","type":"delta","ts":1704258149892,"data":{"s":"BTCUSDT","b":[["45162.50","4.900"],["45157.00","0.836"],["45156.30","3.179"],["45154.80","0.267"]],"a":[["45162.60","3.614"],["45164.10","0.276"],["45164.70","0"],["45165.40","0.274"],["45168.10","3.217"],["45170.30","2.957"],["45170.40","0.443"],["45171.20","0.044"],["45171.40","0.244"],["45171.80","1.810"],["45171.90","0.137"],["45172.10","0.066"],["45172.80","0.766"]],"u":20459122,"seq":114533111201},"cts":1704258149889}
{"topic":"orderbook.50.BTCUSDT","type":"delta","ts":1704258149911,"data":{"s":"BTCUSDT","b":[["45157.00","1.454"],["45155.30","0.269"]],"a":[["45165.40","0.271"],["45166.00","0.116"],["45170.30","2.979"],["45171.90","0.115"]],"u":20459123,"seq":114533111272},"cts":1704258149910}
{"topic":"orderbook.50.BTCUSDT","type":"delta","ts":1704258149932,"data":{"s":"BTCUSDT","b":[["45158.70","0.038"]],"a":[["45170.50","0.025"],["45171.50","1.695"],["45172.70","0.077"],["45172.80","0"]],"u":20459124,"seq":114533111327},"cts":1704258149930}
{"topic":"orderbook.50.BTCUSDT","type":"delta","ts":1704258149952,"data":{"s":"BTCUSDT","b":[["45160.10","0.006"],["45158.60","0.544"],["45156.50","0.356"]],"a":[["45172.70","0.066"]],"u":20459125,"seq":114533111368},"cts":1704258149950}
{"topic":"orderbook.50.BTCUSDT","type":"delta","ts":1704258149972,"data":{"s":"BTCUSDT","b":[["45154.80","0.673"]],"a":[["45164.10","0.076"],["45171.50","1.706"],["45172.20","0.011"],["45172.70","0"]],"u":20459126,"seq":114533111401},"cts":1704258149970}
{"topic":"orderbook.50.BTCUSDT","type":"delta","ts":1704258149992,"data":{"s":"BTCUSDT","b":[["45162.50","4.911"],["45157.90","1.200"],["45154.40","0"]],"a":[["45166.20","1.050"],["45170.10","0.122"],["45171.80","0.305"],["45172.00","0.124"],["45172.20","0"],["45172.70","0.066"]],"u":20459127,"seq":114533111448},"cts":1704258149989}
{"topic":"orderbook.50.BTCUSDT","type":"delta","ts":1704258150012,"data":{"s":"BTCUSDT","b":[],"a":[["45166.20","0.850"],["45171.50","1.695"],["45172.70","0.044"]],"u":20459128,"seq":114533111485},"cts":1704258150009}
{"topic":"orderbook.50.BTCUSDT","type":"delta","ts":1704258150031,"data":{"s":"BTCUSDT","b":[["45158.70","0.001"]],"a":[["45171.50","1.658"]],"u":20459129,"seq":114533111534},"cts":1704258150029}
{"topic":"orderbook.50.BTCUSDT","type":"delta","ts":1704258150052,"data":{"s":"BTCUSDT","b":[],"a":[["45170.10","0.111"],["45172.00","0.113"]],"u":20459130,"seq":114533111575},"cts":1704258150049}
{"topic":"orderbook.50.BTCUSDT","type":"delta","ts":1704258150072,"data":{"s":"BTCUSDT","b":[["45162.50","4.910"],["45160.20","1.647"],["45158.70","0.019"]],"a":[["45162.60","1.629"],["45166.00","0.113"],["45171.40","0.255"]],"u":20459131,"seq":114533111629},"cts":1704258150070}
{"topic":"orderbook.50.BTCUSDT","type":"delta","ts":1704258150091,"data":{"s":"BTCUSDT","b":[["45162.50","4.911"],["45158.70","0.095"],["45156.10","0"],["45154.40","0.573"]],"a":[["45166.20","0.780"],["45169.20","0.411"],["45169.90","1.118"],["45171.40","0.244"],["45171.80","1.810"],["45172.00","0.157"],["45172.40","0.011"],["45172.70","0"]],"u":20459132,"seq":114533111707},"cts":1704258150090}
{"topic":"orderbook.50.BTCUSDT","type":"delta","ts":1704258150112,"data":{"s":"BTCUSDT","b":[["45160.10","0.005"],["45156.90","1.547"],["45154.40","0"]],"a":[["45162.60","1.601"],["45171.40","0.255"],["45172.40","0"],["45172.70","0.044"]],"u":20459133,"seq":114533111756},"cts":1704258150109}
{"topic":"orderbook.50.BTCUSDT","type":"delta","ts":1704258150151,"data":{"s":"BTCUSDT","b":[],"a":[["45171.40","0.244"]],"u":20459134,"seq":114533111849},"cts":1704258150149}
{"topic":"orderbook.50.BTCUSDT","type":"delta","ts":1704258150171,"data":{"s":"BTCUSDT","b":[["45158.90","0.148"]],"a":[["45168.00","0.124"],["45171.70","2.600"]],"u":20459135,"seq":114533111891},"cts":1704258150169}
{"topic":"orderbook.50.BTCUSDT","type":"delta","ts":1704258150191,"data":{"s":"BTCUSDT","b":[["45158.90","0.111"],["45158.60","0.552"]],"a":[],"u":20459136,"seq":114533111933},"cts":1704258150189}
{"topic":"orderbook.50.BTCUSDT","type":"delta","ts":1704258150212,"data":{"s":"BTCUSDT","b":[],"a":[["45167.90","0.011"],["45168.00","0.113"],["45172.10","0.176"],["45172.70","0"]],"u":20459137,"seq":114533111981},"cts":1704258150210}
{"topic":"orderbook.50.BTCUSDT","type":"delta","ts":1704258150232,"data":{"s":"BTCUSDT","b":[],"a":[["45168.10","2.407"],["45171.70","2.563"]],"u":20459138,"seq":114533112024},"cts":1704258150229}
{"topic":"orderbook.50.BTCUSDT","type":"delta","ts":1704258150252,"data":{"s":"BTCUSDT","b":[["45159.90","0.165"],["45158.50","0"],["45154.40","0.573"]],"a":[["45166.20","0.580"]],"u":20459139,"seq":114533112061},"cts":1704258150249}
{"topic":"orderbook.50.BTCUSDT","type":"delta","ts":1704258150272,"data":{"s":"BTCUSDT","b":[["45158.90","0.148"]],"a":[["45171.60","0.480"]],"u":20459140,"seq":114533112102},"cts":1704258150269}
{"topic":"orderbook.50.BTCUSDT","type":"delta","ts":1704258150291,"data":{"s":"BTCUSDT","b":[["45158.80","0.112"],["45154.40","0"]],"a":[["45171.00","0"],["45172.30","0.070"],["45172.70","0.044"]],"u":20459141,"seq":114533112136},"cts":1704258150289}
{"topic":"orderbook.50.BTCUSDT","type":"delta","ts":1704258150311,"data":{"s":"BTCUSDT","b":[],"a":[["45172.20","0.011"],["45172.70","0"]],"u":20459142,"seq":114533112179},"cts":1704258150310}
{"topic":"orderbook.50.BTCUSDT","type":"delta","ts":1704258150332,"data":{"s":"BTCUSDT","b":[["45160.30","1.600"],["45158.90","0.111"],["45155.00","0.410"],["45154.50","0"]],"a":[["45171.60","0.443"]],"u":20459143,"seq":114533112222},"cts":1704258150328}
{"topic":"orderbook.50.BTCUSDT","type":"delta","ts":1704258150352,"data":{"s":"BTCUSDT","b":[],"a":[["45167.70","0.055"],["45167.90","0"],["45172.20","0.232"],["45172.70","0.044"]],"u":20459144,"seq":114533112265},"cts":1704258150349}
{"topic":"orderbook.50.BTCUSDT","type":"delta","ts":1704258150372,"data":{"s":"BTCUSDT","b":[["45158.30","0.037"],["45154.80","0"]],"a":[["45165.20","0.003"],["45171.70","2.600"],["45172.70","0"]],"u":20459145,"seq":114533112307},"cts":1704258150370}
{"topic":"orderbook.50.BTCUSDT","type":"delta","ts":1704258150392,"data":{"s":"BTCUSDT","b":[],"a":[["45166.00","0.114"],["45168.00","0.114"],["45170.00","0.225"],["45172.00","0.158"],["45172.50","0.454"]],"u":20459146,"seq":114533112349},"cts":1704258150389}
{"topic":"orderbook.50.BTCUSDT","type":"delta","ts":1704258150411,"data":{"s":"BTCUSDT","b":[],"a":[["45162.60","1.101"],["45167.60","0.092"],["45167.70","0.044"]],"u":20459147,"seq":114533112390},"cts":1704258150410}
{"topic":"orderbook.50.BTCUSDT","type":"delta","ts":1704258150431,"data":{"s":"BTCUSDT","b":[["45162.50","4.944"],["45160.10","0.002"]],"a":[["45162.60","0.947"],["45171.40","0.354"]],"u":20459148,"seq":114533112490},"cts":1704258150430}
{"topic":"orderbook.50.BTCUSDT","type":"delta","ts":1704258150451,"data":{"s":"BTCUSDT","b":[["45162.20","0.001"],["45162.10","0.001"],["45162.00","0.115"],["45161.90","0.001"],["45161.80","0.001"],["45160.10","0.001"],["45158.20","0.112"],["45155.40","0"],["45155.30","0"],["45155.20","0"],["45155.10","0"],["45155.00","0"]],"a":[["45162.60","0.900"]],"u":20459149,"seq":114533112561},"cts":1704258150450}
{"topic":"orderbook.50.BTCUSDT","type":"delta","ts":1704258150471,"data":{"s":"BTCUSDT","b":[["45162.40","0.011"],["45162.30","0.001"],["45161.70","0.001"],["45161.40","0.001"],["45161.30","0.167"],["45161.20","0.002"],["45161.10","1.659"],["45161.00","0.001"],["45160.10","0"],["45158.60","0.508"],["45156.50","0.400"],["45155.80","0"],["45155.70","0"],["45155.60","0"]],"a":[["45162.60","0.872"]],"u":20459150,"seq":114533112629},"cts":1704258150470}
{"topic":"orderbook.50.BTCUSDT","type":"delta","ts":1704258150491,"data":{"s":"BTCUSDT","b":[["45161.20","0.001"]],"a":[["45162.60","0.044"]],"u":20459151,"seq":114533112683},"cts":1704258150489}
{"topic":"orderbook.50.BTCUSDT","type":"delta","ts":1704258150511,"data":{"s":"BTCUSDT","b":[["45160.10","0.078"],["45157.60","0"],["45157.00","1.861"]],"a":[["45171.80","0.305"]],"u":20459152,"seq":114533112769},"cts":1704258150510}
{"topic":"orderbook.50.BTCUSDT","type":"delta","ts":1704258150531,"data":{"s":"BTCUSDT","b":[["45162.40","0.010"],["45162.30","0"],["45162.20","0"],["45162.10","0"],["45161.90","0"],["45161.70","0"],["45161.40","0"],["45161.20","0"],["45161.00","0"],["45158.30","0"],["45155.80","0.002"],["45155.70","0.111"],["45155.60","1.660"],["45155.40","2.543"],["45155.30","0.269"],["45155.20","0.487"],["45155.10","2.411"],["45155.00","0.301"],["45154.80","0.673"]],"a":[["45167.50","0.011"],["45167.60","0.081"],["45170.10","3.874"],["45171.70","2.563"],["45172.50","0.443"],["45172.60","0"]],"u":20459153,"seq":114533112829},"cts":1704258150530}
{"topic":"orderbook.50.BTCUSDT","type":"delta","ts":1704258150551,"data":{"s":"BTCUSDT","b":[["45162.00","0.114"],["45161.80","0"],["45158.20","0.149"],["45154.90","0.109"]],"a":[["45167.20","0.011"],["45167.50","0"],["45168.00","0.718"],["45168.10","2.329"],["45169.50","3.884"],["45170.10","0.111"],["45171.40","2.301"],["45171.60","0.480"]],"u":20459154,"seq":114533112889},"cts":1704258150550}
{"topic":"orderbook.50.BTCUSDT","type":"delta","ts":1704258150571,"data":{"s":"BTCUSDT","b":[["45161.30","0.166"]],"a":[["45167.20","0"],["45167.50","0.011"],["45167.90","0.044"],["45169.50","0.121"],["45169.70","0.078"],["45171.30","3.874"],["45171.40","0.354"],["45172.30","0"],["45172.50","0"]],"u":20459155,"seq":114533112954},"cts":1704258150570}
{"topic":"orderbook.50.BTCUSDT","type":"delta","ts":1704258150592,"data":{"s":"BTCUSDT","b":[["45161.20","1.600"],["45154.80","0"]],"a":[["45166.90","0.011"],["45167.50","0"],["45169.40","3.763"],["45169.50","2.069"],["45171.30","0.111"],["45172.20","0"]],"u":20459156,"seq":114533113007},"cts":1704258150588}
{"topic":"orderbook.50.BTCUSDT","type":"delta","ts":1704258150611,"data":{"s":"BTCUSDT","b":[],"a":[["45165.20","0.004"]],"u":20459157,"seq":114533113062},"cts":1704258150609}
{"topic":"orderbook.50.BTCUSDT","type":"delta","ts":1704258150631,"data":{"s":"BTCUSDT","b":[["45158.20","0.112"]],"a":[["45169.40","5.711"],["45169.50","0.121"],["45170.70","0.154"],["45171.60","0.443"]],"u":20459158,"seq":114533113119},"cts":1704258150630}
{"topic":"orderbook.50.BTCUSDT","type":"delta","ts":1704258150651,"data":{"s":"BTCUSDT","b":[["45158.30","0.037"],["45154.90","0"]],"a":[["45169.40","0"],["45171.70","2.600"],["45172.20","0.232"]],"u":20459159,"seq":114533113176},"cts":1704258150649}
{"topic":"orderbook.50.BTCUSDT","type":"delta","ts":1704258150672,"data":{"s":"BTCUSDT","b":[],"a":[["45169.40","3.763"],["45172.20","0"]],"u":20459160,"seq":114533113227},"cts":1704258150669}
{"topic":"orderbook.50.BTCUSDT","type":"delta","ts":1704258150692,"data":{"s":"BTCUSDT","b":[["45161.10","1.658"]],"a":[["45169.40","0"],["45172.20","0.221"]],"u":20459161,"seq":114533113276},"cts":1704258150689}
{"topic":"orderbook.50.BTCUSDT","type":"delta","ts":1704258150711,"data":{"s":"BTCUSDT","b":[],"a":[["45168.10","2.129"]],"u":20459162,"seq":114533113329},"cts":1704258150709}
{"topic":"orderbook.50.BTCUSDT","type":"delta","ts":1704258150731,"data":{"s":"BTCUSDT","b":[["45159.70","0.239"]],"a":[["45165.20","0.005"]],"u":20459163,"seq":114533113377},"cts":1704258150728}
{"topic":"orderbook.50.BTCUSDT","type":"delta","ts":1704258150751,"data":{"s":"BTCUSDT","b":[["45162.50","6.144"]],"a":[["45162.70","0.010"],["45166.90","0"],["45167.20","0.011"],["45168.10","1.929"],["45168.60","0.111"],["45169.60","0"],["45170.30","2.361"]],"u":20459164,"seq":114533113459},"cts":1704258150750}
{"topic":"orderbook.50.BTCUSDT","type":"delta","ts":1704258150771,"data":{"s":"BTCUSDT","b":[["45161.60","0.966"],["45159.20","0.193"],["45156.80","1.770"]],"a":[["45164.00","0.200"],["45167.20","0"],["45167.50","0.011"],["45167.90","0.048"],["45170.20","1.858"]],"u":20459165,"seq":114533113540},"cts":1704258150769}
{"topic":"orderbook.50.BTCUSDT","type":"delta","ts":1704258150812,"data":{"s":"BTCUSDT","b":[["45158.40","0.037"],["45158.30","0"]],"a":[["45171.70","2.563"],["45171.90","0.152"]],"u":20459166,"seq":114533113646},"cts":1704258150810}
{"topic":"orderbook.50.BTCUSDT","type":"delta","ts":1704258150831,"data":{"s":"BTCUSDT","b":[["45162.50","6.223"],["45161.50","0"],["45158.40","0"],["45154.80","0.673"],["45154.50","0.435"]],"a":[["45163.90","0"],["45170.00","0.335"],["45171.90","0.115"],["45172.30","0.834"]],"u":20459167,"seq":114533113711},"cts":1704258150829}
{"topic":"orderbook.50.BTCUSDT","type":"delta","ts":1704258150852,"data":{"s":"BTCUSDT","b":[["45161.70","1.600"],["45160.20","0.047"],["45154.50","0"]],"a":[["45164.00","0.113"],["45169.60","3.763"],["45171.30","2.058"],["45172.30","0"]],"u":20459168,"seq":114533113777},"cts":1704258150850}
{"topic":"orderbook.50.BTCUSDT","type":"delta","ts":1704258150872,"data":{"s":"BTCUSDT","b":[],"a":[["45164.00","0"],["45169.80","1.947"],["45171.30","0.111"]],"u":20459169,"seq":114533113827},"cts":1704258150869}
{"topic":"orderbook.50.BTCUSDT","type":"delta","ts":1704258150912,"data":{"s":"BTCUSDT","b":[["45162.50","6.224"]],"a":[],"u":20459170,"seq":114533113925},"cts":1704258150910}
{"topic":"orderbook.50.BTCUSDT","type":"delta","ts":1704258150932,"data":{"s":"BTCUSDT","b":[["45158.80","0.149"]],"a":[["45172.20","0.258"]],"u":20459171,"seq":114533113966},"cts":1704258150930}
{"topic":"orderbook.50.BTCUSDT","type":"delta","ts":1704258150951,"data":{"s":"BTCUSDT","b":[["45158.80","0.112"]],"a":[["45164.10","0"],["45165.30","0.047"],["45166.10","0.076"],["45169.80","0"],["45172.20","0.221"],["45172.30","0.834"]],"u":20459172,"seq":114533114027},"cts":1704258150950}
{"topic":"orderbook.50.BTCUSDT","type":"delta","ts":1704258150972,"data":{"s":"BTCUSDT","b":[],"a":[["45167.50","0"],["45167.60","0.092"],["45169.60","0"],["45169.70","3.841"],["45172.40","0.011"],["45172.50","0.443"]],"u":20459173,"seq":114533114097},"cts":1704258150970}
{"topic":"orderbook.50.BTCUSDT","type":"delta","ts":1704258150991,"data":{"s":"BTCUSDT","b":[],"a":[["45167.60","0.081"],["45167.70","0.055"],["45169.70","0.078"]],"u":20459174,"seq":114533114152},"cts":1704258150989}
{"topic":"orderbook.50.BTCUSDT","type":"delta","ts":1704258151012,"data":{"s":"BTCUSDT","b":[],"a":[["45172.00","0.114"]],"u":20459175,"seq":114533114194},"cts":1704258151009}
{"topic":"orderbook.50.BTCUSDT","type":"delta","ts":1704258151031,"data":{"s":"BTCUSDT","b":[["45162.50","7.474"],["45160.30","0"],["45154.60","0.109"]],"a":[["45169.30","0.110"],["45172.50","0"]],"u":20459176,"seq":114533114255},"cts":1704258151030}
{"topic":"orderbook.50.BTCUSDT","type":"delta","ts":1704258151052,"data":{"s":"BTCUSDT","b":[["45162.50","7.491"]],"a":[["45167.60","0.092"],["45167.70","0.044"],["45171.40","0.575"]],"u":20459177,"seq":114533114315},"cts":1704258151050}
{"topic":"orderbook.50.BTCUSDT","type":"delta","ts":1704258151071,"data":{"s":"BTCUSDT","b":[["45158.50","0.037"],["45154.60","0"]],"a":[["45166.90","0.076"],["45167.70","0.123"],["45171.40","0.612"],["45172.40","0"]],"u":20459178,"seq":114533114367},"cts":1704258151070}
{"topic":"orderbook.50.BTCUSDT","type":"delta","ts":1704258151091,"data":{"s":"BTCUSDT","b":[["45158.50","0"],["45154.60","0.109"]],"a":[["45167.60","0.081"],["45167.70","0.134"],["45171.40","0.575"]],"u":20459179,"seq":114533114423},"cts":1704258151089}
{"topic":"orderbook.50.BTCUSDT","type":"delta","ts":1704258151112,"data":{"s":"BTCUSDT","b":[["45162.50","6.241"],["45161.40","1.600"],["45154.60","0"]],"a":[],"u":20459180,"seq":114533114483},"cts":1704258151110}
{"topic":"orderbook.50.BTCUSDT","type":"delta","ts":1704258151132,"data":{"s":"BTCUSDT","b":[["45162.50","5.041"],["45161.70","0"],["45161.40","0"],["45161.20","0"],["45154.60","0.109"],["45154.50","0.435"],["45154.40","0.464"]],"a":[["45164.00","0.113"],["45166.20","0.659"],["45167.20","1.200"],["45172.20","0"],["45172.30","0"]],"u":20459181,"seq":114533114556},"cts":1704258151129}
{"topic":"orderbook.50.BTCUSDT","type":"delta","ts":1704258151172,"data":{"s":"BTCUSDT","b":[["45158.70","0.132"],["45156.30","1.674"]],"a":[["45167.20","0"],["45167.70","0.123"],["45167.90","0.059"],["45171.70","2.600"],["45172.20","0.221"]],"u":20459182,"seq":114533114645},"cts":1704258151169}
{"topic":"orderbook.50.BTCUSDT","type":"delta","ts":1704258151191,"data":{"s":"BTCUSDT","b":[["45158.70","0.095"]],"a":[["45167.90","0.015"],["45168.00","0.114"],["45171.70","2.563"]],"u":20459183,"seq":114533114693},"cts":1704258151190}
{"topic":"orderbook.50.BTCUSDT","type":"delta","ts":1704258151231,"data":{"s":"BTCUSDT","b":[["45156.90","0"],["45154.30","0.111"]],"a":[["45167.90","0.004"],["45168.60","0.221"],["45169.60","0.011"],["45172.20","0"]],"u":20459184,"seq":114533114790},"cts":1704258151229}
{"topic":"orderbook.50.BTCUSDT","type":"delta","ts":1704258151271,"data":{"s":"BTCUSDT","b":[["45156.40","1.556"]],"a":[["45169.10","0.011"],["45169.60","0"]],"u":20459185,"seq":114533114889},"cts":1704258151270}
{"topic":"orderbook.50.BTCUSDT","type":"delta","ts":1704258151292,"data":{"s":"BTCUSDT","b":[],"a":[["45168.00","0.125"],["45169.10","0"],["45169.60","3.763"]],"u":20459186,"seq":114533114942},"cts":1704258151289}
{"topic":"orderbook.50.BTCUSDT","type":"delta","ts":1704258151312,"data":{"s":"BTCUSDT","b":[],"a":[["45169.80","1.947"],["45172.10","0"]],"u":20459187,"seq":114533114991},"cts":1704258151309}
{"topic":"orderbook.50.BTCUSDT","type":"delta","ts":1704258151331,"data":{"s":"BTCUSDT","b":[],"a":[["45167.90","0.015"],["45168.00","0.275"],["45169.80","0"],["45172.10","0.176"]],"u":20459188,"seq":114533115050},"cts":1704258151329}
{"topic":"orderbook.50.BTCUSDT","type":"delta","ts":1704258151352,"data":{"s":"BTCUSDT","b":[["45154.60","0"],["45154.30","0.220"],["45154.20","0.443"]],"a":[],"u":20459189,"seq":114533115111},"cts":1704258151348}
{"topic":"orderbook.50.BTCUSDT","type":"delta","ts":1704258151371,"data":{"s":"BTCUSDT","b":[],"a":[["45169.80","1.947"],["45172.10","0"]],"u":20459190,"seq":114533115171},"cts":1704258151370}
{"topic":"orderbook.50.BTCUSDT","type":"delta","ts":1704258151391,"data":{"s":"BTCUSDT","b":[["45162.50","3.964"]],"a":[["45169.80","0"],["45172.10","0.176"]],"u":20459191,"seq":114533115236},"cts":1704258151390}
{"topic":"orderbook.50.BTCUSDT","type":"delta","ts":1704258151432,"data":{"s":"BTCUSDT","b":[["45162.50","3.982"],["45160.10","1.678"]],"a":[],"u":20459192,"seq":114533115327},"cts":1704258151429}
{"topic":"orderbook.50.BTCUSDT","type":"delta","ts":1704258151451,"data":{"s":"BTCUSDT","b":[["45160.30","1.013"],["45159.50","0"]],"a":[],"u":20459193,"seq":114533115377},"cts":1704258151450}
{"topic":"orderbook.50.BTCUSDT","type":"delta","ts":1704258151491,"data":{"s":"BTCUSDT","b":[["45155.30","0.378"],["45154.30","0.111"]],"a":[],"u":20459194,"seq":114533115454},"cts":1704258151490}
{"topic":"orderbook.50.BTCUSDT","type":"delta","ts":1704258151532,"data":{"s":"BTCUSDT","b":[["45158.10","0.110"],["45154.20","0"]],"a":[],"u":20459195,"seq":114533115545},"cts":1704258151530}
{"topic":"orderbook.50.BTCUSDT","type":"delta","ts":1704258151551,"data":{"s":"BTCUSDT","b":[["45162.50","5.182"]],"a":[["45169.40","3.763"],["45169.60","0"]],"u":20459196,"seq":114533115596},"cts":1704258151550}
{"topic":"orderbook.50.BTCUSDT","type":"delta","ts":1704258151591,"data":{"s":"BTCUSDT","b":[["45160.10","0.078"],["45155.30","0.269"]],"a":[],"u":20459197,"seq":114533115689},"cts":1704258151588}
{"topic":"orderbook.50.BTCUSDT","type":"delta","ts":1704258151611,"data":{"s":"BTCUSDT","b":[["45162.50","5.192"],["45161.60","0.854"],["45160.30","0"],["45159.50","0.305"]],"a":[["45169.50","2.069"]],"u":20459198,"seq":114533115743},"cts":1704258151609}
{"topic":"orderbook.50.BTCUSDT","type":"delta","ts":1704258151631,"data":{"s":"BTCUSDT","b":[["45162.50","3.992"]],"a":[],"u":20459199,"seq":114533115813},"cts":1704258151629}
{"topic":"orderbook.50.BTCUSDT","type":"delta","ts":1704258151652,"data":{"s":"BTCUSDT","b":[["45158.40","0.037"],["45154.30","0"]],"a":[["45166.10","0.680"],["45169.50","0.121"],["45170.70","0.375"],["45171.30","0.148"]],"u":20459200,"seq":114533115862},"cts":1704258151650}
{"topic":"orderbook.50.BTCUSDT","type":"delta","ts":1704258151672,"data":{"s":"BTCUSDT","b":[["45158.40","0"],["45155.10","2.520"],["45154.30","0.111"]],"a":[["45167.50","0.011"],["45167.90","0.004"],["45169.10","3.763"],["45169.40","0"],["45171.30","0.111"],["45172.10","0"]],"u":20459201,"seq":114533115924},"cts":1704258151668}
{"topic":"orderbook.50.BTCUSDT","type":"delta","ts":1704258151692,"data":{"s":"BTCUSDT","b":[],"a":[["45168.90","3.763"],["45169.10","0"],["45169.30","2.058"]],"u":20459202,"seq":114533115965},"cts":1704258151688}
{"topic":"orderbook.50.BTCUSDT","type":"delta","ts":1704258151711,"data":{"s":"BTCUSDT","b":[["45155.10","2.411"]],"a":[["45168.90","0"],["45169.10","3.763"],["45171.90","0.159"]],"u":20459203,"seq":114533116021},"cts":1704258151709}
{"topic":"orderbook.50.BTCUSDT","type":"delta","ts":1704258151731,"data":{"s":"BTCUSDT","b":[["45160.10","1.678"]],"a":[["45167.50","0"],["45167.90","3.767"],["45169.10","0"],["45169.30","0.110"],["45172.10","0.176"],["45172.20","0.232"]],"u":20459204,"seq":114533116074},"cts":1704258151730}
{"topic":"orderbook.50.BTCUSDT","type":"delta","ts":1704258151752,"data":{"s":"BTCUSDT","b":[["45160.30","1.012"],["45159.50","0"],["45158.10","0.147"]],"a":[["45167.90","0.015"],["45169.40","3.763"],["45171.10","0.040"],["45172.20","0"]],"u":20459205,"seq":114533116131},"cts":1704258151750}
{"topic":"orderbook.50.BTCUSDT","type":"delta","ts":1704258151771,"data":{"s":"BTCUSDT","b":[["45160.10","0.078"],["45159.70","0.127"],["45156.40","0.051"]],"a":[["45162.60","0.344"],["45169.40","0"],["45169.60","0.812"]],"u":20459206,"seq":114533116185},"cts":1704258151769}
{"topic":"orderbook.50.BTCUSDT","type":"delta","ts":1704258151791,"data":{"s":"BTCUSDT","b":[["45162.50","3.991"],["45160.30","0"],["45159.50","0.314"],["45158.70","0.077"]],"a":[["45162.60","0.044"],["45167.70","0.134"],["45167.90","0.004"],["45169.10","3.763"],["45172.10","0"]],"u":20459207,"seq":114533116246},"cts":1704258151789}
{"topic":"orderbook.50.BTCUSDT","type":"delta","ts":1704258151812,"data":{"s":"BTCUSDT","b":[],"a":[["45169.10","0"],["45172.10","0.176"]],"u":20459208,"seq":114533116326},"cts":1704258151810}
{"topic":"orderbook.50.BTCUSDT","type":"delta","ts":1704258151832,"data":{"s":"BTCUSDT","b":[["45158.10","0.110"]],"a":[["45170.70","1.587"],["45171.10","0.003"]],"u":20459209,"seq":114533116378},"cts":1704258151830}
{"topic":"orderbook.50.BTCUSDT","type":"delta","ts":1704258151851,"data":{"s":"BTCUSDT","b":[["45158.20","0.149"]],"a":[["45169.10","1.948"],["45171.20","0.081"],["45172.10","0"]],"u":20459210,"seq":114533116419},"cts":1704258151848}
{"topic":"orderbook.50.BTCUSDT","type":"delta","ts":1704258151872,"data":{"s":"BTCUSDT","b":[["45156.40","1.556"]],"a":[["45167.70","0.123"],["45167.90","0.015"],["45169.10","0"],["45169.40","1.948"]],"u":20459211,"seq":114533116463},"cts":1704258151870}
{"topic":"orderbook.50.BTCUSDT","type":"delta","ts":1704258151891,"data":{"s":"BTCUSDT","b":[["45158.20","0.112"]],"a":[["45168.90","3.763"],["45169.40","0"],["45171.20","0.044"]],"u":20459212,"seq":114533116499},"cts":1704258151889}
{"topic":"orderbook.50.BTCUSDT","type":"delta","ts":1704258151911,"data":{"s":"BTCUSDT","b":[],"a":[["45169.10","1.948"],["45172.00","0"]],"u":20459213,"seq":114533116531},"cts":1704258151909}
{"topic":"orderbook.50.BTCUSDT","type":"delta","ts":1704258151932,"data":{"s":"BTCUSDT","b":[],"a":[["45167.70","0.134"],["45167.90","0.004"]],"u":20459214,"seq":114533116571},"cts":1704258151928}
{"topic":"orderbook.50.BTCUSDT","type":"delta","ts":1704258151952,"data":{"s":"BTCUSDT","b":[],"a":[["45169.10","0"],["45172.00","0.114"]],"u":20459215,"seq":114533116616},"cts":1704258151949}
{"topic":"orderbook.50.BTCUSDT","type":"delta","ts":1704258151972,"data":{"s":"BTCUSDT","b":[],"a":[["45169.10","1.948"],["45172.00","0"]],"u":20459216,"seq":114533116655},"cts":1704258151967}
{"topic":"orderbook.50.BTCUSDT","type":"delta","ts":1704258151992,"data":{"s":"BTCUSDT","b":[],"a":[["45169.10","0"],["45172.00","0.114"]],"u":20459217,"seq":114533116694},"cts":1704258151989}
{"topic":"orderbook.50.BTCUSDT","type":"delta","ts":1704258152012,"data":{"s":"BTCUSDT","b":[["45160.10","1.678"]],"a":[],"u":20459218,"seq":114533116731},"cts":1704258152009}
{"topic":"orderbook.50.BTCUSDT","type":"delta","ts":1704258152032,"data":{"s":"BTCUSDT","b":[["45160.30","1.013"],["45159.50","0"]],"a":[["45167.60","0.092"],["45167.70","0.123"]],"u":20459219,"seq":114533116769},"cts":1704258152029}
{"topic":"orderbook.50.BTCUSDT","type":"delta","ts":1704258152051,"data":{"s":"BTCUSDT","b":[["45158.30","0.037"],["45154.30","0"]],"a":[["45167.90","3.767"],["45168.90","0"],["45171.20","0.081"],["45172.10","0.176"]],"u":20459220,"seq":114533116815},"cts":1704258152049}
{"topic":"orderbook.50.BTCUSDT","type":"delta","ts":1704258152072,"data":{"s":"BTCUSDT","b":[],"a":[["45167.90","0.004"]],"u":20459221,"seq":114533116862},"cts":1704258152069}
{"topic":"orderbook.50.BTCUSDT","type":"delta","ts":1704258152092,"data":{"s":"BTCUSDT","b":[["45158.30","0"],["45154.30","0.111"]],"a":[["45167.90","3.767"],["45171.20","0.044"]],"u":20459222,"seq":114533116915},"cts":1704258152090}
{"topic":"orderbook.50.BTCUSDT","type":"delta","ts":1704258152132,"data":{"s":"BTCUSDT","b":[["45154.60","0.110"],["45154.30","0"]],"a":[],"u":20459223,"seq":114533116993},"cts":1704258152129}
{"topic":"orderbook.50.BTCUSDT","type":"delta","ts":1704258152152,"data":{"s":"BTCUSDT","b":[["45158.10","0.147"]],"a":[["45166.10","0.076"],["45167.90","0.004"],["45171.00","0.037"],["45172.10","0"]],"u":20459224,"seq":114533117027},"cts":1704258152149}
{"topic":"orderbook.50.BTCUSDT","type":"delta","ts":1704258152172,"data":{"s":"BTCUSDT","b":[["45162.50","4.006"],["45158.10","0.110"]],"a":[["45167.90","3.767"],["45168.90","1.948"],["45171.00","0"]],"u":20459225,"seq":114533117075},"cts":1704258152169}
{"topic":"orderbook.50.BTCUSDT","type":"delta","ts":1704258152192,"data":{"s":"BTCUSDT","b":[],"a":[["45168.90","0"],["45172.10","0.176"]],"u":20459226,"seq":114533117116},"cts":1704258152189}
{"topic":"orderbook.50.BTCUSDT","type":"delta","ts":1704258152231,"data":{"s":"BTCUSDT","b":[],"a":[["45167.90","0.004"]],"u":20459227,"seq":114533117178},"cts":1704258152229}
{"topic":"orderbook.50.BTCUSDT","type":"delta","ts":1704258152251,"data":{"s":"BTCUSDT","b":[["45154.70","0.109"],["45154.40","0"]],"a":[["45167.50","0.011"],["45167.60","2.029"],["45172.10","0"]],"u":20459228,"seq":114533117230},"cts":1704258152249}
{"topic":"orderbook.50.BTCUSDT","type":"delta","ts":1704258152271,"data":{"s":"BTCUSDT","b":[["45160.40","1.600"],["45158.60","0.545"],["45154.50","0"]],"a":[["45167.50","3.774"],["45171.30","0.148"]],"u":20459229,"seq":114533117277},"cts":1704258152270}
{"topic":"orderbook.50.BTCUSDT","type":"delta","ts":1704258152352,"data":{"s":"BTCUSDT","b":[["45160.10","0.078"],["45156.40","0.051"]],"a":[["45167.20","0.011"],["45167.40","3.763"],["45167.50","0"],["45172.00","0"]],"u":20459230,"seq":114533117430},"cts":1704258152350}
{"topic":"orderbook.50.BTCUSDT","type":"delta","ts":1704258152372,"data":{"s":"BTCUSDT","b":[["45160.30","0"],["45159.50","0.330"],["45158.70","0.095"]],"a":[["45167.60","0.081"]],"u":20459231,"seq":114533117474},"cts":1704258152369}
{"topic":"orderbook.50.BTCUSDT","type":"delta","ts":1704258152431,"data":{"s":"BTCUSDT","b":[["45162.50","3.955"],["45158.60","0.508"]],"a":[["45167.40","0"],["45171.30","0.111"],["45172.00","0.114"]],"u":20459232,"seq":114533117572},"cts":1704258152429}
{"topic":"orderbook.50.BTCUSDT","type":"delta","ts":1704258152451,"data":{"s":"BTCUSDT","b":[["45162.50","3.242"],["45158.70","0.132"],["45156.40","1.556"]],"a":[["45169.10","3.763"],["45171.50","1.695"],["45172.00","0"]],"u":20459233,"seq":114533117626},"cts":1704258152450}
{"topic":"orderbook.50.BTCUSDT","type":"delta","ts":1704258152472,"data":{"s":"BTCUSDT","b":[],"a":[["45167.50","3.763"],["45169.10","0"]],"u":20459234,"seq":114533117672},"cts":1704258152469}
{"topic":"orderbook.50.BTCUSDT","type":"delta","ts":1704258152492,"data":{"s":"BTCUSDT","b":[["45158.00","0.225"],["45156.00","1.774"]],"a":[["45167.20","0"],["45167.30","0.122"],["45172.00","0.114"]],"u":20459235,"seq":114533117709},"cts":1704258152490}
{"topic":"orderbook.50.BTCUSDT","type":"delta","ts":1704258152512,"data":{"s":"BTCUSDT","b":[],"a":[["45167.50","0"],["45172.10","0.176"]],"u":20459236,"seq":114533117742},"cts":1704258152509}
{"topic":"orderbook.50.BTCUSDT","type":"delta","ts":1704258152531,"data":{"s":"BTCUSDT","b":[["45160.40","0"],["45160.10","1.678"],["45158.70","0.095"],["45154.50","0.435"]],"a":[["45167.20","0.011"],["45167.30","0.111"],["45171.50","1.658"],["45172.10","0"]],"u":20459237,"seq":114533117795},"cts":1704258152528}
{"topic":"orderbook.50.BTCUSDT","type":"delta","ts":1704258152551,"data":{"s":"BTCUSDT","b":[["45160.30","1.007"],["45159.50","0"],["45154.90","0.221"],["45154.50","0"]],"a":[["45167.50","5.711"],["45172.00","0"]],"u":20459238,"seq":114533117844},"cts":1704258152550}
{"topic":"orderbook.50.BTCUSDT","type":"delta","ts":1704258152571,"data":{"s":"BTCUSDT","b":[],"a":[["45167.20","0"],["45167.40","0.011"],["45167.50","3.763"]],"u":20459239,"seq":114533117890},"cts":1704258152568}
{"topic":"orderbook.50.BTCUSDT","type":"delta","ts":1704258152592,"data":{"s":"BTCUSDT","b":[["45158.50","0.037"],["45154.60","0"]],"a":[["45167.50","0"],["45171.30","0.148"],["45172.00","0.114"]],"u":20459240,"seq":114533117936},"cts":1704258152589}
{"topic":"orderbook.50.BTCUSDT","type":"delta","ts":1704258152611,"data":{"s":"BTCUSDT","b":[],"a":[["45167.50","5.711"],["45168.00","0.231"],["45172.00","0"]],"u":20459241,"seq":114533118012},"cts":1704258152609}
{"topic":"orderbook.50.BTCUSDT","type":"delta","ts":1704258152632,"data":{"s":"BTCUSDT","b":[["45158.50","0"],["45154.60","0.110"]],"a":[["45167.20","0.011"],["45167.40","0"],["45171.30","0.111"]],"u":20459242,"seq":114533118057},"cts":1704258152630}
{"topic":"orderbook.50.BTCUSDT","type":"delta","ts":1704258152652,"data":{"s":"BTCUSDT","b":[],"a":[["45167.20","0"],["45167.40","0.011"],["45167.50","0"],["45172.00","0.114"]],"u":20459243,"seq":114533118106},"cts":1704258152650}
{"topic":"orderbook.50.BTCUSDT","type":"delta","ts":1704258152672,"data":{"s":"BTCUSDT","b":[],"a":[["45167.40","0"],["45167.50","3.763"]],"u":20459244,"seq":114533118159},"cts":1704258152669}
{"topic":"orderbook.50.BTCUSDT","type":"delta","ts":1704258152691,"data":{"s":"BTCUSDT","b":[["45158.90","0.149"]],"a":[["45167.20","0.011"],["45167.30","3.874"],["45167.50","0"],["45170.80","0.038"],["45172.00","0"]],"u":20459245,"seq":114533118208},"cts":1704258152690}
{"topic":"orderbook.50.BTCUSDT","type":"delta","ts":1704258152712,"data":{"s":"BTCUSDT","b":[],"a":[["45167.20","1.211"]],"u":20459246,"seq":114533118246},"cts":1704258152709}
{"topic":"orderbook.50.BTCUSDT","type":"delta","ts":1704258152731,"data":{"s":"BTCUSDT","b":[["45158.90","0.111"],["45155.30","0.379"]],"a":[["45167.20","4.974"],["45167.30","0.111"],["45170.80","0"],["45172.00","0.114"]],"u":20459247,"seq":114533118276},"cts":1704258152726}
{"topic":"orderbook.50.BTCUSDT","type":"delta","ts":1704258152752,"data":{"s":"BTCUSDT","b":[["45155.40","2.764"]],"a":[["45167.50","1.948"],["45172.00","0"]],"u":20459248,"seq":114533118320},"cts":1704258152749}
{"topic":"orderbook.50.BTCUSDT","type":"delta","ts":1704258152772,"data":{"s":"BTCUSDT","b":[["45160.40","1.600"],["45154.60","0"]],"a":[["45167.50","0"],["45172.00","0.114"]],"u":20459249,"seq":114533118363},"cts":1704258152769}
{"topic":"orderbook.50.BTCUSDT","type":"delta","ts":1704258152792,"data":{"s":"BTCUSDT","b":[["45159.00","0.115"]],"a":[["45167.20","1.200"],["45167.50","3.763"],["45170.10","0.122"],["45170.90","0.260"],["45172.00","0"]],"u":20459250,"seq":114533118402},"cts":1704258152789}
{"topic":"orderbook.50.BTCUSDT","type":"delta","ts":1704258152812,"data":{"s":"BTCUSDT","b":[],"a":[["45167.50","0"],["45170.10","0.111"],["45172.00","0.114"]],"u":20459251,"seq":114533118437},"cts":1704258152809}
{"topic":"orderbook.50.BTCUSDT","type":"delta","ts":1704258152831,"data":{"s":"BTCUSDT","b":[["45162.60","1.554"],["45159.00","0.077"],["45154.70","0"]],"a":[["45162.60","0"],["45164.00","0"],["45168.90","3.763"],["45170.70","1.366"],["45170.90","0.222"],["45171.40","0.354"],["45172.10","0.176"]],"u":20459252,"seq":114533118496},"cts":1704258152830}
{"topic":"orderbook.50.BTCUSDT","type":"delta","ts":1704258152851,"data":{"s":"BTCUSDT","b":[["45162.60","7.177"],["45162.50","0.833"],["45160.10","0.078"],["45158.00","1.425"],["45157.90","0"],["45156.40","0.051"],["45155.10","3.916"],["45154.60","0.110"]],"a":[["45164.00","0.113"],["45167.20","0"],["45167.70","0.079"],["45168.20","0.022"],["45168.40","0.137"],["45168.90","0"],["45169.00","0.126"],["45170.30","2.321"]],"u":20459253,"seq":114533118702},"cts":1704258152850}
{"topic":"orderbook.50.BTCUSDT","type":"delta","ts":1704258152871,"data":{"s":"BTCUSDT","b":[["45160.30","0"],["45159.50","0.306"],["45155.90","0"],["45155.70","2.463"],["45154.50","0.435"]],"a":[["45168.20","0"],["45168.40","0.115"],["45172.30","0.834"]],"u":20459254,"seq":114533118833},"cts":1704258152870}
{"topic":"orderbook.50.BTCUSDT","type":"delta","ts":1704258152891,"data":{"s":"BTCUSDT","b":[["45163.90","6.531"],["45162.60","4.213"],["45162.50","0.522"],["45162.40","0"],["45160.40","0"],["45156.40","1.556"],["45155.10","2.411"],["45154.40","0.685"]],"a":[["45162.70","0"],["45164.00","0.457"],["45168.20","0.022"],["45168.40","0.137"],["45169.60","0"],["45169.80","0.022"],["45170.00","0.224"],["45170.70","0.154"],["45170.90","0.111"],["45171.50","1.769"],["45171.70","2.452"]],"u":20459255,"seq":114533118992},"cts":1704258152890}
{"topic":"orderbook.50.BTCUSDT","type":"delta","ts":1704258152911,"data":{"s":"BTCUSDT","b":[["45163.90","6.731"],["45163.70","0.001"],["45162.60","1.997"],["45158.40","1.035"],["45155.70","1.775"],["45155.50","0.022"],["45154.60","0"],["45154.50","0"],["45154.40","0"]],"a":[["45165.30","0"],["45165.90","0.076"],["45168.00","0.242"],["45168.40","0.133"],["45168.90","3.763"],["45169.10","1.948"],["45169.50","0.010"],["45170.00","0.228"],["45171.00","0.111"],["45171.40","0.243"],["45171.90","0.115"],["45172.10","0"],["45172.30","0"]],"u":20459256,"seq":114533119165},"cts":1704258152909}
{"topic":"orderbook.50.BTCUSDT","type":"delta","ts":1704258152931,"data":{"s":"BTCUSDT","b":[["45159.50","0"],["45159.30","0.628"],["45156.00","1.884"],["45155.50","0"],["45154.60","0.110"]],"a":[["45168.00","0.231"],["45168.90","0"],["45169.10","0"],["45172.10","0.176"],["45172.30","0.834"]],"u":20459257,"seq":114533119268},"cts":1704258152930}
{"topic":"orderbook.50.BTCUSDT","type":"delta","ts":1704258152952,"data":{"s":"BTCUSDT","b":[["45163.90","6.131"],["45163.80","0.010"],["45158.40","1.878"],["45156.00","2.105"],["45154.60","0"]],"a":[["45164.10","0.010"],["45167.20","0.011"],["45167.50","3.763"],["45167.60","2.029"],["45172.00","0"],["45172.10","0"],["45172.30","0"]],"u":20459258,"seq":114533119373},"cts":1704258152949}
{"topic":"orderbook.50.BTCUSDT","type":"delta","ts":1704258152972,"data":{"s":"BTCUSDT","b":[["45159.30","1.048"]],"a":[],"u":20459259,"seq":114533119470},"cts":1704258152970}
{"topic":"orderbook.50.BTCUSDT","type":"delta","ts":1704258152992,"data":{"s":"BTCUSDT","b":[["45158.70","0.077"]],"a":[["45167.20","0"],["45167.50","0.011"],["45167.60","3.844"],["45167.90","1.952"],["45172.00","0.114"]],"u":20459260,"seq":114533119555},"cts":1704258152990}
{"topic":"orderbook.50.BTCUSDT","type":"delta","ts":1704258153012,"data":{"s":"BTCUSDT","b":[],"a":[["45167.50","3.774"],["45167.60","0.081"]],"u":20459261,"seq":114533119603},"cts":1704258153009}
{"topic":"orderbook.50.BTCUSDT","type":"delta","ts":1704258153032,"data":{"s":"BTCUSDT","b":[["45159.20","0.231"]],"a":[["45166.90","0.123"],["45167.60","0.159"]],"u":20459262,"seq":114533119653},"cts":1704258153030}
{"topic":"orderbook.50.BTCUSDT","type":"delta","ts":1704258153052,"data":{"s":"BTCUSDT","b":[["45163.90","6.145"],["45162.60","1.999"],["45162.50","0.490"]],"a":[["45167.50","0"],["45167.90","0.004"],["45169.40","3.763"],["45171.30","2.058"],["45171.40","0.254"]],"u":20459263,"seq":114533119715},"cts":1704258153049}
{"topic":"orderbook.50.BTCUSDT","type":"delta","ts":1704258153071,"data":{"s":"BTCUSDT","b":[],"a":[["45165.20","0.004"],["45166.80","0.001"],["45171.30","0.111"],["45172.00","0"]],"u":20459264,"seq":114533119762},"cts":1704258153070}
{"topic":"orderbook.50.BTCUSDT","type":"delta","ts":1704258153092,"data":{"s":"BTCUSDT","b":[["45159.20","0.193"]],"a":[["45167.50","3.763"],["45169.40","0"],["45171.30","2.058"]],"u":20459265,"seq":114533119813},"cts":1704258153090}
{"topic":"orderbook.50.BTCUSDT","type":"delta","ts":1704258153112,"data":{"s":"BTCUSDT","b":[],"a":[["45165.20","0.003"],["45166.80","0.003"]],"u":20459266,"seq":114533119861},"cts":1704258153110}
{"topic":"orderbook.50.BTCUSDT","type":"delta","ts":1704258153132,"data":{"s":"BTCUSDT","b":[["45159.20","0.231"],["45156.70","0.111"]],"a":[["45165.20","0.002"],["45167.50","0"],["45171.00","0.149"],["45171.30","0.111"],["45171.40","0.243"],["45172.00","0.114"]],"u":20459267,"seq":114533119915},"cts":1704258153129}
{"topic":"orderbook.50.BTCUSDT","type":"delta","ts":1704258153152,"data":{"s":"BTCUSDT","b":[["45163.90","7.516"],["45156.60","0.221"],["45155.40","3.264"],["45154.80","0"]],"a":[["45166.80","0.004"],["45167.50","0.011"],["45167.70","3.842"],["45172.00","0"]],"u":20459268,"seq":114533119962},"cts":1704258153148}
{"topic":"orderbook.50.BTCUSDT","type":"delta","ts":1704258153172,"data":{"s":"BTCUSDT","b":[],"a":[["45165.20","0"],["45166.80","0.005"],["45168.90","1.948"]],"u":20459269,"seq":114533120014},"cts":1704258153170}
{"topic":"orderbook.50.BTCUSDT","type":"delta","ts":1704258153191,"data":{"s":"BTCUSDT","b":[],"a":[["45167.50","0"],["45168.90","0"],["45169.80","0.033"],["45171.40","2.190"],["45172.00","0.114"],["45172.10","0.176"]],"u":20459270,"seq":114533120059},"cts":1704258153189}
{"topic":"orderbook.50.BTCUSDT","type":"delta","ts":1704258153212,"data":{"s":"BTCUSDT","b":[],"a":[["45167.70","0.079"],["45171.20","3.807"],["45171.40","0.243"]],"u":20459271,"seq":114533120098},"cts":1704258153209}
{"topic":"orderbook.50.BTCUSDT","type":"delta","ts":1704258153232,"data":{"s":"BTCUSDT","b":[],"a":[["45167.70","3.842"],["45168.90","1.948"],["45169.80","0.022"],["45171.20","0.044"],["45172.10","0"]],"u":20459272,"seq":114533120152},"cts":1704258153230}
{"topic":"orderbook.50.BTCUSDT","type":"delta","ts":1704258153252,"data":{"s":"BTCUSDT","b":[["45159.30","1.086"],["45159.20","0.193"]],"a":[["45167.60","0.170"],["45168.90","0"],["45172.10","0.176"]],"u":20459273,"seq":114533120205},"cts":1704258153249}
{"topic":"orderbook.50.BTCUSDT","type":"delta","ts":1704258153272,"data":{"s":"BTCUSDT","b":[["45162.50","0.480"]],"a":[["45167.70","0.079"],["45167.80","3.874"]],"u":20459274,"seq":114533120247},"cts":1704258153269}
{"topic":"orderbook.50.BTCUSDT","type":"delta","ts":1704258153291,"data":{"s":"BTCUSDT","b":[["45163.90","7.545"],["45161.70","1.600"],["45154.90","0"]],"a":[["45167.80","0.111"],["45171.20","3.807"]],"u":20459275,"seq":114533120297},"cts":1704258153290}
{"topic":"orderbook.50.BTCUSDT","type":"delta","ts":1704258153312,"data":{"s":"BTCUSDT","b":[],"a":[["45167.60","0.159"],["45167.70","0.090"],["45169.10","1.948"],["45171.20","0.044"],["45172.10","0"]],"u":20459276,"seq":114533120359},"cts":1704258153310}
{"topic":"orderbook.50.BTCUSDT","type":"delta","ts":1704258153332,"data":{"s":"BTCUSDT","b":[],"a":[["45167.70","0.079"],["45169.10","0"],["45169.60","3.763"]],"u":20459277,"seq":114533120425},"cts":1704258153329}
{"topic":"orderbook.50.BTCUSDT","type":"delta","ts":1704258153352,"data":{"s":"BTCUSDT","b":[["45157.20","1.879"]],"a":[["45169.60","0"],["45171.30","0.122"],["45171.40","4.005"],["45172.10","0.176"]],"u":20459278,"seq":114533120484},"cts":1704258153350}
{"topic":"orderbook.50.BTCUSDT","type":"delta","ts":1704258153371,"data":{"s":"BTCUSDT","b":[],"a":[["45171.40","0.243"]],"u":20459279,"seq":114533120534},"cts":1704258153370}
{"topic":"orderbook.50.BTCUSDT","type":"delta","ts":1704258153391,"data":{"s":"BTCUSDT","b":[],"a":[["45167.90","0.015"],["45168.90","3.763"],["45169.60","1.947"],["45171.30","0.111"],["45172.00","0"],["45172.10","0"]],"u":20459280,"seq":114533120589},"cts":1704258153390}
{"topic":"orderbook.50.BTCUSDT","type":"delta","ts":1704258153411,"data":{"s":"BTCUSDT","b":[["45155.00","0.410"]],"a":[["45169.60","0"],["45172.00","0.114"]],"u":20459281,"seq":114533120636},"cts":1704258153410}
{"topic":"orderbook.50.BTCUSDT","type":"delta","ts":1704258153431,"data":{"s":"BTCUSDT","b":[],"a":[["45169.50","1.957"],["45171.00","0.111"]],"u":20459282,"seq":114533120685},"cts":1704258153429}
{"topic":"orderbook.50.BTCUSDT","type":"delta","ts":1704258153452,"data":{"s":"BTCUSDT","b":[["45163.90","7.666"],["45162.50","0.355"]],"a":[["45169.50","0.010"],["45169.60","1.947"],["45170.90","0.149"],["45172.00","0"]],"u":20459283,"seq":114533120730},"cts":1704258153448}
{"topic":"orderbook.50.BTCUSDT","type":"delta","ts":1704258153492,"data":{"s":"BTCUSDT","b":[],"a":[["45169.60","0"],["45172.00","0.114"]],"u":20459284,"seq":114533120830},"cts":1704258153489}
{"topic":"orderbook.50.BTCUSDT","type":"delta","ts":1704258153531,"data":{"s":"BTCUSDT","b":[],"a":[["45170.90","0.111"]],"u":20459285,"seq":114533120913},"cts":1704258153529}
{"topic":"orderbook.50.BTCUSDT","type":"delta","ts":1704258153552,"data":{"s":"BTCUSDT","b":[],"a":[["45168.90","0"],["45169.10","3.763"],["45171.00","0.149"]],"u":20459286,"seq":114533120959},"cts":1704258153548}
{"topic":"orderbook.50.BTCUSDT","type":"delta","ts":1704258153571,"data":{"s":"BTCUSDT","b":[],"a":[["45164.00","0.344"]],"u":20459287,"seq":114533121037},"cts":1704258153570}
{"topic":"orderbook.50.BTCUSDT","type":"delta","ts":1704258153592,"data":{"s":"BTCUSDT","b":[["45158.70","0.095"]],"a":[],"u":20459288,"seq":114533121090},"cts":1704258153589}
{"topic":"orderbook.50.BTCUSDT","type":"delta","ts":1704258153612,"data":{"s":"BTCUSDT","b":[["45155.00","0.301"]],"a":[],"u":20459289,"seq":114533121136},"cts":1704258153610}
{"topic":"orderbook.50.BTCUSDT","type":"delta","ts":1704258153631,"data":{"s":"BTCUSDT","b":[["45159.30","1.048"]],"a":[["45169.10","0"],["45171.00","0.111"],["45172.10","0.176"]],"u":20459290,"seq":114533121182},"cts":1704258153629}
{"topic":"orderbook.50.BTCUSDT","type":"delta","ts":1704258153652,"data":{"s":"BTCUSDT","b":[["45162.10","1.600"],["45161.70","0"]],"a":[["45168.90","3.763"],["45172.10","0"]],"u":20459291,"seq":114533121247},"cts":1704258153650}
{"topic":"orderbook.50.BTCUSDT","type":"delta","ts":1704258153671,"data":{"s":"BTCUSDT","b":[],"a":[["45166.20","0.645"]],"u":20459292,"seq":114533121307},"cts":1704258153670}
{"topic":"orderbook.50.BTCUSDT","type":"delta","ts":1704258153692,"data":{"s":"BTCUSDT","b":[["45155.40","1.270"]],"a":[["45164.00","0.360"]],"u":20459293,"seq":114533121352},"cts":1704258153689}
{"topic":"orderbook.50.BTCUSDT","type":"delta","ts":1704258153711,"data":{"s":"BTCUSDT","b":[],"a":[["45169.60","1.947"],["45172.00","0"]],"u":20459294,"seq":114533121397},"cts":1704258153710}
{"topic":"orderbook.50.BTCUSDT","type":"delta","ts":1704258153731,"data":{"s":"BTCUSDT","b":[],"a":[["45168.90","0"],["45169.10","3.763"]],"u":20459295,"seq":114533121448},"cts":1704258153729}
{"topic":"orderbook.50.BTCUSDT","type":"delta","ts":1704258153752,"data":{"s":"BTCUSDT","b":[],"a":[["45169.60","0"],["45172.00","0.114"]],"u":20459296,"seq":114533121488},"cts":1704258153749}
{"topic":"orderbook.50.BTCUSDT","type":"delta","ts":1704258153771,"data":{"s":"BTCUSDT","b":[],"a":[["45169.10","0"],["45172.10","0.176"]],"u":20459297,"seq":114533121538},"cts":1704258153770}
{"topic":"orderbook.50.BTCUSDT","type":"delta","ts":1704258153792,"data":{"s":"BTCUSDT","b":[],"a":[["45169.10","3.763"],["45171.00","0.150"],["45172.10","0"]],"u":20459298,"seq":114533121579},"cts":1704258153789}
{"topic":"orderbook.50.BTCUSDT","type":"delta","ts":1704258153811,"data":{"s":"BTCUSDT","b":[],"a":[["45167.90","0.004"],["45169.10","0"],["45172.10","0.176"]],"u":20459299,"seq":114533121626},"cts":1704258153810}
{"topic":"orderbook.50.BTCUSDT","type":"delta","ts":1704258153832,"data":{"s":"BTCUSDT","b":[],"a":[["45169.10","3.763"],["45171.00","0.111"],["45172.10","0"]],"u":20459300,"seq":114533121677},"cts":1704258153830}
{"topic":"orderbook.50.BTCUSDT","type":"delta","ts":1704258153852,"data":{"s":"BTCUSDT","b":[],"a":[["45168.90","0.011"],["45169.00","3.889"],["45169.10","0"],["45169.60","1.947"],["45172.00","0"]],"u":20459301,"seq":114533121729},"cts":1704258153849}
{"topic":"orderbook.50.BTCUSDT","type":"delta","ts":1704258153871,"data":{"s":"BTCUSDT","b":[["45163.90","6.066"],["45162.60","0.399"],["45157.20","1.658"],["45156.60","0"],["45154.90","0.221"]],"a":[["45164.00","0.473"],["45167.90","0.015"],["45168.90","0"],["45169.00","0.126"],["45169.10","3.763"]],"u":20459302,"seq":114533121789},"cts":1704258153870}
{"topic":"orderbook.50.BTCUSDT","type":"delta","ts":1704258153891,"data":{"s":"BTCUSDT","b":[["45159.70","0.166"]],"a":[["45169.60","0"],["45170.80","0.039"]],"u":20459303,"seq":114533121839},"cts":1704258153888}
{"topic":"orderbook.50.BTCUSDT","type":"delta","ts":1704258153912,"data":{"s":"BTCUSDT","b":[["45161.20","1.600"],["45154.90","0"]],"a":[["45168.90","3.763"],["45169.10","0"]],"u":20459304,"seq":114533121884},"cts":1704258153910}
{"topic":"orderbook.50.BTCUSDT","type":"delta","ts":1704258153932,"data":{"s":"BTCUSDT","b":[["45159.70","0.127"]],"a":[["45170.80","0"],["45172.00","0.114"]],"u":20459305,"seq":114533121940},"cts":1704258153929}
{"topic":"orderbook.50.BTCUSDT","type":"delta","ts":1704258153971,"data":{"s":"BTCUSDT","b":[],"a":[["45167.90","0.004"],["45168.90","0.011"],["45169.10","3.763"],["45172.00","0"]],"u":20459306,"seq":114533122021},"cts":1704258153970}
{"topic":"orderbook.50.BTCUSDT","type":"delta","ts":1704258153992,"data":{"s":"BTCUSDT","b":[["45159.50","0.039"],["45155.00","0"]],"a":[["45170.60","0.061"]],"u":20459307,"seq":114533122064},"cts":1704258153990}
{"topic":"orderbook.50.BTCUSDT","type":"delta","ts":1704258154011,"data":{"s":"BTCUSDT","b":[],"a":[["45164.00","0.360"],["45168.90","0"],["45172.00","0.114"]],"u":20459308,"seq":114533122133},"cts":1704258154010}
{"topic":"orderbook.50.BTCUSDT","type":"delta","ts":1704258154032,"data":{"s":"BTCUSDT","b":[["45159.50","0"],["45155.00","0.301"]],"a":[["45170.60","0.022"]],"u":20459309,"seq":114533122182},"cts":1704258154029}
{"topic":"orderbook.50.BTCUSDT","type":"delta","ts":1704258154052,"data":{"s":"BTCUSDT","b":[["45163.90","6.082"]],"a":[["45171.60","0.664"]],"u":20459310,"seq":114533122226},"cts":1704258154049}
{"topic":"orderbook.50.BTCUSDT","type":"delta","ts":1704258154072,"data":{"s":"BTCUSDT","b":[],"a":[["45168.90","0.011"],["45169.10","0"]],"u":20459311,"seq":114533122271},"cts":1704258154070}
{"topic":"orderbook.50.BTCUSDT","type":"delta","ts":1704258154091,"data":{"s":"BTCUSDT","b":[["45159.70","0.166"]],"a":[["45168.90","0"],["45169.00","0.137"],["45170.80","0.039"]],"u":20459312,"seq":114533122317},"cts":1704258154090}
{"topic":"orderbook.50.BTCUSDT","type":"delta","ts":1704258154111,"data":{"s":"BTCUSDT","b":[["45162.60","0.449"]],"a":[["45169.10","3.763"],["45172.00","0"]],"u":20459313,"seq":114533122357},"cts":1704258154109}
{"topic":"orderbook.50.BTCUSDT","type":"delta","ts":1704258154132,"data":{"s":"BTCUSDT","b":[["45159.70","0.127"]],"a":[["45170.80","0"],["45172.00","0.114"]],"u":20459314,"seq":114533122400},"cts":1704258154129}
{"topic":"orderbook.50.BTCUSDT","type":"delta","ts":1704258154152,"data":{"s":"BTCUSDT","b":[["45156.60","0.221"],["45155.00","0"]],"a":[["45169.00","3.900"],["45169.10","0"],["45172.10","0.176"]],"u":20459315,"seq":114533122443},"cts":1704258154149}
{"topic":"orderbook.50.BTCUSDT","type":"delta","ts":1704258154171,"data":{"s":"BTCUSDT","b":[["45161.40","1.600"],["45155.10","0"]],"a":[["45169.00","0.126"],["45169.10","3.763"],["45169.60","1.947"],["45172.00","0"],["45172.10","0"]],"u":20459316,"seq":114533122492},"cts":1704258154169}
{"topic":"orderbook.50.BTCUSDT","type":"delta","ts":1704258154192,"data":{"s":"BTCUSDT","b":[],"a":[["45168.90","0.011"],["45171.90","0"]],"u":20459317,"seq":114533122534},"cts":1704258154189}
{"topic":"orderbook.50.BTCUSDT","type":"delta","ts":1704258154212,"data":{"s":"BTCUSDT","b":[],"a":[["45169.60","0"],["45171.90","0.115"]],"u":20459318,"seq":114533122582},"cts":1704258154209}
{"topic":"orderbook.50.BTCUSDT","type":"delta","ts":1704258154232,"data":{"s":"BTCUSDT","b":[["45159.80","0.039"],["45155.20","0"]],"a":[["45166.30","0"],["45168.20","0.066"],["45169.00","3.889"],["45169.10","0"],["45170.80","0.039"],["45172.00","0.114"]],"u":20459319,"seq":114533122631},"cts":1704258154229}
{"topic":"orderbook.50.BTCUSDT","type":"delta","ts":1704258154252,"data":{"s":"BTCUSDT","b":[["45157.10","0.221"],["45156.40","0.051"],["45155.30","0"]],"a":[["45168.90","0"],["45169.00","0.126"],["45172.10","0.176"]],"u":20459320,"seq":114533122678},"cts":1704258154250}
{"topic":"orderbook.50.BTCUSDT","type":"delta","ts":1704258154291,"data":{"s":"BTCUSDT","b":[],"a":[["45169.00","0.137"],["45169.10","3.763"],["45172.10","0"]],"u":20459321,"seq":114533122796},"cts":1704258154290}
{"topic":"orderbook.50.BTCUSDT","type":"delta","ts":1704258154331,"data":{"s":"BTCUSDT","b":[["45159.80","0"],["45155.30","0.379"]],"a":[["45169.00","0.126"],["45169.10","0"],["45170.80","0"],["45172.10","0.176"],["45172.30","1.066"]],"u":20459322,"seq":114533122882},"cts":1704258154329}
{"topic":"orderbook.50.BTCUSDT","type":"delta","ts":1704258154352,"data":{"s":"BTCUSDT","b":[["45159.70","0.166"],["45156.40","1.556"]],"a":[["45169.10","3.774"],["45169.60","1.947"],["45170.70","0.193"],["45172.10","0"],["45172.30","0"]],"u":20459323,"seq":114533122944},"cts":1704258154350}
{"topic":"orderbook.50.BTCUSDT","type":"delta","ts":1704258154392,"data":{"s":"BTCUSDT","b":[["45163.90","6.053"]],"a":[["45169.60","0"],["45172.10","0.176"]],"u":20459324,"seq":114533123025},"cts":1704258154389}
{"topic":"orderbook.50.BTCUSDT","type":"delta","ts":1704258154412,"data":{"s":"BTCUSDT","b":[["45163.90","6.088"],["45161.70","1.600"],["45161.20","0"]],"a":[["45169.00","3.889"],["45169.10","0"],["45172.30","1.066"]],"u":20459325,"seq":114533123077},"cts":1704258154410}
{"topic":"orderbook.50.BTCUSDT","type":"delta","ts":1704258154432,"data":{"s":"BTCUSDT","b":[["45159.70","0.127"],["45157.40","0.176"]],"a":[["45164.00","0.060"],["45169.00","0.126"],["45169.60","1.958"],["45170.70","0.154"],["45171.60","0.443"],["45172.30","0"]],"u":20459326,"seq":114533123157},"cts":1704258154430}
{"topic":"orderbook.50.BTCUSDT","type":"delta","ts":1704258154451,"data":{"s":"BTCUSDT","b":[["45163.90","7.167"],["45160.00","0.420"],["45157.60","0.221"],["45155.30","0"]],"a":[["45166.20","0.445"],["45169.60","0.011"],["45171.00","0.150"]],"u":20459327,"seq":114533123276},"cts":1704258154450}
{"topic":"orderbook.50.BTCUSDT","type":"delta","ts":1704258154472,"data":{"s":"BTCUSDT","b":[["45163.90","7.289"],["45161.60","2.054"],["45160.00","0.381"]],"a":[["45164.00","0.016"],["45165.40","0"],["45166.00","0.001"],["45168.10","0.411"],["45168.20","0.044"],["45168.40","0.111"],["45169.90","1.561"],["45170.30","1.121"],["45171.00","0.111"],["45171.10","0.446"],["45172.00","0.557"],["45172.30","1.100"]],"u":20459328,"seq":114533123385},"cts":1704258154469}
{"topic":"orderbook.50.BTCUSDT","type":"delta","ts":1704258154492,"data":{"s":"BTCUSDT","b":[["45165.80","7.146"],["45165.30","0.080"],["45164.90","1.400"],["45164.80","0.003"],["45164.00","4.179"],["45163.90","2.198"],["45162.60","0.052"],["45161.40","0"],["45158.30","1.505"],["45157.90","0.004"],["45156.40","0.051"],["45156.30","0"],["45156.00","0"],["45155.80","0"],["45155.70","0"],["45155.60","0"],["45155.40","0"]],"a":[["45164.00","0"],["45164.10","0"],["45165.00","0"],["45165.90","0.015"],["45167.90","0"],["45168.60","0.111"],["45169.50","0"],["45169.60","0"],["45169.70","0.082"],["45169.90","0.943"],["45170.00","0.224"],["45170.30","0.921"],["45170.40","0.543"],["45170.80","0.100"],["45171.10","0.443"],["45171.70","0.804"],["45172.20","0.100"],["45172.30","1.104"],["45172.40","0.111"],["45172.50","0.454"],["45172.60","0.266"],["45172.70","0.267"]],"u":20459329,"seq":114533123888},"cts":1704258154489}
{"topic":"orderbook.50.BTCUSDT","type":"delta","ts":1704258154512,"data":{"s":"BTCUSDT","b":[["45165.80","4.460"],["45165.30","0.052"],["45164.90","0"],["45164.80","0"],["45164.00","2.937"],["45163.90","1.887"],["45162.20","0.078"],["45160.30","0.629"],["45160.10","0"],["45159.90","0.087"],["45156.30","1.674"]],"a":[["45165.90","1.010"],["45166.20","0.066"],["45166.90","0.076"],["45169.20","0.300"],["45169.40","0.022"],["45169.60","0.022"],["45169.70","0.026"],["45169.80","0"],["45170.30","0.721"],["45170.40","0.443"],["45170.70","0.110"],["45170.80","0"],["45170.90","0"],["45171.00","0"],["45171.40","0.324"],["45171.50","1.658"],["45171.70","0.401"],["45172.20","0"],["45172.40","0"],["45172.50","0.565"],["45172.80","2.520"],["45172.90","0.820"],["45173.00","0.044"],["45173.10","1.233"]],"u":20459330,"seq":114533124151},"cts":1704258154510}
{"topic":"orderbook.50.BTCUSDT","type":"delta","ts":1704258154532,"data":{"s":"BTCUSDT","b":[["45165.30","0.024"],["45164.10","0.670"],["45164.00","1.713"],["45156.30","0"]],"a":[["45167.60","0.270"],["45167.90","0.111"],["45169.60","0.133"],["45170.90","0.111"],["45172.50","0.554"],["45173.00","0"],["45173.10","0"]],"u":20459331,"seq":114533124293},"cts":1704258154529}
{"topic":"orderbook.50.BTCUSDT","type":"delta","ts":1704258154552,"data":{"s":"BTCUSDT","b":[["45163.80","0"],["45160.30","1.472"],["45158.30","0"],["45158.10","1.615"],["45156.30","1.674"],["45156.20","0.697"]],"a":[["45166.00","0.114"]],"u":20459332,"seq":114533124395},"cts":1704258154550}
{"topic":"orderbook.50.BTCUSDT","type":"delta","ts":1704258154571,"data":{"s":"BTCUSDT","b":[["45162.50","0.405"],["45161.00","0.040"],["45156.20","0"]],"a":[["45168.30","0.001"],["45169.50","3.763"],["45169.60","0.144"],["45169.80","1.947"],["45171.60","0.483"],["45172.70","0"],["45172.80","0"],["45172.90","0"]],"u":20459333,"seq":114533124515},"cts":1704258154570}
{"topic":"orderbook.50.BTCUSDT","type":"delta","ts":1704258154591,"data":{"s":"BTCUSDT","b":[["45163.60","0.078"],["45162.20","0"]],"a":[["45166.80","0.004"],["45168.30","0.002"],["45169.50","0"],["45169.60","3.896"],["45169.80","0"],["45172.70","0.267"],["45172.80","2.520"]],"u":20459334,"seq":114533124604},"cts":1704258154589}
{"topic":"orderbook.50.BTCUSDT","type":"delta","ts":1704258154611,"data":{"s":"BTCUSDT","b":[],"a":[["45169.80","0.011"],["45172.80","0"]],"u":20459335,"seq":114533124662},"cts":1704258154609}
{"topic":"orderbook.50.BTCUSDT","type":"delta","ts":1704258154632,"data":{"s":"BTCUSDT","b":[["45165.30","0"],["45162.60","0.130"],["45161.00","0"],["45159.90","0.011"],["45158.30","0.082"],["45158.10","1.725"],["45156.20","0.697"]],"a":[["45166.80","0.003"],["45168.20","0.120"],["45168.30","0.003"],["45168.50","0.047"],["45169.60","0.133"],["45169.80","0"],["45171.60","0.443"],["45172.60","0.277"]],"u":20459336,"seq":114533124739},"cts":1704258154630}
{"topic":"orderbook.50.BTCUSDT","type":"delta","ts":1704258154651,"data":{"s":"BTCUSDT","b":[["45165.80","4.626"],["45164.10","0"],["45158.10","1.946"],["45156.00","2.105"]],"a":[["45166.80","0.002"],["45167.60","0.111"],["45168.30","0.004"],["45172.60","0.266"]],"u":20459337,"seq":114533124807},"cts":1704258154650}
{"topic":"orderbook.50.BTCUSDT","type":"delta","ts":1704258154672,"data":{"s":"BTCUSDT","b":[["45160.70","0.040"],["45156.00","0"]],"a":[["45165.90","1.113"],["45168.30","0.005"],["45171.40","0.364"]],"u":20459338,"seq":114533124872},"cts":1704258154670}
{"topic":"orderbook.50.BTCUSDT","type":"delta","ts":1704258154692,"data":{"s":"BTCUSDT","b":[],"a":[["45168.30","0.006"]],"u":20459339,"seq":114533124925},"cts":1704258154689}
{"topic":"orderbook.50.BTCUSDT","type":"delta","ts":1704258154711,"data":{"s":"BTCUSDT","b":[],"a":[["45166.80","0"],["45172.70","4.029"],["45172.80","2.520"]],"u":20459340,"seq":114533124978},"cts":1704258154710}
{"topic":"orderbook.50.BTCUSDT","type":"delta","ts":1704258154731,"data":{"s":"BTCUSDT","b":[["45165.80","5.857"],["45162.60","1.730"],["45161.70","0"],["45160.70","0"],["45156.00","2.105"],["45155.90","0.629"]],"a":[["45172.70","0.267"]],"u":20459341,"seq":114533125044},"cts":1704258154730}
{"topic":"orderbook.50.BTCUSDT","type":"delta","ts":1704258154751,"data":{"s":"BTCUSDT","b":[],"a":[["45165.90","1.010"],["45169.50","0.078"],["45172.70","4.029"],["45172.80","0"]],"u":20459342,"seq":114533125129},"cts":1704258154750}
{"topic":"orderbook.50.BTCUSDT","type":"delta","ts":1704258154771,"data":{"s":"BTCUSDT","b":[["45160.80","0.040"],["45155.90","0"]],"a":[],"u":20459343,"seq":114533125195},"cts":1704258154769}
{"topic":"orderbook.50.BTCUSDT","type":"delta","ts":1704258154792,"data":{"s":"BTCUSDT","b":[],"a":[["45169.10","0.076"],["45172.70","0"]],"u":20459344,"seq":114533125256},"cts":1704258154790}
{"topic":"orderbook.50.BTCUSDT","type":"delta","ts":1704258154831,"data":{"s":"BTCUSDT","b":[["45163.70","0"],["45158.80","0.222"],["45155.90","0.629"]],"a":[],"u":20459345,"seq":114533125373},"cts":1704258154829}
{"topic":"orderbook.50.BTCUSDT","type":"delta","ts":1704258154851,"data":{"s":"BTCUSDT","b":[["45158.60","0.729"]],"a":[],"u":20459346,"seq":114533125434},"cts":1704258154850}
{"topic":"orderbook.50.BTCUSDT","type":"delta","ts":1704258154871,"data":{"s":"BTCUSDT","b":[["45165.80","5.847"]],"a":[["45165.90","1.054"]],"u":20459347,"seq":114533125522},"cts":1704258154869}
{"topic":"orderbook.50.BTCUSDT","type":"delta","ts":1704258154911,"data":{"s":"BTCUSDT","b":[["45164.00","0.113"]],"a":[["45165.90","1.554"]],"u":20459348,"seq":114533125627},"cts":1704258154909}
{"topic":"orderbook.50.BTCUSDT","type":"delta","ts":1704258154932,"data":{"s":"BTCUSDT","b":[["45161.60","0.854"],["45160.80","0"],["45155.80","0.002"]],"a":[["45165.90","1.573"],["45170.50","1.225"],["45171.40","0.324"]],"u":20459349,"seq":114533125692},"cts":1704258154929}
{"topic":"orderbook.50.BTCUSDT","type":"delta","ts":1704258154952,"data":{"s":"BTCUSDT","b":[["45160.50","0.040"],["45156.10","0.500"],["45155.90","0"],["45155.80","0"]],"a":[["45165.90","1.638"],["45166.20","0"],["45171.10","0.483"],["45172.70","0.266"]],"u":20459350,"seq":114533125732},"cts":1704258154949}
{"topic":"orderbook.50.BTCUSDT","type":"delta","ts":1704258154971,"data":{"s":"BTCUSDT","b":[["45165.80","5.882"],["45163.90","1.852"],["45160.50","0"],["45155.90","0.629"]],"a":[["45165.90","1.694"]],"u":20459351,"seq":114533125765},"cts":1704258154970}
{"topic":"orderbook.50.BTCUSDT","type":"delta","ts":1704258154991,"data":{"s":"BTCUSDT","b":[["45165.80","5.868"],["45161.70","1.600"],["45155.90","0"]],"a":[["45165.90","1.722"],["45168.30","0.005"]],"u":20459352,"seq":114533125818},"cts":1704258154989}
{"topic":"orderbook.50.BTCUSDT","type":"delta","ts":1704258155011,"data":{"s":"BTCUSDT","b":[],"a":[["45165.90","1.666"]],"u":20459353,"seq":114533125857},"cts":1704258155010}
{"topic":"orderbook.50.BTCUSDT","type":"delta","ts":1704258155032,"data":{"s":"BTCUSDT","b":[["45163.90","1.836"]],"a":[["45171.10","0.443"]],"u":20459354,"seq":114533125902},"cts":1704258155029}
{"topic":"orderbook.50.BTCUSDT","type":"delta","ts":1704258155052,"data":{"s":"BTCUSDT","b":[["45163.90","0.622"],["45160.60","0.040"],["45156.00","0"]],"a":[["45171.30","0.151"]],"u":20459355,"seq":114533125947},"cts":1704258155049}
{"topic":"orderbook.50.BTCUSDT","type":"delta","ts":1704258155091,"data":{"s":"BTCUSDT","b":[],"a":[["45169.40","0.100"]],"u":20459356,"seq":114533126008},"cts":1704258155089}
{"topic":"orderbook.50.BTCUSDT","type":"delta","ts":1704258155132,"data":{"s":"BTCUSDT","b":[["45163.60","0.128"],["45160.60","0"],["45156.00","2.105"]],"a":[["45171.30","0.111"]],"u":20459357,"seq":114533126067},"cts":1704258155129}
{"topic":"orderbook.50.BTCUSDT","type":"delta","ts":1704258155172,"data":{"s":"BTCUSDT","b":[["45165.80","5.882"],["45160.50","0.040"],["45156.00","0"]],"a":[["45171.00","0.040"],["45172.70","0"]],"u":20459358,"seq":114533126132},"cts":1704258155169}
{"topic":"orderbook.50.BTCUSDT","type":"delta","ts":1704258155191,"data":{"s":"BTCUSDT","b":[["45160.00","0.464"],["45157.70","0"],["45156.00","2.105"]],"a":[],"u":20459359,"seq":114533126163},"cts":1704258155190}
{"topic":"orderbook.50.BTCUSDT","type":"delta","ts":1704258155211,"data":{"s":"BTCUSDT","b":[["45162.70","0.001"],["45156.00","0"]],"a":[],"u":20459360,"seq":114533126209},"cts":1704258155210}
{"topic":"orderbook.50.BTCUSDT","type":"delta","ts":1704258155232,"data":{"s":"BTCUSDT","b":[["45162.70","0.901"],["45161.70","0"],["45160.50","0"],["45156.00","2.105"],["45155.90","0.629"]],"a":[["45171.00","0"],["45172.70","0.266"]],"u":20459361,"seq":114533126245},"cts":1704258155228}
{"topic":"orderbook.50.BTCUSDT","type":"delta","ts":1704258155272,"data":{"s":"BTCUSDT","b":[["45160.60","0.040"],["45156.10","0"]],"a":[["45171.20","0.084"]],"u":20459362,"seq":114533126301},"cts":1704258155270}
{"topic":"orderbook.50.BTCUSDT","type":"delta","ts":1704258155292,"data":{"s":"BTCUSDT","b":[],"a":[["45165.90","1.638"]],"u":20459363,"seq":114533126330},"cts":1704258155289}
{"topic":"orderbook.50.BTCUSDT","type":"delta","ts":1704258155312,"data":{"s":"BTCUSDT","b":[],"a":[["45168.30","0.006"]],"u":20459364,"seq":114533126361},"cts":1704258155309}
{"topic":"orderbook.50.BTCUSDT","type":"delta","ts":1704258155332,"data":{"s":"BTCUSDT","b":[["45160.60","0"],["45155.80","0.002"]],"a":[["45168.20","0.076"],["45170.00","0.268"],["45171.20","0.044"]],"u":20459365,"seq":114533126391},"cts":1704258155329}
{"topic":"orderbook.50.BTCUSDT","type":"delta","ts":1704258155472,"data":{"s":"BTCUSDT","b":[["45163.90","0.500"]],"a":[],"u":20459366,"seq":114533126580},"cts":1704258155469}
{"topic":"orderbook.50.BTCUSDT","type":"delta","ts":1704258155492,"data":{"s":"BTCUSDT","b":[["45165.80","6.012"]],"a":[],"u":20459367,"seq":114533126605},"cts":1704258155489}
{"topic":"orderbook.50.BTCUSDT","type":"delta","ts":1704258155512,"data":{"s":"BTCUSDT","b":[["45162.80","0.001"],["45162.70","0.900"],["45155.80","0"]],"a":[],"u":20459368,"seq":114533126636},"cts":1704258155510}
{"topic":"orderbook.50.BTCUSDT","type":"delta","ts":1704258155532,"data":{"s":"BTCUSDT","b":[["45165.80","6.011"]],"a":[],"u":20459369,"seq":114533126674},"cts":1704258155529}
{"topic":"orderbook.50.BTCUSDT","type":"delta","ts":1704258155571,"data":{"s":"BTCUSDT","b":[["45164.10","0.001"],["45162.80","0.003"],["45158.70","0.077"],["45158.60","0.508"],["45158.10","1.725"],["45157.60","0"]],"a":[["45165.90","1.694"],["45168.30","0.005"]],"u":20459370,"seq":114533126750},"cts":1704258155570}
{"topic":"orderbook.50.BTCUSDT","type":"delta","ts":1704258155591,"data":{"s":"BTCUSDT","b":[["45165.80","5.997"],["45164.10","0"],["45163.60","0.178"],["45162.90","1.200"],["45162.80","0"],["45162.10","0"],["45155.80","0.002"],["45155.70","1.775"]],"a":[["45165.90","1.703"],["45166.00","0.001"],["45168.30","0.004"]],"u":20459371,"seq":114533126817},"cts":1704258155590}
{"topic":"orderbook.50.BTCUSDT","type":"delta","ts":1704258155612,"data":{"s":"BTCUSDT","b":[["45163.70","0.721"],["45155.70","0"]],"a":[["45165.90","1.638"],["45168.30","0.005"],["45171.40","0.739"]],"u":20459372,"seq":114533126870},"cts":1704258155609}
{"topic":"orderbook.50.BTCUSDT","type":"delta","ts":1704258155632,"data":{"s":"BTCUSDT","b":[["45160.50","0.040"],["45155.80","0"]],"a":[["45171.90","0.155"]],"u":20459373,"seq":114533126923},"cts":1704258155629}
{"topic":"orderbook.50.BTCUSDT","type":"delta","ts":1704258155652,"data":{"s":"BTCUSDT","b":[["45160.50","0"],["45155.80","0.002"]],"a":[["45171.90","0.115"]],"u":20459374,"seq":114533126958},"cts":1704258155649}
{"topic":"orderbook.50.BTCUSDT","type":"delta","ts":1704258155692,"data":{"s":"BTCUSDT","b":[],"a":[["45166.00","0.114"]],"u":20459375,"seq":114533127006},"cts":1704258155689}
{"topic":"orderbook.50.BTCUSDT","type":"delta","ts":1704258155771,"data":{"s":"BTCUSDT","b":[["45160.60","0.040"],["45155.80","0"]],"a":[["45172.00","0.597"]],"u":20459376,"seq":114533127109},"cts":1704258155769}
{"topic":"orderbook.50.BTCUSDT","type":"delta","ts":1704258155811,"data":{"s":"BTCUSDT","b":[["45163.00","0.001"],["45157.00","2.303"],["45155.90","0"]],"a":[["45168.30","0.006"]],"u":20459377,"seq":114533127168},"cts":1704258155810}
{"topic":"orderbook.50.BTCUSDT","type":"delta","ts":1704258155831,"data":{"s":"BTCUSDT","b":[["45163.10","1.600"],["45162.90","0"]],"a":[],"u":20459378,"seq":114533127203},"cts":1704258155828}
{"topic":"orderbook.50.BTCUSDT","type":"delta","ts":1704258155852,"data":{"s":"BTCUSDT","b":[["45157.70","0.221"],["45156.00","0"]],"a":[],"u":20459379,"seq":114533127229},"cts":1704258155849}
{"topic":"orderbook.50.BTCUSDT","type":"delta","ts":1704258155911,"data":{"s":"BTCUSDT","b":[["45163.70","0.722"],["45163.10","0"],["45162.60","0.130"],["45156.00","2.105"]],"a":[],"u":20459380,"seq":114533127312},"cts":1704258155910}
{"topic":"orderbook.50.BTCUSDT","type":"delta","ts":1704258155932,"data":{"s":"BTCUSDT","b":[["45163.70","0.001"],["45162.70","0"],["45160.60","0"],["45155.90","0.629"],["45155.80","0.002"]],"a":[["45172.00","0.557"]],"u":20459381,"seq":114533127350},"cts":1704258155929}
{"topic":"orderbook.50.BTCUSDT","type":"delta","ts":1704258155952,"data":{"s":"BTCUSDT","b":[["45160.70","0.040"],["45155.80","0"]],"a":[["45172.10","0.216"]],"u":20459382,"seq":114533127381},"cts":1704258155949}
{"topic":"orderbook.50.BTCUSDT","type":"delta","ts":1704258156012,"data":{"s":"BTCUSDT","b":[["45162.70","0.001"],["45155.90","0"]],"a":[["45165.90","1.750"]],"u":20459383,"seq":114533127455},"cts":1704258156009}
{"topic":"orderbook.50.BTCUSDT","type":"delta","ts":1704258156031,"data":{"s":"BTCUSDT","b":[["45164.10","0.001"],["45162.70","0.003"],["45160.70","0"]],"a":[["45165.90","2.292"],["45172.10","0.176"]],"u":20459384,"seq":114533127506},"cts":1704258156030}
{"topic":"orderbook.50.BTCUSDT","type":"delta","ts":1704258156052,"data":{"s":"BTCUSDT","b":[["45165.80","6.157"],["45162.70","0.004"]],"a":[],"u":20459385,"seq":114533127546},"cts":1704258156050}
{"topic":"orderbook.50.BTCUSDT","type":"delta","ts":1704258156072,"data":{"s":"BTCUSDT","b":[["45160.90","0.040"],["45156.00","0"]],"a":[["45172.20","0.040"],["45172.70","0"]],"u":20459386,"seq":114533127588},"cts":1704258156069}
{"topic":"orderbook.50.BTCUSDT","type":"delta","ts":1704258156092,"data":{"s":"BTCUSDT","b":[["45165.80","6.123"],["45162.60","1.180"]],"a":[],"u":20459387,"seq":114533127620},"cts":1704258156089}
{"topic":"orderbook.50.BTCUSDT","type":"delta","ts":1704258156112,"data":{"s":"BTCUSDT","b":[["45165.80","6.162"],["45163.00","0"],["45162.70","0.005"],["45156.00","2.105"]],"a":[],"u":20459388,"seq":114533127655},"cts":1704258156110}
{"topic":"orderbook.50.BTCUSDT","type":"delta","ts":1704258156131,"data":{"s":"BTCUSDT","b":[["45160.90","0"],["45155.90","0.629"]],"a":[["45172.20","0"],["45172.70","0.266"]],"u":20459389,"seq":114533127693},"cts":1704258156129}
{"topic":"orderbook.50.BTCUSDT","type":"delta","ts":1704258156171,"data":{"s":"BTCUSDT","b":[["45165.80","6.160"]],"a":[],"u":20459390,"seq":114533127767},"cts":1704258156169}
{"topic":"orderbook.50.BTCUSDT","type":"delta","ts":1704258156191,"data":{"s":"BTCUSDT","b":[],"a":[["45167.80","1.711"]],"u":20459391,"seq":114533127809},"cts":1704258156189}
{"topic":"orderbook.50.BTCUSDT","type":"delta","ts":1704258156212,"data":{"s":"BTCUSDT","b":[["45163.90","0.550"]],"a":[["45167.80","0.111"]],"u":20459392,"seq":114533127843},"cts":1704258156209}
{"topic":"orderbook.50.BTCUSDT","type":"delta","ts":1704258156231,"data":{"s":"BTCUSDT","b":[["45162.70","0.006"]],"a":[],"u":20459393,"seq":114533127878},"cts":1704258156230}
{"topic":"orderbook.50.BTCUSDT","type":"delta","ts":1704258156252,"data":{"s":"BTCUSDT","b":[],"a":[["45171.70","0.441"]],"u":20459394,"seq":114533127908},"cts":1704258156250}
{"topic":"orderbook.50.BTCUSDT","type":"delta","ts":1704258156351,"data":{"s":"BTCUSDT","b":[["45163.70","0"],["45162.10","1.600"]],"a":[],"u":20459395,"seq":114533128044},"cts":1704258156349}
{"topic":"orderbook.50.BTCUSDT","type":"delta","ts":1704258156372,"data":{"s":"BTCUSDT","b":[["45160.80","0.040"],["45158.70","0.095"],["45155.90","0"]],"a":[],"u":20459396,"seq":114533128075},"cts":1704258156369}
{"topic":"orderbook.50.BTCUSDT","type":"delta","ts":1704258156432,"data":{"s":"BTCUSDT","b":[["45160.80","0"],["45155.90","0.629"]],"a":[],"u":20459397,"seq":114533128149},"cts":1704258156429}
{"topic":"orderbook.50.BTCUSDT","type":"delta","ts":1704258156472,"data":{"s":"BTCUSDT","b":[["45160.90","0.040"],["45155.90","0"]],"a":[["45172.30","1.034"]],"u":20459398,"seq":114533128197},"cts":1704258156469}
{"topic":"orderbook.50.BTCUSDT","type":"delta","ts":1704258156512,"data":{"s":"BTCUSDT","b":[["45158.20","0.554"]],"a":[],"u":20459399,"seq":114533128249},"cts":1704258156509}
{"topic":"orderbook.50.BTCUSDT","type":"delta","ts":1704258156531,"data":{"s":"BTCUSDT","b":[["45160.90","0"],["45155.90","0.629"]],"a":[["45171.70","0.401"]],"u":20459400,"seq":114533128275},"cts":1704258156530}
{"topic":"orderbook.50.BTCUSDT","type":"delta","ts":1704258156552,"data":{"s":"BTCUSDT","b":[["45164.10","0"],["45162.70","0.001"],["45158.20","0.775"],["45155.80","0.002"]],"a":[["45165.90","1.619"],["45168.30","0.004"],["45172.50","0.594"]],"u":20459401,"seq":114533128337},"cts":1704258156550}
{"topic":"orderbook.50.BTCUSDT","type":"delta","ts":1704258156571,"data":{"s":"BTCUSDT","b":[["45162.70","0"],["45161.00","0.040"]],"a":[["45165.90","1.792"],["45172.70","0.267"]],"u":20459402,"seq":114533128407},"cts":1704258156569}
{"topic":"orderbook.50.BTCUSDT","type":"delta","ts":1704258156591,"data":{"s":"BTCUSDT","b":[["45158.20","0.554"],["45158.10","0.220"],["45157.70","0"],["45155.70","1.996"]],"a":[],"u":20459403,"seq":114533128446},"cts":1704258156590}
{"topic":"orderbook.50.BTCUSDT","type":"delta","ts":1704258156632,"data":{"s":"BTCUSDT","b":[["45162.70","0.001"],["45155.70","0"]],"a":[],"u":20459404,"seq":114533128491},"cts":1704258156629}
{"topic":"orderbook.50.BTCUSDT","type":"delta","ts":1704258156651,"data":{"s":"BTCUSDT","b":[["45164.10","0.001"],["45162.70","0.003"],["45161.40","1.600"],["45155.90","0"],["45155.80","0"]],"a":[["45172.20","0.221"],["45172.70","0"]],"u":20459405,"seq":114533128539},"cts":1704258156648}
{"topic":"orderbook.50.BTCUSDT","type":"delta","ts":1704258156711,"data":{"s":"BTCUSDT","b":[["45162.70","0.002"]],"a":[["45165.90","0.945"],["45166.00","0.001"],["45168.30","0.005"]],"u":20459406,"seq":114533128636},"cts":1704258156710}
{"topic":"orderbook.50.BTCUSDT","type":"delta","ts":1704258156731,"data":{"s":"BTCUSDT","b":[["45164.10","0"],["45162.70","0"],["45161.70","0.112"],["45161.20","1.200"],["45161.00","0"],["45155.90","0.629"]],"a":[["45165.90","0.789"],["45168.00","0.118"],["45169.90","0.443"],["45171.40","0.324"],["45171.50","0"],["45171.70","0"],["45172.20","0"],["45172.50","0.554"],["45172.70","0.266"],["45172.80","2.520"],["45172.90","0.820"]],"u":20459407,"seq":114533128789},"cts":1704258156729}
{"topic":"orderbook.50.BTCUSDT","type":"delta","ts":1704258156751,"data":{"s":"BTCUSDT","b":[["45165.80","9.143"],["45164.30","0.112"],["45163.80","0.040"],["45163.50","0.112"],["45159.20","0.082"],["45158.70","0.077"],["45158.20","2.059"],["45158.10","0.110"],["45157.60","0.221"],["45157.30","1.399"],["45156.30","0"],["45156.20","0"],["45156.00","0"],["45155.90","0"]],"a":[["45165.90","1.075"],["45169.60","0.111"],["45170.50","0.025"]],"u":20459408,"seq":114533128986},"cts":1704258156750}
{"topic":"orderbook.50.BTCUSDT","type":"delta","ts":1704258156772,"data":{"s":"BTCUSDT","b":[["45164.40","0.076"],["45163.80","0"],["45160.30","1.889"],["45160.20","0.177"],["45159.60","0.111"],["45159.40","0.241"],["45159.30","1.344"],["45158.60","0.397"],["45158.00","1.314"],["45157.80","0"],["45157.30","1.410"],["45156.50","0.044"],["45156.40","0.846"]],"a":[["45165.90","0.710"],["45166.10","0"],["45167.00","0"],["45167.30","0"],["45167.60","0"],["45167.70","0"],["45167.80","0"],["45167.90","0"],["45168.00","0.001"],["45168.10","0.300"],["45168.40","0"],["45169.60","0"],["45170.10","0"],["45170.30","0.610"],["45170.90","0"],["45171.40","0.135"],["45172.30","0.270"],["45172.80","2.598"],["45173.00","0.044"],["45173.10","1.233"],["45173.20","0.266"],["45173.30","0.443"],["45173.40","0.831"],["45173.50","0.110"],["45173.60","0.266"],["45173.90","1.669"],["45174.00","1.772"],["45174.20","0.058"],["45174.30","2.275"]],"u":20459409,"seq":114533129188},"cts":1704258156770}
{"topic":"orderbook.50.BTCUSDT","type":"delta","ts":1704258156792,"data":{"s":"BTCUSDT","b":[["45165.10","0.078"],["45163.60","0.100"],["45163.50","1.312"],["45161.30","0.210"],["45160.40","0.003"],["45159.20","0.779"],["45156.50","0"],["45156.40","0"]],"a":[["45165.90","1.010"],["45168.30","0.004"],["45168.40","0.001"],["45172.80","1.398"],["45174.30","0"]],"u":20459410,"seq":114533129323},"cts":1704258156790}
{"topic":"orderbook.50.BTCUSDT","type":"delta","ts":1704258156811,"data":{"s":"BTCUSDT","b":[["45164.40","0"],["45164.10","0.791"],["45163.60","0.704"]],"a":[["45169.30","0"],["45174.30","2.275"]],"u":20459411,"seq":114533129392},"cts":1704258156810}
{"topic":"orderbook.50.BTCUSDT","type":"delta","ts":1704258156832,"data":{"s":"BTCUSDT","b":[["45159.50","0.110"],["45156.60","0"]],"a":[["45168.00","0.114"],["45168.40","0.002"],["45172.80","2.598"],["45173.40","0.820"],["45173.90","1.658"],["45174.20","0.168"]],"u":20459412,"seq":114533129476},"cts":1704258156830}
{"topic":"orderbook.50.BTCUSDT","type":"delta","ts":1704258156851,"data":{"s":"BTCUSDT","b":[["45163.50","0.112"],["45161.70","0.187"],["45159.00","0"],["45158.10","0.331"],["45156.60","0.221"]],"a":[["45168.00","0.179"]],"u":20459413,"seq":114533129525},"cts":1704258156849}
{"topic":"orderbook.50.BTCUSDT","type":"delta","ts":1704258156871,"data":{"s":"BTCUSDT","b":[["45165.80","7.943"],["45164.10","0"],["45162.90","0.037"],["45160.40","0"],["45159.60","0"],["45159.40","0.130"],["45159.10","0"],["45158.90","0"],["45157.30","1.299"],["45156.80","1.659"],["45156.50","0.044"],["45156.40","0.846"],["45156.30","1.674"],["45156.00","2.105"]],"a":[["45166.90","0"],["45169.10","0"],["45170.40","0.554"],["45170.70","0.221"],["45172.40","0.111"],["45173.80","0.111"]],"u":20459414,"seq":114533129610},"cts":1704258156869}
{"topic":"orderbook.50.BTCUSDT","type":"delta","ts":1704258156892,"data":{"s":"BTCUSDT","b":[["45163.60","0.100"],["45158.60","0.286"],["45158.20","0.554"]],"a":[["45171.80","0.383"]],"u":20459415,"seq":114533129684},"cts":1704258156890}
{"topic":"orderbook.50.BTCUSDT","type":"delta","ts":1704258156912,"data":{"s":"BTCUSDT","b":[["45165.80","7.944"],["45163.60","0.150"],["45162.70","1.600"],["45162.10","0"],["45161.70","0.264"],["45161.50","0.082"],["45161.40","0"],["45161.30","0.285"],["45160.20","0.130"],["45159.20","0.697"],["45158.90","0.442"],["45158.70","0.001"],["45158.30","0"]],"a":[],"u":20459416,"seq":114533129757},"cts":1704258156910}
{"topic":"orderbook.50.BTCUSDT","type":"delta","ts":1704258156932,"data":{"s":"BTCUSDT","b":[["45164.40","0.339"],["45162.90","0"],["45158.60","0.397"],["45156.00","1.995"]],"a":[],"u":20459417,"seq":114533129804},"cts":1704258156930}
{"topic":"orderbook.50.BTCUSDT","type":"delta","ts":1704258156971,"data":{"s":"BTCUSDT","b":[["45162.80","0.037"],["45161.40","0.111"],["45156.30","0"],["45156.00","0"]],"a":[["45166.00","0.114"]],"u":20459418,"seq":114533129899},"cts":1704258156969}
{"topic":"orderbook.50.BTCUSDT","type":"delta","ts":1704258156992,"data":{"s":"BTCUSDT","b":[["45165.20","0.076"],["45162.50","0.326"],["45158.10","1.836"],["45156.40","0"]],"a":[["45169.10","0.077"],["45169.40","0.181"],["45171.80","0.465"],["45174.30","0"]],"u":20459419,"seq":114533129955},"cts":1704258156988}
{"topic":"orderbook.50.BTCUSDT","type":"delta","ts":1704258157011,"data":{"s":"BTCUSDT","b":[["45161.20","1.311"],["45159.00","0.111"],["45157.70","0.111"],["45156.60","0"],["45156.50","0"]],"a":[["45166.00","0.001"]],"u":20459420,"seq":114533129990},"cts":1704258157010}
{"topic":"orderbook.50.BTCUSDT","type":"delta","ts":1704258157031,"data":{"s":"BTCUSDT","b":[["45165.80","7.385"],["45162.80","0"],["45156.60","0.221"]],"a":[["45168.30","0.003"],["45168.40","0.003"]],"u":20459421,"seq":114533130052},"cts":1704258157030}
{"topic":"orderbook.50.BTCUSDT","type":"delta","ts":1704258157051,"data":{"s":"BTCUSDT","b":[["45165.80","6.161"],["45158.70","0.222"]],"a":[["45165.90","1.510"],["45170.50","1.225"],["45172.70","4.028"],["45173.60","1.771"]],"u":20459422,"seq":114533130095},"cts":1704258157049}
{"topic":"orderbook.50.BTCUSDT","type":"delta","ts":1704258157072,"data":{"s":"BTCUSDT","b":[["45162.40","0.037"],["45156.60","0"]],"a":[["45166.00","0.114"],["45172.70","0.266"]],"u":20459423,"seq":114533130141},"cts":1704258157069}
{"topic":"orderbook.50.BTCUSDT","type":"delta","ts":1704258157092,"data":{"s":"BTCUSDT","b":[],"a":[["45168.30","0.001"],["45172.40","3.873"],["45172.70","0.277"]],"u":20459424,"seq":114533130192},"cts":1704258157088}
{"topic":"orderbook.50.BTCUSDT","type":"delta","ts":1704258157132,"data":{"s":"BTCUSDT","b":[["45162.40","0"],["45156.60","0.221"]],"a":[["45168.40","0.005"],["45172.40","0.111"],["45172.70","0.266"]],"u":20459425,"seq":114533130272},"cts":1704258157129}
{"topic":"orderbook.50.BTCUSDT","type":"delta","ts":1704258157152,"data":{"s":"BTCUSDT","b":[["45165.80","4.193"],["45164.30","0"],["45163.50","0"],["45161.70","0.152"],["45161.20","0.111"],["45156.50","0.044"],["45156.40","0.846"]],"a":[["45165.90","2.054"],["45166.20","0.003"],["45174.20","0"]],"u":20459426,"seq":114533130330},"cts":1704258157150}
{"topic":"orderbook.50.BTCUSDT","type":"delta","ts":1704258157171,"data":{"s":"BTCUSDT","b":[["45162.60","0.130"],["45162.50","0.363"],["45161.30","0.241"],["45158.90","0.502"]],"a":[["45173.60","2.188"]],"u":20459427,"seq":114533130390},"cts":1704258157170}
{"topic":"orderbook.50.BTCUSDT","type":"delta","ts":1704258157192,"data":{"s":"BTCUSDT","b":[["45156.60","0.442"]],"a":[["45166.20","0"],["45174.20","0.168"]],"u":20459428,"seq":114533130425},"cts":1704258157186}
{"topic":"orderbook.50.BTCUSDT","type":"delta","ts":1704258157212,"data":{"s":"BTCUSDT","b":[["45165.80","4.243"],["45162.60","1.730"],["45162.50","0.326"]],"a":[["45174.10","0.011"],["45174.20","0"]],"u":20459429,"seq":114533130457},"cts":1704258157209}
{"topic":"orderbook.50.BTCUSDT","type":"delta","ts":1704258157271,"data":{"s":"BTCUSDT","b":[["45162.40","0.037"],["45156.40","0"]],"a":[],"u":20459430,"seq":114533130555},"cts":1704258157268}
{"topic":"orderbook.50.BTCUSDT","type":"delta","ts":1704258157292,"data":{"s":"BTCUSDT","b":[["45162.40","0"],["45156.40","0.846"]],"a":[["45174.10","0"],["45174.20","0.168"]],"u":20459431,"seq":114533130588},"cts":1704258157288}
{"topic":"orderbook.50.BTCUSDT","type":"delta","ts":1704258157311,"data":{"s":"BTCUSDT","b":[["45165.80","4.251"]],"a":[],"u":20459432,"seq":114533130614},"cts":1704258157309}
{"topic":"orderbook.50.BTCUSDT","type":"delta","ts":1704258157332,"data":{"s":"BTCUSDT","b":[["45165.80","4.694"],["45161.20","0.155"]],"a":[],"u":20459433,"seq":114533130637},"cts":1704258157329}
{"topic":"orderbook.50.BTCUSDT","type":"delta","ts":1704258157351,"data":{"s":"BTCUSDT","b":[["45159.20","0.918"]],"a":[],"u":20459434,"seq":114533130658},"cts":1704258157349}
{"topic":"orderbook.50.BTCUSDT","type":"delta","ts":1704258157372,"data":{"s":"BTCUSDT","b":[["45160.80","0.018"],["45156.40","0"]],"a":[],"u":20459435,"seq":114533130696},"cts":1704258157370}
{"topic":"orderbook.50.BTCUSDT","type":"delta","ts":1704258157392,"data":{"s":"BTCUSDT","b":[["45162.90","0.037"],["45161.60","0.943"],["45161.40","0.222"],["45160.80","0.129"],["45160.60","0.111"],["45158.40","1.989"],["45156.60","0"],["45156.50","0"]],"a":[["45169.80","0.111"],["45170.10","0.111"],["45170.60","0.133"],["45170.80","0.127"],["45173.10","1.344"],["45173.90","0"],["45174.00","0"],["45174.20","0"]],"u":20459436,"seq":114533130755},"cts":1704258157388}
{"topic":"orderbook.50.BTCUSDT","type":"delta","ts":1704258157432,"data":{"s":"BTCUSDT","b":[["45162.90","0"],["45156.60","0.442"]],"a":[["45173.80","0.122"]],"u":20459437,"seq":114533130799},"cts":1704258157429}
{"topic":"orderbook.50.BTCUSDT","type":"delta","ts":1704258157471,"data":{"s":"BTCUSDT","b":[["45165.80","4.713"]],"a":[],"u":20459438,"seq":114533130846},"cts":1704258157470}
{"topic":"orderbook.50.BTCUSDT","type":"delta","ts":1704258157512,"data":{"s":"BTCUSDT","b":[["45162.80","0.037"],["45156.60","0"]],"a":[["45173.80","0.111"]],"u":20459439,"seq":114533130889},"cts":1704258157510}
{"topic":"orderbook.50.BTCUSDT","type":"delta","ts":1704258157532,"data":{"s":"BTCUSDT","b":[["45162.90","1.150"],["45156.70","0"]],"a":[],"u":20459440,"seq":114533130920},"cts":1704258157530}
{"topic":"orderbook.50.BTCUSDT","type":"delta","ts":1704258157552,"data":{"s":"BTCUSDT","b":[["45164.40","0"],["45163.70","0.698"],["45162.80","0"],["45156.70","0.111"]],"a":[],"u":20459441,"seq":114533130944},"cts":1704258157550}
{"topic":"orderbook.50.BTCUSDT","type":"delta","ts":1704258157632,"data":{"s":"BTCUSDT","b":[["45162.20","0.037"],["45156.70","0"]],"a":[],"u":20459442,"seq":114533131066},"cts":1704258157629}
{"topic":"orderbook.50.BTCUSDT","type":"delta","ts":1704258157672,"data":{"s":"BTCUSDT","b":[["45162.20","0"],["45156.70","0.111"]],"a":[],"u":20459443,"seq":114533131100},"cts":1704258157668}
{"topic":"orderbook.50.BTCUSDT","type":"delta","ts":1704258157731,"data":{"s":"BTCUSDT","b":[["45162.30","0.037"],["45156.70","0"]],"a":[],"u":20459444,"seq":114533131146},"cts":1704258157725}
{"topic":"orderbook.50.BTCUSDT","type":"delta","ts":1704258157772,"data":{"s":"BTCUSDT","b":[["45162.30","0"],["45156.70","0.111"]],"a":[],"u":20459445,"seq":114533131203},"cts":1704258157769}
{"topic":"orderbook.50.BTCUSDT","type":"delta","ts":1704258157791,"data":{"s":"BTCUSDT","b":[["45163.00","1.600"],["45162.90","0"]],"a":[],"u":20459446,"seq":114533131222},"cts":1704258157786}
{"topic":"orderbook.50.BTCUSDT","type":"delta","ts":1704258157851,"data":{"s":"BTCUSDT","b":[["45165.80","4.763"],["45162.50","0.363"]],"a":[],"u":20459447,"seq":114533131283},"cts":1704258157850}
{"topic":"orderbook.50.BTCUSDT","type":"delta","ts":1704258157872,"data":{"s":"BTCUSDT","b":[["45162.50","0.326"]],"a":[],"u":20459448,"seq":114533131307},"cts":1704258157868}
{"topic":"orderbook.50.BTCUSDT","type":"delta","ts":1704258157952,"data":{"s":"BTCUSDT","b":[["45163.00","0"],["45162.50","0.363"],["45156.60","0.442"]],"a":[],"u":20459449,"seq":114533131374},"cts":1704258157950}
{"topic":"orderbook.50.BTCUSDT","type":"delta","ts":1704258157972,"data":{"s":"BTCUSDT","b":[["45164.10","0.332"],["45163.70","0"]],"a":[],"u":20459450,"seq":114533131398},"cts":1704258157969}
{"topic":"orderbook.50.BTCUSDT","type":"delta","ts":1704258157991,"data":{"s":"BTCUSDT","b":[["45162.50","0.326"]],"a":[],"u":20459451,"seq":114533131418},"cts":1704258157990}
{"topic":"orderbook.50.BTCUSDT","type":"delta","ts":1704258158092,"data":{"s":"BTCUSDT","b":[["45162.20","0.037"],["45156.60","0"]],"a":[],"u":20459452,"seq":114533131507},"cts":1704258158089}
{"topic":"orderbook.50.BTCUSDT","type":"delta","ts":1704258158191,"data":{"s":"BTCUSDT","b":[["45162.20","0"],["45161.20","1.355"],["45160.30","1.893"],["45157.90","0"],["45156.60","0.442"],["45156.50","0.044"]],"a":[],"u":20459453,"seq":114533131605},"cts":1704258158190}
{"topic":"orderbook.50.BTCUSDT","type":"delta","ts":1704258158212,"data":{"s":"BTCUSDT","b":[["45162.20","0.037"],["45156.50","0"]],"a":[["45170.30","0.544"],["45171.20","0.022"],["45171.40","0.113"]],"u":20459454,"seq":114533131629},"cts":1704258158208}
{"topic":"orderbook.50.BTCUSDT","type":"delta","ts":1704258158232,"data":{"s":"BTCUSDT","b":[["45162.20","0"],["45156.50","0.044"]],"a":[["45170.30","0.433"],["45171.30","0"],["45173.60","0.683"],["45173.90","1.669"]],"u":20459455,"seq":114533131656},"cts":1704258158229}
{"topic":"orderbook.50.BTCUSDT","type":"delta","ts":1704258158251,"data":{"s":"BTCUSDT","b":[["45165.80","4.762"],["45160.80","0.111"]],"a":[],"u":20459456,"seq":114533131688},"cts":1704258158249}
{"topic":"orderbook.50.BTCUSDT","type":"delta","ts":1704258158312,"data":{"s":"BTCUSDT","b":[["45165.80","4.723"],["45162.30","0.037"],["45156.50","0"]],"a":[],"u":20459457,"seq":114533131765},"cts":1704258158309}
{"topic":"orderbook.50.BTCUSDT","type":"delta","ts":1704258158332,"data":{"s":"BTCUSDT","b":[["45165.80","4.771"],["45162.30","0"],["45156.50","0.044"]],"a":[["45173.50","1.615"],["45173.90","1.658"]],"u":20459458,"seq":114533131804},"cts":1704258158330}
{"topic":"orderbook.50.BTCUSDT","type":"delta","ts":1704258158351,"data":{"s":"BTCUSDT","b":[["45159.70","0.348"]],"a":[["45166.00","0.001"]],"u":20459459,"seq":114533131835},"cts":1704258158348}
{"topic":"orderbook.50.BTCUSDT","type":"delta","ts":1704258158371,"data":{"s":"BTCUSDT","b":[["45165.80","5.766"],["45157.30","1.303"]],"a":[["45165.90","0.710"],["45168.00","0.066"],["45170.20","1.658"],["45170.60","0.111"],["45172.30","0.266"],["45173.50","0.110"],["45173.90","1.662"]],"u":20459460,"seq":114533131903},"cts":1704258158370}
{"topic":"orderbook.50.BTCUSDT","type":"delta","ts":1704258158392,"data":{"s":"BTCUSDT","b":[["45165.80","9.283"],["45163.50","1.200"],["45163.00","0.112"],["45161.10","1.773"],["45160.80","0.222"],["45160.40","0.003"],["45160.30","1.889"],["45157.40","0.110"],["45156.70","0"],["45156.60","0"],["45156.50","0"]],"a":[["45168.10","0"],["45168.60","0"],["45169.00","0"],["45169.70","0.022"],["45169.90","0"],["45170.00","0.114"],["45170.40","0.111"],["45170.50","0.025"],["45171.10","0"],["45171.40","0.110"],["45171.60","0"],["45172.00","0.158"],["45172.10","0.110"],["45172.30","0"],["45172.50","0.111"],["45172.60","0"],["45172.70","0"],["45172.80","0.615"],["45172.90","0.111"],["45173.10","0.812"],["45173.20","0"],["45173.30","0"],["45173.40","0.111"],["45173.60","0"],["45174.00","1.772"],["45174.10","0.011"],["45174.20","0.168"],["45174.30","2.275"],["45174.60","0.011"],["45174.70","0.044"],["45174.80","0.003"],["45174.90","0.111"],["45175.10","0.558"],["45175.20","0.111"],["45175.30","0.003"],["45175.40","2.141"]],"u":20459461,"seq":114533132073},"cts":1704258158390}
{"topic":"orderbook.50.BTCUSDT","type":"delta","ts":1704258158412,"data":{"s":"BTCUSDT","b":[["45165.80","9.741"],["45164.80","0.112"],["45164.10","0.685"],["45163.60","0.754"],["45162.90","0.111"],["45162.20","0.036"],["45161.80","0.066"],["45161.00","0.697"],["45159.20","0.221"],["45157.30","0"],["45157.20","0"],["45157.10","0"],["45157.00","0"],["45156.80","0"]],"a":[["45168.00","0.001"],["45170.20","0"],["45170.30","0.437"],["45172.70","0.003"],["45172.80","0.611"],["45174.10","0"],["45174.20","0.123"],["45174.30","2.230"],["45174.40","0.078"],["45174.70","0"],["45175.30","0.036"],["45175.40","1.703"],["45176.00","1.082"]],"u":20459462,"seq":114533132177},"cts":1704258158410}
{"topic":"orderbook.50.BTCUSDT","type":"delta","ts":1704258158431,"data":{"s":"BTCUSDT","b":[["45165.90","11.234"],["45165.80","7.436"],["45163.90","0.250"],["45162.20","0"],["45161.60","1.640"],["45161.10","0.115"],["45158.30","1.505"],["45158.10","0.331"],["45157.40","0"]],"a":[["45165.90","0"],["45169.40","0.159"],["45169.70","0"],["45173.80","1.769"],["45174.40","0"],["45174.60","0"],["45175.50","0.110"],["45176.30","0.003"],["45176.40","0.136"],["45176.60","1.266"]],"u":20459463,"seq":114533132337},"cts":1704258158430}
{"topic":"orderbook.50.BTCUSDT","type":"delta","ts":1704258158452,"data":{"s":"BTCUSDT","b":[["45168.20","1.246"],["45168.10","1.546"],["45167.90","1.500"],["45165.90","11.188"],["45165.80","4.814"],["45164.10","0"],["45161.10","0.111"],["45161.00","0"],["45159.20","0.225"],["45158.90","0.442"],["45157.50","0"]],"a":[["45166.00","0"],["45168.00","0"],["45168.20","0"],["45168.50","0"],["45169.10","0"],["45169.40","0.081"],["45169.50","0"],["45170.30","0.433"],["45170.70","0.287"],["45171.80","0.305"],["45172.20","0.004"],["45173.90","1.658"],["45175.70","0.004"],["45176.00","1.160"],["45176.70","0.538"],["45176.80","2.038"],["45176.90","0.313"],["45177.00","1.658"]],"u":20459464,"seq":114533132548},"cts":1704258158449}
{"topic":"orderbook.50.BTCUSDT","type":"delta","ts":1704258158472,"data":{"s":"BTCUSDT","b":[["45168.20","5.318"],["45168.10","0.600"],["45168.00","0.113"],["45167.90","0.300"],["45166.00","2.145"],["45165.90","4.793"],["45165.80","1.896"],["45164.80","0"],["45163.50","0"],["45162.70","0.416"],["45162.60","0.130"],["45160.60","1.616"],["45160.40","0.070"],["45158.30","0"],["45157.80","2.213"]],"a":[["45168.30","0.301"],["45170.70","0.177"],["45172.90","1.311"],["45173.00","0"],["45173.10","0.811"],["45174.30","2.119"],["45175.70","0.048"],["45176.00","1.161"],["45176.70","0.649"],["45177.10","0.026"]],"u":20459465,"seq":114533132803},"cts":1704258158470}
{"topic":"orderbook.50.BTCUSDT","type":"delta","ts":1704258158491,"data":{"s":"BTCUSDT","b":[["45168.20","5.488"],["45168.10","0"],["45167.90","0"],["45166.10","1.600"],["45165.30","0.083"],["45164.10","0.454"],["45162.70","1.272"],["45162.60","0.052"],["45160.80","0.244"],["45158.30","0.044"],["45157.70","0"],["45157.60","0"]],"a":[["45170.30","0.300"],["45171.90","0.137"],["45172.40","0.222"],["45172.50","0"],["45172.90","1.200"],["45173.40","0"],["45174.30","2.008"],["45175.20","0"],["45175.30","0.147"],["45175.80","0.111"],["45176.70","0.760"],["45176.80","1.994"],["45177.30","0.598"],["45177.40","0.880"]],"u":20459466,"seq":114533132956},"cts":1704258158489}
{"topic":"orderbook.50.BTCUSDT","type":"delta","ts":1704258158512,"data":{"s":"BTCUSDT","b":[["45167.80","0.078"],["45165.10","0"],["45165.00","0.112"],["45163.60","1.954"],["45162.70","1.907"],["45160.80","0.222"],["45160.50","0.032"],["45159.30","1.610"],["45158.30","0"],["45157.80","0"]],"a":[["45170.50","0"],["45171.90","0.115"],["45172.90","0"],["45174.20","0.145"],["45174.80","0.446"],["45176.00","1.604"],["45176.40","0.036"],["45176.50","0.011"],["45177.50","0.266"]],"u":20459467,"seq":114533133099},"cts":1704258158510}
{"topic":"orderbook.50.BTCUSDT","type":"delta","ts":1704258158531,"data":{"s":"BTCUSDT","b":[["45165.90","4.758"],["45164.10","0"],["45164.00","1.289"],["45163.30","0.697"],["45161.60","0.943"],["45160.50","0"],["45160.20","0.240"],["45157.80","2.656"]],"a":[["45173.40","3.762"],["45176.00","1.526"],["45176.20","0.110"],["45176.90","0.324"],["45177.40","0"],["45177.50","0"]],"u":20459468,"seq":114533133229},"cts":1704258158529}
{"topic":"orderbook.50.BTCUSDT","type":"delta","ts":1704258158551,"data":{"s":"BTCUSDT","b":[["45161.50","0.086"],["45160.20","0.461"],["45159.20","0.221"]],"a":[["45168.30","0.001"],["45169.40","0"],["45172.70","0.081"],["45173.40","0"],["45174.20","0.223"],["45176.50","0"],["45177.40","0.880"],["45177.50","0.266"],["45177.60","0.554"]],"u":20459469,"seq":114533133374},"cts":1704258158550}
{"topic":"orderbook.50.BTCUSDT","type":"delta","ts":1704258158572,"data":{"s":"BTCUSDT","b":[["45168.10","0.112"],["45166.80","0.112"],["45158.00","0"],["45157.80","0"]],"a":[["45170.00","0.001"],["45171.30","0.045"],["45171.80","0.300"],["45174.30","1.808"],["45176.30","3.765"],["45176.40","0.025"],["45176.90","0.313"],["45177.60","0"]],"u":20459470,"seq":114533133493},"cts":1704258158570}
{"topic":"orderbook.50.BTCUSDT","type":"delta","ts":1704258158591,"data":{"s":"BTCUSDT","b":[["45164.10","0.080"],["45163.10","0.079"],["45161.70","0.077"],["45160.00","0.381"],["45158.20","0"],["45158.10","0"]],"a":[["45170.00","0.114"],["45171.30","0"],["45173.70","0.076"],["45174.20","0.303"],["45174.70","0.080"],["45177.50","0"]],"u":20459471,"seq":114533133556},"cts":1704258158590}
{"topic":"orderbook.50.BTCUSDT","type":"delta","ts":1704258158611,"data":{"s":"BTCUSDT","b":[],"a":[["45173.60","0.080"],["45176.30","0.003"],["45177.40","0"]],"u":20459472,"seq":114533133614},"cts":1704258158610}
{"topic":"orderbook.50.BTCUSDT","type":"delta","ts":1704258158651,"data":{"s":"BTCUSDT","b":[],"a":[["45173.40","3.773"],["45177.30","0"]],"u":20459473,"seq":114533133730},"cts":1704258158648}
{"topic":"orderbook.50.BTCUSDT","type":"delta","ts":1704258158672,"data":{"s":"BTCUSDT","b":[["45168.20","6.716"],["45163.60","1.350"],["45163.30","2.355"],["45162.00","1.772"]],"a":[["45168.30","0.301"]],"u":20459474,"seq":114533133793},"cts":1704258158670}
{"topic":"orderbook.50.BTCUSDT","type":"delta","ts":1704258158691,"data":{"s":"BTCUSDT","b":[["45162.80","0.067"],["45160.40","0.003"],["45158.40","0"]],"a":[["45172.00","0.239"],["45173.40","0.011"]],"u":20459475,"seq":114533133865},"cts":1704258158690}
{"topic":"orderbook.50.BTCUSDT","type":"delta","ts":1704258158711,"data":{"s":"BTCUSDT","b":[["45162.90","0"],["45158.40","1.989"]],"a":[["45173.40","0"],["45173.60","0.125"],["45177.30","0.598"]],"u":20459476,"seq":114533133918},"cts":1704258158709}
{"topic":"orderbook.50.BTCUSDT","type":"delta","ts":1704258158731,"data":{"s":"BTCUSDT","b":[["45160.90","0.110"],["45158.40","0"]],"a":[],"u":20459477,"seq":114533133971},"cts":1704258158730}
{"topic":"orderbook.50.BTCUSDT","type":"delta","ts":1704258158752,"data":{"s":"BTCUSDT","b":[["45168.20","5.040"],["45168.10","0"],["45166.90","0.866"],["45166.80","0"],["45166.00","0"],["45160.90","0.220"],["45160.70","0.221"],["45158.40","1.989"]],"a":[["45168.30","0.845"],["45168.40","0.001"]],"u":20459478,"seq":114533134053},"cts":1704258158750}
{"topic":"orderbook.50.BTCUSDT","type":"delta","ts":1704258158772,"data":{"s":"BTCUSDT","b":[["45165.00","0"],["45158.20","0.554"]],"a":[["45172.90","1.200"],["45175.90","1.505"],["45177.10","0"],["45177.30","0"]],"u":20459479,"seq":114533134114},"cts":1704258158769}
{"topic":"orderbook.50.BTCUSDT","type":"delta","ts":1704258158791,"data":{"s":"BTCUSDT","b":[["45164.10","0.155"],["45161.30","0.166"]],"a":[],"u":20459480,"seq":114533134200},"cts":1704258158790}
{"topic":"orderbook.50.BTCUSDT","type":"delta","ts":1704258158812,"data":{"s":"BTCUSDT","b":[["45159.90","0.453"]],"a":[["45172.70","0.092"],["45173.40","3.762"],["45177.00","0"]],"u":20459481,"seq":114533134256},"cts":1704258158809}
{"topic":"orderbook.50.BTCUSDT","type":"delta","ts":1704258158832,"data":{"s":"BTCUSDT","b":[["45160.00","0.412"]],"a":[["45168.40","0"],["45177.00","1.658"]],"u":20459482,"seq":114533134299},"cts":1704258158829}
{"topic":"orderbook.50.BTCUSDT","type":"delta","ts":1704258158852,"data":{"s":"BTCUSDT","b":[],"a":[["45172.70","0.081"],["45173.40","0.011"]],"u":20459483,"seq":114533134336},"cts":1704258158849}
{"topic":"orderbook.50.BTCUSDT","type":"delta","ts":1704258158871,"data":{"s":"BTCUSDT","b":[],"a":[["45170.70","0.178"],["45173.40","0"],["45175.50","0.111"],["45177.10","0.026"]],"u":20459484,"seq":114533134375},"cts":1704258158868}
{"topic":"orderbook.50.BTCUSDT","type":"delta","ts":1704258158892,"data":{"s":"BTCUSDT","b":[["45168.20","5.088"],["45166.10","0"],["45166.00","1.600"],["45165.80","1.848"]],"a":[],"u":20459485,"seq":114533134409},"cts":1704258158889}
{"topic":"orderbook.50.BTCUSDT","type":"delta","ts":1704258158911,"data":{"s":"BTCUSDT","b":[["45166.20","0.053"],["45158.20","0"]],"a":[["45177.00","2.047"]],"u":20459486,"seq":114533134455},"cts":1704258158910}
{"topic":"orderbook.50.BTCUSDT","type":"delta","ts":1704258158932,"data":{"s":"BTCUSDT","b":[["45162.80","0"],["45160.60","1.683"],["45160.00","0.381"],["45159.80","0.266"],["45159.60","0.443"],["45159.50","0.819"],["45159.40","0.396"],["45158.90","0.708"],["45158.70","0.665"],["45158.40","0"]],"a":[["45176.30","0.081"],["45177.00","2.490"]],"u":20459487,"seq":114533134513},"cts":1704258158929}
{"topic":"orderbook.50.BTCUSDT","type":"delta","ts":1704258158952,"data":{"s":"BTCUSDT","b":[["45161.20","1.576"]],"a":[],"u":20459488,"seq":114533134557},"cts":1704258158949}
{"topic":"orderbook.50.BTCUSDT","type":"delta","ts":1704258158992,"data":{"s":"BTCUSDT","b":[],"a":[["45170.70","0.180"]],"u":20459489,"seq":114533134613},"cts":1704258158989}
{"topic":"orderbook.50.BTCUSDT","type":"delta","ts":1704258159011,"data":{"s":"BTCUSDT","b":[["45160.80","0.664"]],"a":[["45170.70","0.181"]],"u":20459490,"seq":114533134646},"cts":1704258159010}
{"topic":"orderbook.50.BTCUSDT","type":"delta","ts":1704258159032,"data":{"s":"BTCUSDT","b":[["45161.60","1.053"]],"a":[["45170.70","0.182"]],"u":20459491,"seq":114533134686},"cts":1704258159029}
{"topic":"orderbook.50.BTCUSDT","type":"delta","ts":1704258159051,"data":{"s":"BTCUSDT","b":[["45165.80","1.688"]],"a":[],"u":20459492,"seq":114533134718},"cts":1704258159049}
{"topic":"orderbook.50.BTCUSDT","type":"delta","ts":1704258159071,"data":{"s":"BTCUSDT","b":[["45160.80","0.682"]],"a":[],"u":20459493,"seq":114533134746},"cts":1704258159070}
{"topic":"orderbook.50.BTCUSDT","type":"delta","ts":1704258159152,"data":{"s":"BTCUSDT","b":[["45161.70","0.298"],["45160.10","0.031"],["45158.60","0"]],"a":[],"u":20459494,"seq":114533134830},"cts":1704258159149}
{"topic":"orderbook.50.BTCUSDT","type":"delta","ts":1704258159172,"data":{"s":"BTCUSDT","b":[["45165.80","1.674"]],"a":[],"u":20459495,"seq":114533134856},"cts":1704258159170}
{"topic":"orderbook.50.BTCUSDT","type":"delta","ts":1704258159192,"data":{"s":"BTCUSDT","b":[["45161.30","0.176"],["45158.70","0.886"]],"a":[["45168.40","0.010"],["45175.20","0.010"],["45177.00","0"],["45177.10","0"]],"u":20459496,"seq":114533134885},"cts":1704258159190}
{"topic":"orderbook.50.BTCUSDT","type":"delta","ts":1704258159212,"data":{"s":"BTCUSDT","b":[["45168.10","0.010"],["45160.10","0"]],"a":[],"u":20459497,"seq":114533134912},"cts":1704258159210}
{"topic":"orderbook.50.BTCUSDT","type":"delta","ts":1704258159292,"data":{"s":"BTCUSDT","b":[],"a":[["45174.20","0.290"]],"u":20459498,"seq":114533135014},"cts":1704258159288}
{"topic":"orderbook.50.BTCUSDT","type":"delta","ts":1704258159372,"data":{"s":"BTCUSDT","b":[["45165.90","3.158"]],"a":[],"u":20459499,"seq":114533135111},"cts":1704258159369}
{"topic":"orderbook.50.BTCUSDT","type":"delta","ts":1704258159432,"data":{"s":"BTCUSDT","b":[["45166.00","0"],["45161.20","1.532"],["45158.80","0.110"],["45158.60","0.397"]],"a":[],"u":20459500,"seq":114533135171},"cts":1704258159428}
{"topic":"orderbook.50.BTCUSDT","type":"delta","ts":1704258159451,"data":{"s":"BTCUSDT","b":[["45168.20","5.040"],["45166.90","0"],["45166.00","1.263"]],"a":[],"u":20459501,"seq":114533135198},"cts":1704258159449}
{"topic":"orderbook.50.BTCUSDT","type":"delta","ts":1704258159471,"data":{"s":"BTCUSDT","b":[["45168.20","5.101"],["45165.30","1.683"]],"a":[],"u":20459502,"seq":114533135240},"cts":1704258159469}
{"topic":"orderbook.50.BTCUSDT","type":"delta","ts":1704258159492,"data":{"s":"BTCUSDT","b":[["45159.40","0.617"]],"a":[],"u":20459503,"seq":114533135260},"cts":1704258159487}
{"topic":"orderbook.50.BTCUSDT","type":"delta","ts":1704258159512,"data":{"s":"BTCUSDT","b":[["45161.10","0"],["45160.80","0.571"],["45159.70","0.221"],["45159.40","0.487"],["45158.40","1.989"]],"a":[["45173.40","0.104"],["45173.50","0.202"],["45176.90","0"]],"u":20459504,"seq":114533135288},"cts":1704258159507}
{"topic":"orderbook.50.BTCUSDT","type":"delta","ts":1704258159532,"data":{"s":"BTCUSDT","b":[["45168.20","3.417"]],"a":[],"u":20459505,"seq":114533135323},"cts":1704258159528}
{"topic":"orderbook.50.BTCUSDT","type":"delta","ts":1704258159551,"data":{"s":"BTCUSDT","b":[["45168.20","3.778"],["45166.00","1.744"],["45160.80","0.553"],["45160.40","0"],["45158.20","1.054"]],"a":[["45175.50","0.110"]],"u":20459506,"seq":114533135353},"cts":1704258159549}
{"topic":"orderbook.50.BTCUSDT","type":"delta","ts":1704258159571,"data":{"s":"BTCUSDT","b":[["45166.20","0"],["45158.10","0.221"]],"a":[],"u":20459507,"seq":114533135376},"cts":1704258159567}
{"topic":"orderbook.50.BTCUSDT","type":"delta","ts":1704258159652,"data":{"s":"BTCUSDT","b":[["45162.20","0.221"],["45158.10","0"]],"a":[],"u":20459508,"seq":114533135463},"cts":1704258159650}
{"topic":"orderbook.50.BTCUSDT","type":"delta","ts":1704258159712,"data":{"s":"BTCUSDT","b":[["45160.70","0.251"]],"a":[],"u":20459509,"seq":114533135527},"cts":1704258159709}
{"topic":"orderbook.50.BTCUSDT","type":"delta","ts":1704258159732,"data":{"s":"BTCUSDT","b":[["45166.10","1.600"],["45158.20","0"]],"a":[],"u":20459510,"seq":114533135549},"cts":1704258159730}
{"topic":"orderbook.50.BTCUSDT","type":"delta","ts":1704258159792,"data":{"s":"BTCUSDT","b":[["45160.70","0.221"]],"a":[],"u":20459511,"seq":114533135607},"cts":1704258159790}
{"topic":"orderbook.50.BTCUSDT","type":"delta","ts":1704258159831,"data":{"s":"BTCUSDT","b":[["45160.70","0.251"]],"a":[],"u":20459512,"seq":114533135645},"cts":1704258159830}
{"topic":"orderbook.50.BTCUSDT","type":"delta","ts":1704258159912,"data":{"s":"BTCUSDT","b":[["45160.70","0.221"]],"a":[],"u":20459513,"seq":114533135724},"cts":1704258159909}
{"topic":"orderbook.50.BTCUSDT","type":"delta","ts":1704258159932,"data":{"s":"BTCUSDT","b":[["45166.10","0"],["45165.30","0.083"],["45160.80","0.583"],["45158.20","1.054"]],"a":[["45175.00","0.084"],["45176.80","0"]],"u":20459514,"seq":114533135748},"cts":1704258159930}
{"topic":"orderbook.50.BTCUSDT","type":"delta","ts":1704258159992,"data":{"s":"BTCUSDT","b":[["45164.20","1.600"],["45158.20","0"]],"a":[],"u":20459515,"seq":114533135819},"cts":1704258159989}
{"topic":"orderbook.50.BTCUSDT","type":"delta","ts":1704258160011,"data":{"s":"BTCUSDT","b":[["45160.80","0.553"]],"a":[],"u":20459516,"seq":114533135837},"cts":1704258160010}
{"topic":"orderbook.50.BTCUSDT","type":"delta","ts":1704258160031,"data":{"s":"BTCUSDT","b":[["45168.20","5.678"],["45160.80","0.583"]],"a":[["45168.30","0.840"]],"u":20459517,"seq":114533135983},"cts":1704258160030}
{"topic":"orderbook.50.BTCUSDT","type":"delta","ts":1704258160051,"data":{"s":"BTCUSDT","b":[["45168.20","5.378"]],"a":[["45172.90","0"],["45176.80","2.215"]],"u":20459518,"seq":114533136035},"cts":1704258160050}
{"topic":"orderbook.50.BTCUSDT","type":"delta","ts":1704258160071,"data":{"s":"BTCUSDT","b":[["45160.80","0.601"]],"a":[],"u":20459519,"seq":114533136103},"cts":1704258160069}
{"topic":"orderbook.50.BTCUSDT","type":"delta","ts":1704258160092,"data":{"s":"BTCUSDT","b":[["45160.10","0.221"],["45158.40","0"]],"a":[],"u":20459520,"seq":114533136172},"cts":1704258160089}
{"topic":"orderbook.50.BTCUSDT","type":"delta","ts":1704258160111,"data":{"s":"BTCUSDT","b":[["45160.80","0.571"]],"a":[["45172.30","0.001"],["45176.80","0"]],"u":20459521,"seq":114533136236},"cts":1704258160110}
{"topic":"orderbook.50.BTCUSDT","type":"delta","ts":1704258160131,"data":{"s":"BTCUSDT","b":[["45160.80","0.583"]],"a":[["45168.30","0.500"],["45170.00","0.001"]],"u":20459522,"seq":114533136317},"cts":1704258160130}
{"topic":"orderbook.50.BTCUSDT","type":"delta","ts":1704258160152,"data":{"s":"BTCUSDT","b":[["45168.30","6.149"],["45168.20","5.104"],["45166.10","0.604"],["45165.90","2.858"],["45165.80","0.474"],["45164.20","0"],["45163.70","0.044"],["45160.50","0.003"],["45158.80","0"],["45158.70","0"],["45158.60","0"]],"a":[["45168.30","0"],["45169.20","0"],["45172.40","0.244"],["45175.90","0"],["45176.80","1.994"],["45176.90","0.313"],["45177.00","2.101"]],"u":20459523,"seq":114533136485},"cts":1704258160150}
{"topic":"orderbook.50.BTCUSDT","type":"delta","ts":1704258160171,"data":{"s":"BTCUSDT","b":[["45168.20","3.549"]],"a":[],"u":20459524,"seq":114533136639},"cts":1704258160169}
{"topic":"orderbook.50.BTCUSDT","type":"delta","ts":1704258160191,"data":{"s":"BTCUSDT","b":[["45169.70","3.832"],["45168.30","2.239"],["45168.20","3.249"],["45168.10","0"],["45164.20","0.434"],["45162.10","1.505"],["45160.80","0.553"],["45160.70","0.765"],["45160.60","0.178"],["45159.90","0.457"],["45159.30","3.823"],["45159.00","0"],["45158.90","0"]],"a":[["45168.40","0"],["45169.80","0.411"],["45171.40","0"],["45172.00","0.195"],["45172.10","0"],["45172.20","0.026"],["45172.40","0.222"],["45174.20","0.334"],["45176.70","0.649"],["45177.10","0.026"],["45177.20","0.266"],["45177.30","0.598"]],"u":20459525,"seq":114533136812},"cts":1704258160190}
{"topic":"orderbook.50.BTCUSDT","type":"delta","ts":1704258160212,"data":{"s":"BTCUSDT","b":[["45169.70","7.435"],["45168.30","1.928"],["45167.90","0.112"],["45167.40","1.200"],["45166.00","1.856"],["45165.90","1.658"],["45164.20","1.521"],["45164.10","0.080"],["45162.90","0.111"],["45161.50","0.004"],["45161.30","0.287"],["45160.90","0.110"],["45160.50","0.653"],["45159.60","2.110"],["45159.40","0"],["45159.30","0"],["45159.20","0"]],"a":[["45169.80","0.111"],["45170.30","0"],["45171.80","0"],["45172.00","0.082"],["45172.20","0.004"],["45172.70","0.078"],["45172.80","0.301"],["45173.10","0.411"],["45173.50","0.095"],["45174.20","0.224"],["45174.30","1.608"],["45174.90","0"],["45175.30","0.003"],["45175.70","0.044"],["45175.80","0"],["45176.00","0.623"],["45176.40","0.136"],["45176.60","0.066"],["45176.70","0.211"],["45176.80","0.111"],["45176.90","0"],["45177.00","0.443"],["45177.30","0.602"],["45177.50","0.266"],["45177.60","0.443"],["45177.70","0.266"],["45177.80","0.720"],["45177.90","1.329"]],"u":20459526,"seq":114533137177},"cts":1704258160209}
{"topic":"orderbook.50.BTCUSDT","type":"delta","ts":1704258160232,"data":{"s":"BTCUSDT","b":[["45169.70","6.934"],["45169.20","0.078"],["45168.30","2.627"],["45167.80","0"],["45167.20","0.389"],["45166.00","1.375"],["45164.20","1.941"],["45164.00","1.293"],["45162.30","0.110"],["45161.50","0"],["45160.50","0.003"],["45159.90","0.479"],["45159.60","0.443"],["45159.50","0"]],"a":[["45170.70","0.179"],["45172.30","0.004"],["45173.50","0.092"],["45174.00","1.775"],["45176.30","0.003"],["45176.90","0.110"],["45177.30","0.558"],["45177.80","0.709"],["45177.90","0"]],"u":20459527,"seq":114533137434},"cts":1704258160230}
{"topic":"orderbook.50.BTCUSDT","type":"delta","ts":1704258160251,"data":{"s":"BTCUSDT","b":[["45169.70","5.734"],["45169.60","0.010"],["45168.40","1.453"],["45168.30","1.900"],["45167.20","0"],["45163.90","0.361"],["45163.00","0.240"],["45162.90","0.664"],["45162.70","2.128"],["45161.40","0.111"],["45161.30","0.176"],["45161.20","1.421"],["45160.80","0.442"],["45160.60","0.067"],["45159.80","0.375"],["45159.60","0"]],"a":[["45169.80","0"],["45169.90","0.010"],["45170.10","0"],["45170.40","0"],["45170.70","0.067"],["45170.80","0"],["45172.30","0.005"],["45172.40","0.111"],["45173.10","0.300"],["45173.80","1.658"],["45174.00","1.772"],["45174.60","0.003"],["45175.10","0"],["45177.30","0.115"],["45177.60","0"],["45177.90","0.521"],["45178.00","0.402"],["45178.20","1.769"],["45178.40","0.442"]],"u":20459528,"seq":114533137721},"cts":1704258160250}
{"topic":"orderbook.50.BTCUSDT","type":"delta","ts":1704258160272,"data":{"s":"BTCUSDT","b":[["45170.60","1.546"],["45170.50","7.919"],["45170.30","1.743"],["45170.20","0.900"],["45170.00","3.818"],["45169.90","5.626"],["45169.80","5.606"],["45169.70","2.110"],["45168.40","0"],["45168.30","3.063"],["45168.20","2.049"],["45166.10","0.652"],["45162.90","0.553"],["45162.70","3.786"],["45162.50","0.276"],["45161.40","0"],["45160.10","0"],["45160.00","0"],["45159.90","0"],["45159.80","0"],["45159.70","0"]],"a":[["45169.90","0"],["45170.00","0"],["45170.60","0"],["45172.20","0"],["45173.80","1.662"],["45173.90","0"],["45174.00","0.114"],["45174.60","0"],["45174.90","0.003"],["45175.40","0.045"],["45175.70","0"],["45176.70","0.100"],["45177.70","0.310"],["45178.00","0.391"],["45178.10","0.011"],["45178.20","0.111"],["45178.30","0.111"],["45178.80","0.112"],["45178.90","0.005"],["45179.10","0.111"],["45179.20","0.100"]],"u":20459529,"seq":114533138127},"cts":1704258160269}
{"topic":"orderbook.50.BTCUSDT","type":"delta","ts":1704258160292,"data":{"s":"BTCUSDT","b":[["45170.60","11.721"],["45170.50","0.528"],["45170.30","0"],["45170.20","0"],["45170.00","0.713"],["45169.90","0.032"],["45169.80","1.730"],["45169.70","0.299"],["45169.60","0"],["45169.20","0"],["45168.40","1.844"],["45168.30","1.600"],["45167.20","0.278"],["45165.10","0.697"],["45163.50","0.305"],["45163.30","1.658"],["45162.90","1.616"],["45162.10","0"],["45160.90","0.219"],["45160.10","2.434"]],"a":[["45171.90","0"],["45172.00","0.081"],["45172.40","0"],["45174.20","0.124"],["45174.40","0.111"],["45174.70","0.044"],["45174.90","0"],["45175.00","0.087"],["45175.20","0"],["45175.50","0"],["45175.80","0.022"],["45176.20","0"],["45176.90","1.768"],["45177.90","0.443"],["45178.00","0.380"],["45178.10","0"],["45178.40","0"],["45179.20","0.001"],["45179.30","1.658"],["45179.40","0.033"],["45179.50","0.665"],["45179.70","0.494"],["45180.00","0.114"],["45180.20","0.880"]],"u":20459530,"seq":114533138754},"cts":1704258160290}
{"topic":"orderbook.50.BTCUSDT","type":"delta","ts":1704258160311,"data":{"s":"BTCUSDT","b":[["45170.60","7.803"],["45170.50","0.800"],["45170.00","0.113"],["45169.90","0"],["45168.40","1.017"],["45166.10","0.698"],["45164.20","2.018"],["45163.60","1.367"],["45162.80","2.277"],["45162.00","1.794"],["45161.90","0.079"],["45161.70","0.221"],["45161.60","0.199"],["45160.60","0"]],"a":[["45175.00","0.084"],["45175.60","0.003"],["45179.20","0"],["45179.70","0.438"]],"u":20459531,"seq":114533138956},"cts":1704258160310}
{"topic":"orderbook.50.BTCUSDT","type":"delta","ts":1704258160331,"data":{"s":"BTCUSDT","b":[["45170.50","0.500"],["45169.80","1.700"],["45166.20","0.053"],["45165.50","0.110"],["45163.90","0.530"],["45163.50","0"],["45163.10","0.158"],["45160.90","0.110"],["45160.10","0"]],"a":[["45173.80","0.004"]],"u":20459532,"seq":114533139133},"cts":1704258160330}
{"topic":"orderbook.50.BTCUSDT","type":"delta","ts":1704258160351,"data":{"s":"BTCUSDT","b":[["45170.60","9.758"],["45166.70","0.697"],["45166.00","1.403"],["45165.10","0"]],"a":[["45177.60","1.200"],["45180.20","0"]],"u":20459533,"seq":114533139313},"cts":1704258160350}
{"topic":"orderbook.50.BTCUSDT","type":"delta","ts":1704258160371,"data":{"s":"BTCUSDT","b":[["45170.60","11.024"],["45166.00","1.486"],["45165.80","0.585"],["45163.70","0.155"],["45162.30","0.221"]],"a":[["45172.00","0.194"],["45175.00","0.195"],["45175.20","1.658"],["45175.30","0.114"],["45177.00","0.554"],["45178.40","0.111"],["45179.10","3.873"],["45179.40","1.980"],["45179.70","0"],["45180.00","0"]],"u":20459534,"seq":114533139489},"cts":1704258160370}
{"topic":"orderbook.50.BTCUSDT","type":"delta","ts":1704258160391,"data":{"s":"BTCUSDT","b":[["45166.10","0.094"],["45162.90","0.111"]],"a":[["45175.20","1.735"],["45178.70","3.762"],["45179.10","0.111"],["45179.40","0.033"],["45179.50","0"]],"u":20459535,"seq":114533139588},"cts":1704258160390}
{"topic":"orderbook.50.BTCUSDT","type":"delta","ts":1704258160412,"data":{"s":"BTCUSDT","b":[["45168.50","0.075"],["45168.10","0.076"],["45166.80","0.080"],["45166.30","0.075"],["45165.30","0"],["45165.20","0"],["45164.10","0"],["45163.10","0.079"],["45160.20","0"]],"a":[["45170.70","0.367"],["45178.70","5.709"]],"u":20459536,"seq":114533139690},"cts":1704258160410}
{"topic":"orderbook.50.BTCUSDT","type":"delta","ts":1704258160432,"data":{"s":"BTCUSDT","b":[["45164.30","1.214"],["45164.00","0.117"],["45163.00","0.350"],["45160.30","0"]],"a":[["45178.70","1.947"]],"u":20459537,"seq":114533139764},"cts":1704258160430}
{"topic":"orderbook.50.BTCUSDT","type":"delta","ts":1704258160452,"data":{"s":"BTCUSDT","b":[["45170.60","10.580"],["45163.20","0.221"],["45160.50","0"]],"a":[["45170.70","0.067"],["45172.00","0.081"],["45175.70","0.080"],["45178.70","5.709"],["45179.40","0"]],"u":20459538,"seq":114533139858},"cts":1704258160450}
{"topic":"orderbook.50.BTCUSDT","type":"delta","ts":1704258160471,"data":{"s":"BTCUSDT","b":[],"a":[["45175.80","0"],["45178.70","0"],["45179.00","0.011"],["45179.40","0.055"]],"u":20459539,"seq":114533139933},"cts":1704258160469}
{"topic":"orderbook.50.BTCUSDT","type":"delta","ts":1704258160492,"data":{"s":"BTCUSDT","b":[["45165.60","0.067"],["45165.00","0.028"],["45163.60","1.300"],["45162.60","1.557"],["45161.20","1.443"],["45160.80","0"],["45160.70","0"]],"a":[["45179.40","0.033"]],"u":20459540,"seq":114533140014},"cts":1704258160490}
{"topic":"orderbook.50.BTCUSDT","type":"delta","ts":1704258160511,"data":{"s":"BTCUSDT","b":[["45162.20","0.243"]],"a":[],"u":20459541,"seq":114533140076},"cts":1704258160510}
{"topic":"orderbook.50.BTCUSDT","type":"delta","ts":1704258160532,"data":{"s":"BTCUSDT","b":[["45170.60","10.746"],["45168.20","1.878"]],"a":[["45172.30","0.002"],["45173.30","0.002"],["45179.40","0"]],"u":20459542,"seq":114533140156},"cts":1704258160529}
{"topic":"orderbook.50.BTCUSDT","type":"delta","ts":1704258160551,"data":{"s":"BTCUSDT","b":[["45165.00","0"],["45164.30","1.313"],["45164.20","2.146"],["45160.80","0.442"]],"a":[["45172.30","0.001"],["45173.30","0.004"]],"u":20459543,"seq":114533140236},"cts":1704258160548}
{"topic":"orderbook.50.BTCUSDT","type":"delta","ts":1704258160571,"data":{"s":"BTCUSDT","b":[["45168.20","1.817"]],"a":[["45179.00","0"],["45179.40","0.033"]],"u":20459544,"seq":114533140309},"cts":1704258160570}
{"topic":"orderbook.50.BTCUSDT","type":"delta","ts":1704258160592,"data":{"s":"BTCUSDT","b":[["45170.60","10.812"]],"a":[],"u":20459545,"seq":114533140369},"cts":1704258160589}
{"topic":"orderbook.50.BTCUSDT","type":"delta","ts":1704258160631,"data":{"s":"BTCUSDT","b":[["45163.70","0.265"]],"a":[],"u":20459546,"seq":114533140471},"cts":1704258160629}
{"topic":"orderbook.50.BTCUSDT","type":"delta","ts":1704258160651,"data":{"s":"BTCUSDT","b":[["45170.60","10.887"],["45169.90","1.600"],["45168.60","0.046"],["45168.50","0"],["45167.30","0.079"],["45166.90","0.077"],["45166.40","0.079"],["45166.10","0.048"],["45164.20","2.069"],["45163.70","0.486"],["45163.10","0"],["45161.90","0"],["45160.90","0"],["45160.80","0"]],"a":[],"u":20459547,"seq":114533140530},"cts":1704258160649}
{"topic":"orderbook.50.BTCUSDT","type":"delta","ts":1704258160692,"data":{"s":"BTCUSDT","b":[["45161.40","0.109"],["45161.20","0"]],"a":[["45172.00","0"],["45179.50","0.665"]],"u":20459548,"seq":114533140647},"cts":1704258160689}
{"topic":"orderbook.50.BTCUSDT","type":"delta","ts":1704258160731,"data":{"s":"BTCUSDT","b":[["45164.10","0.028"],["45161.30","0"]],"a":[],"u":20459549,"seq":114533140747},"cts":1704258160729}
{"topic":"orderbook.50.BTCUSDT","type":"delta","ts":1704258160751,"data":{"s":"BTCUSDT","b":[["45164.10","0"],["45161.30","0.176"]],"a":[],"u":20459550,"seq":114533140808},"cts":1704258160750}
{"topic":"orderbook.50.BTCUSDT","type":"delta","ts":1704258160771,"data":{"s":"BTCUSDT","b":[["45170.60","10.812"],["45167.30","0"],["45166.40","0"],["45161.20","1.443"],["45160.90","0.110"]],"a":[],"u":20459551,"seq":114533140862},"cts":1704258160770}
{"topic":"orderbook.50.BTCUSDT","type":"delta","ts":1704258160791,"data":{"s":"BTCUSDT","b":[["45170.60","10.596"],["45161.40","0"],["45160.80","0.663"]],"a":[],"u":20459552,"seq":114533140934},"cts":1704258160790}
{"topic":"orderbook.50.BTCUSDT","type":"delta","ts":1704258160812,"data":{"s":"BTCUSDT","b":[["45170.60","10.762"],["45166.00","1.597"],["45165.40","0.111"],["45165.20","0.111"],["45163.00","0.461"],["45160.90","0"],["45160.80","0"]],"a":[["45172.00","0.113"],["45174.40","0.222"],["45174.70","0.155"],["45175.20","1.846"],["45177.70","0.421"],["45179.50","0"]],"u":20459553,"seq":114533141023},"cts":1704258160810}
{"topic":"orderbook.50.BTCUSDT","type":"delta","ts":1704258160832,"data":{"s":"BTCUSDT","b":[["45164.50","0.028"],["45164.40","0.110"],["45161.80","0.508"],["45161.30","0"],["45161.20","0"]],"a":[],"u":20459554,"seq":114533141075},"cts":1704258160829}
{"topic":"orderbook.50.BTCUSDT","type":"delta","ts":1704258160852,"data":{"s":"BTCUSDT","b":[["45164.50","0"],["45164.20","2.290"],["45162.80","4.271"],["45161.30","0.176"]],"a":[],"u":20459555,"seq":114533141132},"cts":1704258160850}
{"topic":"orderbook.50.BTCUSDT","type":"delta","ts":1704258160872,"data":{"s":"BTCUSDT","b":[],"a":[["45179.20","0.001"],["45179.40","0"]],"u":20459556,"seq":114533141193},"cts":1704258160870}
{"topic":"orderbook.50.BTCUSDT","type":"delta","ts":1704258160891,"data":{"s":"BTCUSDT","b":[["45168.70","0.075"],["45164.10","0.079"],["45161.60","0"],["45161.30","0"]],"a":[["45173.90","0.077"],["45179.30","0"]],"u":20459557,"seq":114533141241},"cts":1704258160890}
{"topic":"orderbook.50.BTCUSDT","type":"delta","ts":1704258160912,"data":{"s":"BTCUSDT","b":[["45168.20","0.217"],["45166.90","0.156"],["45166.20","0"],["45166.10","0.127"],["45164.10","0"],["45161.60","0.199"],["45161.50","0.221"]],"a":[],"u":20459558,"seq":114533141315},"cts":1704258160910}
{"topic":"orderbook.50.BTCUSDT","type":"delta","ts":1704258160931,"data":{"s":"BTCUSDT","b":[],"a":[["45174.40","0.111"],["45176.20","0.111"],["45179.20","0"]],"u":20459559,"seq":114533141372},"cts":1704258160929}
{"topic":"orderbook.50.BTCUSDT","type":"delta","ts":1704258160952,"data":{"s":"BTCUSDT","b":[],"a":[["45176.20","0"],["45177.90","0.554"],["45179.20","0.001"]],"u":20459560,"seq":114533141433},"cts":1704258160949}
{"topic":"orderbook.50.BTCUSDT","type":"delta","ts":1704258160972,"data":{"s":"BTCUSDT","b":[["45164.00","0.145"]],"a":[["45175.40","0"],["45179.20","0.012"],["45179.30","1.658"]],"u":20459561,"seq":114533141495},"cts":1704258160970}
{"topic":"orderbook.50.BTCUSDT","type":"delta","ts":1704258161012,"data":{"s":"BTCUSDT","b":[],"a":[["45179.20","0.001"]],"u":20459562,"seq":114533141581},"cts":1704258161009}
{"topic":"orderbook.50.BTCUSDT","type":"delta","ts":1704258161032,"data":{"s":"BTCUSDT","b":[["45170.50","0.553"],["45170.10","1.000"],["45164.00","0.117"],["45162.90","0.553"],["45161.50","0"]],"a":[],"u":20459563,"seq":114533141624},"cts":1704258161029}
{"topic":"orderbook.50.BTCUSDT","type":"delta","ts":1704258161052,"data":{"s":"BTCUSDT","b":[["45170.60","10.787"],["45164.70","0.221"],["45161.60","0"]],"a":[],"u":20459564,"seq":114533141678},"cts":1704258161050}
{"topic":"orderbook.50.BTCUSDT","type":"delta","ts":1704258161072,"data":{"s":"BTCUSDT","b":[["45163.30","1.676"],["45162.20","0.221"]],"a":[],"u":20459565,"seq":114533141737},"cts":1704258161070}
{"topic":"orderbook.50.BTCUSDT","type":"delta","ts":1704258161091,"data":{"s":"BTCUSDT","b":[["45162.00","1.816"]],"a":[],"u":20459566,"seq":114533141779},"cts":1704258161090}
{"topic":"orderbook.50.BTCUSDT","type":"delta","ts":1704258161131,"data":{"s":"BTCUSDT","b":[],"a":[["45172.00","0"],["45179.40","0.033"]],"u":20459567,"seq":114533141858},"cts":1704258161130}
{"topic":"orderbook.50.BTCUSDT","type":"delta","ts":1704258161152,"data":{"s":"BTCUSDT","b":[["45170.60","10.867"],["45168.70","0"],["45161.60","0.199"]],"a":[],"u":20459568,"seq":114533141909},"cts":1704258161150}
{"topic":"orderbook.50.BTCUSDT","type":"delta","ts":1704258161171,"data":{"s":"BTCUSDT","b":[["45168.20","0.200"],["45163.90","0.558"],["45161.70","0.330"]],"a":[],"u":20459569,"seq":114533141958},"cts":1704258161170}
{"topic":"orderbook.50.BTCUSDT","type":"delta","ts":1704258161192,"data":{"s":"BTCUSDT","b":[["45163.90","0.530"],["45161.70","0.221"]],"a":[],"u":20459570,"seq":114533142017},"cts":1704258161190}
{"topic":"orderbook.50.BTCUSDT","type":"delta","ts":1704258161231,"data":{"s":"BTCUSDT","b":[["45162.80","5.776"],["45162.60","0.052"]],"a":[],"u":20459571,"seq":114533142084},"cts":1704258161229}
{"topic":"orderbook.50.BTCUSDT","type":"delta","ts":1704258161251,"data":{"s":"BTCUSDT","b":[["45164.30","0.099"],["45163.70","2.593"]],"a":[],"u":20459572,"seq":114533142119},"cts":1704258161250}
{"topic":"orderbook.50.BTCUSDT","type":"delta","ts":1704258161272,"data":{"s":"BTCUSDT","b":[["45161.90","0.109"],["45161.60","0"]],"a":[],"u":20459573,"seq":114533142166},"cts":1704258161269}
{"topic":"orderbook.50.BTCUSDT","type":"delta","ts":1704258161291,"data":{"s":"BTCUSDT","b":[["45164.10","0.028"],["45162.20","0.442"],["45161.70","0"]],"a":[],"u":20459574,"seq":114533142208},"cts":1704258161289}
{"topic":"orderbook.50.BTCUSDT","type":"delta","ts":1704258161311,"data":{"s":"BTCUSDT","b":[["45170.10","0"],["45161.90","0"],["45161.70","0.221"],["45161.60","0.199"]],"a":[["45175.40","0.121"],["45179.40","0"]],"u":20459575,"seq":114533142250},"cts":1704258161309}
{"topic":"orderbook.50.BTCUSDT","type":"delta","ts":1704258161332,"data":{"s":"BTCUSDT","b":[["45169.90","0"],["45164.10","0"],["45161.50","0.221"],["45161.30","0.176"]],"a":[["45172.00","0.113"],["45179.30","0"]],"u":20459576,"seq":114533142291},"cts":1704258161329}
{"topic":"orderbook.50.BTCUSDT","type":"delta","ts":1704258161351,"data":{"s":"BTCUSDT","b":[["45161.90","0.109"],["45161.50","0.770"],["45161.30","0"]],"a":[],"u":20459577,"seq":114533142336},"cts":1704258161348}
{"topic":"orderbook.50.BTCUSDT","type":"delta","ts":1704258161371,"data":{"s":"BTCUSDT","b":[["45161.90","0"],["45161.30","0.176"]],"a":[],"u":20459578,"seq":114533142387},"cts":1704258161370}
{"topic":"orderbook.50.BTCUSDT","type":"delta","ts":1704258161431,"data":{"s":"BTCUSDT","b":[["45164.20","2.318"],["45161.90","0.109"],["45161.30","0"]],"a":[["45170.70","0.367"]],"u":20459579,"seq":114533142479},"cts":1704258161428}
{"topic":"orderbook.50.BTCUSDT","type":"delta","ts":1704258161452,"data":{"s":"BTCUSDT","b":[["45164.20","2.290"],["45161.90","0"],["45161.30","0.176"]],"a":[],"u":20459580,"seq":114533142525},"cts":1704258161450}
{"topic":"orderbook.50.BTCUSDT","type":"delta","ts":1704258161492,"data":{"s":"BTCUSDT","b":[],"a":[["45177.90","0.443"]],"u":20459581,"seq":114533142609},"cts":1704258161490}
{"topic":"orderbook.50.BTCUSDT","type":"delta","ts":1704258161532,"data":{"s":"BTCUSDT","b":[["45170.60","10.701"],["45164.30","0.127"]],"a":[],"u":20459582,"seq":114533142682},"cts":1704258161530}
{"topic":"orderbook.50.BTCUSDT","type":"delta","ts":1704258161552,"data":{"s":"BTCUSDT","b":[["45170.60","10.866"]],"a":[],"u":20459583,"seq":114533142734},"cts":1704258161550}
{"topic":"orderbook.50.BTCUSDT","type":"delta","ts":1704258161571,"data":{"s":"BTCUSDT","b":[["45170.50","0.500"],["45163.30","1.658"]],"a":[["45176.00","0.579"],["45178.50","0.044"],["45179.20","0"]],"u":20459584,"seq":114533142785},"cts":1704258161570}
{"topic":"orderbook.50.BTCUSDT","type":"delta","ts":1704258161651,"data":{"s":"BTCUSDT","b":[["45164.60","0.029"],["45164.30","0.099"],["45161.30","0"]],"a":[],"u":20459585,"seq":114533142923},"cts":1704258161650}
{"topic":"orderbook.50.BTCUSDT","type":"delta","ts":1704258161692,"data":{"s":"BTCUSDT","b":[["45164.60","0"],["45161.30","0.176"]],"a":[],"u":20459586,"seq":114533143008},"cts":1704258161689}
{"topic":"orderbook.50.BTCUSDT","type":"delta","ts":1704258161831,"data":{"s":"BTCUSDT","b":[["45170.60","12.410"],["45169.70","0.200"]],"a":[],"u":20459587,"seq":114533143278},"cts":1704258161830}
{"topic":"orderbook.50.BTCUSDT","type":"delta","ts":1704258161852,"data":{"s":"BTCUSDT","b":[["45170.60","10.738"]],"a":[],"u":20459588,"seq":114533143378},"cts":1704258161850}
{"topic":"orderbook.50.BTCUSDT","type":"delta","ts":1704258161892,"data":{"s":"BTCUSDT","b":[["45170.60","10.103"],["45168.30","0"],["45167.90","0"],["45164.60","0.029"],["45163.70","2.549"],["45162.80","4.271"],["45161.20","1.421"]],"a":[["45170.70","1.601"]],"u":20459589,"seq":114533143477},"cts":1704258161890}
{"topic":"orderbook.50.BTCUSDT","type":"delta","ts":1704258161911,"data":{"s":"BTCUSDT","b":[["45170.60","8.903"],["45169.80","0.500"],["45168.40","0"],["45167.40","0"],["45167.20","0"],["45166.00","1.485"],["45164.70","0"],["45164.60","0"],["45164.50","1.377"],["45164.20","2.069"],["45163.70","0.221"],["45161.00","0.022"],["45160.90","1.505"],["45160.80","0.663"],["45160.70","0.544"]],"a":[["45170.70","2.101"],["45175.30","1.314"],["45178.50","1.549"],["45179.00","0.011"],["45179.10","0"]],"u":20459590,"seq":114533143571},"cts":1704258161910}
{"topic":"orderbook.50.BTCUSDT","type":"delta","ts":1704258161932,"data":{"s":"BTCUSDT","b":[["45166.70","0"],["45163.40","0.697"]],"a":[["45171.80","0.025"],["45176.20","0.420"],["45177.90","0.521"],["45178.40","0.533"],["45178.70","0.011"],["45178.80","0"],["45178.90","0"],["45179.00","0"]],"u":20459591,"seq":114533143633},"cts":1704258161930}
{"topic":"orderbook.50.BTCUSDT","type":"delta","ts":1704258161952,"data":{"s":"BTCUSDT","b":[["45169.70","0"],["45167.00","1.600"],["45162.00","1.794"]],"a":[["45178.40","0.544"],["45178.70","0"],["45178.80","0.112"]],"u":20459592,"seq":114533143680},"cts":1704258161950}
{"topic":"orderbook.50.BTCUSDT","type":"delta","ts":1704258161971,"data":{"s":"BTCUSDT","b":[["45168.20","0"],["45162.50","0.309"],["45160.60","0.221"]],"a":[["45178.40","1.191"],["45178.70","1.947"],["45178.80","0"]],"u":20459593,"seq":114533143724},"cts":1704258161970}
{"topic":"orderbook.50.BTCUSDT","type":"delta","ts":1704258161991,"data":{"s":"BTCUSDT","b":[],"a":[["45178.40","1.180"],["45178.70","0.011"]],"u":20459594,"seq":114533143761},"cts":1704258161989}
{"topic":"orderbook.50.BTCUSDT","type":"delta","ts":1704258162011,"data":{"s":"BTCUSDT","b":[["45163.70","0.250"]],"a":[["45178.70","0"],["45178.80","0.112"]],"u":20459595,"seq":114533143800},"cts":1704258162010}
{"topic":"orderbook.50.BTCUSDT","type":"delta","ts":1704258162032,"data":{"s":"BTCUSDT","b":[["45163.70","0.221"]],"a":[["45176.20","0.842"]],"u":20459596,"seq":114533143837},"cts":1704258162029}
{"topic":"orderbook.50.BTCUSDT","type":"delta","ts":1704258162052,"data":{"s":"BTCUSDT","b":[["45167.00","0"],["45160.50","0.003"]],"a":[],"u":20459597,"seq":114533143870},"cts":1704258162050}
{"topic":"orderbook.50.BTCUSDT","type":"delta","ts":1704258162092,"data":{"s":"BTCUSDT","b":[["45165.30","0.018"],["45162.90","2.058"],["45160.90","0"]],"a":[],"u":20459598,"seq":114533143938},"cts":1704258162087}
{"topic":"orderbook.50.BTCUSDT","type":"delta","ts":1704258162131,"data":{"s":"BTCUSDT","b":[["45165.30","0"],["45160.30","1.889"]],"a":[],"u":20459599,"seq":114533143996},"cts":1704258162129}
{"topic":"orderbook.50.BTCUSDT","type":"delta","ts":1704258162192,"data":{"s":"BTCUSDT","b":[],"a":[["45170.70","0.911"]],"u":20459600,"seq":114533144071},"cts":1704258162188}
{"topic":"orderbook.50.BTCUSDT","type":"delta","ts":1704258162232,"data":{"s":"BTCUSDT","b":[["45170.60","8.825"],["45170.50","0.553"],["45166.40","1.600"],["45160.30","0"]],"a":[],"u":20459601,"seq":114533144162},"cts":1704258162230}
{"topic":"orderbook.50.BTCUSDT","type":"delta","ts":1704258162251,"data":{"s":"BTCUSDT","b":[["45170.60","7.170"],["45168.70","0.147"],["45160.50","0"]],"a":[],"u":20459602,"seq":114533144213},"cts":1704258162249}
{"topic":"orderbook.50.BTCUSDT","type":"delta","ts":1704258162272,"data":{"s":"BTCUSDT","b":[["45170.60","7.169"],["45168.80","0.091"],["45168.70","0.078"],["45160.60","0"]],"a":[],"u":20459603,"seq":114533144255},"cts":1704258162269}
{"topic":"orderbook.50.BTCUSDT","type":"delta","ts":1704258162291,"data":{"s":"BTCUSDT","b":[["45167.20","0.278"],["45160.70","0"]],"a":[],"u":20459604,"seq":114533144296},"cts":1704258162289}
{"topic":"orderbook.50.BTCUSDT","type":"delta","ts":1704258162332,"data":{"s":"BTCUSDT","b":[["45166.00","2.685"],["45163.80","0.029"],["45160.80","0"]],"a":[["45172.00","0"],["45176.20","0"],["45178.90","0.005"],["45179.10","0.111"]],"u":20459605,"seq":114533144379},"cts":1704258162329}
{"topic":"orderbook.50.BTCUSDT","type":"delta","ts":1704258162351,"data":{"s":"BTCUSDT","b":[["45163.80","0"],["45160.80","0.663"]],"a":[],"u":20459606,"seq":114533144406},"cts":1704258162349}
{"topic":"orderbook.50.BTCUSDT","type":"delta","ts":1704258162412,"data":{"s":"BTCUSDT","b":[],"a":[["45170.70","0.926"]],"u":20459607,"seq":114533144491},"cts":1704258162409}
{"topic":"orderbook.50.BTCUSDT","type":"delta","ts":1704258162432,"data":{"s":"BTCUSDT","b":[["45163.80","0.029"],["45160.80","0"]],"a":[["45172.00","0.113"],["45179.10","0"]],"u":20459608,"seq":114533144521},"cts":1704258162428}
{"topic":"orderbook.50.BTCUSDT","type":"delta","ts":1704258162472,"data":{"s":"BTCUSDT","b":[["45167.30","1.600"],["45166.40","0"],["45163.70","0.442"]],"a":[],"u":20459609,"seq":114533144573},"cts":1704258162470}
{"topic":"orderbook.50.BTCUSDT","type":"delta","ts":1704258162491,"data":{"s":"BTCUSDT","b":[["45167.20","0"],["45160.80","0.663"]],"a":[],"u":20459610,"seq":114533144603},"cts":1704258162489}
{"topic":"orderbook.50.BTCUSDT","type":"delta","ts":1704258162532,"data":{"s":"BTCUSDT","b":[["45164.00","0.146"],["45163.80","0"],["45160.70","0.544"]],"a":[],"u":20459611,"seq":114533144663},"cts":1704258162530}
{"topic":"orderbook.50.BTCUSDT","type":"delta","ts":1704258162551,"data":{"s":"BTCUSDT","b":[["45170.60","7.160"]],"a":[],"u":20459612,"seq":114533144686},"cts":1704258162549}
{"topic":"orderbook.50.BTCUSDT","type":"delta","ts":1704258162572,"data":{"s":"BTCUSDT","b":[["45164.20","2.290"]],"a":[],"u":20459613,"seq":114533144716},"cts":1704258162568}
{"topic":"orderbook.50.BTCUSDT","type":"delta","ts":1704258162612,"data":{"s":"BTCUSDT","b":[["45164.00","0.117"]],"a":[],"u":20459614,"seq":114533144766},"cts":1704258162610}
{"topic":"orderbook.50.BTCUSDT","type":"delta","ts":1704258162632,"data":{"s":"BTCUSDT","b":[["45160.70","0.653"]],"a":[],"u":20459615,"seq":114533144792},"cts":1704258162626}
{"topic":"orderbook.50.BTCUSDT","type":"delta","ts":1704258162711,"data":{"s":"BTCUSDT","b":[],"a":[["45170.70","0.626"]],"u":20459616,"seq":114533144880},"cts":1704258162708}
{"topic":"orderbook.50.BTCUSDT","type":"delta","ts":1704258162732,"data":{"s":"BTCUSDT","b":[["45167.20","0.278"],["45166.10","0.171"],["45160.70","0"]],"a":[["45170.70","0.582"],["45172.00","0"],["45178.50","0.044"],["45179.10","0.111"]],"u":20459617,"seq":114533144971},"cts":1704258162730}
{"topic":"orderbook.50.BTCUSDT","type":"delta","ts":1704258162751,"data":{"s":"BTCUSDT","b":[["45170.60","10.713"],["45168.20","1.600"],["45166.20","0.112"],["45161.00","0"],["45160.80","0"]],"a":[["45170.70","0.069"],["45175.30","0.114"],["45178.40","0.533"]],"u":20459618,"seq":114533145150},"cts":1704258162750}
{"topic":"orderbook.50.BTCUSDT","type":"delta","ts":1704258162771,"data":{"s":"BTCUSDT","b":[["45169.60","0.112"],["45168.80","0.952"],["45168.70","0.190"],["45167.70","0.112"],["45165.60","0.097"],["45164.70","0.221"],["45161.80","0.617"],["45161.50","0"],["45161.30","0"],["45161.20","0"]],"a":[["45178.40","0.111"]],"u":20459619,"seq":114533145285},"cts":1704258162770}
{"topic":"orderbook.50.BTCUSDT","type":"delta","ts":1704258162791,"data":{"s":"BTCUSDT","b":[["45168.30","1.200"],["45166.10","0.282"],["45165.60","0.067"],["45164.10","0.269"],["45164.00","0.468"],["45161.70","0"],["45161.60","0"]],"a":[],"u":20459620,"seq":114533145377},"cts":1704258162789}
{"topic":"orderbook.50.BTCUSDT","type":"delta","ts":1704258162811,"data":{"s":"BTCUSDT","b":[["45162.00","1.903"],["45161.80","0.508"]],"a":[],"u":20459621,"seq":114533145427},"cts":1704258162809}
{"topic":"orderbook.50.BTCUSDT","type":"delta","ts":1704258162872,"data":{"s":"BTCUSDT","b":[],"a":[["45172.70","0"],["45173.60","0"],["45174.20","0.044"],["45175.20","1.769"],["45175.70","0"],["45179.20","0.001"],["45179.30","1.658"],["45179.40","0.033"]],"u":20459622,"seq":114533145581},"cts":1704258162870}
{"topic":"orderbook.50.BTCUSDT","type":"delta","ts":1704258162892,"data":{"s":"BTCUSDT","b":[["45167.30","0"],["45167.20","0"],["45162.90","0.553"],["45161.70","0.221"],["45161.60","0.199"]],"a":[],"u":20459623,"seq":114533145656},"cts":1704258162889}
{"topic":"orderbook.50.BTCUSDT","type":"delta","ts":1704258162932,"data":{"s":"BTCUSDT","b":[["45170.30","0.078"],["45168.70","0.112"],["45168.30","0"]],"a":[],"u":20459624,"seq":114533145756},"cts":1704258162930}
{"topic":"orderbook.50.BTCUSDT","type":"delta","ts":1704258162952,"data":{"s":"BTCUSDT","b":[["45170.60","11.213"],["45167.20","0.278"],["45165.70","0.115"],["45165.60","0.191"],["45162.30","0.225"],["45161.80","0.442"],["45161.70","0"],["45161.60","0"]],"a":[["45170.70","0.016"],["45173.40","0"],["45173.50","0"],["45174.00","0.001"],["45174.20","0"],["45174.70","0.111"],["45174.80","0.003"],["45175.70","0.044"],["45176.00","0.136"],["45176.60","0"],["45177.00","0.111"],["45177.20","0"],["45177.50","0"],["45177.70","0.155"],["45177.80","0"],["45177.90","0.078"],["45178.00","0.114"],["45179.50","0.665"],["45179.70","1.162"],["45179.80","0.111"],["45180.00","0.114"],["45180.20","0.880"],["45180.30","0.111"]],"u":20459625,"seq":114533145874},"cts":1704258162950}
{"topic":"orderbook.50.BTCUSDT","type":"delta","ts":1704258162972,"data":{"s":"BTCUSDT","b":[["45168.30","1.200"],["45162.10","0.022"],["45162.00","0"],["45161.80","0"]],"a":[["45173.70","0"],["45175.30","0.191"],["45176.20","0.046"],["45177.50","0.076"],["45179.70","1.118"],["45180.30","0"]],"u":20459626,"seq":114533145949},"cts":1704258162969}
{"topic":"orderbook.50.BTCUSDT","type":"delta","ts":1704258162991,"data":{"s":"BTCUSDT","b":[["45170.50","0.563"],["45164.30","0.517"],["45164.00","0.117"],["45163.90","0.250"],["45162.90","2.058"],["45162.10","0.131"]],"a":[["45170.80","0.010"],["45173.30","0.003"],["45173.80","0.005"],["45178.80","0.188"],["45180.20","0"]],"u":20459627,"seq":114533146040},"cts":1704258162990}
{"topic":"orderbook.50.BTCUSDT","type":"delta","ts":1704258163011,"data":{"s":"BTCUSDT","b":[["45170.60","11.537"],["45170.40","1.600"],["45168.20","0"],["45168.10","0"],["45162.00","1.794"]],"a":[["45176.30","0.085"],["45176.60","0.076"],["45177.60","0"]],"u":20459628,"seq":114533146114},"cts":1704258163010}
{"topic":"orderbook.50.BTCUSDT","type":"delta","ts":1704258163032,"data":{"s":"BTCUSDT","b":[["45170.60","11.781"],["45166.10","0.171"],["45166.00","2.573"],["45165.80","0.474"],["45165.40","0"],["45165.20","0"],["45165.00","0.506"],["45164.30","0.099"],["45164.10","0"],["45163.70","0.331"],["45163.20","0.330"],["45163.00","0.222"],["45162.30","0.114"],["45162.10","0.022"],["45161.80","0.442"],["45161.70","0.221"]],"a":[],"u":20459629,"seq":114533146197},"cts":1704258163030}
{"topic":"orderbook.50.BTCUSDT","type":"delta","ts":1704258163052,"data":{"s":"BTCUSDT","b":[["45170.60","11.700"],["45163.20","0.221"],["45162.10","0.131"]],"a":[["45176.30","0.528"],["45177.60","0.443"],["45179.10","0.377"],["45180.00","0"]],"u":20459630,"seq":114533146278},"cts":1704258163050}
{"topic":"orderbook.50.BTCUSDT","type":"delta","ts":1704258163072,"data":{"s":"BTCUSDT","b":[["45165.30","0.018"],["45161.70","0"]],"a":[["45175.90","0.076"],["45178.80","0.112"],["45179.80","0"]],"u":20459631,"seq":114533146342},"cts":1704258163070}
{"topic":"orderbook.50.BTCUSDT","type":"delta","ts":1704258163091,"data":{"s":"BTCUSDT","b":[["45167.40","0.031"],["45162.90","2.279"],["45161.80","0"]],"a":[],"u":20459632,"seq":114533146383},"cts":1704258163090}
{"topic":"orderbook.50.BTCUSDT","type":"delta","ts":1704258163111,"data":{"s":"BTCUSDT","b":[["45166.10","0.127"],["45163.20","0.330"],["45162.10","0.022"]],"a":[["45175.30","0.272"]],"u":20459633,"seq":114533146430},"cts":1704258163110}
