{"topic":"orderbook.50.BTCUSDT","type":"delta","ts":1704258128011,"data":{"s":"BTCUSDT","b":[],"a":[["45180.70","3.761"],["45182.20","0"]],"u":20458200,"seq":114533051530},"cts":1704258128009}
{"topic":"orderbook.50.BTCUSDT","type":"snapshot","ts":1704258127072,"data":{"s":"BTCUSDT","b":[["45174.20","2.366"],["45174.10","0.045"],["45174.00","0.113"],["45173.00","0.001"],["45172.90","0.081"],["45172.30","0.072"],["45172.20","0.056"],["45172.00","0.113"],["45171.60","0.007"],["45171.50","0.111"],["45171.20","0.112"],["45171.00","0.049"],["45170.80","0.075"],["45170.70","0.049"],["45170.30","0.339"],["45170.20","0.113"],["45170.10","0.233"],["45170.00","0.558"],["45169.90","0.111"],["45169.80","0.041"],["45169.70","0.223"],["45169.50","0.914"],["45169.40","0.222"],["45169.30","0.128"],["45169.20","0.147"],["45169.10","0.216"],["45168.90","0.080"],["45168.80","0.234"],["45168.70","1.658"],["45168.60","0.999"],["45168.50","0.025"],["45168.30","0.110"],["45168.20","0.075"],["45168.10","1.824"],["45168.00","0.114"],["45167.60","0.399"],["45167.50","0.193"],["45167.30","1.658"],["45167.20","0.500"],["45167.10","1.660"],["45166.90","0.066"],["45166.70","3.700"],["45166.40","0.581"],["45166.00","0.224"],["45165.90","0.110"],["45165.50","0.220"],["45165.40","0.010"],["45165.30","1.204"],["45165.20","0.221"],["45165.10","2.708"]],"a":[["45174.30","3.862"],["45174.40","0.010"],["45175.00","0.001"],["45175.70","0.200"],["45176.00","0.114"],["45176.20","0.003"],["45176.40","0.111"],["45176.70","0.005"],["45176.80","0.051"],["45176.90","0.011"],["45177.00","0.083"],["45177.10","0.078"],["45177.70","1.947"],["45177.80","0.022"],["45177.90","0.115"],["45178.00","0.113"],["45178.10","0.115"],["45178.20","0.111"],["45178.30","0.089"],["45178.40","0.210"],["45178.50","0.173"],["45178.60","0.133"],["45178.70","0.066"],["45178.90","1.721"],["45179.10","0.115"],["45179.20","0.293"],["45179.30","1.743"],["45179.40","0.648"],["45179.50","0.665"],["45179.70","0.133"],["45179.80","2.506"],["45179.90","0.079"],["45180.00","0.161"],["45180.30","0.110"],["45180.40","0.110"],["45180.50","0.443"],["45180.60","0.044"],["45180.80","1.769"],["45180.90","1.492"],["45181.00","0.443"],["45181.10","0.110"],["45181.20","1.909"],["45181.30","0.125"],["45181.40","0.111"],["45181.70","0.554"],["45181.80","2.446"],["45181.90","2.510"],["45182.00","1.500"],["45182.10","0.044"],["45182.20","0.532"]],"u":20458155,"seq":114533050234},"cts":1704258127070}
{"topic":"orderbook.50.BTCUSDT","type":"delta","ts":1704258127551,"data":{"s":"BTCUSDT","b":[["45174.20","2.374"]],"a":[["45178.50","0.173"]],"u":20458177,"seq":114533050675},"cts":1704258127550}
{"topic":"orderbook.50.BTCUSDT","type":"delta","ts":1704258127592,"data":{"s":"BTCUSDT","b":[["45165.20","0.765"]],"a":[],"u":20458179,"seq":114533050746},"cts":1704258127590}
{"topic":"orderbook.50.BTCUSDT","type":"delta","ts":1704258127612,"data":{"s":"BTCUSDT","b":[["45169.90","0.147"]],"a":[["45178.10","0.115"],["45181.00","0.479"]],"u":20458180,"seq":114533050770},"cts":1704258127610}
{"topic":"orderbook.50.BTCUSDT","type":"delta","ts":1704258127632,"data":{"s":"BTCUSDT","b":[["45166.10","0.221"],["45165.10","0"]],"a":[["45177.70","0.011"],["45177.80","0.022"],["45178.20","2.058"],["45182.30","0"]],"u":20458181,"seq":114533050797},"cts":1704258127629}
{"topic":"orderbook.50.BTCUSDT","type":"delta","ts":1704258127652,"data":{"s":"BTCUSDT","b":[["45174.20","2.680"]],"a":[["45174.30","3.634"],["45178.20","0.111"],["45181.30","0.125"]],"u":20458182,"seq":114533050835},"cts":1704258127650}
{"topic":"orderbook.50.BTCUSDT","type":"delta","ts":1704258127671,"data":{"s":"BTCUSDT","b":[["45173.00","0"],["45171.60","0.003"],["45165.10","2.708"]],"a":[["45174.30","2.156"],["45176.70","0.004"],["45178.50","2.120"],["45181.70","0.554"],["45181.80","2.457"]],"u":20458183,"seq":114533050918},"cts":1704258127670}
{"topic":"orderbook.50.BTCUSDT","type":"delta","ts":1704258127691,"data":{"s":"BTCUSDT","b":[["45171.60","1.601"]],"a":[["45176.70","0.003"]],"u":20458184,"seq":114533050973},"cts":1704258127689}
{"topic":"orderbook.50.BTCUSDT","type":"delta","ts":1704258127711,"data":{"s":"BTCUSDT","b":[["45171.70","0.970"],["45170.30","0"],["45166.00","0.227"]],"a":[],"u":20458185,"seq":114533051008},"cts":1704258127709}
{"topic":"orderbook.50.BTCUSDT","type":"delta","ts":1704258127732,"data":{"s":"BTCUSDT","b":[["45169.90","0.111"],["45166.80","0.221"],["45165.10","0"]],"a":[["45178.50","0.173"],["45181.00","0.443"],["45181.30","0.114"],["45181.50","0.011"],["45182.20","0"]],"u":20458186,"seq":114533051053},"cts":1704258127729}
{"topic":"orderbook.50.BTCUSDT","type":"delta","ts":1704258127752,"data":{"s":"BTCUSDT","b":[["45170.20","0.149"]],"a":[["45176.70","0.004"],["45176.90","0.011"],["45177.70","1.947"],["45179.80","0.830"],["45181.30","0.150"],["45182.10","0"]],"u":20458187,"seq":114533051097},"cts":1704258127750}
{"topic":"orderbook.50.BTCUSDT","type":"delta","ts":1704258127772,"data":{"s":"BTCUSDT","b":[["45171.80","0.001"],["45171.60","1.600"],["45165.20","0"]],"a":[["45178.00","3.874"]],"u":20458188,"seq":114533051130},"cts":1704258127769}
{"topic":"orderbook.50.BTCUSDT","type":"delta","ts":1704258127792,"data":{"s":"BTCUSDT","b":[],"a":[["45181.50","0"],["45181.80","2.446"],["45181.90","2.521"],["45182.10","0.044"]],"u":20458189,"seq":114533051161},"cts":1704258127789}
{"topic":"orderbook.50.BTCUSDT","type":"delta","ts":1704258127812,"data":{"s":"BTCUSDT","b":[["45170.20","0.113"]],"a":[["45176.70","0.005"],["45178.00","0.113"],["45178.10","3.876"],["45181.30","0.114"]],"u":20458190,"seq":114533051189},"cts":1704258127810}
{"topic":"orderbook.50.BTCUSDT","type":"delta","ts":1704258127832,"data":{"s":"BTCUSDT","b":[],"a":[["45178.00","3.874"],["45178.10","0.115"],["45178.80","4.920"],["45182.10","0"]],"u":20458191,"seq":114533051222},"cts":1704258127829}
{"topic":"orderbook.50.BTCUSDT","type":"delta","ts":1704258127851,"data":{"s":"BTCUSDT","b":[["45171.60","0"],["45170.20","0.149"],["45165.20","0.765"]],"a":[["45176.20","0"],["45178.00","0.113"],["45178.80","0"],["45180.70","3.761"],["45181.30","0.150"],["45182.10","0.044"]],"u":20458192,"seq":114533051255},"cts":1704258127850}
{"topic":"orderbook.50.BTCUSDT","type":"delta","ts":1704258127872,"data":{"s":"BTCUSDT","b":[["45174.20","3.948"],["45171.70","0"],["45170.30","0.339"]],"a":[["45181.60","0"],["45181.80","0.941"],["45182.20","0.753"]],"u":20458193,"seq":114533051291},"cts":1704258127869}
{"topic":"orderbook.50.BTCUSDT","type":"delta","ts":1704258127892,"data":{"s":"BTCUSDT","b":[["45172.20","0.168"]],"a":[["45180.70","0"],["45181.90","2.510"],["45182.10","0.055"],["45182.20","0.532"],["45182.30","0.266"]],"u":20458194,"seq":114533051315},"cts":1704258127888}
{"topic":"orderbook.50.BTCUSDT","type":"delta","ts":1704258127912,"data":{"s":"BTCUSDT","b":[["45169.60","1.200"],["45165.20","0"]],"a":[["45174.30","1.956"],["45180.70","3.761"],["45182.30","0"]],"u":20458195,"seq":114533051334},"cts":1704258127908}
{"topic":"orderbook.50.BTCUSDT","type":"delta","ts":1704258127932,"data":{"s":"BTCUSDT","b":[["45170.20","0.113"],["45167.70","0.221"],["45165.30","0"]],"a":[["45180.70","0"],["45181.30","0.114"],["45182.30","0.266"]],"u":20458196,"seq":114533051401},"cts":1704258127929}
{"topic":"orderbook.50.BTCUSDT","type":"delta","ts":1704258127952,"data":{"s":"BTCUSDT","b":[["45171.30","1.600"],["45165.40","0"]],"a":[["45180.70","3.761"],["45181.60","0.011"],["45182.20","0"],["45182.30","0"]],"u":20458197,"seq":114533051430},"cts":1704258127949}
{"topic":"orderbook.50.BTCUSDT","type":"delta","ts":1704258127972,"data":{"s":"BTCUSDT","b":[["45171.60","0.967"],["45170.30","0"],["45170.20","0.149"]],"a":[["45180.70","0"],["45181.30","0.150"],["45181.80","2.446"],["45182.10","0.044"],["45182.20","0.532"]],"u":20458198,"seq":114533051470},"cts":1704258127969}
{"topic":"orderbook.50.BTCUSDT","type":"delta","ts":1704258127992,"data":{"s":"BTCUSDT","b":[["45170.20","0.113"]],"a":[["45181.30","0.114"]],"u":20458199,"seq":114533051500},"cts":1704258127989}
{"topic":"orderbook.50.BTCUSDT","type":"delta","ts":1704258127312,"data":{"s":"BTCUSDT","b":[],"a":[["45178.00","2.060"],["45180.70","0"],["45182.40","0.754"]],"u":20458166,"seq":114533050480},"cts":1704258127310}
{"topic":"orderbook.50.BTCUSDT","type":"delta","ts":1704258127092,"data":{"s":"BTCUSDT","b":[["45169.20","0.111"]],"a":[["45180.40","0.074"]],"u":20458156,"seq":114533050258},"cts":1704258127090}
{"topic":"orderbook.50.BTCUSDT","type":"delta","ts":1704258127112,"data":{"s":"BTCUSDT","b":[],"a":[["45177.70","0"],["45178.50","2.120"],["45182.30","0.266"]],"u":20458157,"seq":114533050280},"cts":1704258127109}
{"topic":"orderbook.50.BTCUSDT","type":"delta","ts":1704258127132,"data":{"s":"BTCUSDT","b":[],"a":[["45177.70","1.947"],["45178.50","0.173"],["45181.30","0.114"],["45182.30","0"]],"u":20458158,"seq":114533050306},"cts":1704258127128}
{"topic":"orderbook.50.BTCUSDT","type":"delta","ts":1704258127171,"data":{"s":"BTCUSDT","b":[["45174.20","3.769"]],"a":[["45176.90","0"],["45177.60","0.011"]],"u":20458159,"seq":114533050352},"cts":1704258127169}
{"topic":"orderbook.50.BTCUSDT","type":"delta","ts":1704258127192,"data":{"s":"BTCUSDT","b":[["45171.60","1.607"]],"a":[["45177.60","0"],["45181.10","0.121"],["45182.30","0.266"]],"u":20458160,"seq":114533050373},"cts":1704258127185}
{"topic":"orderbook.50.BTCUSDT","type":"delta","ts":1704258127212,"data":{"s":"BTCUSDT","b":[["45171.70","0.965"],["45171.60","0.007"],["45170.30","0"]],"a":[["45177.00","0.094"],["45177.70","0"],["45178.30","3.850"],["45182.40","0.754"]],"u":20458161,"seq":114533050390},"cts":1704258127209}
{"topic":"orderbook.50.BTCUSDT","type":"delta","ts":1704258127231,"data":{"s":"BTCUSDT","b":[["45171.70","0"],["45170.30","0.337"]],"a":[["45174.30","3.834"],["45177.00","0.083"],["45177.60","0.011"],["45177.90","2.062"],["45178.30","0.089"],["45180.80","1.805"],["45182.20","0.753"],["45182.40","0"]],"u":20458162,"seq":114533050416},"cts":1704258127230}
{"topic":"orderbook.50.BTCUSDT","type":"delta","ts":1704258127252,"data":{"s":"BTCUSDT","b":[["45169.60","0.036"],["45165.10","0"]],"a":[["45177.60","0"],["45177.80","0.033"],["45182.40","0.754"]],"u":20458163,"seq":114533050437},"cts":1704258127248}
{"topic":"orderbook.50.BTCUSDT","type":"delta","ts":1704258127272,"data":{"s":"BTCUSDT","b":[["45174.20","3.777"]],"a":[["45177.90","0.115"],["45178.00","2.060"],["45180.80","1.769"],["45181.10","0.110"]],"u":20458164,"seq":114533050457},"cts":1704258127269}
{"topic":"orderbook.50.BTCUSDT","type":"delta","ts":1704258127291,"data":{"s":"BTCUSDT","b":[["45169.60","0"],["45165.10","2.708"]],"a":[["45178.00","0.113"],["45180.70","1.947"],["45181.70","0.565"],["45182.40","0"]],"u":20458165,"seq":114533050466},"cts":1704258127284}
{"topic":"orderbook.50.BTCUSDT","type":"delta","ts":1704258127412,"data":{"s":"BTCUSDT","b":[],"a":[["45178.60","0.133"],["45180.70","1.947"],["45181.30","0.125"],["45182.40","0"]],"u":20458171,"seq":114533050542},"cts":1704258127409}
{"topic":"orderbook.50.BTCUSDT","type":"delta","ts":1704258127332,"data":{"s":"BTCUSDT","b":[],"a":[["45177.80","0.022"]],"u":20458167,"seq":114533050501},"cts":1704258127329}
{"topic":"orderbook.50.BTCUSDT","type":"delta","ts":1704258127352,"data":{"s":"BTCUSDT","b":[["45170.10","0.269"]],"a":[["45178.00","0.113"],["45181.20","1.945"],["45181.70","0.554"]],"u":20458168,"seq":114533050513},"cts":1704258127345}
{"topic":"orderbook.50.BTCUSDT","type":"delta","ts":1704258127371,"data":{"s":"BTCUSDT","b":[],"a":[["45177.80","0.033"],["45180.70","1.947"],["45182.40","0"]],"u":20458169,"seq":114533050526},"cts":1704258127369}
{"topic":"orderbook.50.BTCUSDT","type":"delta","ts":1704258127391,"data":{"s":"BTCUSDT","b":[["45168.70","2.283"]],"a":[["45178.60","3.894"],["45180.70","0"],["45182.40","0.754"]],"u":20458170,"seq":114533050532},"cts":1704258127383}
{"topic":"orderbook.50.BTCUSDT","type":"delta","ts":1704258127492,"data":{"s":"BTCUSDT","b":[],"a":[["45178.60","0.133"],["45181.30","0.114"]],"u":20458174,"seq":114533050593},"cts":1704258127486}
{"topic":"orderbook.50.BTCUSDT","type":"delta","ts":1704258127432,"data":{"s":"BTCUSDT","b":[["45170.10","0.233"]],"a":[["45177.70","0.011"],["45177.80","0.022"],["45181.20","1.909"],["45181.60","0.221"],["45182.20","0"],["45182.30","0"]],"u":20458172,"seq":114533050553},"cts":1704258127429}
{"topic":"orderbook.50.BTCUSDT","type":"delta","ts":1704258127452,"data":{"s":"BTCUSDT","b":[["45169.80","0.077"]],"a":[["45177.70","0"],["45177.80","0.033"],["45178.00","2.060"],["45178.60","3.894"],["45180.70","0"],["45180.80","1.805"],["45182.20","0.753"],["45182.30","0.266"]],"u":20458173,"seq":114533050565},"cts":1704258127448}
{"topic":"orderbook.50.BTCUSDT","type":"delta","ts":1704258127512,"data":{"s":"BTCUSDT","b":[],"a":[["45177.70","0.011"],["45177.80","0.022"],["45178.60","3.894"],["45181.70","0.565"],["45182.30","0"]],"u":20458175,"seq":114533050606},"cts":1704258127509}
{"topic":"orderbook.50.BTCUSDT","type":"delta","ts":1704258127532,"data":{"s":"BTCUSDT","b":[["45169.80","0.041"]],"a":[["45177.70","0"],["45177.80","0.033"],["45177.90","2.062"],["45178.00","0.113"],["45178.50","3.934"],["45178.60","0.133"],["45180.80","1.769"],["45182.30","0.266"]],"u":20458176,"seq":114533050622},"cts":1704258127529}
{"topic":"orderbook.50.BTCUSDT","type":"delta","ts":1704258127571,"data":{"s":"BTCUSDT","b":[["45174.20","2.606"]],"a":[["45177.90","0.115"],["45178.10","2.062"]],"u":20458178,"seq":114533050726},"cts":1704258127570}
{"topic":"orderbook.50.BTCUSDT","type":"delta","ts":1704258128332,"data":{"s":"BTCUSDT","b":[["45169.60","1.200"]],"a":[["45180.60","0.044"],["45181.70","0.554"]],"u":20458214,"seq":114533051938},"cts":1704258128330}
{"topic":"orderbook.50.BTCUSDT","type":"delta","ts":1704258128452,"data":{"s":"BTCUSDT","b":[],"a":[["45177.60","0.011"],["45177.80","0.022"],["45178.00","0.113"],["45180.20","1.947"],["45182.50","0"],["45182.60","0"]],"u":20458218,"seq":114533052078},"cts":1704258128449}
{"topic":"orderbook.50.BTCUSDT","type":"delta","ts":1704258128472,"data":{"s":"BTCUSDT","b":[],"a":[["45180.20","0"],["45182.50","0.443"]],"u":20458219,"seq":114533052095},"cts":1704258128468}
{"topic":"orderbook.50.BTCUSDT","type":"delta","ts":1704258128492,"data":{"s":"BTCUSDT","b":[],"a":[["45177.60","0"],["45177.80","1.969"],["45178.00","0.124"],["45180.60","0"],["45181.60","0.011"],["45182.10","0.088"],["45182.50","0.487"],["45182.60","0.111"]],"u":20458220,"seq":114533052118},"cts":1704258128487}
{"topic":"orderbook.50.BTCUSDT","type":"delta","ts":1704258128371,"data":{"s":"BTCUSDT","b":[],"a":[["45177.60","0"],["45177.70","0"],["45177.80","1.969"],["45177.90","0.126"],["45182.50","0.443"],["45182.60","0.111"]],"u":20458215,"seq":114533051999},"cts":1704258128369}
{"topic":"orderbook.50.BTCUSDT","type":"delta","ts":1704258128551,"data":{"s":"BTCUSDT","b":[],"a":[["45177.70","0.011"],["45178.10","0.115"],["45178.50","3.934"],["45180.20","0"]],"u":20458222,"seq":114533052167},"cts":1704258128549}
{"topic":"orderbook.50.BTCUSDT","type":"delta","ts":1704258128572,"data":{"s":"BTCUSDT","b":[["45171.30","0"],["45165.60","0.109"]],"a":[["45177.80","1.969"],["45180.70","1.947"],["45181.60","0"]],"u":20458223,"seq":114533052193},"cts":1704258128570}
{"topic":"orderbook.50.BTCUSDT","type":"delta","ts":1704258128592,"data":{"s":"BTCUSDT","b":[["45171.60","0"],["45170.30","0.341"]],"a":[["45177.70","0"],["45178.10","0.126"],["45178.50","0.173"],["45180.70","2.973"],["45182.60","0.111"]],"u":20458224,"seq":114533052216},"cts":1704258128589}
{"topic":"orderbook.50.BTCUSDT","type":"delta","ts":1704258128032,"data":{"s":"BTCUSDT","b":[],"a":[["45181.60","0"],["45182.20","0.532"]],"u":20458201,"seq":114533051558},"cts":1704258128029}
{"topic":"orderbook.50.BTCUSDT","type":"delta","ts":1704258128611,"data":{"s":"BTCUSDT","b":[],"a":[["45177.80","0.022"],["45180.30","2.057"],["45180.70","0"],["45182.70","0.753"]],"u":20458225,"seq":114533052234},"cts":1704258128609}
{"topic":"orderbook.50.BTCUSDT","type":"delta","ts":1704258128631,"data":{"s":"BTCUSDT","b":[["45169.90","0.111"]],"a":[["45177.70","0.011"],["45178.10","0.115"],["45178.60","3.894"],["45180.30","0.110"],["45180.80","1.769"],["45182.70","0"]],"u":20458226,"seq":114533052252},"cts":1704258128630}
{"topic":"orderbook.50.BTCUSDT","type":"delta","ts":1704258128652,"data":{"s":"BTCUSDT","b":[["45170.20","0.149"]],"a":[["45177.90","2.062"],["45181.00","0.479"]],"u":20458227,"seq":114533052277},"cts":1704258128646}
{"topic":"orderbook.50.BTCUSDT","type":"delta","ts":1704258128052,"data":{"s":"BTCUSDT","b":[["45174.20","3.975"]],"a":[["45180.60","3.805"],["45180.70","0"],["45182.30","0.266"]],"u":20458202,"seq":114533051587},"cts":1704258128049}
{"topic":"orderbook.50.BTCUSDT","type":"delta","ts":1704258128071,"data":{"s":"BTCUSDT","b":[["45171.80","0"],["45171.70","0.001"],["45169.70","0.259"]],"a":[["45180.60","0.044"],["45180.70","3.797"],["45182.30","0"]],"u":20458203,"seq":114533051611},"cts":1704258128069}
{"topic":"orderbook.50.BTCUSDT","type":"delta","ts":1704258128111,"data":{"s":"BTCUSDT","b":[],"a":[["45180.70","0.036"],["45182.10","0.055"]],"u":20458204,"seq":114533051653},"cts":1704258128110}
{"topic":"orderbook.50.BTCUSDT","type":"delta","ts":1704258128692,"data":{"s":"BTCUSDT","b":[["45171.70","0"],["45171.60","0.001"]],"a":[["45178.20","0.122"]],"u":20458229,"seq":114533052342},"cts":1704258128688}
{"topic":"orderbook.50.BTCUSDT","type":"delta","ts":1704258128132,"data":{"s":"BTCUSDT","b":[["45174.20","3.977"],["45169.70","0.223"],["45168.30","0.331"]],"a":[],"u":20458205,"seq":114533051683},"cts":1704258128130}
{"topic":"orderbook.50.BTCUSDT","type":"delta","ts":1704258128172,"data":{"s":"BTCUSDT","b":[],"a":[["45180.70","3.797"]],"u":20458206,"seq":114533051726},"cts":1704258128170}
{"topic":"orderbook.50.BTCUSDT","type":"delta","ts":1704258128192,"data":{"s":"BTCUSDT","b":[],"a":[["45181.60","0.011"],["45182.20","0"]],"u":20458207,"seq":114533051746},"cts":1704258128189}
{"topic":"orderbook.50.BTCUSDT","type":"delta","ts":1704258128251,"data":{"s":"BTCUSDT","b":[["45171.60","0"],["45170.30","0.335"]],"a":[],"u":20458210,"seq":114533051811},"cts":1704258128250}
{"topic":"orderbook.50.BTCUSDT","type":"delta","ts":1704258128271,"data":{"s":"BTCUSDT","b":[["45174.20","3.263"]],"a":[["45176.90","0"],["45177.00","0.094"],["45180.70","0.036"],["45181.60","0"],["45181.70","0.565"],["45182.20","0.532"],["45182.30","0.266"]],"u":20458211,"seq":114533051844},"cts":1704258128270}
{"topic":"orderbook.50.BTCUSDT","type":"delta","ts":1704258128292,"data":{"s":"BTCUSDT","b":[["45174.20","4.303"],["45171.30","1.600"],["45165.40","0"]],"a":[],"u":20458212,"seq":114533051872},"cts":1704258128289}
{"topic":"orderbook.50.BTCUSDT","type":"delta","ts":1704258128312,"data":{"s":"BTCUSDT","b":[["45173.00","0.112"],["45171.60","0.961"],["45170.30","0"],["45169.60","1.236"],["45165.50","0"]],"a":[["45177.00","0.083"],["45177.60","0.011"],["45179.80","0"],["45180.60","0.080"],["45180.70","0"],["45182.40","0.754"]],"u":20458213,"seq":114533051898},"cts":1704258128308}
{"topic":"orderbook.50.BTCUSDT","type":"delta","ts":1704258128672,"data":{"s":"BTCUSDT","b":[["45169.60","0"],["45168.30","0.110"],["45167.70","0"],["45166.80","0"],["45166.10","0"],["45165.50","0.111"],["45165.40","0.010"],["45165.30","1.204"],["45165.10","2.708"]],"a":[["45174.30","1.978"],["45177.70","0"],["45178.60","0.133"],["45182.70","0.753"]],"u":20458228,"seq":114533052312},"cts":1704258128670}
{"topic":"orderbook.50.BTCUSDT","type":"delta","ts":1704258128432,"data":{"s":"BTCUSDT","b":[],"a":[["45177.90","0.115"],["45178.00","0.124"],["45181.90","2.477"]],"u":20458217,"seq":114533052063},"cts":1704258128429}
{"topic":"orderbook.50.BTCUSDT","type":"delta","ts":1704258128232,"data":{"s":"BTCUSDT","b":[["45171.30","0"],["45169.60","1.200"],["45165.40","0.010"]],"a":[["45180.70","3.797"]],"u":20458209,"seq":114533051794},"cts":1704258128229}
{"topic":"orderbook.50.BTCUSDT","type":"delta","ts":1704258128411,"data":{"s":"BTCUSDT","b":[["45169.90","0.147"]],"a":[["45180.80","1.805"]],"u":20458216,"seq":114533052042},"cts":1704258128409}
{"topic":"orderbook.50.BTCUSDT","type":"delta","ts":1704258128532,"data":{"s":"BTCUSDT","b":[],"a":[["45177.80","0.022"],["45178.00","0.113"],["45178.10","0.126"],["45180.20","1.947"],["45182.60","0"]],"u":20458221,"seq":114533052148},"cts":1704258128528}
{"topic":"orderbook.50.BTCUSDT","type":"delta","ts":1704258128211,"data":{"s":"BTCUSDT","b":[["45169.60","1.236"]],"a":[["45180.70","0.036"]],"u":20458208,"seq":114533051769},"cts":1704258128209}
{"topic":"orderbook.50.BTCUSDT","type":"delta","ts":1704258128711,"data":{"s":"BTCUSDT","b":[],"a":[["45177.70","0.011"],["45177.80","1.969"],["45177.90","0.115"],["45178.20","0.111"],["45178.60","3.894"],["45182.70","0"]],"u":20458230,"seq":114533052367},"cts":1704258128709}
{"topic":"orderbook.50.BTCUSDT","type":"delta","ts":1704258128731,"data":{"s":"BTCUSDT","b":[["45170.20","0.113"],["45165.40","0.231"]],"a":[["45178.40","0.188"],["45181.60","0.011"],["45181.90","2.499"],["45182.60","0"]],"u":20458231,"seq":114533052395},"cts":1704258128730}
{"topic":"orderbook.50.BTCUSDT","type":"delta","ts":1704258128751,"data":{"s":"BTCUSDT","b":[["45170.10","0.269"]],"a":[["45178.50","0.151"],["45178.60","0.133"],["45179.40","0.537"],["45179.70","0.111"],["45181.80","2.468"]],"u":20458232,"seq":114533052428},"cts":1704258128749}
{"topic":"orderbook.50.BTCUSDT","type":"delta","ts":1704258128771,"data":{"s":"BTCUSDT","b":[],"a":[["45176.40","0"],["45177.80","1.947"],["45178.60","0.111"],["45180.00","0.272"],["45181.10","0.132"],["45182.20","0.554"],["45182.60","0.111"]],"u":20458233,"seq":114533052457},"cts":1704258128770}
{"topic":"orderbook.50.BTCUSDT","type":"delta","ts":1704258128791,"data":{"s":"BTCUSDT","b":[],"a":[["45174.30","1.956"],["45181.50","0.022"],["45181.60","0"]],"u":20458234,"seq":114533052475},"cts":1704258128787}
{"topic":"orderbook.50.BTCUSDT","type":"delta","ts":1704258128811,"data":{"s":"BTCUSDT","b":[],"a":[["45177.70","0"],["45178.10","0.126"],["45180.90","1.470"],["45182.70","0.775"]],"u":20458235,"seq":114533052500},"cts":1704258128809}
{"topic":"orderbook.50.BTCUSDT","type":"delta","ts":1704258128832,"data":{"s":"BTCUSDT","b":[["45170.10","0.233"],["45166.30","0.221"],["45165.10","0"]],"a":[["45179.20","0.271"],["45181.00","0.443"]],"u":20458236,"seq":114533052523},"cts":1704258128830}
{"topic":"orderbook.50.BTCUSDT","type":"delta","ts":1704258128852,"data":{"s":"BTCUSDT","b":[["45169.90","0.147"]],"a":[["45180.70","0.036"],["45182.70","0"]],"u":20458237,"seq":114533052545},"cts":1704258128849}
{"topic":"orderbook.50.BTCUSDT","type":"delta","ts":1704258128872,"data":{"s":"BTCUSDT","b":[],"a":[["45178.00","0.124"],["45178.10","0.115"],["45181.60","0.011"],["45182.60","0"]],"u":20458238,"seq":114533052566},"cts":1704258128869}
{"topic":"orderbook.50.BTCUSDT","type":"delta","ts":1704258128891,"data":{"s":"BTCUSDT","b":[],"a":[["45177.70","0.011"],["45178.00","0.113"],["45182.50","0"]],"u":20458239,"seq":114533052584},"cts":1704258128889}
{"topic":"orderbook.50.BTCUSDT","type":"delta","ts":1704258128911,"data":{"s":"BTCUSDT","b":[["45174.00","0.153"]],"a":[["45177.70","0"],["45178.00","0.124"],["45182.50","0.487"]],"u":20458240,"seq":114533052601},"cts":1704258128910}
{"topic":"orderbook.50.BTCUSDT","type":"delta","ts":1704258128932,"data":{"s":"BTCUSDT","b":[["45173.70","0.038"],["45169.90","0.111"],["45167.20","0.721"],["45165.30","0"]],"a":[["45174.80","0.003"],["45177.90","0.126"],["45178.00","0.113"],["45180.70","0"]],"u":20458241,"seq":114533052626},"cts":1704258128929}
{"topic":"orderbook.50.BTCUSDT","type":"delta","ts":1704258128952,"data":{"s":"BTCUSDT","b":[["45166.20","0.006"],["45165.40","0"]],"a":[["45176.30","0.003"],["45180.60","3.761"],["45180.90","1.506"],["45182.40","0"],["45182.50","0"]],"u":20458242,"seq":114533052650},"cts":1704258128949}
{"topic":"orderbook.50.BTCUSDT","type":"delta","ts":1704258128971,"data":{"s":"BTCUSDT","b":[],"a":[["45177.70","0.011"],["45177.90","0.115"],["45182.30","0"]],"u":20458243,"seq":114533052669},"cts":1704258128969}
{"topic":"orderbook.50.BTCUSDT","type":"delta","ts":1704258128991,"data":{"s":"BTCUSDT","b":[["45170.00","0.594"]],"a":[["45180.90","1.470"]],"u":20458244,"seq":114533052689},"cts":1704258128985}
{"topic":"orderbook.50.BTCUSDT","type":"delta","ts":1704258129012,"data":{"s":"BTCUSDT","b":[["45174.20","4.302"],["45172.60","0.168"],["45169.30","0.110"],["45169.10","0.104"],["45165.50","0"]],"a":[["45175.30","0.003"],["45182.20","0"]],"u":20458245,"seq":114533052713},"cts":1704258129009}
{"topic":"orderbook.50.BTCUSDT","type":"delta","ts":1704258129032,"data":{"s":"BTCUSDT","b":[["45170.00","0.558"]],"a":[["45180.60","0"],["45182.00","1.721"],["45182.20","0.554"]],"u":20458246,"seq":114533052735},"cts":1704258129028}
{"topic":"orderbook.50.BTCUSDT","type":"delta","ts":1704258129052,"data":{"s":"BTCUSDT","b":[["45174.20","4.327"]],"a":[["45180.40","3.835"],["45180.60","0.036"],["45182.20","0"]],"u":20458247,"seq":114533052761},"cts":1704258129050}
{"topic":"orderbook.50.BTCUSDT","type":"delta","ts":1704258129111,"data":{"s":"BTCUSDT","b":[["45169.80","0.077"]],"a":[],"u":20458248,"seq":114533052813},"cts":1704258129109}
{"topic":"orderbook.50.BTCUSDT","type":"delta","ts":1704258129132,"data":{"s":"BTCUSDT","b":[["45169.80","0.041"]],"a":[["45180.60","0"],["45181.30","0.335"],["45182.20","0.554"]],"u":20458249,"seq":114533052843},"cts":1704258129130}
{"topic":"orderbook.50.BTCUSDT","type":"delta","ts":1704258129172,"data":{"s":"BTCUSDT","b":[],"a":[["45177.00","0.094"],["45177.70","3.761"],["45180.40","0.074"],["45180.90","1.506"]],"u":20458250,"seq":114533052893},"cts":1704258129169}
{"topic":"orderbook.50.BTCUSDT","type":"delta","ts":1704258129192,"data":{"s":"BTCUSDT","b":[],"a":[["45176.70","0.016"],["45177.00","0.083"],["45180.90","1.470"]],"u":20458251,"seq":114533052920},"cts":1704258129188}
{"topic":"orderbook.50.BTCUSDT","type":"delta","ts":1704258129232,"data":{"s":"BTCUSDT","b":[["45169.80","0.077"]],"a":[],"u":20458252,"seq":114533052956},"cts":1704258129228}
{"topic":"orderbook.50.BTCUSDT","type":"delta","ts":1704258129251,"data":{"s":"BTCUSDT","b":[["45174.20","4.339"]],"a":[["45176.70","0.005"],["45177.00","0.094"],["45177.70","0"],["45180.00","0.228"],["45182.00","1.765"],["45182.30","0.266"]],"u":20458253,"seq":114533053001},"cts":1704258129250}
{"topic":"orderbook.50.BTCUSDT","type":"delta","ts":1704258129272,"data":{"s":"BTCUSDT","b":[],"a":[["45177.80","0"],["45180.40","3.835"],["45180.70","0.036"],["45181.30","0.114"]],"u":20458254,"seq":114533053029},"cts":1704258129270}
{"topic":"orderbook.50.BTCUSDT","type":"delta","ts":1704258129291,"data":{"s":"BTCUSDT","b":[["45174.20","4.341"]],"a":[],"u":20458255,"seq":114533053051},"cts":1704258129289}
{"topic":"orderbook.50.BTCUSDT","type":"delta","ts":1704258129332,"data":{"s":"BTCUSDT","b":[["45170.30","0.377"],["45169.80","0.041"]],"a":[["45180.40","0.074"],["45180.70","0"],["45182.40","0.754"]],"u":20458256,"seq":114533053094},"cts":1704258129328}
{"topic":"orderbook.50.BTCUSDT","type":"delta","ts":1704258129371,"data":{"s":"BTCUSDT","b":[["45169.60","1.200"],["45165.60","0"]],"a":[["45177.00","0.083"],["45177.80","1.958"],["45182.40","0"]],"u":20458257,"seq":114533053149},"cts":1704258129369}
{"topic":"orderbook.50.BTCUSDT","type":"delta","ts":1704258129392,"data":{"s":"BTCUSDT","b":[],"a":[["45178.20","3.872"]],"u":20458258,"seq":114533053171},"cts":1704258129388}
{"topic":"orderbook.50.BTCUSDT","type":"delta","ts":1704258129411,"data":{"s":"BTCUSDT","b":[],"a":[["45181.00","0.479"]],"u":20458259,"seq":114533053188},"cts":1704258129409}
{"topic":"orderbook.50.BTCUSDT","type":"delta","ts":1704258129431,"data":{"s":"BTCUSDT","b":[["45170.30","0.341"]],"a":[["45181.00","0.443"],["45181.60","0"],["45181.70","0.565"],["45182.40","0.754"]],"u":20458260,"seq":114533053215},"cts":1704258129429}
{"topic":"orderbook.50.BTCUSDT","type":"delta","ts":1704258129452,"data":{"s":"BTCUSDT","b":[["45169.90","0.147"]],"a":[["45174.30","1.978"],["45180.40","3.047"]],"u":20458261,"seq":114533053234},"cts":1704258129450}
{"topic":"orderbook.50.BTCUSDT","type":"delta","ts":1704258129472,"data":{"s":"BTCUSDT","b":[],"a":[["45174.30","3.378"],["45177.70","0.011"],["45177.80","1.947"],["45178.20","0.111"],["45180.40","0.074"],["45180.70","3.761"],["45182.30","0"],["45182.40","0"]],"u":20458262,"seq":114533053257},"cts":1704258129470}
{"topic":"orderbook.50.BTCUSDT","type":"delta","ts":1704258129492,"data":{"s":"BTCUSDT","b":[],"a":[["45181.70","0.554"]],"u":20458263,"seq":114533053268},"cts":1704258129489}
{"topic":"orderbook.50.BTCUSDT","type":"delta","ts":1704258129512,"data":{"s":"BTCUSDT","b":[],"a":[["45174.30","3.356"],["45176.30","0.006"],["45180.40","3.835"],["45180.70","0"],["45182.30","0.266"]],"u":20458264,"seq":114533053274},"cts":1704258129508}
{"topic":"orderbook.50.BTCUSDT","type":"delta","ts":1704258129532,"data":{"s":"BTCUSDT","b":[],"a":[["45180.60","0.036"],["45182.30","0"]],"u":20458265,"seq":114533053283},"cts":1704258129530}
{"topic":"orderbook.50.BTCUSDT","type":"delta","ts":1704258129551,"data":{"s":"BTCUSDT","b":[],"a":[["45180.40","0.074"]],"u":20458266,"seq":114533053293},"cts":1704258129548}
{"topic":"orderbook.50.BTCUSDT","type":"delta","ts":1704258129572,"data":{"s":"BTCUSDT","b":[["45169.10","0.216"]],"a":[["45177.70","0"],["45177.80","0"],["45178.50","0.162"],["45178.80","1.947"],["45182.30","0.266"]],"u":20458267,"seq":114533053304},"cts":1704258129565}
{"topic":"orderbook.50.BTCUSDT","type":"delta","ts":1704258129592,"data":{"s":"BTCUSDT","b":[["45169.30","0.128"]],"a":[["45178.50","0.151"],["45178.60","0.122"],["45182.00","1.544"]],"u":20458268,"seq":114533053310},"cts":1704258129590}
{"topic":"orderbook.50.BTCUSDT","type":"delta","ts":1704258129632,"data":{"s":"BTCUSDT","b":[["45168.00","0.335"]],"a":[["45178.50","0.162"],["45178.60","0.111"]],"u":20458269,"seq":114533053320},"cts":1704258129625}
{"topic":"orderbook.50.BTCUSDT","type":"delta","ts":1704258129652,"data":{"s":"BTCUSDT","b":[],"a":[["45178.50","0.151"],["45178.80","0"],["45180.70","1.947"],["45181.60","0.011"],["45182.30","0"]],"u":20458270,"seq":114533053334},"cts":1704258129648}
{"topic":"orderbook.50.BTCUSDT","type":"delta","ts":1704258129672,"data":{"s":"BTCUSDT","b":[],"a":[["45177.80","0.011"],["45178.80","1.947"],["45180.70","0"],["45182.20","0"]],"u":20458271,"seq":114533053344},"cts":1704258129668}
{"topic":"orderbook.50.BTCUSDT","type":"delta","ts":1704258129732,"data":{"s":"BTCUSDT","b":[["45169.90","0.111"]],"a":[["45180.60","0"],["45182.20","0.554"]],"u":20458272,"seq":114533053365},"cts":1704258129728}
{"topic":"orderbook.50.BTCUSDT","type":"delta","ts":1704258129752,"data":{"s":"BTCUSDT","b":[["45169.80","0.077"]],"a":[["45178.80","0"],["45180.30","3.871"],["45180.50","0.479"],["45182.30","0.266"]],"u":20458273,"seq":114533053374},"cts":1704258129744}
{"topic":"orderbook.50.BTCUSDT","type":"delta","ts":1704258129772,"data":{"s":"BTCUSDT","b":[],"a":[["45178.80","1.947"],["45180.30","0.110"],["45182.30","0"]],"u":20458274,"seq":114533053388},"cts":1704258129766}
{"topic":"orderbook.50.BTCUSDT","type":"delta","ts":1704258129832,"data":{"s":"BTCUSDT","b":[],"a":[["45176.70","0.105"],["45178.70","2.013"],["45178.80","0"],["45182.30","0.266"]],"u":20458275,"seq":114533053418},"cts":1704258129828}
{"topic":"orderbook.50.BTCUSDT","type":"delta","ts":1704258129852,"data":{"s":"BTCUSDT","b":[["45173.00","0.113"],["45171.60","0.004"]],"a":[["45178.70","0.066"],["45178.80","1.947"],["45182.30","0"]],"u":20458276,"seq":114533053430},"cts":1704258129844}
{"topic":"orderbook.50.BTCUSDT","type":"delta","ts":1704258129872,"data":{"s":"BTCUSDT","b":[["45171.60","0.005"]],"a":[],"u":20458277,"seq":114533053444},"cts":1704258129869}
{"topic":"orderbook.50.BTCUSDT","type":"delta","ts":1704258129891,"data":{"s":"BTCUSDT","b":[["45171.60","0.006"]],"a":[],"u":20458278,"seq":114533053450},"cts":1704258129880}
{"topic":"orderbook.50.BTCUSDT","type":"delta","ts":1704258129912,"data":{"s":"BTCUSDT","b":[["45174.20","4.342"],["45171.60","0.005"]],"a":[["45176.30","0.003"],["45178.70","2.013"],["45178.80","0"],["45182.30","0.266"]],"u":20458279,"seq":114533053459},"cts":1704258129907}
{"topic":"orderbook.50.BTCUSDT","type":"delta","ts":1704258129932,"data":{"s":"BTCUSDT","b":[["45169.80","0.041"]],"a":[["45178.70","0.066"],["45180.50","0.443"]],"u":20458280,"seq":114533053469},"cts":1704258129929}
{"topic":"orderbook.50.BTCUSDT","type":"delta","ts":1704258129952,"data":{"s":"BTCUSDT","b":[["45169.80","0.077"]],"a":[["45178.80","1.947"],["45180.60","0.036"],["45182.20","0"],["45182.30","0"]],"u":20458281,"seq":114533053479},"cts":1704258129943}
{"topic":"orderbook.50.BTCUSDT","type":"delta","ts":1704258129972,"data":{"s":"BTCUSDT","b":[],"a":[["45180.50","0"],["45181.00","0"],["45182.20","0.554"],["45182.30","0.266"]],"u":20458282,"seq":114533053491},"cts":1704258129969}
{"topic":"orderbook.50.BTCUSDT","type":"delta","ts":1704258129992,"data":{"s":"BTCUSDT","b":[],"a":[["45178.70","2.013"],["45178.80","0"],["45182.40","0.754"]],"u":20458283,"seq":114533053500},"cts":1704258129988}
{"topic":"orderbook.50.BTCUSDT","type":"delta","ts":1704258130012,"data":{"s":"BTCUSDT","b":[["45174.20","4.190"],["45168.00","0.114"]],"a":[["45178.70","0.066"],["45181.70","2.501"]],"u":20458284,"seq":114533053510},"cts":1704258130006}
{"topic":"orderbook.50.BTCUSDT","type":"delta","ts":1704258130032,"data":{"s":"BTCUSDT","b":[["45169.80","0.041"]],"a":[["45178.80","1.947"],["45180.20","3.761"],["45180.60","0"],["45181.70","0.554"],["45182.40","0"]],"u":20458285,"seq":114533053527},"cts":1704258130029}
{"topic":"orderbook.50.BTCUSDT","type":"delta","ts":1704258130052,"data":{"s":"BTCUSDT","b":[["45169.70","0.259"]],"a":[["45180.20","0"],["45180.50","0.036"]],"u":20458286,"seq":114533053543},"cts":1704258130049}
{"topic":"orderbook.50.BTCUSDT","type":"delta","ts":1704258130072,"data":{"s":"BTCUSDT","b":[],"a":[["45178.60","2.058"],["45178.80","0"],["45180.70","3.761"]],"u":20458287,"seq":114533053561},"cts":1704258130069}
{"topic":"orderbook.50.BTCUSDT","type":"delta","ts":1704258130092,"data":{"s":"BTCUSDT","b":[["45169.60","0"],["45165.50","0.111"]],"a":[],"u":20458288,"seq":114533053567},"cts":1704258130089}
{"topic":"orderbook.50.BTCUSDT","type":"delta","ts":1704258130112,"data":{"s":"BTCUSDT","b":[["45165.60","0.109"],["45165.50","0"]],"a":[["45180.20","3.761"],["45180.70","0"]],"u":20458289,"seq":114533053579},"cts":1704258130109}
{"topic":"orderbook.50.BTCUSDT","type":"delta","ts":1704258130132,"data":{"s":"BTCUSDT","b":[["45169.70","0.223"]],"a":[["45180.20","0"],["45180.50","0"],["45182.40","0.754"],["45182.50","0.487"]],"u":20458290,"seq":114533053595},"cts":1704258130126}
{"topic":"orderbook.50.BTCUSDT","type":"delta","ts":1704258130151,"data":{"s":"BTCUSDT","b":[["45174.20","4.179"],["45171.60","0.006"]],"a":[["45181.60","3.772"]],"u":20458291,"seq":114533053606},"cts":1704258130149}
{"topic":"orderbook.50.BTCUSDT","type":"delta","ts":1704258130172,"data":{"s":"BTCUSDT","b":[["45169.80","0.077"]],"a":[["45180.60","0.036"],["45180.80","2.212"],["45182.50","0"]],"u":20458292,"seq":114533053620},"cts":1704258130166}
{"topic":"orderbook.50.BTCUSDT","type":"delta","ts":1704258130192,"data":{"s":"BTCUSDT","b":[["45173.00","0.112"],["45171.60","0.003"]],"a":[["45176.70","0.104"],["45178.60","0.111"],["45178.80","1.947"],["45180.60","0"],["45181.60","0.011"],["45182.00","1.555"],["45182.10","0.077"]],"u":20458293,"seq":114533053686},"cts":1704258130190}
{"topic":"orderbook.50.BTCUSDT","type":"delta","ts":1704258130211,"data":{"s":"BTCUSDT","b":[],"a":[["45176.20","0.003"],["45178.50","2.098"],["45178.80","0"]],"u":20458294,"seq":114533053707},"cts":1704258130210}
{"topic":"orderbook.50.BTCUSDT","type":"delta","ts":1704258130232,"data":{"s":"BTCUSDT","b":[["45169.80","0.041"],["45168.00","0.335"]],"a":[["45178.40","2.135"],["45178.50","0.151"],["45180.70","3.761"],["45182.40","0"]],"u":20458295,"seq":114533053730},"cts":1704258130228}
{"topic":"orderbook.50.BTCUSDT","type":"delta","ts":1704258130252,"data":{"s":"BTCUSDT","b":[["45171.60","0.002"],["45166.00","0.224"]],"a":[["45174.30","3.556"]],"u":20458296,"seq":114533053749},"cts":1704258130250}
{"topic":"orderbook.50.BTCUSDT","type":"delta","ts":1704258130271,"data":{"s":"BTCUSDT","b":[["45174.20","2.911"],["45169.60","0.036"],["45165.60","0"]],"a":[["45178.30","2.036"],["45178.40","0.188"],["45180.40","0.110"],["45180.50","3.761"],["45180.70","0"]],"u":20458297,"seq":114533053805},"cts":1704258130270}
{"topic":"orderbook.50.BTCUSDT","type":"delta","ts":1704258130291,"data":{"s":"BTCUSDT","b":[["45174.20","2.176"],["45171.60","0.003"]],"a":[["45176.70","0.105"],["45178.30","0.089"],["45178.40","2.135"],["45178.60","3.872"],["45180.50","0"],["45182.40","0.754"]],"u":20458298,"seq":114533053851},"cts":1704258130290}
{"topic":"orderbook.50.BTCUSDT","type":"delta","ts":1704258130311,"data":{"s":"BTCUSDT","b":[["45174.20","2.519"],["45174.00","0.040"],["45171.60","0"],["45169.30","0.110"],["45169.10","0.104"],["45166.70","2.195"],["45165.50","0.111"]],"a":[["45176.70","0.100"],["45178.60","0.111"],["45179.80","0.425"],["45180.60","0.044"],["45180.70","3.761"],["45182.20","0"],["45182.30","0"],["45182.40","0"]],"u":20458299,"seq":114533053945},"cts":1704258130310}
{"topic":"orderbook.50.BTCUSDT","type":"delta","ts":1704258130332,"data":{"s":"BTCUSDT","b":[["45174.20","2.751"],["45169.60","0"],["45168.00","0.114"],["45165.60","0.109"]],"a":[["45174.30","3.570"],["45178.30","2.036"],["45178.40","0.188"],["45180.40","0.074"],["45182.00","1.776"]],"u":20458300,"seq":114533054038},"cts":1704258130330}
{"topic":"orderbook.50.BTCUSDT","type":"delta","ts":1704258130352,"data":{"s":"BTCUSDT","b":[["45173.00","0"],["45165.40","0.231"]],"a":[["45178.30","0.089"],["45180.70","0"],["45182.00","1.765"],["45182.10","0.088"],["45182.20","0.554"]],"u":20458301,"seq":114533054082},"cts":1704258130350}
{"topic":"orderbook.50.BTCUSDT","type":"delta","ts":1704258130371,"data":{"s":"BTCUSDT","b":[["45174.20","2.458"],["45167.20","0.500"]],"a":[["45176.60","1.200"],["45177.00","0.094"],["45177.80","5.708"],["45182.20","0"]],"u":20458302,"seq":114533054113},"cts":1704258130369}
{"topic":"orderbook.50.BTCUSDT","type":"delta","ts":1704258130391,"data":{"s":"BTCUSDT","b":[["45174.20","2.451"],["45172.20","0.056"],["45168.70","1.658"],["45168.30","0"],["45167.50","0.083"],["45166.30","0"],["45165.40","0.010"],["45165.30","1.200"],["45165.20","0.544"]],"a":[["45179.80","1.661"]],"u":20458303,"seq":114533054200},"cts":1704258130389}
{"topic":"orderbook.50.BTCUSDT","type":"delta","ts":1704258130411,"data":{"s":"BTCUSDT","b":[["45168.70","1.693"]],"a":[["45180.40","0.109"],["45180.50","1.947"],["45181.40","0.122"],["45181.60","0"],["45182.10","0.077"]],"u":20458304,"seq":114533054236},"cts":1704258130409}
{"topic":"orderbook.50.BTCUSDT","type":"delta","ts":1704258130431,"data":{"s":"BTCUSDT","b":[["45168.70","1.658"],["45166.70","3.700"]],"a":[["45179.80","2.477"],["45180.40","0.074"],["45180.50","4.920"]],"u":20458305,"seq":114533054276},"cts":1704258130429}
{"topic":"orderbook.50.BTCUSDT","type":"delta","ts":1704258130452,"data":{"s":"BTCUSDT","b":[["45173.00","0.001"],["45165.20","0"]],"a":[["45177.70","3.761"],["45177.80","1.947"],["45178.50","3.125"],["45178.60","2.058"],["45180.50","0"]],"u":20458306,"seq":114533054298},"cts":1704258130445}
{"topic":"orderbook.50.BTCUSDT","type":"delta","ts":1704258130471,"data":{"s":"BTCUSDT","b":[["45171.60","0.001"],["45168.60","0.113"],["45165.30","0"]],"a":[["45177.00","0.083"],["45177.70","0"],["45177.80","0"],["45178.50","0.151"],["45178.60","0.111"],["45180.20","3.772"],["45180.50","1.947"]],"u":20458307,"seq":114533054335},"cts":1704258130469}
{"topic":"orderbook.50.BTCUSDT","type":"delta","ts":1704258130492,"data":{"s":"BTCUSDT","b":[["45174.20","2.683"],["45171.60","0.003"]],"a":[["45176.70","0.102"],["45178.90","1.278"],["45179.40","0.094"],["45180.20","0"],["45180.50","3.772"],["45181.40","0.111"],["45181.60","1.947"],["45181.90","1.790"]],"u":20458308,"seq":114533054376},"cts":1704258130490}
{"topic":"orderbook.50.BTCUSDT","type":"delta","ts":1704258130511,"data":{"s":"BTCUSDT","b":[["45171.60","0.005"]],"a":[["45176.70","0.104"],["45180.40","0.085"],["45180.50","0"],["45181.60","0"],["45182.20","0.288"],["45182.30","0.266"]],"u":20458309,"seq":114533054410},"cts":1704258130510}
{"topic":"orderbook.50.BTCUSDT","type":"delta","ts":1704258130531,"data":{"s":"BTCUSDT","b":[],"a":[["45180.40","0.074"],["45181.30","0.335"]],"u":20458310,"seq":114533054448},"cts":1704258130530}
{"topic":"orderbook.50.BTCUSDT","type":"delta","ts":1704258130552,"data":{"s":"BTCUSDT","b":[],"a":[["45179.40","0.537"],["45182.30","0.532"]],"u":20458311,"seq":114533054488},"cts":1704258130548}
{"topic":"orderbook.50.BTCUSDT","type":"delta","ts":1704258130572,"data":{"s":"BTCUSDT","b":[],"a":[["45177.80","0.011"],["45178.40","2.135"],["45178.60","3.872"],["45181.80","2.479"],["45182.30","0"]],"u":20458312,"seq":114533054519},"cts":1704258130569}
{"topic":"orderbook.50.BTCUSDT","type":"delta","ts":1704258130592,"data":{"s":"BTCUSDT","b":[],"a":[["45176.70","0.105"]],"u":20458313,"seq":114533054535},"cts":1704258130589}
{"topic":"orderbook.50.BTCUSDT","type":"delta","ts":1704258130612,"data":{"s":"BTCUSDT","b":[],"a":[["45178.30","2.036"],["45178.40","0.188"],["45180.90","1.448"]],"u":20458314,"seq":114533054559},"cts":1704258130609}
{"topic":"orderbook.50.BTCUSDT","type":"delta","ts":1704258130632,"data":{"s":"BTCUSDT","b":[["45171.60","0.006"],["45168.70","1.693"]],"a":[["45178.30","0.089"],["45178.40","2.135"],["45180.40","0.109"],["45181.00","0.022"],["45181.30","0.346"],["45181.80","2.457"],["45181.90","1.768"],["45182.20","0"]],"u":20458315,"seq":114533054589},"cts":1704258130629}
{"topic":"orderbook.50.BTCUSDT","type":"delta","ts":1704258130651,"data":{"s":"BTCUSDT","b":[],"a":[["45178.40","0.188"],["45178.50","2.098"],["45180.40","0.074"],["45181.70","0.565"],["45181.80","2.446"],["45182.00","1.787"],["45182.10","0.099"]],"u":20458316,"seq":114533054617},"cts":1704258130649}
{"topic":"orderbook.50.BTCUSDT","type":"delta","ts":1704258130672,"data":{"s":"BTCUSDT","b":[["45174.10","0.070"]],"a":[["45178.50","0.151"],["45178.60","0.111"]],"u":20458317,"seq":114533054647},"cts":1704258130669}
{"topic":"orderbook.50.BTCUSDT","type":"delta","ts":1704258130692,"data":{"s":"BTCUSDT","b":[["45168.70","1.658"]],"a":[],"u":20458318,"seq":114533054667},"cts":1704258130689}
{"topic":"orderbook.50.BTCUSDT","type":"delta","ts":1704258130711,"data":{"s":"BTCUSDT","b":[],"a":[["45181.30","0.335"],["45181.70","0.554"]],"u":20458319,"seq":114533054687},"cts":1704258130710}
{"topic":"orderbook.50.BTCUSDT","type":"delta","ts":1704258130732,"data":{"s":"BTCUSDT","b":[["45169.10","0.139"]],"a":[["45181.00","0.057"]],"u":20458320,"seq":114533054708},"cts":1704258130728}
{"topic":"orderbook.50.BTCUSDT","type":"delta","ts":1704258130752,"data":{"s":"BTCUSDT","b":[["45169.10","0.104"]],"a":[["45176.60","0"],["45181.00","0.022"],["45182.20","0.288"]],"u":20458321,"seq":114533054727},"cts":1704258130748}
{"topic":"orderbook.50.BTCUSDT","type":"delta","ts":1704258130772,"data":{"s":"BTCUSDT","b":[],"a":[["45178.80","1.947"],["45182.20","0"]],"u":20458322,"seq":114533054751},"cts":1704258130769}
{"topic":"orderbook.50.BTCUSDT","type":"delta","ts":1704258130792,"data":{"s":"BTCUSDT","b":[],"a":[["45180.50","3.761"],["45182.10","0"]],"u":20458323,"seq":114533054768},"cts":1704258130790}
{"topic":"orderbook.50.BTCUSDT","type":"delta","ts":1704258130832,"data":{"s":"BTCUSDT","b":[["45170.50","0.035"],["45165.40","0"]],"a":[["45178.60","3.872"],["45180.50","0"],["45180.70","0.221"]],"u":20458324,"seq":114533054811},"cts":1704258130830}
{"topic":"orderbook.50.BTCUSDT","type":"delta","ts":1704258130852,"data":{"s":"BTCUSDT","b":[["45171.60","0.007"],["45170.50","0"],["45165.40","0.010"]],"a":[["45178.10","3.876"],["45178.60","0.111"],["45178.80","0"],["45182.10","0.099"]],"u":20458325,"seq":114533054835},"cts":1704258130849}
{"topic":"orderbook.50.BTCUSDT","type":"delta","ts":1704258130872,"data":{"s":"BTCUSDT","b":[["45169.10","0.216"]],"a":[["45177.90","2.062"],["45181.30","0.346"],["45181.80","2.457"]],"u":20458326,"seq":114533054859},"cts":1704258130866}
{"topic":"orderbook.50.BTCUSDT","type":"delta","ts":1704258130892,"data":{"s":"BTCUSDT","b":[],"a":[["45177.90","0.115"],["45178.10","0.115"],["45178.20","2.058"],["45178.40","3.949"]],"u":20458327,"seq":114533054891},"cts":1704258130890}
{"topic":"orderbook.50.BTCUSDT","type":"delta","ts":1704258130911,"data":{"s":"BTCUSDT","b":[["45174.20","2.684"]],"a":[],"u":20458328,"seq":114533054910},"cts":1704258130910}
{"topic":"orderbook.50.BTCUSDT","type":"delta","ts":1704258130932,"data":{"s":"BTCUSDT","b":[["45166.40","0.508"],["45165.60","0.330"]],"a":[["45181.30","0.406"]],"u":20458329,"seq":114533054932},"cts":1704258130930}
{"topic":"orderbook.50.BTCUSDT","type":"delta","ts":1704258130951,"data":{"s":"BTCUSDT","b":[["45169.10","0.251"]],"a":[["45178.20","0.111"],["45178.40","0.188"],["45181.10","0.167"],["45181.30","0.395"],["45181.80","2.446"],["45182.00","1.798"]],"u":20458330,"seq":114533054962},"cts":1704258130949}
{"topic":"orderbook.50.BTCUSDT","type":"delta","ts":1704258130971,"data":{"s":"BTCUSDT","b":[["45169.10","0.216"],["45168.70","2.511"]],"a":[["45180.70","3.982"],["45181.10","0.132"],["45182.10","0.066"]],"u":20458331,"seq":114533054995},"cts":1704258130969}
{"topic":"orderbook.50.BTCUSDT","type":"delta","ts":1704258130992,"data":{"s":"BTCUSDT","b":[["45169.50","1.399"]],"a":[["45178.20","2.058"]],"u":20458332,"seq":114533055012},"cts":1704258130989}
{"topic":"orderbook.50.BTCUSDT","type":"delta","ts":1704258131012,"data":{"s":"BTCUSDT","b":[["45174.20","2.683"],["45169.10","0.104"]],"a":[["45178.10","2.062"],["45178.20","0.111"]],"u":20458333,"seq":114533055029},"cts":1704258131008}
{"topic":"orderbook.50.BTCUSDT","type":"delta","ts":1704258131032,"data":{"s":"BTCUSDT","b":[],"a":[["45178.10","0.115"],["45180.70","0.221"],["45182.00","1.787"]],"u":20458334,"seq":114533055053},"cts":1704258131029}
{"topic":"orderbook.50.BTCUSDT","type":"delta","ts":1704258131052,"data":{"s":"BTCUSDT","b":[],"a":[["45178.20","2.058"],["45178.30","3.850"],["45181.40","0.122"]],"u":20458335,"seq":114533055083},"cts":1704258131050}
{"topic":"orderbook.50.BTCUSDT","type":"delta","ts":1704258131071,"data":{"s":"BTCUSDT","b":[["45169.30","0.128"]],"a":[],"u":20458336,"seq":114533055109},"cts":1704258131070}
{"topic":"orderbook.50.BTCUSDT","type":"delta","ts":1704258131092,"data":{"s":"BTCUSDT","b":[],"a":[["45178.30","0.089"],["45180.70","3.982"],["45181.40","0.111"]],"u":20458337,"seq":114533055129},"cts":1704258131089}
{"topic":"orderbook.50.BTCUSDT","type":"delta","ts":1704258131111,"data":{"s":"BTCUSDT","b":[],"a":[["45178.20","0.111"],["45180.60","1.991"],["45180.70","0.221"]],"u":20458338,"seq":114533055146},"cts":1704258131110}
{"topic":"orderbook.50.BTCUSDT","type":"delta","ts":1704258131132,"data":{"s":"BTCUSDT","b":[],"a":[["45178.20","2.058"],["45178.40","3.949"],["45180.60","0.044"]],"u":20458339,"seq":114533055173},"cts":1704258131129}
{"topic":"orderbook.50.BTCUSDT","type":"delta","ts":1704258131152,"data":{"s":"BTCUSDT","b":[["45170.00","0.594"]],"a":[["45178.40","0.188"],["45180.70","3.982"],["45181.50","0.058"]],"u":20458340,"seq":114533055198},"cts":1704258131149}
{"topic":"orderbook.50.BTCUSDT","type":"delta","ts":1704258131172,"data":{"s":"BTCUSDT","b":[["45172.10","0.033"],["45170.00","0.558"],["45165.40","0"]],"a":[["45180.70","0.221"],["45181.50","0.022"],["45182.00","1.798"]],"u":20458341,"seq":114533055223},"cts":1704258131170}
{"topic":"orderbook.50.BTCUSDT","type":"delta","ts":1704258131191,"data":{"s":"BTCUSDT","b":[],"a":[["45178.20","0.111"],["45180.60","1.991"]],"u":20458342,"seq":114533055239},"cts":1704258131188}
{"topic":"orderbook.50.BTCUSDT","type":"delta","ts":1704258131212,"data":{"s":"BTCUSDT","b":[["45172.10","0"],["45165.40","0.010"]],"a":[["45178.20","2.058"],["45180.60","0.044"]],"u":20458343,"seq":114533055264},"cts":1704258131209}
{"topic":"orderbook.50.BTCUSDT","type":"delta","ts":1704258131251,"data":{"s":"BTCUSDT","b":[],"a":[["45181.60","0.011"],["45182.00","1.787"],["45182.10","0"]],"u":20458344,"seq":114533055310},"cts":1704258131249}
{"topic":"orderbook.50.BTCUSDT","type":"delta","ts":1704258131272,"data":{"s":"BTCUSDT","b":[],"a":[["45180.70","3.982"]],"u":20458345,"seq":114533055341},"cts":1704258131270}
{"topic":"orderbook.50.BTCUSDT","type":"delta","ts":1704258131291,"data":{"s":"BTCUSDT","b":[],"a":[["45178.20","0.111"],["45178.30","3.850"],["45180.70","0.221"],["45181.90","2.210"]],"u":20458346,"seq":114533055356},"cts":1704258131286}
{"topic":"orderbook.50.BTCUSDT","type":"delta","ts":1704258131311,"data":{"s":"BTCUSDT","b":[["45174.20","2.666"]],"a":[["45178.20","2.058"],["45178.30","0.089"],["45180.70","3.982"]],"u":20458347,"seq":114533055420},"cts":1704258131310}
{"topic":"orderbook.50.BTCUSDT","type":"delta","ts":1704258131331,"data":{"s":"BTCUSDT","b":[["45174.20","2.165"],["45166.50","0.221"],["45165.40","0"]],"a":[["45181.30","0.335"],["45181.60","0"],["45182.10","0.066"]],"u":20458348,"seq":114533055483},"cts":1704258131330}
{"topic":"orderbook.50.BTCUSDT","type":"delta","ts":1704258131352,"data":{"s":"BTCUSDT","b":[],"a":[["45174.30","4.150"]],"u":20458349,"seq":114533055515},"cts":1704258131349}
{"topic":"orderbook.50.BTCUSDT","type":"delta","ts":1704258131371,"data":{"s":"BTCUSDT","b":[],"a":[["45180.70","0.221"]],"u":20458350,"seq":114533055541},"cts":1704258131370}
{"topic":"orderbook.50.BTCUSDT","type":"delta","ts":1704258131392,"data":{"s":"BTCUSDT","b":[["45170.70","0.082"],["45169.40","0.258"]],"a":[["45181.10","0.168"]],"u":20458351,"seq":114533055565},"cts":1704258131389}
{"topic":"orderbook.50.BTCUSDT","type":"delta","ts":1704258131411,"data":{"s":"BTCUSDT","b":[],"a":[["45180.70","3.982"],["45181.80","2.457"]],"u":20458352,"seq":114533055586},"cts":1704258131409}
{"topic":"orderbook.50.BTCUSDT","type":"delta","ts":1704258131432,"data":{"s":"BTCUSDT","b":[["45169.40","0.222"]],"a":[["45181.10","0.132"]],"u":20458353,"seq":114533055607},"cts":1704258131430}
{"topic":"orderbook.50.BTCUSDT","type":"delta","ts":1704258131451,"data":{"s":"BTCUSDT","b":[],"a":[["45178.20","0.111"],["45180.70","0.221"]],"u":20458354,"seq":114533055626},"cts":1704258131448}
{"topic":"orderbook.50.BTCUSDT","type":"delta","ts":1704258131472,"data":{"s":"BTCUSDT","b":[],"a":[["45178.40","2.135"],["45181.40","0.122"]],"u":20458355,"seq":114533055654},"cts":1704258131470}
{"topic":"orderbook.50.BTCUSDT","type":"delta","ts":1704258131491,"data":{"s":"BTCUSDT","b":[["45174.20","1.933"]],"a":[["45178.40","0.188"],["45178.50","2.098"],["45181.80","2.446"],["45181.90","2.221"]],"u":20458356,"seq":114533055677},"cts":1704258131488}
{"topic":"orderbook.50.BTCUSDT","type":"delta","ts":1704258131511,"data":{"s":"BTCUSDT","b":[["45169.20","0.147"]],"a":[["45180.00","0.296"],["45181.10","0.168"]],"u":20458357,"seq":114533055757},"cts":1704258131510}
{"topic":"orderbook.50.BTCUSDT","type":"delta","ts":1704258131532,"data":{"s":"BTCUSDT","b":[],"a":[["45178.50","0.151"]],"u":20458358,"seq":114533055777},"cts":1704258131529}
{"topic":"orderbook.50.BTCUSDT","type":"delta","ts":1704258131551,"data":{"s":"BTCUSDT","b":[],"a":[["45178.50","2.098"],["45178.80","3.761"],["45181.40","0.111"],["45181.60","0.011"],["45182.00","0"],["45182.10","0"]],"u":20458359,"seq":114533055800},"cts":1704258131550}
{"topic":"orderbook.50.BTCUSDT","type":"delta","ts":1704258131572,"data":{"s":"BTCUSDT","b":[["45169.20","0.111"],["45169.10","0.216"],["45166.70","2.195"]],"a":[["45178.50","0.151"],["45178.80","0"],["45180.70","2.168"],["45181.10","0.132"],["45182.00","1.787"]],"u":20458360,"seq":114533055827},"cts":1704258131570}
{"topic":"orderbook.50.BTCUSDT","type":"delta","ts":1704258131591,"data":{"s":"BTCUSDT","b":[],"a":[["45176.60","1.200"],["45178.50","2.098"],["45180.70","0.221"],["45182.00","0"]],"u":20458361,"seq":114533055850},"cts":1704258131589}
{"topic":"orderbook.50.BTCUSDT","type":"delta","ts":1704258131611,"data":{"s":"BTCUSDT","b":[],"a":[["45178.50","0.151"]],"u":20458362,"seq":114533055876},"cts":1704258131610}
{"topic":"orderbook.50.BTCUSDT","type":"delta","ts":1704258131631,"data":{"s":"BTCUSDT","b":[],"a":[["45178.50","2.098"],["45181.90","2.210"]],"u":20458363,"seq":114533055902},"cts":1704258131629}
{"topic":"orderbook.50.BTCUSDT","type":"delta","ts":1704258131652,"data":{"s":"BTCUSDT","b":[["45170.70","0.049"]],"a":[["45178.50","0.151"]],"u":20458364,"seq":114533055925},"cts":1704258131649}
{"topic":"orderbook.50.BTCUSDT","type":"delta","ts":1704258131671,"data":{"s":"BTCUSDT","b":[],"a":[["45178.30","2.036"],["45178.40","3.949"]],"u":20458365,"seq":114533055957},"cts":1704258131669}
{"topic":"orderbook.50.BTCUSDT","type":"delta","ts":1704258131692,"data":{"s":"BTCUSDT","b":[["45166.70","3.700"]],"a":[["45178.30","0.089"],["45178.40","0.188"],["45181.70","0.576"]],"u":20458366,"seq":114533055981},"cts":1704258131689}
{"topic":"orderbook.50.BTCUSDT","type":"delta","ts":1704258131711,"data":{"s":"BTCUSDT","b":[["45169.70","0.259"]],"a":[["45178.80","1.947"],["45179.10","3.876"],["45181.00","0.058"],["45181.90","0"]],"u":20458367,"seq":114533056010},"cts":1704258131710}
{"topic":"orderbook.50.BTCUSDT","type":"delta","ts":1704258131732,"data":{"s":"BTCUSDT","b":[["45169.70","0.223"],["45166.50","0"],["45165.40","0.010"]],"a":[["45178.80","0"],["45179.10","0.115"],["45181.00","0.022"],["45181.90","2.210"]],"u":20458368,"seq":114533056040},"cts":1704258131729}
{"topic":"orderbook.50.BTCUSDT","type":"delta","ts":1704258131752,"data":{"s":"BTCUSDT","b":[["45165.60","0.109"]],"a":[["45178.80","1.947"],["45179.10","3.876"],["45181.90","0"]],"u":20458369,"seq":114533056061},"cts":1704258131747}
{"topic":"orderbook.50.BTCUSDT","type":"delta","ts":1704258131772,"data":{"s":"BTCUSDT","b":[["45169.40","0.255"],["45169.10","0.104"],["45166.70","2.195"]],"a":[["45174.30","5.378"],["45178.80","0"],["45179.10","0.115"],["45181.90","2.210"]],"u":20458370,"seq":114533056094},"cts":1704258131770}
{"topic":"orderbook.50.BTCUSDT","type":"delta","ts":1704258131791,"data":{"s":"BTCUSDT","b":[["45169.30","0.110"]],"a":[["45178.80","1.947"],["45179.20","4.032"],["45181.90","0"]],"u":20458371,"seq":114533056147},"cts":1704258131790}
{"topic":"orderbook.50.BTCUSDT","type":"delta","ts":1704258131812,"data":{"s":"BTCUSDT","b":[["45169.30","0.146"]],"a":[["45178.60","2.058"],["45178.70","3.827"],["45178.80","0"],["45179.20","0.271"],["45180.90","1.484"],["45181.90","2.210"]],"u":20458372,"seq":114533056212},"cts":1704258131810}
{"topic":"orderbook.50.BTCUSDT","type":"delta","ts":1704258131832,"data":{"s":"BTCUSDT","b":[["45169.30","0.110"],["45168.70","1.658"]],"a":[["45178.50","2.098"],["45178.60","0.111"],["45178.70","0.066"],["45180.20","0.221"],["45180.90","1.448"],["45181.90","0"]],"u":20458373,"seq":114533056279},"cts":1704258131829}
{"topic":"orderbook.50.BTCUSDT","type":"delta","ts":1704258131851,"data":{"s":"BTCUSDT","b":[["45172.00","0"],["45169.50","0.914"],["45165.30","1.200"]],"a":[["45178.50","0.151"],["45178.60","3.872"]],"u":20458374,"seq":114533056336},"cts":1704258131849}
{"topic":"orderbook.50.BTCUSDT","type":"delta","ts":1704258131871,"data":{"s":"BTCUSDT","b":[["45174.20","1.922"],["45173.00","0.102"],["45172.30","0"],["45166.70","3.700"],["45165.10","2.708"]],"a":[["45178.60","0.111"],["45179.20","2.218"],["45180.50","3.761"],["45181.80","0"]],"u":20458375,"seq":114533056392},"cts":1704258131870}
{"topic":"orderbook.50.BTCUSDT","type":"delta","ts":1704258131892,"data":{"s":"BTCUSDT","b":[],"a":[["45176.50","1.600"],["45179.20","0.271"],["45180.50","0"]],"u":20458376,"seq":114533056461},"cts":1704258131889}
{"topic":"orderbook.50.BTCUSDT","type":"delta","ts":1704258131911,"data":{"s":"BTCUSDT","b":[["45174.20","1.923"],["45169.10","0.140"]],"a":[["45180.70","0.257"]],"u":20458377,"seq":114533056521},"cts":1704258131910}
{"topic":"orderbook.50.BTCUSDT","type":"delta","ts":1704258131931,"data":{"s":"BTCUSDT","b":[["45169.10","0.104"]],"a":[["45180.70","0.221"]],"u":20458378,"seq":114533056584},"cts":1704258131930}
{"topic":"orderbook.50.BTCUSDT","type":"delta","ts":1704258131992,"data":{"s":"BTCUSDT","b":[],"a":[["45177.80","0"],["45178.20","0.122"],["45181.80","2.446"]],"u":20458379,"seq":114533056734},"cts":1704258131990}
{"topic":"orderbook.50.BTCUSDT","type":"delta","ts":1704258132032,"data":{"s":"BTCUSDT","b":[["45168.80","0.270"]],"a":[["45180.80","2.248"]],"u":20458380,"seq":114533056843},"cts":1704258132030}
{"topic":"orderbook.50.BTCUSDT","type":"delta","ts":1704258132051,"data":{"s":"BTCUSDT","b":[["45174.20","1.922"],["45168.80","0.234"]],"a":[],"u":20458381,"seq":114533056930},"cts":1704258132050}
{"topic":"orderbook.50.BTCUSDT","type":"delta","ts":1704258132112,"data":{"s":"BTCUSDT","b":[],"a":[["45180.80","2.212"]],"u":20458382,"seq":114533057079},"cts":1704258132110}
{"topic":"orderbook.50.BTCUSDT","type":"delta","ts":1704258132132,"data":{"s":"BTCUSDT","b":[["45171.20","0"],["45165.00","0.376"]],"a":[],"u":20458383,"seq":114533057142},"cts":1704258132130}
{"topic":"orderbook.50.BTCUSDT","type":"delta","ts":1704258132152,"data":{"s":"BTCUSDT","b":[["45168.80","0.270"]],"a":[["45178.10","0.126"],["45178.20","0.111"],["45180.90","1.484"]],"u":20458384,"seq":114533057204},"cts":1704258132150}
{"topic":"orderbook.50.BTCUSDT","type":"delta","ts":1704258132191,"data":{"s":"BTCUSDT","b":[["45165.20","0.544"],["45165.00","0"]],"a":[],"u":20458385,"seq":114533057316},"cts":1704258132190}
{"topic":"orderbook.50.BTCUSDT","type":"delta","ts":1704258132211,"data":{"s":"BTCUSDT","b":[["45174.20","2.678"]],"a":[["45174.30","4.178"],["45176.50","0"],["45178.10","0.115"],["45178.30","0.100"],["45181.90","2.210"]],"u":20458386,"seq":114533057378},"cts":1704258132209}
{"topic":"orderbook.50.BTCUSDT","type":"delta","ts":1704258132232,"data":{"s":"BTCUSDT","b":[["45168.80","0.234"],["45165.50","0.332"]],"a":[["45180.90","1.448"]],"u":20458387,"seq":114533057442},"cts":1704258132230}
{"topic":"orderbook.50.BTCUSDT","type":"delta","ts":1704258132252,"data":{"s":"BTCUSDT","b":[["45168.70","1.694"]],"a":[["45180.80","2.248"]],"u":20458388,"seq":114533057463},"cts":1704258132249}
{"topic":"orderbook.50.BTCUSDT","type":"delta","ts":1704258132292,"data":{"s":"BTCUSDT","b":[],"a":[["45178.30","0.089"],["45178.40","0.199"]],"u":20458389,"seq":114533057502},"cts":1704258132287}
{"topic":"orderbook.50.BTCUSDT","type":"delta","ts":1704258132332,"data":{"s":"BTCUSDT","b":[["45174.20","2.669"],["45168.70","1.658"]],"a":[["45177.80","0.011"],["45180.60","5.752"],["45180.80","2.212"],["45181.90","0"]],"u":20458391,"seq":114533057619},"cts":1704258132330}
{"topic":"orderbook.50.BTCUSDT","type":"delta","ts":1704258132311,"data":{"s":"BTCUSDT","b":[["45174.20","1.964"]],"a":[["45178.40","0.188"],["45180.60","3.805"]],"u":20458390,"seq":114533057563},"cts":1704258132310}
{"topic":"orderbook.50.BTCUSDT","type":"delta","ts":1704258132371,"data":{"s":"BTCUSDT","b":[["45169.30","0.128"],["45168.80","0.270"]],"a":[["45180.60","0.044"],["45180.70","5.929"],["45180.90","1.484"]],"u":20458393,"seq":114533057655},"cts":1704258132365}
{"topic":"orderbook.50.BTCUSDT","type":"delta","ts":1704258132352,"data":{"s":"BTCUSDT","b":[],"a":[["45180.60","1.991"],["45180.70","3.982"]],"u":20458392,"seq":114533057635},"cts":1704258132348}
{"topic":"orderbook.50.BTCUSDT","type":"delta","ts":1704258132392,"data":{"s":"BTCUSDT","b":[],"a":[["45180.90","1.448"]],"u":20458394,"seq":114533057674},"cts":1704258132389}
{"topic":"orderbook.50.BTCUSDT","type":"delta","ts":1704258132412,"data":{"s":"BTCUSDT","b":[],"a":[["45180.70","3.982"]],"u":20458395,"seq":114533057698},"cts":1704258132409}
{"topic":"orderbook.50.BTCUSDT","type":"delta","ts":1704258132432,"data":{"s":"BTCUSDT","b":[["45168.80","0.234"]],"a":[["45180.70","0.221"]],"u":20458396,"seq":114533057725},"cts":1704258132430}
{"topic":"orderbook.50.BTCUSDT","type":"delta","ts":1704258132452,"data":{"s":"BTCUSDT","b":[["45165.60","0"],["45165.00","0.376"]],"a":[],"u":20458397,"seq":114533057745},"cts":1704258132448}
{"topic":"orderbook.50.BTCUSDT","type":"delta","ts":1704258132472,"data":{"s":"BTCUSDT","b":[["45174.20","2.437"],["45169.30","0.110"],["45165.20","0"],["45164.80","0.442"]],"a":[],"u":20458398,"seq":114533057770},"cts":1704258132469}
{"topic":"orderbook.50.BTCUSDT","type":"delta","ts":1704258132492,"data":{"s":"BTCUSDT","b":[["45174.20","2.436"],["45166.70","2.195"],["45166.50","1.505"],["45166.00","0.225"],["45164.80","0"]],"a":[["45178.00","0.114"],["45180.00","0.297"],["45181.80","0.941"]],"u":20458399,"seq":114533057855},"cts":1704258132489}
{"topic":"orderbook.50.BTCUSDT","type":"delta","ts":1704258132511,"data":{"s":"BTCUSDT","b":[["45168.70","1.694"]],"a":[["45180.90","1.484"]],"u":20458400,"seq":114533057878},"cts":1704258132509}
{"topic":"orderbook.50.BTCUSDT","type":"delta","ts":1704258132532,"data":{"s":"BTCUSDT","b":[["45174.20","2.486"],["45168.70","1.658"]],"a":[["45180.90","1.448"]],"u":20458401,"seq":114533057907},"cts":1704258132527}
{"topic":"orderbook.50.BTCUSDT","type":"delta","ts":1704258132571,"data":{"s":"BTCUSDT","b":[["45169.10","0.216"]],"a":[],"u":20458402,"seq":114533057942},"cts":1704258132570}
{"topic":"orderbook.50.BTCUSDT","type":"delta","ts":1704258132611,"data":{"s":"BTCUSDT","b":[["45168.50","0.061"]],"a":[["45180.70","0.257"]],"u":20458403,"seq":114533057984},"cts":1704258132609}
{"topic":"orderbook.50.BTCUSDT","type":"delta","ts":1704258132632,"data":{"s":"BTCUSDT","b":[["45165.60","0.109"],["45165.50","0.111"],["45165.00","0"]],"a":[],"u":20458404,"seq":114533058003},"cts":1704258132629}
{"topic":"orderbook.50.BTCUSDT","type":"delta","ts":1704258132652,"data":{"s":"BTCUSDT","b":[["45168.50","0.025"]],"a":[],"u":20458405,"seq":114533058022},"cts":1704258132650}
{"topic":"orderbook.50.BTCUSDT","type":"delta","ts":1704258132671,"data":{"s":"BTCUSDT","b":[],"a":[["45180.70","0.221"]],"u":20458406,"seq":114533058044},"cts":1704258132668}
{"topic":"orderbook.50.BTCUSDT","type":"delta","ts":1704258132712,"data":{"s":"BTCUSDT","b":[["45170.10","0.155"],["45168.70","1.736"]],"a":[],"u":20458407,"seq":114533058075},"cts":1704258132709}
{"topic":"orderbook.50.BTCUSDT","type":"delta","ts":1704258132732,"data":{"s":"BTCUSDT","b":[["45168.90","0.116"]],"a":[["45176.50","1.600"],["45180.50","0.036"],["45180.60","3.805"],["45181.70","0"],["45181.80","0"]],"u":20458408,"seq":114533058120},"cts":1704258132729}
{"topic":"orderbook.50.BTCUSDT","type":"delta","ts":1704258132752,"data":{"s":"BTCUSDT","b":[],"a":[["45175.90","0.083"],["45176.40","0.082"],["45176.50","0"],["45176.70","0.153"],["45178.50","0.075"],["45179.20","0.223"],["45179.90","0"],["45180.50","0"],["45180.60","1.991"],["45180.70","3.982"],["45181.70","0.576"]],"u":20458409,"seq":114533058154},"cts":1704258132749}
{"topic":"orderbook.50.BTCUSDT","type":"delta","ts":1704258132771,"data":{"s":"BTCUSDT","b":[],"a":[["45180.60","0.044"],["45180.70","5.929"]],"u":20458410,"seq":114533058175},"cts":1704258132768}
{"topic":"orderbook.50.BTCUSDT","type":"delta","ts":1704258132812,"data":{"s":"BTCUSDT","b":[["45168.90","0.080"]],"a":[["45180.60","1.991"],["45180.70","3.982"],["45181.40","0.122"],["45181.60","0"],["45181.80","0.941"]],"u":20458411,"seq":114533058209},"cts":1704258132809}
{"topic":"orderbook.50.BTCUSDT","type":"delta","ts":1704258132832,"data":{"s":"BTCUSDT","b":[],"a":[["45177.80","0"],["45177.90","0.126"],["45180.60","0.044"],["45180.70","0.221"],["45181.90","2.431"]],"u":20458412,"seq":114533058237},"cts":1704258132829}
{"topic":"orderbook.50.BTCUSDT","type":"delta","ts":1704258132852,"data":{"s":"BTCUSDT","b":[["45169.00","0.036"],["45165.10","0"]],"a":[["45180.80","2.248"]],"u":20458413,"seq":114533058260},"cts":1704258132850}
{"topic":"orderbook.50.BTCUSDT","type":"delta","ts":1704258132872,"data":{"s":"BTCUSDT","b":[["45168.70","2.156"]],"a":[["45180.60","3.805"]],"u":20458414,"seq":114533058279},"cts":1704258132866}
{"topic":"orderbook.50.BTCUSDT","type":"delta","ts":1704258132892,"data":{"s":"BTCUSDT","b":[],"a":[["45180.40","0.066"],["45180.60","5.752"],["45181.40","0.111"]],"u":20458415,"seq":114533058294},"cts":1704258132888}
{"topic":"orderbook.50.BTCUSDT","type":"delta","ts":1704258132912,"data":{"s":"BTCUSDT","b":[],"a":[["45180.60","0.044"]],"u":20458416,"seq":114533058310},"cts":1704258132910}
{"topic":"orderbook.50.BTCUSDT","type":"delta","ts":1704258132932,"data":{"s":"BTCUSDT","b":[["45169.00","0"],["45165.10","2.708"]],"a":[["45177.80","0.011"],["45177.90","0.115"],["45180.60","5.752"],["45180.80","2.212"],["45181.90","0"]],"u":20458417,"seq":114533058336},"cts":1704258132929}
{"topic":"orderbook.50.BTCUSDT","type":"delta","ts":1704258132952,"data":{"s":"BTCUSDT","b":[["45168.90","0.116"]],"a":[["45180.60","5.788"]],"u":20458418,"seq":114533058349},"cts":1704258132947}
{"topic":"orderbook.50.BTCUSDT","type":"delta","ts":1704258132972,"data":{"s":"BTCUSDT","b":[["45168.90","0.080"],["45168.70","2.581"]],"a":[["45180.60","3.841"]],"u":20458419,"seq":114533058373},"cts":1704258132969}
{"topic":"orderbook.50.BTCUSDT","type":"delta","ts":1704258132992,"data":{"s":"BTCUSDT","b":[["45169.50","1.442"]],"a":[["45180.60","0.080"]],"u":20458420,"seq":114533058392},"cts":1704258132988}
{"topic":"orderbook.50.BTCUSDT","type":"delta","ts":1704258133012,"data":{"s":"BTCUSDT","b":[],"a":[["45180.60","5.788"]],"u":20458421,"seq":114533058413},"cts":1704258133010}
{"topic":"orderbook.50.BTCUSDT","type":"delta","ts":1704258133032,"data":{"s":"BTCUSDT","b":[["45169.70","0.111"]],"a":[["45180.60","0.044"]],"u":20458422,"seq":114533058442},"cts":1704258133030}
{"topic":"orderbook.50.BTCUSDT","type":"delta","ts":1704258133052,"data":{"s":"BTCUSDT","b":[["45174.20","2.487"]],"a":[["45181.60","0.011"],["45181.80","0"]],"u":20458423,"seq":114533058464},"cts":1704258133050}
{"topic":"orderbook.50.BTCUSDT","type":"delta","ts":1704258133072,"data":{"s":"BTCUSDT","b":[["45169.30","0.128"]],"a":[],"u":20458424,"seq":114533058492},"cts":1704258133068}
{"topic":"orderbook.50.BTCUSDT","type":"delta","ts":1704258133091,"data":{"s":"BTCUSDT","b":[["45174.20","1.157"],["45173.00","0.001"],["45171.60","0.006"],["45170.00","0.445"],["45169.30","0.110"],["45169.10","0.104"],["45168.70","0.923"],["45168.10","0.166"],["45166.70","2.085"],["45166.50","0"],["45166.40","0.066"],["45165.60","0"],["45165.00","0.376"],["45164.80","0.442"]],"a":[["45174.30","4.576"],["45176.70","0.150"],["45180.60","5.752"]],"u":20458425,"seq":114533058557},"cts":1704258133090}
{"topic":"orderbook.50.BTCUSDT","type":"delta","ts":1704258133111,"data":{"s":"BTCUSDT","b":[["45174.10","0.035"],["45171.60","0.004"],["45171.50","0"],["45169.50","0.657"],["45168.90","0.116"],["45168.70","0"],["45167.20","0.111"],["45166.70","0.111"],["45165.90","0"],["45165.30","0"],["45165.00","0.266"],["45164.80","0"],["45164.50","0.266"],["45164.40","2.367"],["45164.20","0.443"],["45164.10","0.266"],["45164.00","0.114"]],"a":[["45174.30","10.292"],["45176.20","1.603"],["45176.70","0.148"],["45177.00","0.094"],["45177.80","0"],["45178.80","0.112"],["45180.60","0.044"],["45180.80","2.248"],["45181.70","0.554"]],"u":20458426,"seq":114533058770},"cts":1704258133110}
{"topic":"orderbook.50.BTCUSDT","type":"delta","ts":1704258133131,"data":{"s":"BTCUSDT","b":[["45170.30","0.543"],["45170.00","0.330"],["45169.90","0"],["45169.50","0"],["45169.40","0.144"],["45169.30","0"],["45168.90","0.080"],["45168.80","0.124"],["45168.60","0"],["45168.30","0.240"],["45167.60","0"],["45167.40","0.997"],["45167.10","0.115"],["45165.10","1.609"],["45163.90","0.709"],["45163.80","0.443"],["45163.70","0.447"]],"a":[["45174.30","14.864"],["45177.00","0.161"],["45178.20","3.085"],["45178.30","0.133"],["45178.40","0.077"],["45178.80","0.156"],["45178.90","1.200"],["45179.40","0.443"],["45180.10","0.144"],["45180.60","0"],["45180.80","2.212"],["45181.60","0"],["45181.70","0.576"],["45181.80","0.335"]],"u":20458427,"seq":114533059012},"cts":1704258133129}
{"topic":"orderbook.50.BTCUSDT","type":"delta","ts":1704258133151,"data":{"s":"BTCUSDT","b":[["45172.30","0.039"],["45170.30","0.202"],["45168.90","0.186"],["45168.30","0"],["45167.20","0.389"],["45167.10","0.111"]],"a":[["45175.20","0.004"],["45175.50","0.044"],["45175.60","0.011"],["45175.80","2.059"],["45178.20","0.122"],["45178.30","0.155"],["45178.70","0.044"],["45179.20","0.263"],["45180.10","0.111"],["45181.40","0"],["45181.50","0"],["45181.70","0"],["45181.80","0"]],"u":20458428,"seq":114533059119},"cts":1704258133149}
{"topic":"orderbook.50.BTCUSDT","type":"delta","ts":1704258133171,"data":{"s":"BTCUSDT","b":[["45174.20","1.162"]],"a":[["45175.10","0.078"],["45175.60","3.773"],["45176.90","1.947"],["45177.00","0.083"],["45177.80","0.011"],["45178.10","0.126"],["45178.20","0.111"],["45178.30","0.166"],["45179.00","0.033"],["45180.60","0.011"],["45180.80","2.909"],["45180.90","0"],["45181.00","0"],["45181.10","0"],["45181.20","0"],["45181.30","0"]],"u":20458429,"seq":114533059265},"cts":1704258133170}
{"topic":"orderbook.50.BTCUSDT","type":"delta","ts":1704258133191,"data":{"s":"BTCUSDT","b":[["45173.00","0.184"],["45172.30","0"],["45170.00","0.108"],["45169.70","0"],["45169.40","0.033"],["45168.40","0.111"],["45168.00","0.224"],["45167.10","0"],["45166.10","0.273"],["45163.60","0.443"]],"a":[["45175.40","0.121"],["45175.50","0"],["45175.60","0.011"],["45175.80","0.112"],["45176.50","2.974"],["45176.90","0"],["45177.00","2.030"],["45177.70","3.762"],["45177.80","0"],["45178.20","0.133"],["45178.30","0.133"],["45178.40","0"],["45180.60","0"],["45180.90","1.448"],["45181.00","0.022"]],"u":20458430,"seq":114533059401},"cts":1704258133190}
{"topic":"orderbook.50.BTCUSDT","type":"delta","ts":1704258133212,"data":{"s":"BTCUSDT","b":[["45172.90","0"],["45172.00","0.113"],["45170.90","0.098"],["45170.80","0"],["45170.30","0"],["45170.00","0.221"],["45169.20","0"],["45168.90","0.106"],["45168.40","0"],["45168.20","0"],["45168.00","0.114"],["45167.20","0.278"],["45166.70","0"],["45166.10","0"],["45166.00","0.224"],["45165.50","0"],["45163.90","0.266"],["45163.80","0"],["45163.70","0.004"],["45163.30","2.100"],["45163.20","0.500"],["45163.10","1.658"],["45163.00","0.222"],["45162.90","0.222"],["45162.70","1.333"],["45162.60","1.980"],["45162.50","0.461"]],"a":[["45174.30","14.964"],["45175.00","0.045"],["45175.40","0.077"],["45175.60","0.076"],["45176.50","0"],["45177.00","0.083"],["45177.70","0.022"],["45178.20","0.111"],["45178.50","0"],["45179.10","0.155"],["45179.20","0.223"],["45180.10","0"],["45180.30","3.084"],["45180.50","1.958"],["45180.90","1.459"],["45181.10","0.132"],["45181.20","1.909"]],"u":20458431,"seq":114533059573},"cts":1704258133210}
{"topic":"orderbook.50.BTCUSDT","type":"delta","ts":1704258133232,"data":{"s":"BTCUSDT","b":[["45171.60","0.002"],["45171.10","0.002"],["45163.20","0"]],"a":[["45174.80","0.047"],["45175.00","0.001"],["45175.80","0.193"],["45176.20","0.003"],["45176.90","0.011"],["45177.60","0.022"],["45177.70","0"],["45178.60","0.151"],["45178.70","3.018"],["45179.10","0.115"],["45179.30","1.668"],["45180.30","0.110"],["45180.50","0"]],"u":20458432,"seq":114533059681},"cts":1704258133230}
{"topic":"orderbook.50.BTCUSDT","type":"delta","ts":1704258133251,"data":{"s":"BTCUSDT","b":[["45173.00","0.001"],["45172.00","0"],["45171.60","0.001"],["45171.10","0.003"],["45170.90","0.320"],["45162.40","0.044"]],"a":[["45176.90","0"],["45177.80","0.011"],["45178.10","0.115"],["45178.70","1.991"],["45179.70","3.872"],["45180.70","2.168"],["45180.90","1.448"]],"u":20458433,"seq":114533059763},"cts":1704258133249}
{"topic":"orderbook.50.BTCUSDT","type":"delta","ts":1704258133272,"data":{"s":"BTCUSDT","b":[["45172.70","0.135"],["45171.10","0.004"],["45170.90","0.098"],["45169.40","0"]],"a":[["45177.80","0"],["45178.70","0.044"],["45179.70","0.111"],["45180.70","0.221"],["45181.30","0.335"]],"u":20458434,"seq":114533059854},"cts":1704258133269}
{"topic":"orderbook.50.BTCUSDT","type":"delta","ts":1704258133291,"data":{"s":"BTCUSDT","b":[["45171.10","0.005"]],"a":[["45176.50","0.604"],["45178.70","0.055"],["45180.60","5.708"],["45181.20","0"],["45181.30","0"]],"u":20458435,"seq":114533059925},"cts":1704258133290}
{"topic":"orderbook.50.BTCUSDT","type":"delta","ts":1704258133311,"data":{"s":"BTCUSDT","b":[["45167.20","0"],["45166.50","0.111"],["45166.20","0.117"],["45163.80","0.111"],["45163.50","0.033"],["45162.70","1.444"],["45162.50","0"],["45162.40","0"]],"a":[["45177.60","0.033"],["45177.90","0.004"],["45178.20","0"],["45178.40","0.033"],["45178.60","2.098"],["45178.70","0.044"],["45179.70","0"],["45180.60","0"],["45180.90","1.337"],["45181.20","1.909"],["45181.30","0.335"]],"u":20458436,"seq":114533060009},"cts":1704258133309}
{"topic":"orderbook.50.BTCUSDT","type":"delta","ts":1704258133332,"data":{"s":"BTCUSDT","b":[["45174.20","0"],["45174.10","0"],["45174.00","0"],["45173.70","0"],["45173.00","0.065"],["45172.90","0.010"],["45171.10","0.006"],["45171.00","0"],["45170.10","0"],["45165.50","0.078"],["45165.10","1.690"],["45163.70","0"],["45163.50","0"],["45163.30","1.658"],["45163.20","0.080"],["45162.70","0.244"],["45162.50","0.014"],["45162.40","0.044"],["45162.30","2.441"],["45162.20","0.044"],["45162.10","0.468"]],"a":[["45173.10","16.301"],["45173.70","1.275"],["45173.80","2.435"],["45173.90","1.858"],["45174.00","0.349"],["45174.10","3.353"],["45174.20","7.988"],["45174.30","14.074"],["45174.40","0"],["45175.50","0.044"],["45177.00","0"],["45177.60","0.022"],["45177.90","3.765"],["45178.40","0"],["45178.60","0.558"],["45178.70","0"],["45179.30","0.010"],["45179.70","0.022"],["45180.90","0"],["45181.00","0"],["45181.10","0"],["45181.20","0"],["45181.30","0"]],"u":20458437,"seq":114533060335},"cts":1704258133328}
{"topic":"orderbook.50.BTCUSDT","type":"delta","ts":1704258133352,"data":{"s":"BTCUSDT","b":[["45173.00","0"],["45172.90","0"],["45172.70","0.238"],["45170.90","0"],["45170.00","0.108"],["45169.00","0.081"],["45167.30","0"],["45163.10","0"],["45162.90","0.111"],["45162.70","0.133"],["45162.40","0"],["45162.00","0.114"],["45161.90","0.111"],["45161.70","1.662"],["45161.60","0.447"],["45161.30","0.210"]],"a":[["45172.80","21.076"],["45173.00","1.616"],["45173.10","5.693"],["45173.70","0.200"],["45173.80","0.394"],["45173.90","1.758"],["45174.00","0.313"],["45174.10","1.697"],["45174.20","0.796"],["45174.30","8.224"],["45175.70","0.100"],["45175.90","0.127"],["45176.50","0.615"],["45176.80","0.162"],["45177.60","0"],["45177.80","1.947"],["45177.90","3.787"],["45178.00","0.225"],["45178.30","0.089"],["45178.40","0.040"],["45178.50","4.943"],["45178.60","2.145"],["45178.80","0.200"],["45179.10","0.137"],["45179.20","0.112"],["45179.60","0.044"],["45179.90","0.022"],["45180.00","0"],["45180.20","0"],["45180.30","0"],["45180.40","0"],["45180.70","0"],["45180.80","0"]],"u":20458438,"seq":114533061124},"cts":1704258133350}
{"topic":"orderbook.50.BTCUSDT","type":"delta","ts":1704258133371,"data":{"s":"BTCUSDT","b":[["45170.80","0.070"],["45167.40","0"],["45166.60","0.137"],["45163.00","0"],["45162.70","0.111"],["45162.10","0.446"],["45161.50","0.111"],["45161.30","0"]],"a":[["45172.80","19.865"],["45173.00","1.800"],["45173.10","5.143"],["45173.80","0.194"],["45173.90","1.738"],["45174.00","0.113"],["45174.20","0.044"],["45174.30","3.652"],["45175.70","0"],["45175.90","0.083"],["45177.10","0"],["45177.80","1.969"],["45178.30","0.509"],["45179.40","0.554"],["45179.60","0.022"],["45180.00","0.319"],["45180.20","0.354"]],"u":20458439,"seq":114533061313},"cts":1704258133370}
{"topic":"orderbook.50.BTCUSDT","type":"delta","ts":1704258133391,"data":{"s":"BTCUSDT","b":[["45172.60","0.178"],["45167.50","0"],["45161.40","0.111"]],"a":[["45172.90","0.010"],["45173.00","1.700"],["45178.50","2.996"],["45179.10","2.084"],["45180.20","0"]],"u":20458440,"seq":114533061455},"cts":1704258133390}
{"topic":"orderbook.50.BTCUSDT","type":"delta","ts":1704258133412,"data":{"s":"BTCUSDT","b":[["45165.60","0.080"],["45163.60","0.476"],["45163.20","0"]],"a":[["45173.10","8.916"],["45174.30","3.647"],["45175.40","0.188"],["45175.70","0.111"],["45176.50","0.604"],["45177.20","0.111"],["45177.80","0.022"],["45177.90","0.026"],["45178.20","0.111"],["45178.50","0.066"],["45179.10","0.137"],["45179.50","0.775"],["45179.80","0"],["45179.90","0"],["45180.00","0"]],"u":20458441,"seq":114533061593},"cts":1704258133410}
{"topic":"orderbook.50.BTCUSDT","type":"delta","ts":1704258133431,"data":{"s":"BTCUSDT","b":[["45163.60","0.443"]],"a":[["45173.10","5.143"],["45173.40","0.078"],["45175.10","0"],["45178.00","0.236"],["45178.50","0.033"],["45179.20","0.809"],["45179.70","0.243"]],"u":20458442,"seq":114533061749},"cts":1704258133430}
{"topic":"orderbook.50.BTCUSDT","type":"delta","ts":1704258133451,"data":{"s":"BTCUSDT","b":[["45167.00","0.045"],["45164.70","0.078"],["45161.50","0"],["45161.40","0"]],"a":[["45173.00","1.600"],["45173.10","4.336"]],"u":20458443,"seq":114533061887},"cts":1704258133450}
{"topic":"orderbook.50.BTCUSDT","type":"delta","ts":1704258133472,"data":{"s":"BTCUSDT","b":[["45167.10","0.160"],["45161.60","0"]],"a":[["45178.50","0.022"]],"u":20458444,"seq":114533061988},"cts":1704258133470}
{"topic":"orderbook.50.BTCUSDT","type":"delta","ts":1704258133491,"data":{"s":"BTCUSDT","b":[["45165.50","0.157"]],"a":[],"u":20458445,"seq":114533062092},"cts":1704258133490}
{"topic":"orderbook.50.BTCUSDT","type":"delta","ts":1704258133511,"data":{"s":"BTCUSDT","b":[["45163.70","0.033"],["45161.70","0"]],"a":[["45178.70","0.033"],["45179.60","0.033"],["45179.70","0"]],"u":20458446,"seq":114533062188},"cts":1704258133510}
{"topic":"orderbook.50.BTCUSDT","type":"delta","ts":1704258133531,"data":{"s":"BTCUSDT","b":[["45171.10","0.003"],["45170.90","0.001"],["45170.30","0.003"],["45162.00","0"],["45161.90","0"]],"a":[["45179.30","0.021"],["45179.60","0.022"]],"u":20458447,"seq":114533062288},"cts":1704258133529}
{"topic":"orderbook.50.BTCUSDT","type":"delta","ts":1704258133551,"data":{"s":"BTCUSDT","b":[],"a":[["45172.80","21.232"]],"u":20458448,"seq":114533062374},"cts":1704258133550}
{"topic":"orderbook.50.BTCUSDT","type":"delta","ts":1704258133572,"data":{"s":"BTCUSDT","b":[["45171.10","0.002"],["45170.30","0.004"]],"a":[],"u":20458449,"seq":114533062468},"cts":1704258133569}
{"topic":"orderbook.50.BTCUSDT","type":"delta","ts":1704258133591,"data":{"s":"BTCUSDT","b":[["45171.10","0.001"],["45170.30","0.005"]],"a":[],"u":20458450,"seq":114533062546},"cts":1704258133590}
{"topic":"orderbook.50.BTCUSDT","type":"delta","ts":1704258133612,"data":{"s":"BTCUSDT","b":[],"a":[["45178.50","0.033"],["45178.70","0.143"]],"u":20458451,"seq":114533062625},"cts":1704258133609}
{"topic":"orderbook.50.BTCUSDT","type":"delta","ts":1704258133631,"data":{"s":"BTCUSDT","b":[["45171.10","0"],["45170.30","0.006"],["45163.70","0"],["45162.10","0.555"],["45162.00","0.114"],["45161.90","0.111"]],"a":[["45174.70","0.111"],["45178.50","0.022"],["45178.60","2.034"],["45178.70","0.110"],["45179.10","0.148"],["45179.20","0.919"],["45179.30","0.010"],["45179.60","0"]],"u":20458452,"seq":114533062731},"cts":1704258133630}
{"topic":"orderbook.50.BTCUSDT","type":"delta","ts":1704258133651,"data":{"s":"BTCUSDT","b":[["45163.40","0.033"],["45161.90","0"]],"a":[["45175.00","0.112"],["45175.70","0.222"],["45177.90","0.137"],["45178.50","0.055"],["45179.10","0.137"],["45179.30","0.021"]],"u":20458453,"seq":114533062832},"cts":1704258133650}
{"topic":"orderbook.50.BTCUSDT","type":"delta","ts":1704258133691,"data":{"s":"BTCUSDT","b":[["45165.70","0.223"],["45163.60","0.554"],["45162.00","0"]],"a":[["45173.00","0"],["45179.60","0.022"]],"u":20458454,"seq":114533063006},"cts":1704258133690}
{"topic":"orderbook.50.BTCUSDT","type":"delta","ts":1704258133712,"data":{"s":"BTCUSDT","b":[["45166.50","0.222"],["45165.50","0.268"],["45163.40","0"],["45162.00","0.114"]],"a":[["45178.50","0.022"]],"u":20458455,"seq":114533063115},"cts":1704258133710}
{"topic":"orderbook.50.BTCUSDT","type":"delta","ts":1704258133731,"data":{"s":"BTCUSDT","b":[],"a":[["45172.80","19.632"]],"u":20458456,"seq":114533063201},"cts":1704258133730}
{"topic":"orderbook.50.BTCUSDT","type":"delta","ts":1704258133751,"data":{"s":"BTCUSDT","b":[["45172.70","0.240"]],"a":[],"u":20458457,"seq":114533063298},"cts":1704258133750}
{"topic":"orderbook.50.BTCUSDT","type":"delta","ts":1704258133771,"data":{"s":"BTCUSDT","b":[],"a":[["45178.50","0.033"]],"u":20458458,"seq":114533063379},"cts":1704258133769}
{"topic":"orderbook.50.BTCUSDT","type":"delta","ts":1704258133812,"data":{"s":"BTCUSDT","b":[["45170.00","0.221"]],"a":[["45179.00","0.044"],["45179.30","0.010"]],"u":20458459,"seq":114533063540},"cts":1704258133809}
{"topic":"orderbook.50.BTCUSDT","type":"delta","ts":1704258133831,"data":{"s":"BTCUSDT","b":[["45170.80","0.129"]],"a":[["45178.70","0.331"]],"u":20458460,"seq":114533063626},"cts":1704258133830}
{"topic":"orderbook.50.BTCUSDT","type":"delta","ts":1704258133851,"data":{"s":"BTCUSDT","b":[],"a":[["45178.50","0.022"]],"u":20458461,"seq":114533063707},"cts":1704258133849}
{"topic":"orderbook.50.BTCUSDT","type":"delta","ts":1704258133872,"data":{"s":"BTCUSDT","b":[["45170.30","0.007"],["45163.50","0.033"],["45162.00","0"]],"a":[["45178.60","2.067"]],"u":20458462,"seq":114533063802},"cts":1704258133870}
{"topic":"orderbook.50.BTCUSDT","type":"delta","ts":1704258133892,"data":{"s":"BTCUSDT","b":[["45171.60","0"],["45162.00","0.114"]],"a":[],"u":20458463,"seq":114533063883},"cts":1704258133890}
{"topic":"orderbook.50.BTCUSDT","type":"delta","ts":1704258133911,"data":{"s":"BTCUSDT","b":[],"a":[["45177.10","0.026"],["45179.60","0"]],"u":20458464,"seq":114533063968},"cts":1704258133910}
{"topic":"orderbook.50.BTCUSDT","type":"delta","ts":1704258133932,"data":{"s":"BTCUSDT","b":[["45163.50","0"],["45161.90","0.111"]],"a":[],"u":20458465,"seq":114533064045},"cts":1704258133930}
{"topic":"orderbook.50.BTCUSDT","type":"delta","ts":1704258133972,"data":{"s":"BTCUSDT","b":[["45170.00","0.108"],["45165.70","0.111"]],"a":[["45179.00","0.033"],["45179.10","0.148"]],"u":20458466,"seq":114533064199},"cts":1704258133970}
{"topic":"orderbook.50.BTCUSDT","type":"delta","ts":1704258133993,"data":{"s":"BTCUSDT","b":[["45172.70","0"],["45172.60","0"],["45172.20","0"],["45170.90","0"],["45170.80","0"],["45170.70","0"],["45170.30","1.399"],["45170.20","0.123"],["45169.10","0"],["45168.80","0"],["45168.00","0.001"],["45167.10","0.260"],["45166.90","0"],["45166.70","0.100"],["45166.40","0"],["45166.30","0.100"],["45165.00","0"],["45164.70","0"],["45164.50","0"],["45164.40","0"],["45164.20","0"],["45164.10","0"],["45163.90","0"],["45163.70","0.100"],["45163.60","0.111"],["45163.40","0.100"],["45163.30","0"],["45163.00","0.100"],["45162.80","0.100"],["45162.60","1.537"],["45162.40","0.100"],["45162.10","0"],["45161.70","1.666"],["45161.60","0.447"],["45161.50","0.111"],["45161.40","0.611"],["45161.30","0.210"],["45161.10","3.758"],["45161.00","0.111"],["45160.90","0.469"],["45160.80","0.111"],["45160.50","1.497"],["45160.40","0.022"],["45160.30","0.022"]],"a":[["45170.40","15.755"],["45170.70","0.049"],["45170.80","6.394"],["45170.90","1.461"],["45171.00","6.861"],["45171.20","1.658"],["45171.80","0.300"],["45172.00","0.113"],["45172.20","1.200"],["45172.30","6.950"],["45172.40","0.200"],["45172.50","0.200"],["45172.60","0.618"],["45172.70","7.695"],["45172.80","16.299"],["45173.00","0.044"],["45173.10","0.908"],["45173.80","0.105"],["45174.20","0.048"],["45174.30","3.147"],["45174.80","0.003"],["45175.50","0"],["45176.80","0.206"],["45177.30","0.040"],["45177.90","0.133"],["45178.10","0"],["45178.20","0"],["45178.30","0"],["45178.40","0"],["45178.50","0"],["45178.60","0"],["45178.70","0"],["45178.80","0"],["45178.90","0"],["45179.00","0"],["45179.10","0"],["45179.20","0"],["45179.30","0"],["45179.40","0"],["45179.50","0"]],"u":20458467,"seq":114533064835},"cts":1704258133988}
{"topic":"orderbook.50.BTCUSDT","type":"delta","ts":1704258134012,"data":{"s":"BTCUSDT","b":[["45167.10","0.160"],["45166.70","0"],["45166.30","0"],["45165.10","0.081"],["45164.10","0.068"],["45163.40","0.033"],["45163.00","0"],["45162.80","0"],["45162.40","0"],["45162.20","0"],["45161.90","0"],["45161.50","0"],["45161.40","0.500"],["45161.00","1.658"],["45160.90","0.447"],["45160.80","0"],["45160.40","0"],["45160.20","0.890"],["45160.10","1.393"],["45160.00","1.275"],["45159.90","0.015"],["45159.80","0.443"],["45159.60","0.443"],["45159.50","2.105"],["45159.40","0.443"],["45159.30","0.894"]],"a":[["45170.40","14.559"],["45170.70","0"],["45170.80","0.133"],["45170.90","0"],["45171.00","0.579"],["45172.20","0"],["45172.30","0.254"],["45172.60","0.200"],["45172.70","1.108"],["45172.80","2.503"],["45173.00","0.097"],["45173.80","0"],["45174.20","0.004"],["45174.80","0.114"],["45175.60","0"],["45175.70","0.266"],["45175.80","0.215"],["45176.20","0.114"],["45176.40","0.104"],["45176.50","0.626"],["45176.80","0.044"],["45177.00","0.111"],["45177.10","0.070"],["45177.30","0.173"],["45177.40","1.219"],["45177.80","0.133"],["45177.90","0.243"],["45178.00","0.125"],["45178.10","1.680"],["45178.20","0.133"],["45178.30","2.058"]],"u":20458468,"seq":114533065252},"cts":1704258134010}
{"topic":"orderbook.50.BTCUSDT","type":"delta","ts":1704258134032,"data":{"s":"BTCUSDT","b":[["45170.30","0"],["45165.10","0.193"],["45164.90","0.100"],["45164.00","0.496"],["45163.40","0"],["45162.50","0.080"],["45160.50","0"],["45160.30","0"],["45160.10","0.929"],["45159.70","1.265"],["45159.20","1.483"],["45159.10","0.133"]],"a":[["45170.30","0.898"],["45170.40","15.118"],["45172.30","0.200"],["45172.70","0.808"],["45174.00","1.771"],["45175.10","0.105"],["45175.40","1.846"],["45175.70","0.310"],["45175.80","0.237"],["45176.30","0.423"],["45176.40","0.902"],["45176.80","0"],["45177.10","0.136"],["45177.90","0.221"],["45178.00","0.158"],["45178.20","0.354"],["45178.30","0"]],"u":20458469,"seq":114533065494},"cts":1704258134030}
{"topic":"orderbook.50.BTCUSDT","type":"delta","ts":1704258134052,"data":{"s":"BTCUSDT","b":[["45170.20","0.329"],["45165.90","0.111"],["45164.10","0.298"],["45164.00","0.114"],["45163.50","0.466"],["45160.00","0.824"],["45159.30","0.443"],["45159.20","0"],["45159.10","0"]],"a":[["45170.30","14.505"],["45170.40","4.173"],["45171.40","0.078"],["45172.30","0.100"],["45172.40","0"],["45172.50","0.100"],["45172.60","0.100"],["45172.70","0.708"],["45172.80","1.303"],["45172.90","0"],["45173.40","0"],["45175.60","0.044"],["45175.70","0.222"],["45176.30","1.660"],["45176.70","0.845"],["45176.80","0.040"],["45177.30","0.133"],["45177.70","5.709"],["45177.80","0.155"],["45177.90","0.232"],["45178.00","0.114"],["45178.20","0"]],"u":20458470,"seq":114533065862},"cts":1704258134050}
{"topic":"orderbook.50.BTCUSDT","type":"delta","ts":1704258134072,"data":{"s":"BTCUSDT","b":[["45165.90","0.129"]],"a":[["45170.30","13.158"],["45170.40","5.116"],["45170.80","0.333"],["45171.00","0.079"],["45172.30","0"],["45172.50","0"],["45172.60","0"],["45173.70","0"],["45174.80","0.003"],["45176.30","1.649"],["45176.40","0.913"],["45177.70","0"],["45178.20","0.354"],["45178.30","1.969"],["45178.40","0.022"],["45178.60","2.034"],["45178.70","0.553"]],"u":20458471,"seq":114533066051},"cts":1704258134070}
{"topic":"orderbook.50.BTCUSDT","type":"delta","ts":1704258134091,"data":{"s":"BTCUSDT","b":[["45170.20","1.058"],["45168.90","0"],["45159.70","1.531"],["45159.40","0.447"],["45159.20","1.483"]],"a":[["45170.30","10.552"],["45170.40","3.179"],["45172.70","0.674"],["45174.30","3.258"],["45175.10","0.548"],["45175.70","0.244"],["45176.40","0.902"],["45176.50","1.069"],["45177.80","0.133"],["45178.00","0.380"],["45178.40","0.033"]],"u":20458472,"seq":114533066233},"cts":1704258134090}
{"topic":"orderbook.50.BTCUSDT","type":"delta","ts":1704258134112,"data":{"s":"BTCUSDT","b":[["45168.60","0.106"],["45165.80","0.124"],["45163.70","0"],["45163.50","0.608"],["45161.60","0.469"],["45159.20","0"]],"a":[["45170.30","12.830"],["45172.70","0.639"],["45175.00","0.202"],["45175.10","0.592"],["45175.30","0.014"],["45175.60","0"],["45176.50","2.994"],["45177.90","0.221"],["45178.40","0.022"],["45178.50","0.011"]],"u":20458473,"seq":114533066394},"cts":1704258134109}
{"topic":"orderbook.50.BTCUSDT","type":"delta","ts":1704258134131,"data":{"s":"BTCUSDT","b":[["45170.10","0.010"],["45167.20","0.002"],["45162.60","1.559"],["45161.60","0.447"],["45159.40","0"],["45159.30","0"]],"a":[["45172.90","0.077"],["45173.80","0.130"],["45174.90","0.078"],["45175.30","0.003"],["45175.40","1.769"],["45176.40","2.767"],["45176.50","1.047"],["45176.70","0.797"],["45177.90","3.195"],["45178.50","0"],["45178.60","0"],["45178.70","0"]],"u":20458474,"seq":114533066566},"cts":1704258134130}
{"topic":"orderbook.50.BTCUSDT","type":"delta","ts":1704258134152,"data":{"s":"BTCUSDT","b":[["45169.00","0"],["45168.70","0.001"],["45167.20","0.003"],["45167.10","0"],["45167.00","0"],["45165.60","0"],["45165.50","0.111"],["45165.10","0.112"],["45162.60","1.537"],["45159.40","0.447"],["45159.30","0.443"],["45159.20","1.483"]],"a":[["45176.20","0.125"],["45176.40","0.845"],["45176.70","0.819"],["45177.30","0.166"],["45177.90","0.221"],["45178.20","4.116"]],"u":20458475,"seq":114533066697},"cts":1704258134150}
{"topic":"orderbook.50.BTCUSDT","type":"delta","ts":1704258134171,"data":{"s":"BTCUSDT","b":[],"a":[["45177.30","0.133"],["45177.90","3.983"],["45178.20","0.354"]],"u":20458476,"seq":114533066788},"cts":1704258134170}
{"topic":"orderbook.50.BTCUSDT","type":"delta","ts":1704258134192,"data":{"s":"BTCUSDT","b":[["45166.70","0.001"],["45159.20","0"]],"a":[["45175.70","0.255"],["45176.20","0.114"],["45177.20","2.058"],["45177.90","0.221"]],"u":20458477,"seq":114533066890},"cts":1704258134190}
{"topic":"orderbook.50.BTCUSDT","type":"delta","ts":1704258134211,"data":{"s":"BTCUSDT","b":[["45166.70","0.002"],["45161.10","4.310"]],"a":[["45170.30","11.230"],["45171.70","0.001"],["45172.70","0.563"],["45175.70","0.244"],["45177.10","0.246"],["45177.20","0.111"],["45178.20","2.301"],["45178.40","0"]],"u":20458478,"seq":114533067001},"cts":1704258134210}
{"topic":"orderbook.50.BTCUSDT","type":"delta","ts":1704258134231,"data":{"s":"BTCUSDT","b":[["45162.60","0"],["45161.80","2.595"],["45161.50","0.033"],["45159.30","0"]],"a":[["45176.10","0.011"],["45177.70","0.221"],["45177.80","2.080"],["45178.20","0"],["45178.30","0"]],"u":20458479,"seq":114533067093},"cts":1704258134229}
{"topic":"orderbook.50.BTCUSDT","type":"delta","ts":1704258134251,"data":{"s":"BTCUSDT","b":[["45166.70","0.086"],["45164.20","0.078"],["45159.40","0"]],"a":[["45170.30","12.600"],["45177.70","2.168"],["45177.80","0.133"],["45177.90","3.983"]],"u":20458480,"seq":114533067184},"cts":1704258134250}
{"topic":"orderbook.50.BTCUSDT","type":"delta","ts":1704258134272,"data":{"s":"BTCUSDT","b":[["45166.60","0.182"],["45163.00","0.081"],["45162.60","0.075"],["45161.50","0"],["45159.50","0"]],"a":[["45176.90","0.011"],["45177.30","0.166"],["45177.90","0.221"],["45178.10","0"]],"u":20458481,"seq":114533067262},"cts":1704258134270}
{"topic":"orderbook.50.BTCUSDT","type":"delta","ts":1704258134292,"data":{"s":"BTCUSDT","b":[["45170.20","1.417"],["45161.20","0.075"],["45159.60","0"]],"a":[["45175.80","0.248"],["45176.10","0"],["45177.80","3.895"],["45178.10","1.680"]],"u":20458482,"seq":114533067353},"cts":1704258134290}
{"topic":"orderbook.50.BTCUSDT","type":"delta","ts":1704258134312,"data":{"s":"BTCUSDT","b":[],"a":[["45171.00","0.003"],["45177.30","2.113"],["45177.70","0.221"]],"u":20458483,"seq":114533067431},"cts":1704258134309}
{"topic":"orderbook.50.BTCUSDT","type":"delta","ts":1704258134331,"data":{"s":"BTCUSDT","b":[["45170.20","2.105"],["45161.70","1.699"],["45160.50","0.078"],["45159.70","0"]],"a":[["45175.80","0.237"],["45175.90","0.094"],["45176.90","0"],["45177.30","0.133"],["45177.80","0.133"],["45177.90","3.983"],["45178.20","0.354"]],"u":20458484,"seq":114533067520},"cts":1704258134330}
{"topic":"orderbook.50.BTCUSDT","type":"delta","ts":1704258134351,"data":{"s":"BTCUSDT","b":[["45163.70","0.078"],["45161.70","1.666"],["45161.40","0"]],"a":[["45177.60","2.022"],["45177.90","0.221"],["45178.20","0"]],"u":20458485,"seq":114533067597},"cts":1704258134349}
{"topic":"orderbook.50.BTCUSDT","type":"delta","ts":1704258134372,"data":{"s":"BTCUSDT","b":[["45164.30","0.083"],["45159.80","0"]],"a":[["45173.00","0.178"],["45175.80","0.156"],["45175.90","0.083"],["45176.10","0.011"],["45177.60","0.075"],["45177.70","2.168"],["45178.00","4.142"],["45178.10","0"]],"u":20458486,"seq":114533067676},"cts":1704258134370}
{"topic":"orderbook.50.BTCUSDT","type":"delta","ts":1704258134391,"data":{"s":"BTCUSDT","b":[["45163.50","0"],["45163.00","0.656"],["45159.80","0.443"]],"a":[["45174.70","0"],["45175.00","0.091"],["45175.40","1.658"],["45175.70","0.022"],["45177.20","0"],["45177.70","0.221"],["45177.90","0.110"],["45178.00","0.380"],["45178.10","1.680"],["45178.20","4.005"]],"u":20458487,"seq":114533067765},"cts":1704258134390}
{"topic":"orderbook.50.BTCUSDT","type":"delta","ts":1704258134412,"data":{"s":"BTCUSDT","b":[["45165.90","0.111"],["45164.10","0"],["45163.90","0.401"],["45163.00","0.081"],["45162.80","0.243"],["45159.80","0"]],"a":[["45170.40","3.183"],["45172.70","0.559"],["45174.90","0.122"],["45175.10","0.548"],["45176.30","1.759"],["45176.70","0.859"],["45176.80","0"],["45177.70","2.168"],["45178.20","0.243"],["45178.30","1.969"]],"u":20458488,"seq":114533067870},"cts":1704258134409}
{"topic":"orderbook.50.BTCUSDT","type":"delta","ts":1704258134431,"data":{"s":"BTCUSDT","b":[["45163.90","0"],["45163.70","0.232"],["45161.80","2.628"],["45159.80","0.443"]],"a":[["45176.10","0"],["45177.20","0.221"]],"u":20458489,"seq":114533067948},"cts":1704258134430}
{"topic":"orderbook.50.BTCUSDT","type":"delta","ts":1704258134452,"data":{"s":"BTCUSDT","b":[["45167.20","0"],["45166.80","0.002"]],"a":[["45176.10","0.011"],["45177.00","0.122"],["45177.70","0.221"],["45177.90","2.057"],["45178.20","4.005"],["45178.30","0"]],"u":20458490,"seq":114533068029},"cts":1704258134450}
{"topic":"orderbook.50.BTCUSDT","type":"delta","ts":1704258134471,"data":{"s":"BTCUSDT","b":[["45166.80","0.003"]],"a":[["45176.10","0"],["45176.20","0.125"],["45177.80","2.080"],["45177.90","0.110"],["45178.20","0.243"],["45178.30","1.969"]],"u":20458491,"seq":114533068102},"cts":1704258134470}
{"topic":"orderbook.50.BTCUSDT","type":"delta","ts":1704258134492,"data":{"s":"BTCUSDT","b":[["45166.80","0.004"],["45166.70","0.085"]],"a":[["45176.60","1.211"]],"u":20458492,"seq":114533068172},"cts":1704258134490}
{"topic":"orderbook.50.BTCUSDT","type":"delta","ts":1704258134511,"data":{"s":"BTCUSDT","b":[["45166.80","0.005"],["45166.70","0.084"],["45166.20","0.006"],["45163.80","0"],["45162.70","0"],["45160.10","1.195"],["45160.00","1.090"],["45159.90","0.901"],["45159.80","0.709"],["45159.70","1.531"],["45159.60","0.443"]],"a":[["45174.00","1.882"],["45174.30","3.369"],["45175.80","0.267"],["45176.90","0.111"],["45177.40","1.662"],["45177.70","0.487"],["45177.80","0.133"],["45177.90","2.057"],["45178.10","1.946"],["45178.20","1.129"],["45178.30","0"]],"u":20458493,"seq":114533068269},"cts":1704258134510}
{"topic":"orderbook.50.BTCUSDT","type":"delta","ts":1704258134531,"data":{"s":"BTCUSDT","b":[["45170.20","1.160"],["45166.80","0.006"],["45166.70","0.083"],["45161.80","2.595"]],"a":[],"u":20458494,"seq":114533068384},"cts":1704258134530}
{"topic":"orderbook.50.BTCUSDT","type":"delta","ts":1704258134551,"data":{"s":"BTCUSDT","b":[["45166.60","0.083"],["45162.60","0.119"]],"a":[["45176.60","1.200"],["45177.90","0.110"],["45178.20","3.076"]],"u":20458495,"seq":114533068528},"cts":1704258134550}
{"topic":"orderbook.50.BTCUSDT","type":"delta","ts":1704258134572,"data":{"s":"BTCUSDT","b":[["45166.10","0.033"],["45165.70","0.223"],["45161.80","2.628"],["45159.60","0"]],"a":[["45178.20","1.129"]],"u":20458496,"seq":114533068606},"cts":1704258134570}
{"topic":"orderbook.50.BTCUSDT","type":"delta","ts":1704258134591,"data":{"s":"BTCUSDT","b":[["45166.60","0.126"],["45161.80","2.595"]],"a":[],"u":20458497,"seq":114533068678},"cts":1704258134590}
{"topic":"orderbook.50.BTCUSDT","type":"delta","ts":1704258134612,"data":{"s":"BTCUSDT","b":[],"a":[["45178.00","2.327"]],"u":20458498,"seq":114533068753},"cts":1704258134610}
{"topic":"orderbook.50.BTCUSDT","type":"delta","ts":1704258134632,"data":{"s":"BTCUSDT","b":[],"a":[["45174.30","3.258"],["45176.00","0.225"],["45176.70","1.080"],["45178.00","0.380"]],"u":20458499,"seq":114533068835},"cts":1704258134630}
{"topic":"orderbook.50.BTCUSDT","type":"delta","ts":1704258134651,"data":{"s":"BTCUSDT","b":[["45164.80","0.111"],["45164.40","0.047"],["45162.30","2.552"],["45161.30","0.321"],["45159.80","0"],["45159.70","0"]],"a":[["45174.30","3.369"],["45176.00","0.114"],["45176.20","0.114"],["45176.80","0.011"],["45177.60","0.109"],["45178.20","0"]],"u":20458500,"seq":114533068923},"cts":1704258134650}
{"topic":"orderbook.50.BTCUSDT","type":"delta","ts":1704258134691,"data":{"s":"BTCUSDT","b":[["45168.00","0.114"]],"a":[["45176.80","0"],["45177.20","0.232"],["45177.60","0.075"],["45178.20","1.129"]],"u":20458501,"seq":114533069059},"cts":1704258134690}
{"topic":"orderbook.50.BTCUSDT","type":"delta","ts":1704258134712,"data":{"s":"BTCUSDT","b":[["45170.20","1.255"],["45162.40","0.034"],["45161.00","2.858"],["45159.90","0"]],"a":[["45172.80","1.103"],["45176.50","1.058"]],"u":20458502,"seq":114533069168},"cts":1704258134710}
{"topic":"orderbook.50.BTCUSDT","type":"delta","ts":1704258134732,"data":{"s":"BTCUSDT","b":[["45170.20","1.450"],["45162.40","0"],["45159.90","0.901"]],"a":[["45170.30","14.200"],["45177.20","0.221"],["45177.50","0.011"],["45178.20","0"]],"u":20458503,"seq":114533069348},"cts":1704258134730}
{"topic":"orderbook.50.BTCUSDT","type":"delta","ts":1704258134772,"data":{"s":"BTCUSDT","b":[],"a":[["45175.70","0"],["45177.50","0"],["45177.70","0.509"],["45177.90","0.121"],["45178.20","1.129"],["45178.30","2.457"]],"u":20458504,"seq":114533069501},"cts":1704258134770}
{"topic":"orderbook.50.BTCUSDT","type":"delta","ts":1704258134792,"data":{"s":"BTCUSDT","b":[["45165.70","0.111"]],"a":[["45170.30","12.600"],["45170.40","1.424"],["45177.90","0.110"]],"u":20458505,"seq":114533069572},"cts":1704258134789}
{"topic":"orderbook.50.BTCUSDT","type":"delta","ts":1704258134831,"data":{"s":"BTCUSDT","b":[["45163.20","0.034"],["45159.90","0"]],"a":[["45176.20","0.335"]],"u":20458506,"seq":114533069680},"cts":1704258134830}
{"topic":"orderbook.50.BTCUSDT","type":"delta","ts":1704258134852,"data":{"s":"BTCUSDT","b":[],"a":[["45170.30","11.400"]],"u":20458507,"seq":114533069746},"cts":1704258134850}
{"topic":"orderbook.50.BTCUSDT","type":"delta","ts":1704258134892,"data":{"s":"BTCUSDT","b":[["45166.80","0.007"]],"a":[["45170.80","0.221"],["45178.00","0.391"]],"u":20458508,"seq":114533069859},"cts":1704258134889}
{"topic":"orderbook.50.BTCUSDT","type":"delta","ts":1704258134911,"data":{"s":"BTCUSDT","b":[["45170.20","2.830"],["45169.90","0.001"],["45166.50","0.111"],["45163.60","0"]],"a":[["45170.40","0.224"],["45170.80","0.213"],["45172.70","0"],["45172.80","0.544"],["45173.30","0.111"],["45173.60","0.111"],["45174.30","3.480"],["45176.50","0.454"],["45176.60","1.311"],["45178.30","0"]],"u":20458509,"seq":114533069947},"cts":1704258134910}
{"topic":"orderbook.50.BTCUSDT","type":"delta","ts":1704258134931,"data":{"s":"BTCUSDT","b":[["45170.20","1.847"],["45163.20","0"],["45162.30","4.057"],["45162.10","0.078"],["45161.00","3.079"],["45160.50","0"],["45159.90","0.901"]],"a":[["45170.80","0.200"],["45175.80","0.223"],["45177.80","0.155"],["45178.00","0.402"]],"u":20458510,"seq":114533070082},"cts":1704258134930}
{"topic":"orderbook.50.BTCUSDT","type":"delta","ts":1704258134951,"data":{"s":"BTCUSDT","b":[],"a":[["45178.00","0.413"]],"u":20458511,"seq":114533070206},"cts":1704258134950}
{"topic":"orderbook.50.BTCUSDT","type":"delta","ts":1704258134972,"data":{"s":"BTCUSDT","b":[],"a":[["45178.00","0.402"]],"u":20458512,"seq":114533070278},"cts":1704258134970}
{"topic":"orderbook.50.BTCUSDT","type":"delta","ts":1704258134991,"data":{"s":"BTCUSDT","b":[],"a":[["45177.90","0.121"]],"u":20458513,"seq":114533070332},"cts":1704258134990}
{"topic":"orderbook.50.BTCUSDT","type":"delta","ts":1704258135011,"data":{"s":"BTCUSDT","b":[],"a":[["45170.30","11.372"]],"u":20458514,"seq":114533070393},"cts":1704258135010}
{"topic":"orderbook.50.BTCUSDT","type":"delta","ts":1704258135032,"data":{"s":"BTCUSDT","b":[["45162.30","2.552"]],"a":[],"u":20458515,"seq":114533070453},"cts":1704258135030}
{"topic":"orderbook.50.BTCUSDT","type":"delta","ts":1704258135051,"data":{"s":"BTCUSDT","b":[["45163.00","0.115"]],"a":[["45174.10","1.805"]],"u":20458516,"seq":114533070514},"cts":1704258135050}
{"topic":"orderbook.50.BTCUSDT","type":"delta","ts":1704258135072,"data":{"s":"BTCUSDT","b":[["45165.90","0.129"],["45162.60","0.075"]],"a":[["45178.20","1.163"]],"u":20458517,"seq":114533070580},"cts":1704258135070}
{"topic":"orderbook.50.BTCUSDT","type":"delta","ts":1704258135091,"data":{"s":"BTCUSDT","b":[],"a":[["45170.30","10.952"],["45176.50","0.443"],["45176.60","1.322"]],"u":20458518,"seq":114533070639},"cts":1704258135089}
{"topic":"orderbook.50.BTCUSDT","type":"delta","ts":1704258135111,"data":{"s":"BTCUSDT","b":[],"a":[["45177.80","0.166"],["45177.90","0.110"]],"u":20458519,"seq":114533070702},"cts":1704258135110}
{"topic":"orderbook.50.BTCUSDT","type":"delta","ts":1704258135132,"data":{"s":"BTCUSDT","b":[["45163.00","0.081"],["45162.30","4.057"]],"a":[["45178.20","1.129"]],"u":20458520,"seq":114533070765},"cts":1704258135130}
{"topic":"orderbook.50.BTCUSDT","type":"delta","ts":1704258135172,"data":{"s":"BTCUSDT","b":[["45163.20","0.034"],["45159.90","0"]],"a":[["45176.60","1.311"]],"u":20458521,"seq":114533070872},"cts":1704258135169}
{"topic":"orderbook.50.BTCUSDT","type":"delta","ts":1704258135232,"data":{"s":"BTCUSDT","b":[["45163.20","0"],["45159.90","0.901"]],"a":[["45177.70","0.520"],["45177.80","0.155"]],"u":20458522,"seq":114533071040},"cts":1704258135229}
{"topic":"orderbook.50.BTCUSDT","type":"delta","ts":1704258135252,"data":{"s":"BTCUSDT","b":[["45161.30","0.821"]],"a":[],"u":20458523,"seq":114533071094},"cts":1704258135249}
{"topic":"orderbook.50.BTCUSDT","type":"delta","ts":1704258135271,"data":{"s":"BTCUSDT","b":[["45162.90","0.145"]],"a":[["45178.10","1.980"]],"u":20458524,"seq":114533071154},"cts":1704258135270}
{"topic":"orderbook.50.BTCUSDT","type":"delta","ts":1704258135311,"data":{"s":"BTCUSDT","b":[],"a":[["45176.50","0.454"]],"u":20458525,"seq":114533071250},"cts":1704258135309}
{"topic":"orderbook.50.BTCUSDT","type":"delta","ts":1704258135331,"data":{"s":"BTCUSDT","b":[["45170.20","1.812"],["45162.90","0.111"]],"a":[["45177.50","0.011"],["45177.70","0.509"],["45178.10","1.946"],["45178.20","0"]],"u":20458526,"seq":114533071365},"cts":1704258135330}
{"topic":"orderbook.50.BTCUSDT","type":"delta","ts":1704258135351,"data":{"s":"BTCUSDT","b":[["45160.30","0.413"],["45159.90","0"]],"a":[],"u":20458527,"seq":114533071440},"cts":1704258135350}
{"topic":"orderbook.50.BTCUSDT","type":"delta","ts":1704258135372,"data":{"s":"BTCUSDT","b":[["45162.90","0.145"]],"a":[["45178.10","1.980"]],"u":20458528,"seq":114533071499},"cts":1704258135370}
{"topic":"orderbook.50.BTCUSDT","type":"delta","ts":1704258135391,"data":{"s":"BTCUSDT","b":[["45170.20","1.490"]],"a":[],"u":20458529,"seq":114533071550},"cts":1704258135389}
{"topic":"orderbook.50.BTCUSDT","type":"delta","ts":1704258135411,"data":{"s":"BTCUSDT","b":[["45170.20","1.862"]],"a":[["45170.80","0"],["45178.20","1.129"]],"u":20458530,"seq":114533071654},"cts":1704258135410}
{"topic":"orderbook.50.BTCUSDT","type":"delta","ts":1704258135431,"data":{"s":"BTCUSDT","b":[["45164.90","0.211"],["45162.90","0.111"],["45162.00","0.225"]],"a":[["45178.10","1.946"]],"u":20458531,"seq":114533071723},"cts":1704258135430}
{"topic":"orderbook.50.BTCUSDT","type":"delta","ts":1704258135491,"data":{"s":"BTCUSDT","b":[["45162.70","0.034"],["45160.00","0"]],"a":[["45177.90","0.144"]],"u":20458532,"seq":114533071864},"cts":1704258135490}
{"topic":"orderbook.50.BTCUSDT","type":"delta","ts":1704258135512,"data":{"s":"BTCUSDT","b":[],"a":[["45177.00","0.111"],["45177.30","0.144"],["45177.50","0"],["45178.10","3.451"],["45178.30","0.996"]],"u":20458533,"seq":114533071925},"cts":1704258135510}
{"topic":"orderbook.50.BTCUSDT","type":"delta","ts":1704258135532,"data":{"s":"BTCUSDT","b":[["45170.20","1.973"],["45162.70","0"],["45160.00","1.090"]],"a":[["45170.30","10.930"],["45177.90","0.110"]],"u":20458534,"seq":114533071989},"cts":1704258135530}
{"topic":"orderbook.50.BTCUSDT","type":"delta","ts":1704258135571,"data":{"s":"BTCUSDT","b":[["45165.80","0.236"]],"a":[],"u":20458535,"seq":114533072080},"cts":1704258135569}
{"topic":"orderbook.50.BTCUSDT","type":"delta","ts":1704258135592,"data":{"s":"BTCUSDT","b":[["45170.20","2.047"],["45163.00","0.115"]],"a":[["45178.20","1.163"]],"u":20458536,"seq":114533072139},"cts":1704258135590}
{"topic":"orderbook.50.BTCUSDT","type":"delta","ts":1704258135611,"data":{"s":"BTCUSDT","b":[["45161.00","3.189"]],"a":[],"u":20458537,"seq":114533072187},"cts":1704258135610}
{"topic":"orderbook.50.BTCUSDT","type":"delta","ts":1704258135631,"data":{"s":"BTCUSDT","b":[["45169.90","0"],["45165.90","0.111"],["45165.80","0.124"],["45163.00","0.081"],["45159.90","0.901"]],"a":[["45178.20","1.129"]],"u":20458538,"seq":114533072248},"cts":1704258135630}
{"topic":"orderbook.50.BTCUSDT","type":"delta","ts":1704258135651,"data":{"s":"BTCUSDT","b":[["45160.30","1.024"]],"a":[],"u":20458539,"seq":114533072299},"cts":1704258135649}
{"topic":"orderbook.50.BTCUSDT","type":"delta","ts":1704258135671,"data":{"s":"BTCUSDT","b":[],"a":[["45177.00","0.122"]],"u":20458540,"seq":114533072361},"cts":1704258135670}
{"topic":"orderbook.50.BTCUSDT","type":"delta","ts":1704258135752,"data":{"s":"BTCUSDT","b":[],"a":[["45177.00","0.111"],["45177.20","0.232"],["45177.30","0.133"]],"u":20458541,"seq":114533072544},"cts":1704258135749}
{"topic":"orderbook.50.BTCUSDT","type":"delta","ts":1704258135771,"data":{"s":"BTCUSDT","b":[["45164.00","0.192"],["45162.10","0"],["45159.80","0.709"]],"a":[["45171.40","0"],["45176.70","0.383"],["45178.40","0.464"]],"u":20458542,"seq":114533072602},"cts":1704258135768}
{"topic":"orderbook.50.BTCUSDT","type":"delta","ts":1704258135792,"data":{"s":"BTCUSDT","b":[],"a":[["45172.80","0.500"],["45173.00","0.256"],["45174.50","0.044"],["45178.40","0"]],"u":20458543,"seq":114533072662},"cts":1704258135790}
{"topic":"orderbook.50.BTCUSDT","type":"delta","ts":1704258135832,"data":{"s":"BTCUSDT","b":[["45170.20","1.936"]],"a":[["45177.90","0.144"]],"u":20458544,"seq":114533072765},"cts":1704258135830}
{"topic":"orderbook.50.BTCUSDT","type":"delta","ts":1704258135872,"data":{"s":"BTCUSDT","b":[["45170.20","2.047"],["45161.40","0.221"],["45159.80","0"]],"a":[["45170.40","0.220"],["45173.00","0.260"],["45174.20","0"],["45175.80","0.227"],["45176.20","0.114"],["45178.40","0.464"]],"u":20458545,"seq":114533072910},"cts":1704258135869}
{"topic":"orderbook.50.BTCUSDT","type":"delta","ts":1704258135891,"data":{"s":"BTCUSDT","b":[],"a":[["45177.00","0.122"]],"u":20458546,"seq":114533072969},"cts":1704258135890}
{"topic":"orderbook.50.BTCUSDT","type":"delta","ts":1704258135911,"data":{"s":"BTCUSDT","b":[],"a":[["45177.00","0.133"],["45177.20","0.221"]],"u":20458547,"seq":114533073031},"cts":1704258135910}
{"topic":"orderbook.50.BTCUSDT","type":"delta","ts":1704258135932,"data":{"s":"BTCUSDT","b":[["45163.30","0.034"],["45159.90","0"]],"a":[["45177.90","0.110"]],"u":20458548,"seq":114533073093},"cts":1704258135930}
{"topic":"orderbook.50.BTCUSDT","type":"delta","ts":1704258135951,"data":{"s":"BTCUSDT","b":[["45163.30","0"],["45159.90","0.901"]],"a":[],"u":20458549,"seq":114533073152},"cts":1704258135950}
{"topic":"orderbook.50.BTCUSDT","type":"delta","ts":1704258135972,"data":{"s":"BTCUSDT","b":[],"a":[["45177.00","0.122"]],"u":20458550,"seq":114533073209},"cts":1704258135969}
{"topic":"orderbook.50.BTCUSDT","type":"delta","ts":1704258136072,"data":{"s":"BTCUSDT","b":[],"a":[["45177.50","0.035"],["45178.40","0"]],"u":20458551,"seq":114533073435},"cts":1704258136070}
{"topic":"orderbook.50.BTCUSDT","type":"delta","ts":1704258136132,"data":{"s":"BTCUSDT","b":[["45163.30","0.035"],["45159.90","0"]],"a":[["45177.50","0"],["45178.40","0.464"]],"u":20458552,"seq":114533073575},"cts":1704258136130}
{"topic":"orderbook.50.BTCUSDT","type":"delta","ts":1704258136171,"data":{"s":"BTCUSDT","b":[["45162.50","1.585"],["45162.30","2.552"]],"a":[["45170.30","10.895"],["45177.00","0.111"],["45177.20","0.232"],["45177.60","0.110"]],"u":20458553,"seq":114533073706},"cts":1704258136170}
{"topic":"orderbook.50.BTCUSDT","type":"delta","ts":1704258136231,"data":{"s":"BTCUSDT","b":[["45170.20","1.973"],["45169.90","0.001"],["45163.30","0"],["45162.50","0.080"]],"a":[["45177.10","0.257"],["45177.20","0.221"],["45177.60","0.075"]],"u":20458554,"seq":114533073879},"cts":1704258136229}
{"topic":"orderbook.50.BTCUSDT","type":"delta","ts":1704258136251,"data":{"s":"BTCUSDT","b":[["45169.90","0"],["45168.00","0.001"],["45163.80","0.075"],["45162.60","0.110"],["45161.20","0"],["45161.00","2.968"],["45159.90","0.901"]],"a":[["45172.80","0.612"],["45175.80","0.238"],["45177.10","0.246"]],"u":20458555,"seq":114533073996},"cts":1704258136250}
{"topic":"orderbook.50.BTCUSDT","type":"delta","ts":1704258136271,"data":{"s":"BTCUSDT","b":[["45165.90","0.129"]],"a":[["45170.30","12.095"],["45171.20","1.758"],["45177.00","0.122"],["45177.60","2.022"],["45177.80","3.917"]],"u":20458556,"seq":114533074076},"cts":1704258136270}
{"topic":"orderbook.50.BTCUSDT","type":"delta","ts":1704258136291,"data":{"s":"BTCUSDT","b":[],"a":[["45170.30","12.123"],["45171.20","1.858"]],"u":20458557,"seq":114533074143},"cts":1704258136290}
{"topic":"orderbook.50.BTCUSDT","type":"delta","ts":1704258136311,"data":{"s":"BTCUSDT","b":[],"a":[["45177.50","1.947"],["45177.60","0.075"],["45178.40","0"]],"u":20458558,"seq":114533074210},"cts":1704258136310}
{"topic":"orderbook.50.BTCUSDT","type":"delta","ts":1704258136331,"data":{"s":"BTCUSDT","b":[["45162.60","0.075"],["45162.50","1.585"]],"a":[["45176.20","0.335"],["45177.50","0"],["45177.60","2.022"],["45178.40","0.464"]],"u":20458559,"seq":114533074287},"cts":1704258136330}
{"topic":"orderbook.50.BTCUSDT","type":"delta","ts":1704258136352,"data":{"s":"BTCUSDT","b":[],"a":[["45177.00","0.111"],["45177.60","0.075"],["45177.80","0.155"],["45177.90","3.872"]],"u":20458560,"seq":114533074354},"cts":1704258136349}
{"topic":"orderbook.50.BTCUSDT","type":"delta","ts":1704258136371,"data":{"s":"BTCUSDT","b":[["45165.90","0.111"],["45162.30","2.587"]],"a":[["45175.80","0.227"],["45176.10","0.011"],["45177.70","2.456"],["45177.90","0.110"],["45178.40","0"]],"u":20458561,"seq":114533074431},"cts":1704258136369}
{"topic":"orderbook.50.BTCUSDT","type":"delta","ts":1704258136391,"data":{"s":"BTCUSDT","b":[],"a":[["45177.70","0.509"]],"u":20458562,"seq":114533074498},"cts":1704258136390}
{"topic":"orderbook.50.BTCUSDT","type":"delta","ts":1704258136412,"data":{"s":"BTCUSDT","b":[],"a":[["45170.30","12.055"]],"u":20458563,"seq":114533074557},"cts":1704258136409}
{"topic":"orderbook.50.BTCUSDT","type":"delta","ts":1704258136432,"data":{"s":"BTCUSDT","b":[["45162.30","2.552"],["45160.80","0.221"],["45159.90","0"]],"a":[["45176.10","0"],["45176.20","0.114"],["45176.80","0.011"]],"u":20458564,"seq":114533074668},"cts":1704258136430}
{"topic":"orderbook.50.BTCUSDT","type":"delta","ts":1704258136451,"data":{"s":"BTCUSDT","b":[],"a":[["45176.50","0.465"],["45176.80","0"],["45178.40","0.464"]],"u":20458565,"seq":114533074735},"cts":1704258136450}
{"topic":"orderbook.50.BTCUSDT","type":"delta","ts":1704258136471,"data":{"s":"BTCUSDT","b":[["45162.90","0.146"]],"a":[],"u":20458566,"seq":114533074799},"cts":1704258136470}
{"topic":"orderbook.50.BTCUSDT","type":"delta","ts":1704258136491,"data":{"s":"BTCUSDT","b":[["45170.20","3.187"],["45168.10","0"],["45162.90","0.111"],["45159.90","0.901"]],"a":[["45170.30","10.855"],["45176.50","0.454"],["45176.90","0.122"],["45177.50","0.011"],["45178.40","0"]],"u":20458567,"seq":114533074885},"cts":1704258136490}
{"topic":"orderbook.50.BTCUSDT","type":"delta","ts":1704258136512,"data":{"s":"BTCUSDT","b":[["45168.60","0"],["45159.80","0.709"]],"a":[["45177.50","0"],["45177.60","0.086"],["45178.40","0.464"]],"u":20458568,"seq":114533074930},"cts":1704258136510}
{"topic":"orderbook.50.BTCUSDT","type":"delta","ts":1704258136532,"data":{"s":"BTCUSDT","b":[["45162.90","0.332"]],"a":[["45177.70","0.544"]],"u":20458569,"seq":114533074962},"cts":1704258136530}
{"topic":"orderbook.50.BTCUSDT","type":"delta","ts":1704258136552,"data":{"s":"BTCUSDT","b":[],"a":[["45177.70","0.509"]],"u":20458570,"seq":114533074989},"cts":1704258136549}
{"topic":"orderbook.50.BTCUSDT","type":"delta","ts":1704258136572,"data":{"s":"BTCUSDT","b":[["45170.20","3.487"],["45168.70","0"],["45168.60","0.001"]],"a":[["45176.90","0.111"]],"u":20458571,"seq":114533075030},"cts":1704258136570}
{"topic":"orderbook.50.BTCUSDT","type":"delta","ts":1704258136592,"data":{"s":"BTCUSDT","b":[["45166.80","0.006"],["45164.10","0.018"],["45163.70","0.267"],["45159.80","0"]],"a":[],"u":20458572,"seq":114533075064},"cts":1704258136588}
{"topic":"orderbook.50.BTCUSDT","type":"delta","ts":1704258136611,"data":{"s":"BTCUSDT","b":[["45165.80","0.236"]],"a":[["45177.50","0.011"],["45177.60","0.075"],["45178.40","0"]],"u":20458573,"seq":114533075096},"cts":1704258136610}
{"topic":"orderbook.50.BTCUSDT","type":"delta","ts":1704258136632,"data":{"s":"BTCUSDT","b":[],"a":[["45176.40","0.856"],["45176.50","0.443"]],"u":20458574,"seq":114533075121},"cts":1704258136629}
{"topic":"orderbook.50.BTCUSDT","type":"delta","ts":1704258136652,"data":{"s":"BTCUSDT","b":[["45166.80","0.007"]],"a":[["45172.70","0.001"],["45178.30","0"]],"u":20458575,"seq":114533075151},"cts":1704258136649}
{"topic":"orderbook.50.BTCUSDT","type":"delta","ts":1704258136671,"data":{"s":"BTCUSDT","b":[],"a":[["45177.30","0.144"],["45177.50","0"],["45178.10","3.486"],["45178.30","0.996"]],"u":20458576,"seq":114533075184},"cts":1704258136669}
{"topic":"orderbook.50.BTCUSDT","type":"delta","ts":1704258136692,"data":{"s":"BTCUSDT","b":[],"a":[["45176.40","0.845"]],"u":20458577,"seq":114533075213},"cts":1704258136689}
{"topic":"orderbook.50.BTCUSDT","type":"delta","ts":1704258136732,"data":{"s":"BTCUSDT","b":[],"a":[["45177.00","0.122"]],"u":20458578,"seq":114533075258},"cts":1704258136728}
{"topic":"orderbook.50.BTCUSDT","type":"delta","ts":1704258136772,"data":{"s":"BTCUSDT","b":[],"a":[["45176.50","0.454"]],"u":20458579,"seq":114533075304},"cts":1704258136769}
{"topic":"orderbook.50.BTCUSDT","type":"delta","ts":1704258136792,"data":{"s":"BTCUSDT","b":[],"a":[["45177.00","0.111"]],"u":20458580,"seq":114533075331},"cts":1704258136789}
{"topic":"orderbook.50.BTCUSDT","type":"delta","ts":1704258136831,"data":{"s":"BTCUSDT","b":[["45170.20","3.187"],["45163.70","0.232"],["45162.50","0.080"]],"a":[["45177.20","0.232"],["45177.30","0.133"],["45178.10","3.451"]],"u":20458581,"seq":114533075384},"cts":1704258136830}
{"topic":"orderbook.50.BTCUSDT","type":"delta","ts":1704258136851,"data":{"s":"BTCUSDT","b":[["45170.20","2.347"],["45166.80","0.006"],["45164.00","0.227"]],"a":[["45172.70","0"],["45177.20","0.221"],["45177.30","0.144"],["45177.60","0.110"],["45178.40","0.464"]],"u":20458582,"seq":114533075477},"cts":1704258136850}
{"topic":"orderbook.50.BTCUSDT","type":"delta","ts":1704258136891,"data":{"s":"BTCUSDT","b":[["45170.20","2.956"]],"a":[],"u":20458583,"seq":114533075565},"cts":1704258136890}
{"topic":"orderbook.50.BTCUSDT","type":"delta","ts":1704258136911,"data":{"s":"BTCUSDT","b":[["45170.20","2.656"],["45169.90","0.001"],["45159.90","0"]],"a":[],"u":20458584,"seq":114533075646},"cts":1704258136910}
{"topic":"orderbook.50.BTCUSDT","type":"delta","ts":1704258136932,"data":{"s":"BTCUSDT","b":[["45170.20","2.641"],["45162.50","1.585"]],"a":[["45176.50","0.443"]],"u":20458585,"seq":114533075703},"cts":1704258136929}
{"topic":"orderbook.50.BTCUSDT","type":"delta","ts":1704258136952,"data":{"s":"BTCUSDT","b":[["45166.80","0.007"]],"a":[["45176.90","0.122"]],"u":20458586,"seq":114533075745},"cts":1704258136949}
{"topic":"orderbook.50.BTCUSDT","type":"delta","ts":1704258136992,"data":{"s":"BTCUSDT","b":[["45166.90","0.046"],["45164.00","0.192"],["45160.40","1.560"],["45160.10","0"],["45160.00","0"]],"a":[["45177.60","0.075"]],"u":20458587,"seq":114533075812},"cts":1704258136989}
{"topic":"orderbook.50.BTCUSDT","type":"delta","ts":1704258137011,"data":{"s":"BTCUSDT","b":[["45164.00","0.227"]],"a":[["45176.90","0.111"],["45177.20","0.232"],["45177.30","0.133"],["45177.60","0.110"]],"u":20458588,"seq":114533075853},"cts":1704258137010}
{"topic":"orderbook.50.BTCUSDT","type":"delta","ts":1704258137051,"data":{"s":"BTCUSDT","b":[["45170.20","2.663"]],"a":[],"u":20458589,"seq":114533075920},"cts":1704258137050}
{"topic":"orderbook.50.BTCUSDT","type":"delta","ts":1704258137072,"data":{"s":"BTCUSDT","b":[],"a":[["45176.50","0.454"]],"u":20458590,"seq":114533075962},"cts":1704258137070}
{"topic":"orderbook.50.BTCUSDT","type":"delta","ts":1704258137091,"data":{"s":"BTCUSDT","b":[],"a":[["45171.90","0.076"],["45174.30","3.399"],["45178.40","0"]],"u":20458591,"seq":114533076006},"cts":1704258137090}
{"topic":"orderbook.50.BTCUSDT","type":"delta","ts":1704258137131,"data":{"s":"BTCUSDT","b":[["45166.10","0"],["45160.10","1.195"]],"a":[],"u":20458592,"seq":114533076065},"cts":1704258137129}
{"topic":"orderbook.50.BTCUSDT","type":"delta","ts":1704258137152,"data":{"s":"BTCUSDT","b":[["45162.90","0.111"]],"a":[["45172.80","0.500"]],"u":20458593,"seq":114533076103},"cts":1704258137147}
{"topic":"orderbook.50.BTCUSDT","type":"delta","ts":1704258137171,"data":{"s":"BTCUSDT","b":[["45167.00","0.001"],["45166.80","0.006"],["45160.10","0"]],"a":[["45176.90","0.122"]],"u":20458594,"seq":114533076147},"cts":1704258137170}
{"topic":"orderbook.50.BTCUSDT","type":"delta","ts":1704258137192,"data":{"s":"BTCUSDT","b":[["45167.00","0.002"],["45166.80","0.004"]],"a":[],"u":20458595,"seq":114533076182},"cts":1704258137189}
{"topic":"orderbook.50.BTCUSDT","type":"delta","ts":1704258137211,"data":{"s":"BTCUSDT","b":[["45164.10","0.053"],["45164.00","0.192"]],"a":[["45177.60","0.075"],["45177.70","0.544"]],"u":20458596,"seq":114533076222},"cts":1704258137210}
{"topic":"orderbook.50.BTCUSDT","type":"delta","ts":1704258137231,"data":{"s":"BTCUSDT","b":[["45167.00","0.003"]],"a":[["45176.40","0.856"],["45176.50","0.443"]],"u":20458597,"seq":114533076253},"cts":1704258137228}
{"topic":"orderbook.50.BTCUSDT","type":"delta","ts":1704258137252,"data":{"s":"BTCUSDT","b":[["45167.00","0.004"],["45166.80","0.002"]],"a":[["45176.90","0.111"],["45177.00","0.122"]],"u":20458598,"seq":114533076289},"cts":1704258137250}
{"topic":"orderbook.50.BTCUSDT","type":"delta","ts":1704258137272,"data":{"s":"BTCUSDT","b":[["45167.00","0.005"]],"a":[["45177.90","1.615"],["45178.10","1.946"]],"u":20458599,"seq":114533076337},"cts":1704258137269}
{"topic":"orderbook.50.BTCUSDT","type":"delta","ts":1704258137292,"data":{"s":"BTCUSDT","b":[],"a":[["45177.10","0.257"],["45177.20","0.221"],["45177.40","2.104"]],"u":20458600,"seq":114533076375},"cts":1704258137290}
{"topic":"orderbook.50.BTCUSDT","type":"delta","ts":1704258137311,"data":{"s":"BTCUSDT","b":[["45167.00","0.006"],["45166.80","0.001"]],"a":[["45176.40","0.845"]],"u":20458601,"seq":114533076419},"cts":1704258137310}
{"topic":"orderbook.50.BTCUSDT","type":"delta","ts":1704258137331,"data":{"s":"BTCUSDT","b":[["45170.20","2.664"]],"a":[["45177.00","0.111"]],"u":20458602,"seq":114533076498},"cts":1704258137330}
{"topic":"orderbook.50.BTCUSDT","type":"delta","ts":1704258137391,"data":{"s":"BTCUSDT","b":[["45170.20","2.907"],["45163.30","1.200"],["45160.20","0"]],"a":[["45170.30","9.785"],["45176.70","0.162"]],"u":20458603,"seq":114533076643},"cts":1704258137390}
{"topic":"orderbook.50.BTCUSDT","type":"delta","ts":1704258137411,"data":{"s":"BTCUSDT","b":[["45163.70","0.788"]],"a":[["45170.30","9.685"],["45177.10","0.246"],["45177.20","0.232"]],"u":20458604,"seq":114533076694},"cts":1704258137410}
{"topic":"orderbook.50.BTCUSDT","type":"delta","ts":1704258137431,"data":{"s":"BTCUSDT","b":[["45164.10","0.018"],["45162.60","0.296"]],"a":[["45177.70","0.509"]],"u":20458605,"seq":114533076729},"cts":1704258137430}
{"topic":"orderbook.50.BTCUSDT","type":"delta","ts":1704258137452,"data":{"s":"BTCUSDT","b":[["45170.20","4.187"],["45164.20","0.113"]],"a":[["45177.20","0.221"],["45177.30","0.144"],["45177.80","0.190"]],"u":20458606,"seq":114533076775},"cts":1704258137450}
{"topic":"orderbook.50.BTCUSDT","type":"delta","ts":1704258137471,"data":{"s":"BTCUSDT","b":[["45170.00","0.221"]],"a":[["45170.30","7.767"],["45172.70","0.002"],["45174.30","2.840"],["45176.90","0.122"],["45177.20","0"],["45177.30","0.133"],["45177.70","0.288"],["45178.20","0.908"]],"u":20458607,"seq":114533076840},"cts":1704258137470}
{"topic":"orderbook.50.BTCUSDT","type":"delta","ts":1704258137491,"data":{"s":"BTCUSDT","b":[["45170.20","4.983"],["45167.00","1.606"],["45165.80","0.311"],["45163.00","0"],["45162.50","1.996"],["45160.20","0.890"]],"a":[["45170.30","6.680"],["45177.70","0.266"]],"u":20458608,"seq":114533076953},"cts":1704258137489}
{"topic":"orderbook.50.BTCUSDT","type":"delta","ts":1704258137511,"data":{"s":"BTCUSDT","b":[["45170.20","5.183"],["45167.00","0.006"],["45166.60","0"],["45165.60","1.200"],["45162.20","0.110"],["45161.70","1.669"],["45160.20","0"]],"a":[["45171.00","0"],["45174.30","1.640"],["45175.80","0.115"],["45177.80","0.168"],["45178.00","0.380"],["45178.40","0.464"]],"u":20458609,"seq":114533076998},"cts":1704258137509}
{"topic":"orderbook.50.BTCUSDT","type":"delta","ts":1704258137532,"data":{"s":"BTCUSDT","b":[["45166.10","0.729"],["45164.20","0.078"],["45163.40","0.221"],["45160.40","0"],["45160.30","0"]],"a":[["45177.80","0.133"]],"u":20458610,"seq":114533077045},"cts":1704258137529}
{"topic":"orderbook.50.BTCUSDT","type":"delta","ts":1704258137552,"data":{"s":"BTCUSDT","b":[["45166.10","0.806"],["45164.70","0.035"],["45163.70","0.710"],["45162.50","2.607"],["45161.20","0.544"],["45160.90","0"],["45160.80","0"]],"a":[["45172.70","0.003"],["45176.90","0.111"],["45178.30","1.031"]],"u":20458611,"seq":114533077081},"cts":1704258137544}
{"topic":"orderbook.50.BTCUSDT","type":"delta","ts":1704258137572,"data":{"s":"BTCUSDT","b":[["45167.10","0.083"],["45167.00","0.005"],["45164.70","0"],["45164.30","0"],["45160.90","0.447"]],"a":[["45170.30","6.436"],["45174.50","0"],["45176.20","0.158"],["45177.90","0.110"],["45178.00","0.391"],["45178.30","0.996"],["45178.60","2.034"]],"u":20458612,"seq":114533077129},"cts":1704258137570}
{"topic":"orderbook.50.BTCUSDT","type":"delta","ts":1704258137591,"data":{"s":"BTCUSDT","b":[["45166.80","0"],["45165.80","0.389"],["45164.00","0.114"],["45160.80","0.221"]],"a":[["45170.30","5.586"],["45170.40","0.020"],["45173.00","0.182"],["45178.00","0.380"],["45178.50","0.011"],["45178.60","0"]],"u":20458613,"seq":114533077203},"cts":1704258137590}
{"topic":"orderbook.50.BTCUSDT","type":"delta","ts":1704258137611,"data":{"s":"BTCUSDT","b":[["45167.00","0.004"]],"a":[["45172.70","0.004"],["45174.70","0.078"],["45177.80","0.144"],["45178.50","0"]],"u":20458614,"seq":114533077248},"cts":1704258137609}
{"topic":"orderbook.50.BTCUSDT","type":"delta","ts":1704258137632,"data":{"s":"BTCUSDT","b":[["45170.20","5.184"],["45167.20","0.001"],["45160.80","0"]],"a":[["45177.80","0.133"]],"u":20458615,"seq":114533077333},"cts":1704258137630}
{"topic":"orderbook.50.BTCUSDT","type":"delta","ts":1704258137671,"data":{"s":"BTCUSDT","b":[["45165.30","0.036"],["45160.90","0"]],"a":[["45177.90","1.615"],["45178.10","1.982"]],"u":20458616,"seq":114533077401},"cts":1704258137668}
{"topic":"orderbook.50.BTCUSDT","type":"delta","ts":1704258137692,"data":{"s":"BTCUSDT","b":[["45167.20","0.077"],["45164.20","0"],["45160.90","0.447"]],"a":[["45178.00","0.391"]],"u":20458617,"seq":114533077421},"cts":1704258137689}
{"topic":"orderbook.50.BTCUSDT","type":"delta","ts":1704258137711,"data":{"s":"BTCUSDT","b":[["45165.30","0"],["45163.30","1.310"],["45160.80","0.221"]],"a":[["45173.10","0.708"],["45178.10","1.946"]],"u":20458618,"seq":114533077463},"cts":1704258137710}
{"topic":"orderbook.50.BTCUSDT","type":"delta","ts":1704258137732,"data":{"s":"BTCUSDT","b":[["45163.90","0.221"],["45160.80","0"]],"a":[],"u":20458619,"seq":114533077497},"cts":1704258137727}
{"topic":"orderbook.50.BTCUSDT","type":"delta","ts":1704258137751,"data":{"s":"BTCUSDT","b":[["45165.90","0.188"],["45162.60","0.221"]],"a":[],"u":20458620,"seq":114533077521},"cts":1704258137744}
{"topic":"orderbook.50.BTCUSDT","type":"delta","ts":1704258137772,"data":{"s":"BTCUSDT","b":[["45167.00","0.003"]],"a":[["45178.00","0.380"]],"u":20458621,"seq":114533077555},"cts":1704258137770}
{"topic":"orderbook.50.BTCUSDT","type":"delta","ts":1704258137791,"data":{"s":"BTCUSDT","b":[["45167.30","0.001"],["45167.00","0.002"],["45160.90","0"]],"a":[],"u":20458622,"seq":114533077586},"cts":1704258137789}
{"topic":"orderbook.50.BTCUSDT","type":"delta","ts":1704258137811,"data":{"s":"BTCUSDT","b":[["45167.00","0.001"],["45165.00","0.036"],["45161.00","0"]],"a":[["45177.80","0.169"]],"u":20458623,"seq":114533077624},"cts":1704258137810}
{"topic":"orderbook.50.BTCUSDT","type":"delta","ts":1704258137831,"data":{"s":"BTCUSDT","b":[["45165.00","0"],["45161.00","2.968"]],"a":[["45170.30","4.096"],["45177.80","0.133"]],"u":20458624,"seq":114533077685},"cts":1704258137830}
{"topic":"orderbook.50.BTCUSDT","type":"delta","ts":1704258137852,"data":{"s":"BTCUSDT","b":[["45167.30","0.004"],["45167.00","0"],["45160.90","0.447"]],"a":[],"u":20458625,"seq":114533077726},"cts":1704258137849}
{"topic":"orderbook.50.BTCUSDT","type":"delta","ts":1704258137872,"data":{"s":"BTCUSDT","b":[["45167.40","0.047"],["45167.30","0.005"],["45164.40","0"]],"a":[["45172.70","0.005"]],"u":20458626,"seq":114533077746},"cts":1704258137868}
{"topic":"orderbook.50.BTCUSDT","type":"delta","ts":1704258137892,"data":{"s":"BTCUSDT","b":[["45167.50","0.036"],["45167.30","0.006"],["45160.90","0"]],"a":[],"u":20458627,"seq":114533077770},"cts":1704258137886}
{"topic":"orderbook.50.BTCUSDT","type":"delta","ts":1704258137911,"data":{"s":"BTCUSDT","b":[["45167.60","0.001"],["45167.20","0.076"],["45165.60","0"],["45164.70","0.036"],["45164.10","0.128"],["45161.00","0"]],"a":[["45177.60","0.086"],["45177.80","0.169"]],"u":20458628,"seq":114533077805},"cts":1704258137910}
{"topic":"orderbook.50.BTCUSDT","type":"delta","ts":1704258137932,"data":{"s":"BTCUSDT","b":[["45166.20","0.248"],["45166.10","0.077"]],"a":[["45178.00","0.391"]],"u":20458629,"seq":114533077837},"cts":1704258137928}
{"topic":"orderbook.50.BTCUSDT","type":"delta","ts":1704258137951,"data":{"s":"BTCUSDT","b":[],"a":[["45177.80","0.180"]],"u":20458630,"seq":114533077849},"cts":1704258137943}
{"topic":"orderbook.50.BTCUSDT","type":"delta","ts":1704258137972,"data":{"s":"BTCUSDT","b":[["45162.50","1.102"]],"a":[],"u":20458631,"seq":114533077871},"cts":1704258137969}
{"topic":"orderbook.50.BTCUSDT","type":"delta","ts":1704258138011,"data":{"s":"BTCUSDT","b":[["45164.70","0"],["45164.30","0.036"]],"a":[["45177.40","2.140"],["45177.80","0.144"]],"u":20458632,"seq":114533077899},"cts":1704258138010}
{"topic":"orderbook.50.BTCUSDT","type":"delta","ts":1704258138032,"data":{"s":"BTCUSDT","b":[["45164.30","0"],["45161.00","2.968"]],"a":[["45177.40","2.104"]],"u":20458633,"seq":114533077922},"cts":1704258138028}
{"topic":"orderbook.50.BTCUSDT","type":"delta","ts":1704258138051,"data":{"s":"BTCUSDT","b":[["45170.20","5.204"]],"a":[["45177.50","0.011"],["45177.60","0.075"],["45178.40","0"]],"u":20458634,"seq":114533077934},"cts":1704258138050}
{"topic":"orderbook.50.BTCUSDT","type":"delta","ts":1704258138072,"data":{"s":"BTCUSDT","b":[["45167.30","0.005"],["45162.60","1.726"]],"a":[["45170.30","5.374"]],"u":20458635,"seq":114533077965},"cts":1704258138068}
{"topic":"orderbook.50.BTCUSDT","type":"delta","ts":1704258138092,"data":{"s":"BTCUSDT","b":[["45167.60","0.002"],["45167.30","0.003"]],"a":[["45170.40","0.010"]],"u":20458636,"seq":114533077991},"cts":1704258138089}
{"topic":"orderbook.50.BTCUSDT","type":"delta","ts":1704258138112,"data":{"s":"BTCUSDT","b":[["45167.60","0.003"],["45166.20","0.325"],["45163.80","0"],["45160.90","0.447"]],"a":[["45177.70","0.277"],["45177.80","0.133"]],"u":20458637,"seq":114533078017},"cts":1704258138109}
{"topic":"orderbook.50.BTCUSDT","type":"delta","ts":1704258138132,"data":{"s":"BTCUSDT","b":[["45165.10","0.148"]],"a":[["45177.50","0"],["45177.70","0.266"],["45178.20","0.944"],["45178.40","0.464"]],"u":20458638,"seq":114533078054},"cts":1704258138127}
{"topic":"orderbook.50.BTCUSDT","type":"delta","ts":1704258138152,"data":{"s":"BTCUSDT","b":[["45167.60","0.005"],["45167.30","0.002"]],"a":[["45177.30","0.144"]],"u":20458639,"seq":114533078080},"cts":1704258138148}
{"topic":"orderbook.50.BTCUSDT","type":"delta","ts":1704258138172,"data":{"s":"BTCUSDT","b":[],"a":[["45177.30","0.133"],["45177.80","0.144"]],"u":20458640,"seq":114533078118},"cts":1704258138168}
{"topic":"orderbook.50.BTCUSDT","type":"delta","ts":1704258138191,"data":{"s":"BTCUSDT","b":[["45167.60","0.006"],["45167.30","0.001"]],"a":[],"u":20458641,"seq":114533078145},"cts":1704258138188}
{"topic":"orderbook.50.BTCUSDT","type":"delta","ts":1704258138212,"data":{"s":"BTCUSDT","b":[],"a":[["45178.20","0.908"]],"u":20458642,"seq":114533078168},"cts":1704258138209}
{"topic":"orderbook.50.BTCUSDT","type":"delta","ts":1704258138232,"data":{"s":"BTCUSDT","b":[["45165.10","0.112"],["45164.80","0.147"]],"a":[["45177.70","0.277"],["45177.80","0.133"]],"u":20458643,"seq":114533078192},"cts":1704258138230}
{"topic":"orderbook.50.BTCUSDT","type":"delta","ts":1704258138251,"data":{"s":"BTCUSDT","b":[],"a":[["45178.00","0.427"]],"u":20458644,"seq":114533078210},"cts":1704258138248}
{"topic":"orderbook.50.BTCUSDT","type":"delta","ts":1704258138272,"data":{"s":"BTCUSDT","b":[],"a":[["45177.30","0.144"],["45177.70","0.266"]],"u":20458645,"seq":114533078233},"cts":1704258138268}
{"topic":"orderbook.50.BTCUSDT","type":"delta","ts":1704258138292,"data":{"s":"BTCUSDT","b":[],"a":[["45177.30","0.133"],["45177.50","0.011"],["45177.70","0.277"],["45178.40","0"]],"u":20458646,"seq":114533078252},"cts":1704258138285}
{"topic":"orderbook.50.BTCUSDT","type":"delta","ts":1704258138312,"data":{"s":"BTCUSDT","b":[],"a":[["45177.30","0.144"],["45177.70","0.266"]],"u":20458647,"seq":114533078270},"cts":1704258138309}
{"topic":"orderbook.50.BTCUSDT","type":"delta","ts":1704258138332,"data":{"s":"BTCUSDT","b":[["45170.20","4.550"],["45164.80","0.111"]],"a":[["45178.00","0.391"]],"u":20458648,"seq":114533078292},"cts":1704258138330}
{"topic":"orderbook.50.BTCUSDT","type":"delta","ts":1704258138352,"data":{"s":"BTCUSDT","b":[["45170.20","5.182"],["45164.70","0.036"],["45161.70","1.666"],["45160.90","0"]],"a":[["45177.90","1.651"]],"u":20458649,"seq":114533078352},"cts":1704258138347}
{"topic":"orderbook.50.BTCUSDT","type":"delta","ts":1704258138411,"data":{"s":"BTCUSDT","b":[],"a":[["45170.30","4.096"]],"u":20458650,"seq":114533078416},"cts":1704258138409}
{"topic":"orderbook.50.BTCUSDT","type":"delta","ts":1704258138431,"data":{"s":"BTCUSDT","b":[["45170.20","4.982"],["45164.70","0"],["45160.90","0.447"]],"a":[["45177.20","0.011"],["45177.30","0.133"],["45177.90","1.615"],["45178.30","0"]],"u":20458651,"seq":114533078451},"cts":1704258138430}
{"topic":"orderbook.50.BTCUSDT","type":"delta","ts":1704258138451,"data":{"s":"BTCUSDT","b":[["45164.60","0.036"],["45160.90","0"]],"a":[["45177.80","0.169"],["45177.90","1.626"],["45178.00","0.380"]],"u":20458652,"seq":114533078462},"cts":1704258138448}
{"topic":"orderbook.50.BTCUSDT","type":"delta","ts":1704258138472,"data":{"s":"BTCUSDT","b":[["45164.60","0"],["45160.90","0.447"]],"a":[["45176.20","0.169"],["45177.20","0"],["45177.80","0.133"],["45178.30","0.996"]],"u":20458653,"seq":114533078487},"cts":1704258138469}
{"topic":"orderbook.50.BTCUSDT","type":"delta","ts":1704258138532,"data":{"s":"BTCUSDT","b":[],"a":[["45176.20","0.158"],["45177.90","1.615"]],"u":20458654,"seq":114533078530},"cts":1704258138529}
{"topic":"orderbook.50.BTCUSDT","type":"delta","ts":1704258138552,"data":{"s":"BTCUSDT","b":[],"a":[["45177.00","0.122"]],"u":20458655,"seq":114533078540},"cts":1704258138547}
{"topic":"orderbook.50.BTCUSDT","type":"delta","ts":1704258138572,"data":{"s":"BTCUSDT","b":[["45170.20","4.880"],["45165.00","0.036"],["45160.90","0"]],"a":[["45178.20","0.944"]],"u":20458656,"seq":114533078553},"cts":1704258138569}
{"topic":"orderbook.50.BTCUSDT","type":"delta","ts":1704258138592,"data":{"s":"BTCUSDT","b":[["45163.90","0"],["45160.90","0.447"]],"a":[["45170.30","5.696"],["45170.80","0.003"],["45171.10","1.600"],["45178.20","0"],["45178.30","0"]],"u":20458657,"seq":114533078593},"cts":1704258138590}
{"topic":"orderbook.50.BTCUSDT","type":"delta","ts":1704258138611,"data":{"s":"BTCUSDT","b":[],"a":[["45170.30","4.096"]],"u":20458658,"seq":114533078631},"cts":1704258138610}
{"topic":"orderbook.50.BTCUSDT","type":"delta","ts":1704258138632,"data":{"s":"BTCUSDT","b":[["45165.00","0"],["45160.80","0.221"]],"a":[],"u":20458659,"seq":114533078650},"cts":1704258138628}
{"topic":"orderbook.50.BTCUSDT","type":"delta","ts":1704258138652,"data":{"s":"BTCUSDT","b":[],"a":[["45170.80","0"],["45171.10","0"],["45178.20","0.908"],["45178.30","0.996"]],"u":20458660,"seq":114533078659},"cts":1704258138646}
{"topic":"orderbook.50.BTCUSDT","type":"delta","ts":1704258138671,"data":{"s":"BTCUSDT","b":[],"a":[["45177.00","0.111"],["45177.20","0.011"],["45178.30","0"]],"u":20458661,"seq":114533078676},"cts":1704258138668}
{"topic":"orderbook.50.BTCUSDT","type":"delta","ts":1704258138712,"data":{"s":"BTCUSDT","b":[["45164.90","0.247"]],"a":[["45178.10","1.982"]],"u":20458662,"seq":114533078695},"cts":1704258138709}
{"topic":"orderbook.50.BTCUSDT","type":"delta","ts":1704258138752,"data":{"s":"BTCUSDT","b":[],"a":[["45176.20","0.169"],["45177.20","0"],["45178.30","0.996"]],"u":20458663,"seq":114533078712},"cts":1704258138748}
{"topic":"orderbook.50.BTCUSDT","type":"delta","ts":1704258138792,"data":{"s":"BTCUSDT","b":[],"a":[["45178.00","0.391"]],"u":20458664,"seq":114533078727},"cts":1704258138788}
{"topic":"orderbook.50.BTCUSDT","type":"delta","ts":1704258138832,"data":{"s":"BTCUSDT","b":[["45164.90","0.211"]],"a":[["45178.10","1.946"]],"u":20458665,"seq":114533078736},"cts":1704258138823}
{"topic":"orderbook.50.BTCUSDT","type":"delta","ts":1704258138852,"data":{"s":"BTCUSDT","b":[["45165.00","0.036"],["45160.80","0"]],"a":[["45178.20","0.944"]],"u":20458666,"seq":114533078744},"cts":1704258138848}
{"topic":"orderbook.50.BTCUSDT","type":"delta","ts":1704258138872,"data":{"s":"BTCUSDT","b":[["45165.00","0"],["45160.80","0.221"]],"a":[["45178.20","0.908"]],"u":20458667,"seq":114533078757},"cts":1704258138869}
{"topic":"orderbook.50.BTCUSDT","type":"delta","ts":1704258138892,"data":{"s":"BTCUSDT","b":[["45167.30","0"],["45160.40","1.560"]],"a":[],"u":20458668,"seq":114533078763},"cts":1704258138887}
{"topic":"orderbook.50.BTCUSDT","type":"delta","ts":1704258138912,"data":{"s":"BTCUSDT","b":[["45167.60","0.007"]],"a":[["45178.00","0.380"]],"u":20458669,"seq":114533078773},"cts":1704258138906}
{"topic":"orderbook.50.BTCUSDT","type":"delta","ts":1704258138952,"data":{"s":"BTCUSDT","b":[["45165.20","0.036"],["45160.40","0"]],"a":[["45178.20","0.944"]],"u":20458670,"seq":114533078786},"cts":1704258138948}
{"topic":"orderbook.50.BTCUSDT","type":"delta","ts":1704258139032,"data":{"s":"BTCUSDT","b":[["45165.20","0"],["45160.40","1.560"]],"a":[["45178.20","0.908"]],"u":20458671,"seq":114533078822},"cts":1704258139029}
{"topic":"orderbook.50.BTCUSDT","type":"delta","ts":1704258139052,"data":{"s":"BTCUSDT","b":[["45170.20","4.898"]],"a":[["45178.00","0.391"]],"u":20458672,"seq":114533078833},"cts":1704258139048}
{"topic":"orderbook.50.BTCUSDT","type":"delta","ts":1704258139112,"data":{"s":"BTCUSDT","b":[["45165.10","0.148"]],"a":[["45178.10","1.982"]],"u":20458673,"seq":114533078855},"cts":1704258139109}
{"topic":"orderbook.50.BTCUSDT","type":"delta","ts":1704258139131,"data":{"s":"BTCUSDT","b":[["45165.10","0.112"]],"a":[["45178.00","0.380"],["45178.10","1.946"]],"u":20458674,"seq":114533078862},"cts":1704258139124}
{"topic":"orderbook.50.BTCUSDT","type":"delta","ts":1704258139152,"data":{"s":"BTCUSDT","b":[],"a":[["45176.20","0.158"],["45177.00","0.122"]],"u":20458675,"seq":114533078867},"cts":1704258139149}
{"topic":"orderbook.50.BTCUSDT","type":"delta","ts":1704258139172,"data":{"s":"BTCUSDT","b":[["45161.10","4.419"]],"a":[["45176.20","0.169"],["45177.00","0.111"]],"u":20458676,"seq":114533078878},"cts":1704258139168}
{"topic":"orderbook.50.BTCUSDT","type":"delta","ts":1704258139192,"data":{"s":"BTCUSDT","b":[],"a":[["45176.20","0.158"],["45177.00","0.122"]],"u":20458677,"seq":114533078889},"cts":1704258139186}
{"topic":"orderbook.50.BTCUSDT","type":"delta","ts":1704258139232,"data":{"s":"BTCUSDT","b":[["45164.70","0.036"],["45160.40","0"]],"a":[["45177.00","0.111"],["45177.70","0.302"]],"u":20458678,"seq":114533078907},"cts":1704258139229}
{"topic":"orderbook.50.BTCUSDT","type":"delta","ts":1704258139251,"data":{"s":"BTCUSDT","b":[],"a":[["45177.00","0.122"]],"u":20458679,"seq":114533078914},"cts":1704258139248}
{"topic":"orderbook.50.BTCUSDT","type":"delta","ts":1704258139292,"data":{"s":"BTCUSDT","b":[["45170.20","4.525"]],"a":[["45178.00","0.391"]],"u":20458680,"seq":114533078933},"cts":1704258139289}
{"topic":"orderbook.50.BTCUSDT","type":"delta","ts":1704258139311,"data":{"s":"BTCUSDT","b":[["45170.20","4.915"]],"a":[],"u":20458681,"seq":114533078983},"cts":1704258139309}
{"topic":"orderbook.50.BTCUSDT","type":"delta","ts":1704258139351,"data":{"s":"BTCUSDT","b":[["45170.20","4.923"],["45161.20","0"],["45160.40","1.560"]],"a":[["45170.30","5.494"],["45171.00","0.003"],["45177.00","0.111"],["45178.00","0.380"],["45178.30","0"]],"u":20458682,"seq":114533079070},"cts":1704258139350}
{"topic":"orderbook.50.BTCUSDT","type":"delta","ts":1704258139372,"data":{"s":"BTCUSDT","b":[],"a":[["45175.70","0.011"],["45178.20","0"]],"u":20458683,"seq":114533079109},"cts":1704258139369}
{"topic":"orderbook.50.BTCUSDT","type":"delta","ts":1704258139411,"data":{"s":"BTCUSDT","b":[],"a":[["45177.20","0.011"],["45177.50","0"]],"u":20458684,"seq":114533079150},"cts":1704258139410}
{"topic":"orderbook.50.BTCUSDT","type":"delta","ts":1704258139432,"data":{"s":"BTCUSDT","b":[],"a":[["45175.70","0"],["45178.20","0.908"]],"u":20458685,"seq":114533079189},"cts":1704258139429}
{"topic":"orderbook.50.BTCUSDT","type":"delta","ts":1704258139452,"data":{"s":"BTCUSDT","b":[],"a":[["45176.10","0.011"],["45178.20","0"]],"u":20458686,"seq":114533079212},"cts":1704258139446}
{"topic":"orderbook.50.BTCUSDT","type":"delta","ts":1704258139472,"data":{"s":"BTCUSDT","b":[["45164.90","0.247"],["45164.70","0"],["45160.30","1.024"]],"a":[["45177.70","0.266"],["45177.80","0.169"]],"u":20458687,"seq":114533079233},"cts":1704258139469}
{"topic":"orderbook.50.BTCUSDT","type":"delta","ts":1704258139512,"data":{"s":"BTCUSDT","b":[],"a":[["45177.70","0.277"]],"u":20458688,"seq":114533079258},"cts":1704258139510}
{"topic":"orderbook.50.BTCUSDT","type":"delta","ts":1704258139551,"data":{"s":"BTCUSDT","b":[["45166.50","0"],["45160.20","0.890"]],"a":[],"u":20458689,"seq":114533079286},"cts":1704258139549}
{"topic":"orderbook.50.BTCUSDT","type":"delta","ts":1704258139592,"data":{"s":"BTCUSDT","b":[],"a":[["45177.70","0.266"]],"u":20458690,"seq":114533079315},"cts":1704258139586}
{"topic":"orderbook.50.BTCUSDT","type":"delta","ts":1704258139611,"data":{"s":"BTCUSDT","b":[],"a":[["45175.90","0.094"],["45176.10","0"],["45178.20","0.908"]],"u":20458691,"seq":114533079342},"cts":1704258139609}
{"topic":"orderbook.50.BTCUSDT","type":"delta","ts":1704258139631,"data":{"s":"BTCUSDT","b":[["45164.90","0.211"]],"a":[["45171.00","0"],["45175.90","0.083"],["45176.10","0.011"]],"u":20458692,"seq":114533079371},"cts":1704258139630}
{"topic":"orderbook.50.BTCUSDT","type":"delta","ts":1704258139652,"data":{"s":"BTCUSDT","b":[["45164.80","0.147"]],"a":[["45177.20","0"],["45177.30","0.144"],["45178.30","0.996"]],"u":20458693,"seq":114533079395},"cts":1704258139649}
{"topic":"orderbook.50.BTCUSDT","type":"delta","ts":1704258139732,"data":{"s":"BTCUSDT","b":[],"a":[["45177.80","0.180"]],"u":20458694,"seq":114533079437},"cts":1704258139729}
{"topic":"orderbook.50.BTCUSDT","type":"delta","ts":1704258139772,"data":{"s":"BTCUSDT","b":[["45164.90","0.322"]],"a":[],"u":20458695,"seq":114533079471},"cts":1704258139769}
{"topic":"orderbook.50.BTCUSDT","type":"delta","ts":1704258139791,"data":{"s":"BTCUSDT","b":[],"a":[["45170.30","5.375"],["45177.30","0.133"],["45177.50","0.011"],["45178.30","0"]],"u":20458696,"seq":114533079504},"cts":1704258139790}
{"topic":"orderbook.50.BTCUSDT","type":"delta","ts":1704258139811,"data":{"s":"BTCUSDT","b":[["45167.60","1.607"],["45162.20","0.113"]],"a":[["45175.90","0.094"],["45176.10","0"],["45178.30","0.996"]],"u":20458697,"seq":114533079580},"cts":1704258139809}
{"topic":"orderbook.50.BTCUSDT","type":"delta","ts":1704258139832,"data":{"s":"BTCUSDT","b":[["45167.70","0.973"],["45167.50","0"],["45163.90","0.221"],["45160.20","0"]],"a":[],"u":20458698,"seq":114533079678},"cts":1704258139830}
{"topic":"orderbook.50.BTCUSDT","type":"delta","ts":1704258139852,"data":{"s":"BTCUSDT","b":[["45169.90","0"],["45165.80","0.277"],["45160.20","0.890"]],"a":[],"u":20458699,"seq":114533079714},"cts":1704258139849}
{"topic":"orderbook.50.BTCUSDT","type":"delta","ts":1704258139872,"data":{"s":"BTCUSDT","b":[["45166.30","0.169"],["45166.20","0.083"],["45160.20","0"]],"a":[["45175.90","0.083"],["45176.10","0.011"],["45178.30","0"]],"u":20458700,"seq":114533079763},"cts":1704258139866}
{"topic":"orderbook.50.BTCUSDT","type":"delta","ts":1704258139891,"data":{"s":"BTCUSDT","b":[["45167.80","0.001"],["45167.60","1.606"],["45160.30","0"]],"a":[["45177.80","0.169"],["45177.90","1.626"]],"u":20458701,"seq":114533079806},"cts":1704258139889}
{"topic":"orderbook.50.BTCUSDT","type":"delta","ts":1704258139912,"data":{"s":"BTCUSDT","b":[["45167.80","0.002"],["45167.60","1.605"],["45162.20","0.110"],["45161.70","1.669"]],"a":[["45170.30","5.387"]],"u":20458702,"seq":114533079842},"cts":1704258139909}
{"topic":"orderbook.50.BTCUSDT","type":"delta","ts":1704258139932,"data":{"s":"BTCUSDT","b":[["45167.80","0.004"],["45167.60","1.603"],["45164.80","0.111"]],"a":[["45177.80","0.133"]],"u":20458703,"seq":114533079880},"cts":1704258139927}
{"topic":"orderbook.50.BTCUSDT","type":"delta","ts":1704258139951,"data":{"s":"BTCUSDT","b":[["45164.60","0.036"],["45160.40","0"]],"a":[],"u":20458704,"seq":114533079896},"cts":1704258139943}
{"topic":"orderbook.50.BTCUSDT","type":"delta","ts":1704258139972,"data":{"s":"BTCUSDT","b":[["45167.80","0.005"],["45167.60","1.602"]],"a":[["45177.90","1.615"]],"u":20458705,"seq":114533079925},"cts":1704258139968}
{"topic":"orderbook.50.BTCUSDT","type":"delta","ts":1704258139992,"data":{"s":"BTCUSDT","b":[],"a":[["45176.20","0.047"]],"u":20458706,"seq":114533079944},"cts":1704258139989}
{"topic":"orderbook.50.BTCUSDT","type":"delta","ts":1704258140051,"data":{"s":"BTCUSDT","b":[],"a":[["45177.50","0.047"]],"u":20458707,"seq":114533079981},"cts":1704258140050}
{"topic":"orderbook.50.BTCUSDT","type":"delta","ts":1704258140071,"data":{"s":"BTCUSDT","b":[["45167.80","1.607"],["45167.60","0"],["45160.40","1.560"]],"a":[],"u":20458708,"seq":114533080010},"cts":1704258140065}
{"topic":"orderbook.50.BTCUSDT","type":"delta","ts":1704258140092,"data":{"s":"BTCUSDT","b":[["45167.90","0.969"],["45167.70","0"],["45164.70","0.036"],["45164.60","0"]],"a":[["45177.50","0.011"]],"u":20458709,"seq":114533080031},"cts":1704258140087}
{"topic":"orderbook.50.BTCUSDT","type":"delta","ts":1704258140112,"data":{"s":"BTCUSDT","b":[["45167.80","0.007"]],"a":[["45177.50","0"],["45177.60","0.086"],["45178.30","0.996"]],"u":20458710,"seq":114533080055},"cts":1704258140109}
{"topic":"orderbook.50.BTCUSDT","type":"delta","ts":1704258140132,"data":{"s":"BTCUSDT","b":[["45167.90","0.036"]],"a":[["45176.10","0"],["45176.20","0.058"],["45178.40","0.464"]],"u":20458711,"seq":114533080072},"cts":1704258140127}
{"topic":"orderbook.50.BTCUSDT","type":"delta","ts":1704258140172,"data":{"s":"BTCUSDT","b":[["45170.20","4.939"]],"a":[["45177.60","0.075"]],"u":20458712,"seq":114533080098},"cts":1704258140170}
{"topic":"orderbook.50.BTCUSDT","type":"delta","ts":1704258140192,"data":{"s":"BTCUSDT","b":[["45161.10","4.310"],["45160.70","0.109"],["45160.40","0"]],"a":[],"u":20458713,"seq":114533080155},"cts":1704258140187}
{"topic":"orderbook.50.BTCUSDT","type":"delta","ts":1704258140212,"data":{"s":"BTCUSDT","b":[["45167.80","0.006"]],"a":[],"u":20458714,"seq":114533080176},"cts":1704258140209}
{"topic":"orderbook.50.BTCUSDT","type":"delta","ts":1704258140232,"data":{"s":"BTCUSDT","b":[["45167.80","0.004"],["45167.50","0.003"],["45165.90","0.220"],["45164.70","0"]],"a":[["45177.60","0.111"]],"u":20458715,"seq":114533080209},"cts":1704258140229}
{"topic":"orderbook.50.BTCUSDT","type":"delta","ts":1704258140252,"data":{"s":"BTCUSDT","b":[["45161.20","0.544"],["45160.70","0"]],"a":[["45176.20","0.047"],["45177.00","0.122"]],"u":20458716,"seq":114533080245},"cts":1704258140249}
{"topic":"orderbook.50.BTCUSDT","type":"delta","ts":1704258140271,"data":{"s":"BTCUSDT","b":[["45167.80","0.003"],["45167.50","0.004"]],"a":[["45177.90","1.626"]],"u":20458717,"seq":114533080276},"cts":1704258140269}
{"topic":"orderbook.50.BTCUSDT","type":"delta","ts":1704258140331,"data":{"s":"BTCUSDT","b":[],"a":[["45177.50","0.011"],["45177.60","0.075"],["45177.90","1.651"],["45178.40","0"]],"u":20458718,"seq":114533080311},"cts":1704258140329}
{"topic":"orderbook.50.BTCUSDT","type":"delta","ts":1704258140352,"data":{"s":"BTCUSDT","b":[["45170.20","4.299"],["45164.80","0.147"]],"a":[],"u":20458719,"seq":114533080327},"cts":1704258140343}
{"topic":"orderbook.50.BTCUSDT","type":"delta","ts":1704258140372,"data":{"s":"BTCUSDT","b":[["45170.20","4.940"],["45167.80","0.001"],["45167.50","0.006"]],"a":[],"u":20458720,"seq":114533080402},"cts":1704258140367}
{"topic":"orderbook.50.BTCUSDT","type":"delta","ts":1704258140412,"data":{"s":"BTCUSDT","b":[["45170.20","4.550"]],"a":[["45177.00","0.111"],["45177.20","0.011"],["45178.30","0"]],"u":20458721,"seq":114533080430},"cts":1704258140408}
{"topic":"orderbook.50.BTCUSDT","type":"delta","ts":1704258140432,"data":{"s":"BTCUSDT","b":[["45170.20","4.938"]],"a":[],"u":20458722,"seq":114533080495},"cts":1704258140428}
{"topic":"orderbook.50.BTCUSDT","type":"delta","ts":1704258140472,"data":{"s":"BTCUSDT","b":[["45161.20","0"],["45160.70","0.109"]],"a":[],"u":20458723,"seq":114533080534},"cts":1704258140469}
{"topic":"orderbook.50.BTCUSDT","type":"delta","ts":1704258140491,"data":{"s":"BTCUSDT","b":[],"a":[["45178.00","0.391"]],"u":20458724,"seq":114533080554},"cts":1704258140483}
{"topic":"orderbook.50.BTCUSDT","type":"delta","ts":1704258140512,"data":{"s":"BTCUSDT","b":[["45169.90","0.001"],["45160.70","0"]],"a":[["45176.20","0.058"],["45177.20","0"],["45178.30","0.996"]],"u":20458725,"seq":114533080586},"cts":1704258140509}
{"topic":"orderbook.50.BTCUSDT","type":"delta","ts":1704258140552,"data":{"s":"BTCUSDT","b":[],"a":[["45176.20","0.047"],["45177.00","0.122"],["45178.00","0.380"]],"u":20458726,"seq":114533080647},"cts":1704258140549}
{"topic":"orderbook.50.BTCUSDT","type":"delta","ts":1704258140571,"data":{"s":"BTCUSDT","b":[["45165.80","0.389"]],"a":[],"u":20458727,"seq":114533080674},"cts":1704258140569}
{"topic":"orderbook.50.BTCUSDT","type":"delta","ts":1704258140591,"data":{"s":"BTCUSDT","b":[],"a":[["45177.00","0.111"],["45177.20","0.011"],["45178.30","0"]],"u":20458728,"seq":114533080692},"cts":1704258140585}
{"topic":"orderbook.50.BTCUSDT","type":"delta","ts":1704258140611,"data":{"s":"BTCUSDT","b":[["45161.70","1.666"]],"a":[],"u":20458729,"seq":114533080714},"cts":1704258140609}
{"topic":"orderbook.50.BTCUSDT","type":"delta","ts":1704258140632,"data":{"s":"BTCUSDT","b":[["45161.70","1.669"]],"a":[],"u":20458730,"seq":114533080740},"cts":1704258140627}
{"topic":"orderbook.50.BTCUSDT","type":"delta","ts":1704258140692,"data":{"s":"BTCUSDT","b":[],"a":[["45177.50","0"],["45177.60","0.086"],["45178.30","0.996"]],"u":20458731,"seq":114533080771},"cts":1704258140682}
{"topic":"orderbook.50.BTCUSDT","type":"delta","ts":1704258140712,"data":{"s":"BTCUSDT","b":[],"a":[["45177.90","1.662"]],"u":20458732,"seq":114533080794},"cts":1704258140710}
{"topic":"orderbook.50.BTCUSDT","type":"delta","ts":1704258140772,"data":{"s":"BTCUSDT","b":[],"a":[["45177.60","0.075"]],"u":20458733,"seq":114533080827},"cts":1704258140769}
{"topic":"orderbook.50.BTCUSDT","type":"delta","ts":1704258140792,"data":{"s":"BTCUSDT","b":[],"a":[["45177.90","1.651"]],"u":20458734,"seq":114533080857},"cts":1704258140788}
{"topic":"orderbook.50.BTCUSDT","type":"delta","ts":1704258140891,"data":{"s":"BTCUSDT","b":[["45167.50","0.007"]],"a":[],"u":20458735,"seq":114533080905},"cts":1704258140889}
{"topic":"orderbook.50.BTCUSDT","type":"delta","ts":1704258140912,"data":{"s":"BTCUSDT","b":[],"a":[["45178.10","1.957"]],"u":20458736,"seq":114533080936},"cts":1704258140910}
{"topic":"orderbook.50.BTCUSDT","type":"delta","ts":1704258140932,"data":{"s":"BTCUSDT","b":[["45167.80","0"],["45160.40","1.560"]],"a":[["45177.20","0"],["45177.30","0.144"],["45177.90","1.615"],["45178.10","1.946"],["45178.40","0.464"]],"u":20458737,"seq":114533080960},"cts":1704258140927}
{"topic":"orderbook.50.BTCUSDT","type":"delta","ts":1704258140952,"data":{"s":"BTCUSDT","b":[["45160.40","1.669"]],"a":[["45177.80","0.169"]],"u":20458738,"seq":114533080984},"cts":1704258140948}
{"topic":"orderbook.50.BTCUSDT","type":"delta","ts":1704258140972,"data":{"s":"BTCUSDT","b":[],"a":[["45177.30","0.133"]],"u":20458739,"seq":114533081006},"cts":1704258140968}
{"topic":"orderbook.50.BTCUSDT","type":"delta","ts":1704258140992,"data":{"s":"BTCUSDT","b":[["45164.80","0.111"]],"a":[["45177.20","0.011"],["45177.80","0.133"],["45178.40","0"]],"u":20458740,"seq":114533081028},"cts":1704258140983}
{"topic":"orderbook.50.BTCUSDT","type":"delta","ts":1704258141012,"data":{"s":"BTCUSDT","b":[["45165.00","0.036"],["45160.40","0"]],"a":[],"u":20458741,"seq":114533081046},"cts":1704258141009}
{"topic":"orderbook.50.BTCUSDT","type":"delta","ts":1704258141032,"data":{"s":"BTCUSDT","b":[["45170.20","4.943"],["45165.00","0"],["45160.40","1.560"]],"a":[],"u":20458742,"seq":114533081064},"cts":1704258141027}
{"topic":"orderbook.50.BTCUSDT","type":"delta","ts":1704258141052,"data":{"s":"BTCUSDT","b":[["45170.20","4.957"],["45160.40","1.669"]],"a":[["45177.50","0.011"],["45178.30","0"]],"u":20458743,"seq":114533081084},"cts":1704258141048}
{"topic":"orderbook.50.BTCUSDT","type":"delta","ts":1704258141091,"data":{"s":"BTCUSDT","b":[],"a":[["45177.90","1.626"]],"u":20458744,"seq":114533081121},"cts":1704258141090}
{"topic":"orderbook.50.BTCUSDT","type":"delta","ts":1704258141112,"data":{"s":"BTCUSDT","b":[["45164.90","0.358"],["45160.40","1.560"]],"a":[],"u":20458745,"seq":114533081140},"cts":1704258141105}
{"topic":"orderbook.50.BTCUSDT","type":"delta","ts":1704258141131,"data":{"s":"BTCUSDT","b":[["45164.90","0.322"]],"a":[],"u":20458746,"seq":114533081161},"cts":1704258141127}
{"topic":"orderbook.50.BTCUSDT","type":"delta","ts":1704258141152,"data":{"s":"BTCUSDT","b":[["45161.20","0.544"],["45160.40","0"]],"a":[["45177.20","0"],["45177.30","0.144"],["45178.30","0.996"]],"u":20458747,"seq":114533081187},"cts":1704258141149}
{"topic":"orderbook.50.BTCUSDT","type":"delta","ts":1704258141192,"data":{"s":"BTCUSDT","b":[],"a":[["45177.70","0.302"]],"u":20458748,"seq":114533081216},"cts":1704258141189}
{"topic":"orderbook.50.BTCUSDT","type":"delta","ts":1704258141211,"data":{"s":"BTCUSDT","b":[],"a":[["45177.50","0"],["45177.70","0.313"],["45177.90","1.615"],["45178.10","1.957"],["45178.40","0.464"]],"u":20458749,"seq":114533081238},"cts":1704258141207}
{"topic":"orderbook.50.BTCUSDT","type":"delta","ts":1704258141232,"data":{"s":"BTCUSDT","b":[],"a":[["45177.70","0.277"],["45178.20","1.129"]],"u":20458750,"seq":114533081257},"cts":1704258141229}
{"topic":"orderbook.50.BTCUSDT","type":"delta","ts":1704258141251,"data":{"s":"BTCUSDT","b":[["45165.00","0.036"],["45160.80","0"]],"a":[],"u":20458751,"seq":114533081274},"cts":1704258141245}
{"topic":"orderbook.50.BTCUSDT","type":"delta","ts":1704258141271,"data":{"s":"BTCUSDT","b":[],"a":[["45177.20","0.011"],["45177.30","0.133"],["45178.40","0"]],"u":20458752,"seq":114533081305},"cts":1704258141266}
{"topic":"orderbook.50.BTCUSDT","type":"delta","ts":1704258141292,"data":{"s":"BTCUSDT","b":[],"a":[["45177.70","0.266"],["45177.80","0.169"],["45178.10","1.946"]],"u":20458753,"seq":114533081325},"cts":1704258141282}
{"topic":"orderbook.50.BTCUSDT","type":"delta","ts":1704258141311,"data":{"s":"BTCUSDT","b":[["45165.00","0"],["45160.80","0.221"]],"a":[["45177.80","0.133"]],"u":20458754,"seq":114533081344},"cts":1704258141310}
{"topic":"orderbook.50.BTCUSDT","type":"delta","ts":1704258141331,"data":{"s":"BTCUSDT","b":[],"a":[["45170.30","3.989"]],"u":20458755,"seq":114533081360},"cts":1704258141328}
{"topic":"orderbook.50.BTCUSDT","type":"delta","ts":1704258141371,"data":{"s":"BTCUSDT","b":[["45170.20","4.969"]],"a":[["45177.20","0"],["45177.30","0.144"],["45178.40","0.464"]],"u":20458756,"seq":114533081460},"cts":1704258141370}
{"topic":"orderbook.50.BTCUSDT","type":"delta","ts":1704258141391,"data":{"s":"BTCUSDT","b":[["45163.90","0"],["45163.40","0"],["45160.40","1.560"],["45160.30","1.024"]],"a":[["45170.70","0.004"],["45173.00","0.178"],["45178.00","0.416"],["45178.40","0"]],"u":20458757,"seq":114533081487},"cts":1704258141390}
{"topic":"orderbook.50.BTCUSDT","type":"delta","ts":1704258141412,"data":{"s":"BTCUSDT","b":[["45160.30","1.133"]],"a":[],"u":20458758,"seq":114533081497},"cts":1704258141408}
{"topic":"orderbook.50.BTCUSDT","type":"delta","ts":1704258141432,"data":{"s":"BTCUSDT","b":[["45169.90","0"],["45164.70","0.837"],["45164.10","0.110"]],"a":[["45177.00","0.122"],["45177.30","0.133"],["45177.70","0.487"],["45177.90","1.626"],["45178.00","0.380"]],"u":20458759,"seq":114533081522},"cts":1704258141429}
{"topic":"orderbook.50.BTCUSDT","type":"delta","ts":1704258141451,"data":{"s":"BTCUSDT","b":[["45165.80","0.277"]],"a":[["45177.50","0.011"],["45178.30","0"]],"u":20458760,"seq":114533081534},"cts":1704258141448}
{"topic":"orderbook.50.BTCUSDT","type":"delta","ts":1704258141492,"data":{"s":"BTCUSDT","b":[["45165.30","0.036"],["45160.30","0"]],"a":[["45178.20","1.165"]],"u":20458761,"seq":114533081556},"cts":1704258141486}
{"topic":"orderbook.50.BTCUSDT","type":"delta","ts":1704258141512,"data":{"s":"BTCUSDT","b":[],"a":[["45177.90","1.615"],["45178.00","0.391"]],"u":20458762,"seq":114533081562},"cts":1704258141508}
{"topic":"orderbook.50.BTCUSDT","type":"delta","ts":1704258141532,"data":{"s":"BTCUSDT","b":[],"a":[["45170.30","3.974"],["45177.50","0"],["45177.70","0.498"],["45178.30","0.996"]],"u":20458763,"seq":114533081571},"cts":1704258141527}
{"topic":"orderbook.50.BTCUSDT","type":"delta","ts":1704258141552,"data":{"s":"BTCUSDT","b":[["45167.50","1.607"]],"a":[["45177.70","0.277"]],"u":20458764,"seq":114533081615},"cts":1704258141550}
{"topic":"orderbook.50.BTCUSDT","type":"delta","ts":1704258141571,"data":{"s":"BTCUSDT","b":[["45167.90","0.964"]],"a":[["45170.30","5.168"]],"u":20458765,"seq":114533081682},"cts":1704258141570}
{"topic":"orderbook.50.BTCUSDT","type":"delta","ts":1704258141591,"data":{"s":"BTCUSDT","b":[["45167.60","0.002"],["45167.50","1.605"],["45160.40","0"]],"a":[["45178.00","0.380"],["45178.20","1.129"]],"u":20458766,"seq":114533081706},"cts":1704258141589}
{"topic":"orderbook.50.BTCUSDT","type":"delta","ts":1704258141611,"data":{"s":"BTCUSDT","b":[],"a":[["45177.70","0.266"]],"u":20458767,"seq":114533081729},"cts":1704258141608}
{"topic":"orderbook.50.BTCUSDT","type":"delta","ts":1704258141632,"data":{"s":"BTCUSDT","b":[["45165.30","0"],["45160.40","1.560"]],"a":[["45177.00","0.111"],["45177.20","0.011"],["45178.30","0"]],"u":20458768,"seq":114533081745},"cts":1704258141628}
{"topic":"orderbook.50.BTCUSDT","type":"delta","ts":1704258141652,"data":{"s":"BTCUSDT","b":[["45165.20","0.036"],["45160.40","0"]],"a":[["45177.20","0"],["45177.30","0.144"],["45178.30","0.996"]],"u":20458769,"seq":114533081773},"cts":1704258141649}
{"topic":"orderbook.50.BTCUSDT","type":"delta","ts":1704258141691,"data":{"s":"BTCUSDT","b":[["45161.20","0.653"]],"a":[],"u":20458770,"seq":114533081806},"cts":1704258141685}
{"topic":"orderbook.50.BTCUSDT","type":"delta","ts":1704258141731,"data":{"s":"BTCUSDT","b":[["45167.60","0.004"],["45167.50","1.603"]],"a":[],"u":20458771,"seq":114533081837},"cts":1704258141729}
{"topic":"orderbook.50.BTCUSDT","type":"delta","ts":1704258141752,"data":{"s":"BTCUSDT","b":[["45167.50","0.002"]],"a":[["45178.10","1.957"]],"u":20458772,"seq":114533081859},"cts":1704258141746}
{"topic":"orderbook.50.BTCUSDT","type":"delta","ts":1704258141772,"data":{"s":"BTCUSDT","b":[["45167.90","0.036"]],"a":[],"u":20458773,"seq":114533081884},"cts":1704258141767}
{"topic":"orderbook.50.BTCUSDT","type":"delta","ts":1704258141792,"data":{"s":"BTCUSDT","b":[["45167.60","0.005"],["45165.20","0"],["45160.40","1.560"]],"a":[],"u":20458774,"seq":114533081903},"cts":1704258141789}
{"topic":"orderbook.50.BTCUSDT","type":"delta","ts":1704258141812,"data":{"s":"BTCUSDT","b":[["45164.90","0.358"]],"a":[["45178.00","0.416"]],"u":20458775,"seq":114533081922},"cts":1704258141810}
{"topic":"orderbook.50.BTCUSDT","type":"delta","ts":1704258141832,"data":{"s":"BTCUSDT","b":[["45164.90","0.322"],["45163.40","0.221"],["45160.40","0"]],"a":[["45178.00","0.380"]],"u":20458776,"seq":114533081942},"cts":1704258141830}
{"topic":"orderbook.50.BTCUSDT","type":"delta","ts":1704258141872,"data":{"s":"BTCUSDT","b":[["45170.20","3.095"],["45163.40","0"],["45161.20","0"],["45160.40","1.560"],["45160.30","1.024"]],"a":[["45170.30","5.668"],["45175.00","0.090"]],"u":20458777,"seq":114533081975},"cts":1704258141870}
{"topic":"orderbook.50.BTCUSDT","type":"delta","ts":1704258141892,"data":{"s":"BTCUSDT","b":[["45170.20","2.863"],["45170.00","0.108"],["45167.60","0.003"],["45162.60","0"],["45161.70","1.666"],["45161.40","0"],["45160.20","0.890"],["45160.10","1.892"]],"a":[["45170.30","6.066"],["45171.00","0.003"],["45172.70","0.001"],["45177.20","0.011"],["45177.30","0.133"],["45178.20","0"],["45178.30","0"]],"u":20458778,"seq":114533082100},"cts":1704258141889}
{"topic":"orderbook.50.BTCUSDT","type":"delta","ts":1704258141911,"data":{"s":"BTCUSDT","b":[["45165.90","0.188"]],"a":[["45172.60","1.200"],["45178.10","0"]],"u":20458779,"seq":114533082148},"cts":1704258141910}
{"topic":"orderbook.50.BTCUSDT","type":"delta","ts":1704258141932,"data":{"s":"BTCUSDT","b":[["45163.30","0.110"]],"a":[["45177.70","0.487"]],"u":20458780,"seq":114533082195},"cts":1704258141930}
{"topic":"orderbook.50.BTCUSDT","type":"delta","ts":1704258141951,"data":{"s":"BTCUSDT","b":[["45165.00","0.510"],["45164.70","0.873"],["45163.70","0"]],"a":[["45175.90","0.094"],["45177.20","0"],["45177.70","0.523"],["45178.10","1.946"]],"u":20458781,"seq":114533082253},"cts":1704258141950}
{"topic":"orderbook.50.BTCUSDT","type":"delta","ts":1704258141971,"data":{"s":"BTCUSDT","b":[["45167.50","0.001"],["45164.70","0.036"]],"a":[["45170.30","7.796"],["45172.50","1.600"],["45172.70","0"],["45173.70","0.011"],["45175.90","0.083"],["45178.10","0"]],"u":20458782,"seq":114533082325},"cts":1704258141970}
{"topic":"orderbook.50.BTCUSDT","type":"delta","ts":1704258141991,"data":{"s":"BTCUSDT","b":[["45170.20","2.789"],["45165.00","0.202"],["45164.70","0"],["45162.70","1.505"]],"a":[["45177.60","0.086"],["45177.70","4.249"],["45177.80","2.080"]],"u":20458783,"seq":114533082393},"cts":1704258141990}
{"topic":"orderbook.50.BTCUSDT","type":"delta","ts":1704258142012,"data":{"s":"BTCUSDT","b":[],"a":[["45170.30","7.824"],["45177.30","3.895"],["45177.70","0.487"],["45177.80","0.133"]],"u":20458784,"seq":114533082460},"cts":1704258142010}
{"topic":"orderbook.50.BTCUSDT","type":"delta","ts":1704258142031,"data":{"s":"BTCUSDT","b":[],"a":[["45173.70","0"],["45175.70","0.011"],["45176.80","0.011"],["45177.20","0.221"],["45177.30","0.133"],["45177.90","0"],["45178.00","0"]],"u":20458785,"seq":114533082517},"cts":1704258142029}
{"topic":"orderbook.50.BTCUSDT","type":"delta","ts":1704258142052,"data":{"s":"BTCUSDT","b":[["45169.90","0.001"],["45167.60","0"],["45167.50","0.004"]],"a":[["45177.60","0.075"],["45177.70","4.249"]],"u":20458786,"seq":114533082583},"cts":1704258142049}
{"topic":"orderbook.50.BTCUSDT","type":"delta","ts":1704258142072,"data":{"s":"BTCUSDT","b":[["45164.10","0.128"]],"a":[["45175.70","0"],["45176.10","0.011"],["45177.70","0.487"]],"u":20458787,"seq":114533082637},"cts":1704258142070}
{"topic":"orderbook.50.BTCUSDT","type":"delta","ts":1704258142091,"data":{"s":"BTCUSDT","b":[["45170.20","2.390"],["45167.50","0.005"],["45162.70","0"],["45160.00","1.199"]],"a":[],"u":20458788,"seq":114533082689},"cts":1704258142090}
{"topic":"orderbook.50.BTCUSDT","type":"delta","ts":1704258142111,"data":{"s":"BTCUSDT","b":[["45170.20","2.776"],["45162.50","0.691"],["45160.80","0"],["45159.90","0.901"]],"a":[["45170.30","9.024"],["45170.70","0"],["45172.20","0.004"],["45174.80","0.115"],["45175.70","0.011"],["45176.10","0"],["45177.30","3.895"]],"u":20458789,"seq":114533082814},"cts":1704258142110}
{"topic":"orderbook.50.BTCUSDT","type":"delta","ts":1704258142131,"data":{"s":"BTCUSDT","b":[["45164.10","0.018"],["45163.90","0.004"],["45162.50","0.080"],["45159.90","0"]],"a":[["45172.20","0"],["45176.80","0"],["45177.20","3.983"],["45177.30","2.080"],["45177.90","1.615"],["45178.00","0.380"]],"u":20458790,"seq":114533082906},"cts":1704258142130}
{"topic":"orderbook.50.BTCUSDT","type":"delta","ts":1704258142152,"data":{"s":"BTCUSDT","b":[["45166.20","0.006"],["45163.80","0.037"],["45160.00","0"]],"a":[["45173.20","0.112"],["45173.50","0.077"],["45175.70","0"],["45175.90","0.037"],["45178.00","0"]],"u":20458791,"seq":114533082977},"cts":1704258142150}
{"topic":"orderbook.50.BTCUSDT","type":"delta","ts":1704258142171,"data":{"s":"BTCUSDT","b":[["45163.80","0"],["45160.00","1.199"]],"a":[["45173.80","0.141"],["45174.60","0.044"],["45175.90","0"],["45176.20","0.003"],["45177.00","3.873"],["45177.20","0.221"],["45177.30","0.133"]],"u":20458792,"seq":114533083034},"cts":1704258142170}
{"topic":"orderbook.50.BTCUSDT","type":"delta","ts":1704258142191,"data":{"s":"BTCUSDT","b":[["45167.50","0.007"],["45162.70","1.505"],["45160.00","0"]],"a":[["45176.90","0.122"],["45177.00","5.820"]],"u":20458793,"seq":114533083083},"cts":1704258142190}
{"topic":"orderbook.50.BTCUSDT","type":"delta","ts":1704258142212,"data":{"s":"BTCUSDT","b":[["45170.20","2.665"],["45169.90","0"],["45164.10","0"],["45162.70","0"],["45160.00","1.199"],["45159.90","0.901"],["45159.80","0.709"]],"a":[["45173.80","0.130"],["45175.30","0.014"],["45176.90","0.111"],["45177.00","3.873"],["45177.10","2.193"]],"u":20458794,"seq":114533083142},"cts":1704258142210}
{"topic":"orderbook.50.BTCUSDT","type":"delta","ts":1704258142231,"data":{"s":"BTCUSDT","b":[["45163.30","0"],["45159.70","0.266"]],"a":[["45171.80","0.412"],["45176.70","0.383"]],"u":20458795,"seq":114533083195},"cts":1704258142228}
{"topic":"orderbook.50.BTCUSDT","type":"delta","ts":1704258142252,"data":{"s":"BTCUSDT","b":[["45165.80","0.199"],["45164.10","0.078"],["45160.10","1.195"],["45159.70","0"]],"a":[["45172.80","0.578"],["45174.70","0"],["45177.00","0.111"],["45177.10","4.008"],["45178.00","0.380"]],"u":20458796,"seq":114533083261},"cts":1704258142249}
{"topic":"orderbook.50.BTCUSDT","type":"delta","ts":1704258142272,"data":{"s":"BTCUSDT","b":[["45161.00","3.077"],["45160.00","1.090"]],"a":[["45175.30","0.003"],["45175.70","0.011"],["45177.10","0.246"],["45177.80","2.080"],["45178.00","0"]],"u":20458797,"seq":114533083316},"cts":1704258142269}
{"topic":"orderbook.50.BTCUSDT","type":"delta","ts":1704258142292,"data":{"s":"BTCUSDT","b":[["45164.40","0.037"],["45163.00","0.077"],["45159.90","0"],["45159.80","0"]],"a":[["45176.50","0.480"],["45176.80","0.011"],["45177.20","3.983"],["45177.80","0.133"],["45177.90","0"]],"u":20458798,"seq":114533083368},"cts":1704258142289}
{"topic":"orderbook.50.BTCUSDT","type":"delta","ts":1704258142311,"data":{"s":"BTCUSDT","b":[],"a":[["45175.30","0.014"],["45175.70","0"],["45176.80","0.022"],["45177.20","0.221"],["45177.30","3.895"],["45177.80","2.080"],["45177.90","1.615"]],"u":20458799,"seq":114533083435},"cts":1704258142309}
{"topic":"orderbook.50.BTCUSDT","type":"delta","ts":1704258142331,"data":{"s":"BTCUSDT","b":[["45164.40","0"],["45159.90","0.901"]],"a":[["45176.50","0.443"],["45177.30","0.133"],["45177.50","3.762"],["45177.80","0.133"],["45177.90","0"]],"u":20458800,"seq":114533083482},"cts":1704258142329}
{"topic":"orderbook.50.BTCUSDT","type":"delta","ts":1704258142351,"data":{"s":"BTCUSDT","b":[["45165.80","0.124"]],"a":[["45175.30","0.003"],["45175.70","0.011"],["45176.80","0.011"],["45177.50","0"],["45177.70","4.249"]],"u":20458801,"seq":114533083531},"cts":1704258142350}
{"topic":"orderbook.50.BTCUSDT","type":"delta","ts":1704258142372,"data":{"s":"BTCUSDT","b":[["45170.20","2.666"]],"a":[["45176.80","0"],["45177.10","4.008"],["45177.70","0.487"],["45177.80","2.080"],["45177.90","1.615"]],"u":20458802,"seq":114533083578},"cts":1704258142370}
{"topic":"orderbook.50.BTCUSDT","type":"delta","ts":1704258142392,"data":{"s":"BTCUSDT","b":[["45161.20","0.544"],["45159.90","0"]],"a":[["45172.50","0"],["45175.30","0.014"],["45175.70","0"],["45177.80","0.133"],["45178.00","0.380"],["45178.10","1.946"]],"u":20458803,"seq":114533083627},"cts":1704258142389}
{"topic":"orderbook.50.BTCUSDT","type":"delta","ts":1704258142411,"data":{"s":"BTCUSDT","b":[["45162.70","1.505"],["45160.00","0"]],"a":[["45176.90","3.873"],["45177.10","2.193"]],"u":20458804,"seq":114533083682},"cts":1704258142410}
{"topic":"orderbook.50.BTCUSDT","type":"delta","ts":1704258142431,"data":{"s":"BTCUSDT","b":[["45164.40","0.037"],["45160.10","0"]],"a":[["45176.20","0.224"],["45176.50","0.480"],["45176.90","0.111"],["45177.10","4.008"]],"u":20458805,"seq":114533083739},"cts":1704258142429}
{"topic":"orderbook.50.BTCUSDT","type":"delta","ts":1704258142452,"data":{"s":"BTCUSDT","b":[],"a":[["45177.20","2.168"]],"u":20458806,"seq":114533083773},"cts":1704258142449}
{"topic":"orderbook.50.BTCUSDT","type":"delta","ts":1704258142471,"data":{"s":"BTCUSDT","b":[["45170.20","1.293"],["45164.20","0.083"],["45160.20","0"]],"a":[["45177.20","0.221"],["45177.70","2.434"]],"u":20458807,"seq":114533083864},"cts":1704258142470}
{"topic":"orderbook.50.BTCUSDT","type":"delta","ts":1704258142492,"data":{"s":"BTCUSDT","b":[["45170.20","1.135"],["45167.90","0"],["45166.00","0.114"],["45160.20","0.890"]],"a":[["45170.80","0.112"],["45172.50","1.600"],["45176.90","0.122"],["45177.00","2.058"],["45177.70","0.487"],["45177.90","1.637"],["45178.00","0"],["45178.10","0"]],"u":20458808,"seq":114533083963},"cts":1704258142489}
{"topic":"orderbook.50.BTCUSDT","type":"delta","ts":1704258142511,"data":{"s":"BTCUSDT","b":[["45167.50","0.040"],["45166.30","0.119"],["45164.40","0"],["45160.10","1.195"]],"a":[["45176.90","3.884"],["45177.00","0.111"],["45177.10","0.246"],["45177.60","0.097"]],"u":20458809,"seq":114533084095},"cts":1704258142510}
{"topic":"orderbook.50.BTCUSDT","type":"delta","ts":1704258142531,"data":{"s":"BTCUSDT","b":[["45164.20","0.120"]],"a":[["45176.20","0.261"],["45176.50","0.454"],["45176.90","0.122"]],"u":20458810,"seq":114533084183},"cts":1704258142530}
{"topic":"orderbook.50.BTCUSDT","type":"delta","ts":1704258142552,"data":{"s":"BTCUSDT","b":[["45167.40","0"],["45165.90","0.111"],["45160.00","3.303"]],"a":[["45177.10","4.008"]],"u":20458811,"seq":114533084248},"cts":1704258142549}
{"topic":"orderbook.50.BTCUSDT","type":"delta","ts":1704258142571,"data":{"s":"BTCUSDT","b":[["45170.20","1.439"],["45167.50","0.007"],["45166.30","0.075"],["45165.80","0.236"]],"a":[["45176.90","0.111"]],"u":20458812,"seq":114533084317},"cts":1704258142569}
{"topic":"orderbook.50.BTCUSDT","type":"delta","ts":1704258142592,"data":{"s":"BTCUSDT","b":[["45166.30","0.134"]],"a":[["45175.30","0.003"],["45175.90","0.011"],["45176.50","0.443"],["45177.10","0.246"],["45177.90","0"]],"u":20458813,"seq":114533084390},"cts":1704258142590}
{"topic":"orderbook.50.BTCUSDT","type":"delta","ts":1704258142611,"data":{"s":"BTCUSDT","b":[],"a":[["45175.70","0.011"],["45175.90","0"]],"u":20458814,"seq":114533084452},"cts":1704258142610}
{"topic":"orderbook.50.BTCUSDT","type":"delta","ts":1704258142632,"data":{"s":"BTCUSDT","b":[["45164.20","0.083"]],"a":[["45176.20","0.224"]],"u":20458815,"seq":114533084520},"cts":1704258142629}
{"topic":"orderbook.50.BTCUSDT","type":"delta","ts":1704258142652,"data":{"s":"BTCUSDT","b":[["45167.50","0.006"],["45167.30","0.002"],["45164.40","0.037"],["45163.10","0.081"],["45160.20","0"],["45160.10","0"],["45160.00","0"]],"a":[["45175.70","0"],["45175.90","0.011"],["45176.40","0.882"],["45177.30","3.895"]],"u":20458816,"seq":114533084602},"cts":1704258142650}
{"topic":"orderbook.50.BTCUSDT","type":"delta","ts":1704258142671,"data":{"s":"BTCUSDT","b":[["45170.20","1.633"],["45167.50","0.005"],["45167.30","0.003"],["45165.50","0.157"]],"a":[["45170.30","7.824"],["45172.50","0"],["45175.90","0"],["45176.10","0.011"],["45177.30","0.133"],["45177.70","4.249"],["45177.90","1.637"]],"u":20458817,"seq":114533084676},"cts":1704258142668}
{"topic":"orderbook.50.BTCUSDT","type":"delta","ts":1704258142691,"data":{"s":"BTCUSDT","b":[["45168.00","0.114"],["45167.50","0.004"],["45167.30","0.004"]],"a":[["45170.30","6.624"]],"u":20458818,"seq":114533084745},"cts":1704258142690}
{"topic":"orderbook.50.BTCUSDT","type":"delta","ts":1704258142712,"data":{"s":"BTCUSDT","b":[["45168.60","0.074"]],"a":[["45170.80","0"],["45178.00","2.327"]],"u":20458819,"seq":114533084805},"cts":1704258142709}
{"topic":"orderbook.50.BTCUSDT","type":"delta","ts":1704258142732,"data":{"s":"BTCUSDT","b":[],"a":[["45176.10","0"],["45176.20","0.235"],["45177.10","0.257"],["45177.70","0.487"],["45178.00","0.380"],["45178.10","1.946"]],"u":20458820,"seq":114533084879},"cts":1704258142730}
{"topic":"orderbook.50.BTCUSDT","type":"delta","ts":1704258142751,"data":{"s":"BTCUSDT","b":[["45167.50","0.003"]],"a":[["45176.20","0.224"],["45176.60","1.322"]],"u":20458821,"seq":114533084951},"cts":1704258142750}
{"topic":"orderbook.50.BTCUSDT","type":"delta","ts":1704258142771,"data":{"s":"BTCUSDT","b":[],"a":[["45177.50","3.762"],["45178.10","0"]],"u":20458822,"seq":114533085009},"cts":1704258142769}
{"topic":"orderbook.50.BTCUSDT","type":"delta","ts":1704258142792,"data":{"s":"BTCUSDT","b":[["45167.50","0.001"],["45167.30","0.005"],["45162.70","0"],["45160.20","0.890"]],"a":[["45176.80","0.011"],["45177.50","0"],["45177.60","2.044"]],"u":20458823,"seq":114533085074},"cts":1704258142790}
{"topic":"orderbook.50.BTCUSDT","type":"delta","ts":1704258142811,"data":{"s":"BTCUSDT","b":[["45167.30","0.006"],["45164.40","0"],["45160.10","1.195"]],"a":[["45176.40","0.845"],["45177.30","3.895"]],"u":20458824,"seq":114533085130},"cts":1704258142810}
{"topic":"orderbook.50.BTCUSDT","type":"delta","ts":1704258142831,"data":{"s":"BTCUSDT","b":[["45163.90","0.041"]],"a":[["45175.90","0.048"],["45176.60","1.311"],["45176.80","0"]],"u":20458825,"seq":114533085203},"cts":1704258142829}
{"topic":"orderbook.50.BTCUSDT","type":"delta","ts":1704258142852,"data":{"s":"BTCUSDT","b":[],"a":[["45175.70","0.011"],["45175.90","0.037"],["45177.20","3.983"],["45177.30","0.133"],["45177.60","0.097"],["45178.00","0"]],"u":20458826,"seq":114533085266},"cts":1704258142850}
{"topic":"orderbook.50.BTCUSDT","type":"delta","ts":1704258142871,"data":{"s":"BTCUSDT","b":[],"a":[["45175.30","0.014"],["45175.70","0"],["45178.00","0.380"]],"u":20458827,"seq":114533085326},"cts":1704258142869}
{"topic":"orderbook.50.BTCUSDT","type":"delta","ts":1704258142891,"data":{"s":"BTCUSDT","b":[["45162.70","1.505"],["45160.10","0"]],"a":[["45177.60","2.044"]],"u":20458828,"seq":114533085394},"cts":1704258142890}
{"topic":"orderbook.50.BTCUSDT","type":"delta","ts":1704258142912,"data":{"s":"BTCUSDT","b":[["45169.90","0.001"],["45167.50","0"],["45167.30","0.007"]],"a":[["45175.30","0.003"],["45175.70","0.011"],["45177.20","0.221"],["45177.30","3.895"],["45177.60","0.097"],["45178.00","0"]],"u":20458829,"seq":114533085459},"cts":1704258142909}
{"topic":"orderbook.50.BTCUSDT","type":"delta","ts":1704258142931,"data":{"s":"BTCUSDT","b":[["45164.40","0.037"],["45163.90","0.004"],["45160.20","0"]],"a":[["45175.90","0"],["45176.40","0.882"],["45177.30","0.133"],["45177.80","3.895"],["45178.00","0.380"]],"u":20458830,"seq":114533085529},"cts":1704258142930}
{"topic":"orderbook.50.BTCUSDT","type":"delta","ts":1704258142952,"data":{"s":"BTCUSDT","b":[["45168.70","0.001"],["45168.60","0.073"],["45160.30","0"]],"a":[["45176.40","0.845"],["45177.00","0.122"],["45177.10","0.246"],["45177.60","3.859"],["45177.80","0.133"]],"u":20458831,"seq":114533085598},"cts":1704258142950}
{"topic":"orderbook.50.BTCUSDT","type":"delta","ts":1704258142971,"data":{"s":"BTCUSDT","b":[],"a":[["45175.70","0"],["45175.80","0.126"],["45178.10","1.946"]],"u":20458832,"seq":114533085660},"cts":1704258142970}
{"topic":"orderbook.50.BTCUSDT","type":"delta","ts":1704258142991,"data":{"s":"BTCUSDT","b":[],"a":[["45177.00","0.111"],["45177.60","0.097"]],"u":20458833,"seq":114533085725},"cts":1704258142989}
{"topic":"orderbook.50.BTCUSDT","type":"delta","ts":1704258143011,"data":{"s":"BTCUSDT","b":[["45165.80","0.124"]],"a":[["45177.60","3.859"]],"u":20458834,"seq":114533085797},"cts":1704258143010}
{"topic":"orderbook.50.BTCUSDT","type":"delta","ts":1704258143032,"data":{"s":"BTCUSDT","b":[["45169.90","0"],["45164.40","0"],["45160.70","0.221"],["45160.30","1.024"]],"a":[["45171.80","0.300"],["45175.70","0.011"],["45175.80","0.115"],["45177.60","0.097"],["45178.10","0"]],"u":20458835,"seq":114533085858},"cts":1704258143030}
{"topic":"orderbook.50.BTCUSDT","type":"delta","ts":1704258143052,"data":{"s":"BTCUSDT","b":[["45164.50","0.037"],["45160.30","0"]],"a":[["45176.30","1.796"]],"u":20458836,"seq":114533085928},"cts":1704258143050}
{"topic":"orderbook.50.BTCUSDT","type":"delta","ts":1704258143072,"data":{"s":"BTCUSDT","b":[["45170.20","1.644"]],"a":[],"u":20458837,"seq":114533085990},"cts":1704258143069}
{"topic":"orderbook.50.BTCUSDT","type":"delta","ts":1704258143091,"data":{"s":"BTCUSDT","b":[["45170.20","1.718"],["45164.10","0.096"]],"a":[["45170.30","6.596"],["45173.00","0.134"],["45174.70","0.044"],["45175.20","0"],["45176.80","0.004"],["45177.10","0.257"],["45177.60","3.859"],["45178.00","0"]],"u":20458838,"seq":114533086072},"cts":1704258143089}
{"topic":"orderbook.50.BTCUSDT","type":"delta","ts":1704258143111,"data":{"s":"BTCUSDT","b":[["45164.50","0"],["45162.50","0.684"],["45160.30","1.024"]],"a":[["45175.70","0"],["45175.90","0.011"],["45176.30","1.759"],["45176.60","1.322"],["45177.60","0.097"]],"u":20458839,"seq":114533086140},"cts":1704258143110}
{"topic":"orderbook.50.BTCUSDT","type":"delta","ts":1704258143131,"data":{"s":"BTCUSDT","b":[],"a":[["45175.90","0"],["45176.60","1.311"],["45178.00","0.380"]],"u":20458840,"seq":114533086219},"cts":1704258143130}
{"topic":"orderbook.50.BTCUSDT","type":"delta","ts":1704258143151,"data":{"s":"BTCUSDT","b":[],"a":[["45176.10","0.011"],["45178.00","0"]],"u":20458841,"seq":114533086293},"cts":1704258143150}
{"topic":"orderbook.50.BTCUSDT","type":"delta","ts":1704258143172,"data":{"s":"BTCUSDT","b":[["45170.20","1.707"]],"a":[["45177.10","0.246"],["45177.80","3.895"]],"u":20458842,"seq":114533086368},"cts":1704258143170}
{"topic":"orderbook.50.BTCUSDT","type":"delta","ts":1704258143191,"data":{"s":"BTCUSDT","b":[["45170.20","1.633"]],"a":[["45170.30","6.624"],["45175.90","0.011"],["45176.10","0"],["45177.80","0.133"]],"u":20458843,"seq":114533086450},"cts":1704258143190}
{"topic":"orderbook.50.BTCUSDT","type":"delta","ts":1704258143212,"data":{"s":"BTCUSDT","b":[["45170.20","1.247"],["45161.20","0"],["45161.00","2.968"],["45160.60","0.109"]],"a":[["45170.30","7.824"],["45177.80","3.895"]],"u":20458844,"seq":114533086528},"cts":1704258143210}
{"topic":"orderbook.50.BTCUSDT","type":"delta","ts":1704258143231,"data":{"s":"BTCUSDT","b":[["45170.20","1.632"]],"a":[["45175.90","0"],["45177.80","0.133"],["45178.00","0.380"]],"u":20458845,"seq":114533086665},"cts":1704258143230}
{"topic":"orderbook.50.BTCUSDT","type":"delta","ts":1704258143252,"data":{"s":"BTCUSDT","b":[["45165.00","0.239"]],"a":[["45175.30","0.014"],["45176.90","0.148"],["45177.20","3.983"],["45177.60","2.044"]],"u":20458846,"seq":114533086744},"cts":1704258143250}
{"topic":"orderbook.50.BTCUSDT","type":"delta","ts":1704258143271,"data":{"s":"BTCUSDT","b":[["45165.00","0.202"]],"a":[["45175.30","0.003"],["45175.90","0.011"],["45176.80","0.015"],["45176.90","0.111"],["45177.20","0.221"],["45177.60","0.097"],["45177.80","3.895"],["45178.00","0"]],"u":20458847,"seq":114533086813},"cts":1704258143268}
{"topic":"orderbook.50.BTCUSDT","type":"delta","ts":1704258143291,"data":{"s":"BTCUSDT","b":[],"a":[["45175.90","0"],["45176.10","0.011"],["45177.80","0.133"]],"u":20458848,"seq":114533086885},"cts":1704258143290}
{"topic":"orderbook.50.BTCUSDT","type":"delta","ts":1704258143312,"data":{"s":"BTCUSDT","b":[],"a":[["45170.30","6.624"]],"u":20458849,"seq":114533086949},"cts":1704258143310}
{"topic":"orderbook.50.BTCUSDT","type":"delta","ts":1704258143331,"data":{"s":"BTCUSDT","b":[],"a":[["45177.10","0.257"]],"u":20458850,"seq":114533087010},"cts":1704258143330}
{"topic":"orderbook.50.BTCUSDT","type":"delta","ts":1704258143351,"data":{"s":"BTCUSDT","b":[["45162.50","1.090"]],"a":[["45176.80","0.004"]],"u":20458851,"seq":114533087063},"cts":1704258143350}
{"topic":"orderbook.50.BTCUSDT","type":"delta","ts":1704258143372,"data":{"s":"BTCUSDT","b":[["45170.20","2.879"],["45170.00","0.221"],["45165.70","0.148"]],"a":[["45172.70","0.001"],["45173.20","0"],["45176.10","0"],["45176.20","0.003"],["45176.70","0.162"],["45177.20","0"],["45177.60","0.134"],["45178.00","0.380"],["45178.10","1.946"]],"u":20458852,"seq":114533087162},"cts":1704258143370}
{"topic":"orderbook.50.BTCUSDT","type":"delta","ts":1704258143392,"data":{"s":"BTCUSDT","b":[["45170.20","3.569"],["45163.30","1.200"],["45160.30","0"]],"a":[["45174.80","0.003"],["45177.10","0.268"]],"u":20458853,"seq":114533087272},"cts":1704258143390}
{"topic":"orderbook.50.BTCUSDT","type":"delta","ts":1704258143411,"data":{"s":"BTCUSDT","b":[["45165.00","0"],["45163.40","0.721"]],"a":[["45170.30","6.596"]],"u":20458854,"seq":114533087318},"cts":1704258143410}
{"topic":"orderbook.50.BTCUSDT","type":"delta","ts":1704258143432,"data":{"s":"BTCUSDT","b":[["45165.70","0.111"],["45162.50","1.311"]],"a":[["45177.60","0.097"]],"u":20458855,"seq":114533087363},"cts":1704258143429}
{"topic":"orderbook.50.BTCUSDT","type":"delta","ts":1704258143452,"data":{"s":"BTCUSDT","b":[["45170.20","3.869"]],"a":[["45172.60","0"],["45178.20","1.129"]],"u":20458856,"seq":114533087406},"cts":1704258143449}
{"topic":"orderbook.50.BTCUSDT","type":"delta","ts":1704258143472,"data":{"s":"BTCUSDT","b":[["45170.20","3.943"]],"a":[["45172.70","0.002"],["45177.10","0.246"],["45177.20","0.011"],["45178.20","0"]],"u":20458857,"seq":114533087446},"cts":1704258143470}
{"topic":"orderbook.50.BTCUSDT","type":"delta","ts":1704258143492,"data":{"s":"BTCUSDT","b":[["45167.30","0.005"],["45165.50","0.194"]],"a":[["45170.30","5.402"],["45172.70","0.001"],["45177.50","0.037"],["45178.10","0"]],"u":20458858,"seq":114533087485},"cts":1704258143490}
{"topic":"orderbook.50.BTCUSDT","type":"delta","ts":1704258143511,"data":{"s":"BTCUSDT","b":[],"a":[["45176.70","0.173"],["45177.20","0"],["45177.60","0.075"],["45177.90","1.615"],["45178.10","1.946"]],"u":20458859,"seq":114533087553},"cts":1704258143510}
{"topic":"orderbook.50.BTCUSDT","type":"delta","ts":1704258143532,"data":{"s":"BTCUSDT","b":[["45170.20","3.954"],["45165.50","0.157"],["45164.70","0.832"],["45161.30","0.824"],["45160.40","0"]],"a":[["45171.00","0"],["45177.50","0"],["45178.20","1.129"],["45178.30","0.996"]],"u":20458860,"seq":114533087616},"cts":1704258143530}
{"topic":"orderbook.50.BTCUSDT","type":"delta","ts":1704258143552,"data":{"s":"BTCUSDT","b":[["45165.60","0.078"],["45164.10","0.018"],["45160.60","0"]],"a":[["45172.80","0.500"],["45177.70","0.266"]],"u":20458861,"seq":114533087660},"cts":1704258143549}
{"topic":"orderbook.50.BTCUSDT","type":"delta","ts":1704258143572,"data":{"s":"BTCUSDT","b":[["45165.80","0.236"]],"a":[["45174.20","0.078"],["45176.70","0.162"],["45178.30","0"]],"u":20458862,"seq":114533087691},"cts":1704258143569}
{"topic":"orderbook.50.BTCUSDT","type":"delta","ts":1704258143592,"data":{"s":"BTCUSDT","b":[["45161.20","0.544"],["45160.70","0"]],"a":[],"u":20458863,"seq":114533087717},"cts":1704258143589}
{"topic":"orderbook.50.BTCUSDT","type":"delta","ts":1704258143612,"data":{"s":"BTCUSDT","b":[["45167.30","0.006"],["45165.60","0.115"]],"a":[["45172.70","0.002"],["45177.60","0.112"]],"u":20458864,"seq":114533087747},"cts":1704258143609}
{"topic":"orderbook.50.BTCUSDT","type":"delta","ts":1704258143631,"data":{"s":"BTCUSDT","b":[["45165.60","0.078"]],"a":[["45177.60","0.075"],["45177.80","0.144"]],"u":20458865,"seq":114533087781},"cts":1704258143626}
{"topic":"orderbook.50.BTCUSDT","type":"delta","ts":1704258143652,"data":{"s":"BTCUSDT","b":[],"a":[["45178.00","0.391"]],"u":20458866,"seq":114533087807},"cts":1704258143649}
{"topic":"orderbook.50.BTCUSDT","type":"delta","ts":1704258143692,"data":{"s":"BTCUSDT","b":[],"a":[["45172.70","0.004"]],"u":20458867,"seq":114533087833},"cts":1704258143689}
{"topic":"orderbook.50.BTCUSDT","type":"delta","ts":1704258143712,"data":{"s":"BTCUSDT","b":[],"a":[["45177.70","0.277"],["45178.00","0.380"]],"u":20458868,"seq":114533087859},"cts":1704258143709}
{"topic":"orderbook.50.BTCUSDT","type":"delta","ts":1704258143732,"data":{"s":"BTCUSDT","b":[["45167.30","0.007"],["45165.30","0.037"],["45160.90","0"]],"a":[["45177.20","0.037"],["45177.30","0.144"],["45178.20","0"]],"u":20458869,"seq":114533087876},"cts":1704258143724}
{"topic":"orderbook.50.BTCUSDT","type":"delta","ts":1704258143771,"data":{"s":"BTCUSDT","b":[],"a":[["45171.20","0.200"],["45172.70","0.005"]],"u":20458870,"seq":114533087899},"cts":1704258143769}
{"topic":"orderbook.50.BTCUSDT","type":"delta","ts":1704258143792,"data":{"s":"BTCUSDT","b":[],"a":[["45174.40","1.658"],["45174.60","0"],["45176.40","0.889"],["45177.30","0.155"],["45177.70","0.266"]],"u":20458871,"seq":114533087920},"cts":1704258143790}
{"topic":"orderbook.50.BTCUSDT","type":"delta","ts":1704258143811,"data":{"s":"BTCUSDT","b":[],"a":[["45177.30","0.144"]],"u":20458872,"seq":114533087935},"cts":1704258143805}
{"topic":"orderbook.50.BTCUSDT","type":"delta","ts":1704258143832,"data":{"s":"BTCUSDT","b":[["45165.30","0"],["45160.90","0.447"]],"a":[["45177.20","0"],["45178.20","1.129"]],"u":20458873,"seq":114533087957},"cts":1704258143825}
{"topic":"orderbook.50.BTCUSDT","type":"delta","ts":1704258143851,"data":{"s":"BTCUSDT","b":[["45165.50","0.194"]],"a":[["45177.50","0.037"],["45178.20","0"]],"u":20458874,"seq":114533087977},"cts":1704258143849}
{"topic":"orderbook.50.BTCUSDT","type":"delta","ts":1704258143872,"data":{"s":"BTCUSDT","b":[["45165.60","0.157"],["45163.00","0"],["45160.70","0.221"]],"a":[["45176.20","0.014"],["45177.30","0.133"]],"u":20458875,"seq":114533088005},"cts":1704258143867}
{"topic":"orderbook.50.BTCUSDT","type":"delta","ts":1704258143912,"data":{"s":"BTCUSDT","b":[["45169.90","0.001"],["45161.20","0"]],"a":[["45176.20","0.003"],["45177.20","0.011"],["45178.10","0"]],"u":20458876,"seq":114533088042},"cts":1704258143909}
{"topic":"orderbook.50.BTCUSDT","type":"delta","ts":1704258143932,"data":{"s":"BTCUSDT","b":[],"a":[["45171.20","0"],["45178.10","1.946"]],"u":20458877,"seq":114533088065},"cts":1704258143929}
{"topic":"orderbook.50.BTCUSDT","type":"delta","ts":1704258143952,"data":{"s":"BTCUSDT","b":[],"a":[["45177.50","0.048"]],"u":20458878,"seq":114533088089},"cts":1704258143948}
{"topic":"orderbook.50.BTCUSDT","type":"delta","ts":1704258144012,"data":{"s":"BTCUSDT","b":[],"a":[["45177.00","0.122"],["45177.10","0.283"],["45177.20","0"],["45177.50","0.011"],["45178.20","1.129"]],"u":20458879,"seq":114533088131},"cts":1704258144008}
{"topic":"orderbook.50.BTCUSDT","type":"delta","ts":1704258144031,"data":{"s":"BTCUSDT","b":[],"a":[["45177.10","0.246"],["45177.50","0"],["45178.30","0.996"]],"u":20458880,"seq":114533088148},"cts":1704258144029}
{"topic":"orderbook.50.BTCUSDT","type":"delta","ts":1704258144052,"data":{"s":"BTCUSDT","b":[["45167.40","1.600"],["45160.70","0"]],"a":[["45170.30","5.389"],["45177.70","1.771"],["45177.90","0.110"]],"u":20458881,"seq":114533088195},"cts":1704258144049}
{"topic":"orderbook.50.BTCUSDT","type":"delta","ts":1704258144072,"data":{"s":"BTCUSDT","b":[["45168.60","0"],["45168.10","0.965"]],"a":[["45176.20","0.014"],["45177.00","0.111"]],"u":20458882,"seq":114533088221},"cts":1704258144067}
{"topic":"orderbook.50.BTCUSDT","type":"delta","ts":1704258144132,"data":{"s":"BTCUSDT","b":[["45165.50","0.157"]],"a":[],"u":20458883,"seq":114533088252},"cts":1704258144130}
{"topic":"orderbook.50.BTCUSDT","type":"delta","ts":1704258144171,"data":{"s":"BTCUSDT","b":[["45168.70","0"],["45168.60","0.001"],["45167.50","0.002"],["45167.30","0.005"],["45160.90","0"]],"a":[["45177.50","0.011"],["45178.30","0"]],"u":20458884,"seq":114533088286},"cts":1704258144169}
{"topic":"orderbook.50.BTCUSDT","type":"delta","ts":1704258144192,"data":{"s":"BTCUSDT","b":[["45167.50","0.003"],["45167.30","0.004"]],"a":[],"u":20458885,"seq":114533088306},"cts":1704258144189}
{"topic":"orderbook.50.BTCUSDT","type":"delta","ts":1704258144211,"data":{"s":"BTCUSDT","b":[["45163.00","0.110"],["45161.00","0"]],"a":[],"u":20458886,"seq":114533088322},"cts":1704258144210}
{"topic":"orderbook.50.BTCUSDT","type":"delta","ts":1704258144232,"data":{"s":"BTCUSDT","b":[["45167.30","0.003"]],"a":[],"u":20458887,"seq":114533088335},"cts":1704258144224}
{"topic":"orderbook.50.BTCUSDT","type":"delta","ts":1704258144252,"data":{"s":"BTCUSDT","b":[["45167.50","0.004"],["45167.40","0"],["45165.30","0.037"]],"a":[["45177.00","0.148"]],"u":20458888,"seq":114533088361},"cts":1704258144250}
{"topic":"orderbook.50.BTCUSDT","type":"delta","ts":1704258144271,"data":{"s":"BTCUSDT","b":[["45168.60","0.078"],["45168.10","0"],["45165.30","0"],["45162.50","1.090"],["45161.00","2.968"],["45160.90","0.447"]],"a":[["45177.00","0.111"]],"u":20458889,"seq":114533088387},"cts":1704258144269}
{"topic":"orderbook.50.BTCUSDT","type":"delta","ts":1704258144332,"data":{"s":"BTCUSDT","b":[],"a":[["45177.30","0.144"],["45177.50","0"],["45178.30","0.996"]],"u":20458890,"seq":114533088423},"cts":1704258144329}
{"topic":"orderbook.50.BTCUSDT","type":"delta","ts":1704258144351,"data":{"s":"BTCUSDT","b":[["45170.20","3.569"],["45165.40","0.047"]],"a":[["45177.10","0.283"]],"u":20458891,"seq":114533088447},"cts":1704258144347}
{"topic":"orderbook.50.BTCUSDT","type":"delta","ts":1704258144372,"data":{"s":"BTCUSDT","b":[["45170.20","3.979"]],"a":[["45173.80","0.141"],["45176.20","0.003"]],"u":20458892,"seq":114533088522},"cts":1704258144369}
{"topic":"orderbook.50.BTCUSDT","type":"delta","ts":1704258144411,"data":{"s":"BTCUSDT","b":[],"a":[["45177.30","0.133"]],"u":20458893,"seq":114533088566},"cts":1704258144408}
{"topic":"orderbook.50.BTCUSDT","type":"delta","ts":1704258144432,"data":{"s":"BTCUSDT","b":[["45165.40","0.010"]],"a":[["45177.10","0.246"]],"u":20458894,"seq":114533088598},"cts":1704258144430}
{"topic":"orderbook.50.BTCUSDT","type":"delta","ts":1704258144452,"data":{"s":"BTCUSDT","b":[["45165.50","0.194"]],"a":[["45177.20","0.037"],["45177.70","1.992"],["45178.30","0"]],"u":20458895,"seq":114533088631},"cts":1704258144450}
{"topic":"orderbook.50.BTCUSDT","type":"delta","ts":1704258144471,"data":{"s":"BTCUSDT","b":[["45168.70","0.001"],["45168.60","0.077"],["45167.50","0.001"],["45167.30","0.004"],["45165.50","0.157"],["45160.90","0"]],"a":[["45177.20","0"],["45178.30","0.996"]],"u":20458896,"seq":114533088668},"cts":1704258144470}
{"topic":"orderbook.50.BTCUSDT","type":"delta","ts":1704258144491,"data":{"s":"BTCUSDT","b":[["45167.30","0.005"],["45164.50","0.110"],["45161.00","0"]],"a":[],"u":20458897,"seq":114533088709},"cts":1704258144490}
{"topic":"orderbook.50.BTCUSDT","type":"delta","ts":1704258144532,"data":{"s":"BTCUSDT","b":[["45167.50","0"],["45167.30","0.006"],["45161.00","2.968"]],"a":[["45173.70","0.011"],["45173.80","0.130"],["45178.30","0"]],"u":20458898,"seq":114533088758},"cts":1704258144528}
{"topic":"orderbook.50.BTCUSDT","type":"delta","ts":1704258144552,"data":{"s":"BTCUSDT","b":[["45167.30","0.007"]],"a":[["45177.30","0.144"]],"u":20458899,"seq":114533088788},"cts":1704258144548}
{"topic":"orderbook.50.BTCUSDT","type":"delta","ts":1704258144592,"data":{"s":"BTCUSDT","b":[["45165.60","0.194"]],"a":[["45177.30","0.181"]],"u":20458900,"seq":114533088830},"cts":1704258144589}
{"topic":"orderbook.50.BTCUSDT","type":"delta","ts":1704258144612,"data":{"s":"BTCUSDT","b":[["45165.60","0.157"]],"a":[["45177.30","0.144"]],"u":20458901,"seq":114533088856},"cts":1704258144609}
{"topic":"orderbook.50.BTCUSDT","type":"delta","ts":1704258144631,"data":{"s":"BTCUSDT","b":[],"a":[["45177.30","0.133"]],"u":20458902,"seq":114533088886},"cts":1704258144629}
{"topic":"orderbook.50.BTCUSDT","type":"delta","ts":1704258144652,"data":{"s":"BTCUSDT","b":[["45162.70","1.726"]],"a":[],"u":20458903,"seq":114533088910},"cts":1704258144649}
{"topic":"orderbook.50.BTCUSDT","type":"delta","ts":1704258144692,"data":{"s":"BTCUSDT","b":[["45165.40","0.047"]],"a":[["45175.10","0.570"],["45175.70","0.111"],["45176.70","0.140"],["45177.00","0.148"],["45178.20","0"]],"u":20458904,"seq":114533088952},"cts":1704258144689}
{"topic":"orderbook.50.BTCUSDT","type":"delta","ts":1704258144712,"data":{"s":"BTCUSDT","b":[["45165.40","0.010"]],"a":[["45177.00","0.111"]],"u":20458905,"seq":114533088991},"cts":1704258144710}
{"topic":"orderbook.50.BTCUSDT","type":"delta","ts":1704258144772,"data":{"s":"BTCUSDT","b":[["45170.20","3.978"]],"a":[["45170.30","6.989"]],"u":20458906,"seq":114533089107},"cts":1704258144770}
{"topic":"orderbook.50.BTCUSDT","type":"delta","ts":1704258144792,"data":{"s":"BTCUSDT","b":[["45165.60","0.194"],["45161.30","0.821"]],"a":[["45170.30","5.389"],["45171.80","0.500"],["45177.20","0.037"],["45177.30","0.144"],["45178.10","0"]],"u":20458907,"seq":114533089194},"cts":1704258144790}
{"topic":"orderbook.50.BTCUSDT","type":"delta","ts":1704258144811,"data":{"s":"BTCUSDT","b":[["45170.20","3.571"]],"a":[["45172.70","1.605"]],"u":20458908,"seq":114533089250},"cts":1704258144809}
{"topic":"orderbook.50.BTCUSDT","type":"delta","ts":1704258144832,"data":{"s":"BTCUSDT","b":[["45170.20","3.980"],["45165.60","0.157"],["45162.70","1.505"]],"a":[["45170.30","5.392"],["45177.20","0"],["45178.10","1.946"]],"u":20458909,"seq":114533089376},"cts":1704258144830}
{"topic":"orderbook.50.BTCUSDT","type":"delta","ts":1704258144852,"data":{"s":"BTCUSDT","b":[["45170.20","3.580"]],"a":[["45170.30","8.294"],["45172.60","1.200"],["45175.10","0.548"],["45176.70","0.162"],["45177.20","0.221"],["45177.30","0.133"],["45178.00","0"],["45178.10","0"]],"u":20458910,"seq":114533089528},"cts":1704258144850}
{"topic":"orderbook.50.BTCUSDT","type":"delta","ts":1704258144872,"data":{"s":"BTCUSDT","b":[["45170.20","3.512"],["45167.30","0.006"]],"a":[["45170.30","6.694"],["45172.70","1.604"],["45173.70","0"],["45178.00","0.380"]],"u":20458911,"seq":114533089667},"cts":1704258144870}
{"topic":"orderbook.50.BTCUSDT","type":"delta","ts":1704258144891,"data":{"s":"BTCUSDT","b":[],"a":[["45173.70","0.011"],["45178.00","0"]],"u":20458912,"seq":114533089733},"cts":1704258144890}
{"topic":"orderbook.50.BTCUSDT","type":"delta","ts":1704258144911,"data":{"s":"BTCUSDT","b":[["45165.80","0.273"]],"a":[["45172.70","1.603"],["45173.70","0"],["45178.00","0.380"]],"u":20458913,"seq":114533089792},"cts":1704258144909}
{"topic":"orderbook.50.BTCUSDT","type":"delta","ts":1704258144931,"data":{"s":"BTCUSDT","b":[["45167.30","0.005"],["45165.80","0.236"]],"a":[["45172.70","1.602"],["45175.90","0.011"],["45178.00","0"]],"u":20458914,"seq":114533089842},"cts":1704258144929}
{"topic":"orderbook.50.BTCUSDT","type":"delta","ts":1704258144951,"data":{"s":"BTCUSDT","b":[["45170.20","3.280"]],"a":[["45174.30","2.640"],["45175.90","0"],["45177.10","0.257"],["45178.00","0.380"]],"u":20458915,"seq":114533089939},"cts":1704258144950}
{"topic":"orderbook.50.BTCUSDT","type":"delta","ts":1704258144972,"data":{"s":"BTCUSDT","b":[],"a":[["45177.70","2.003"],["45177.80","0.133"]],"u":20458916,"seq":114533089985},"cts":1704258144969}
{"topic":"orderbook.50.BTCUSDT","type":"delta","ts":1704258144992,"data":{"s":"BTCUSDT","b":[["45170.20","2.095"],["45162.70","0"],["45160.90","0.447"]],"a":[["45176.20","0.014"],["45177.10","0.246"]],"u":20458917,"seq":114533090025},"cts":1704258144989}
{"topic":"orderbook.50.BTCUSDT","type":"delta","ts":1704258145011,"data":{"s":"BTCUSDT","b":[["45170.00","0.108"],["45164.70","0"],["45160.70","0.221"]],"a":[["45172.70","1.601"],["45177.30","0.144"]],"u":20458918,"seq":114533090145},"cts":1704258145010}
{"topic":"orderbook.50.BTCUSDT","type":"delta","ts":1704258145032,"data":{"s":"BTCUSDT","b":[],"a":[["45175.30","0.047"]],"u":20458919,"seq":114533090224},"cts":1704258145030}
{"topic":"orderbook.50.BTCUSDT","type":"delta","ts":1704258145052,"data":{"s":"BTCUSDT","b":[],"a":[["45170.30","6.682"],["45177.70","1.992"]],"u":20458920,"seq":114533090350},"cts":1704258145049}
{"topic":"orderbook.50.BTCUSDT","type":"delta","ts":1704258145072,"data":{"s":"BTCUSDT","b":[["45167.40","1.600"],["45160.70","0"]],"a":[["45172.50","1.600"],["45178.00","0"]],"u":20458921,"seq":114533090411},"cts":1704258145070}
{"topic":"orderbook.50.BTCUSDT","type":"delta","ts":1704258145092,"data":{"s":"BTCUSDT","b":[["45168.60","0"],["45168.10","0.967"],["45162.80","1.748"]],"a":[],"u":20458922,"seq":114533090486},"cts":1704258145090}
{"topic":"orderbook.50.BTCUSDT","type":"delta","ts":1704258145111,"data":{"s":"BTCUSDT","b":[],"a":[["45172.50","0"],["45172.70","0.001"],["45177.40","2.126"],["45178.00","0.380"]],"u":20458923,"seq":114533090536},"cts":1704258145110}
{"topic":"orderbook.50.BTCUSDT","type":"delta","ts":1704258145132,"data":{"s":"BTCUSDT","b":[["45165.20","0.037"],["45160.90","0"]],"a":[["45176.20","0.003"],["45176.70","0.199"],["45176.80","0.015"]],"u":20458924,"seq":114533090604},"cts":1704258145129}
{"topic":"orderbook.50.BTCUSDT","type":"delta","ts":1704258145151,"data":{"s":"BTCUSDT","b":[["45167.50","0.001"],["45165.20","0"],["45162.10","0.221"],["45161.00","0"]],"a":[["45176.70","0.162"],["45177.30","0.133"],["45177.40","2.104"]],"u":20458925,"seq":114533090671},"cts":1704258145150}
{"topic":"orderbook.50.BTCUSDT","type":"delta","ts":1704258145171,"data":{"s":"BTCUSDT","b":[["45161.30","0.777"]],"a":[["45176.80","0.004"],["45176.90","0.122"]],"u":20458926,"seq":114533090734},"cts":1704258145169}
{"topic":"orderbook.50.BTCUSDT","type":"delta","ts":1704258145211,"data":{"s":"BTCUSDT","b":[],"a":[["45173.80","0.141"],["45176.90","0.111"],["45177.70","2.003"]],"u":20458927,"seq":114533090886},"cts":1704258145210}
{"topic":"orderbook.50.BTCUSDT","type":"delta","ts":1704258145232,"data":{"s":"BTCUSDT","b":[["45167.50","0.002"],["45167.30","0.004"],["45165.20","0.037"],["45161.10","0"]],"a":[["45176.70","0.199"]],"u":20458928,"seq":114533090945},"cts":1704258145229}
{"topic":"orderbook.50.BTCUSDT","type":"delta","ts":1704258145251,"data":{"s":"BTCUSDT","b":[["45167.50","0.003"],["45163.50","0.221"],["45161.30","0"]],"a":[],"u":20458929,"seq":114533090985},"cts":1704258145249}
{"topic":"orderbook.50.BTCUSDT","type":"delta","ts":1704258145272,"data":{"s":"BTCUSDT","b":[["45167.40","0"],["45165.20","0"],["45161.30","0.777"],["45161.10","4.310"]],"a":[["45176.70","0.162"]],"u":20458930,"seq":114533091049},"cts":1704258145269}
{"topic":"orderbook.50.BTCUSDT","type":"delta","ts":1704258145291,"data":{"s":"BTCUSDT","b":[["45168.60","0.070"],["45168.10","0"]],"a":[],"u":20458931,"seq":114533091094},"cts":1704258145289}
{"topic":"orderbook.50.BTCUSDT","type":"delta","ts":1704258145312,"data":{"s":"BTCUSDT","b":[],"a":[["45177.30","0.144"]],"u":20458932,"seq":114533091146},"cts":1704258145309}
{"topic":"orderbook.50.BTCUSDT","type":"delta","ts":1704258145331,"data":{"s":"BTCUSDT","b":[["45165.00","0.037"],["45161.10","0"]],"a":[["45172.80","2.100"],["45176.50","0.480"]],"u":20458933,"seq":114533091203},"cts":1704258145329}
{"topic":"orderbook.50.BTCUSDT","type":"delta","ts":1704258145351,"data":{"s":"BTCUSDT","b":[["45165.00","0"],["45161.10","4.310"]],"a":[["45174.70","0.088"],["45176.40","0.845"],["45176.50","0.443"]],"u":20458934,"seq":114533091253},"cts":1704258145350}
{"topic":"orderbook.50.BTCUSDT","type":"delta","ts":1704258145372,"data":{"s":"BTCUSDT","b":[["45170.20","1.405"]],"a":[["45172.80","0.500"]],"u":20458935,"seq":114533091304},"cts":1704258145369}
{"topic":"orderbook.50.BTCUSDT","type":"delta","ts":1704258145392,"data":{"s":"BTCUSDT","b":[["45170.20","2.096"],["45167.50","0.002"]],"a":[["45172.70","0"],["45178.10","1.946"]],"u":20458936,"seq":114533091404},"cts":1704258145390}
{"topic":"orderbook.50.BTCUSDT","type":"delta","ts":1704258145411,"data":{"s":"BTCUSDT","b":[["45170.20","2.106"]],"a":[],"u":20458937,"seq":114533091468},"cts":1704258145410}
{"topic":"orderbook.50.BTCUSDT","type":"delta","ts":1704258145432,"data":{"s":"BTCUSDT","b":[["45164.50","0.147"]],"a":[["45173.80","0.130"],["45176.20","0.014"],["45176.50","0.480"]],"u":20458938,"seq":114533091533},"cts":1704258145430}
{"topic":"orderbook.50.BTCUSDT","type":"delta","ts":1704258145451,"data":{"s":"BTCUSDT","b":[["45167.50","0.001"],["45167.30","0.005"]],"a":[],"u":20458939,"seq":114533091585},"cts":1704258145449}
{"topic":"orderbook.50.BTCUSDT","type":"delta","ts":1704258145472,"data":{"s":"BTCUSDT","b":[],"a":[["45173.80","0.141"],["45176.20","0.003"],["45177.20","0.232"],["45177.30","0.133"]],"u":20458940,"seq":114533091653},"cts":1704258145470}
{"topic":"orderbook.50.BTCUSDT","type":"delta","ts":1704258145531,"data":{"s":"BTCUSDT","b":[["45167.50","0"],["45167.30","0.006"],["45164.50","0.110"],["45161.00","2.968"]],"a":[["45176.50","0.443"]],"u":20458941,"seq":114533091823},"cts":1704258145529}
{"topic":"orderbook.50.BTCUSDT","type":"delta","ts":1704258145552,"data":{"s":"BTCUSDT","b":[["45167.30","0.007"],["45164.10","0.055"]],"a":[["45172.70","0.001"],["45176.10","0.037"],["45177.20","0.221"],["45178.00","0"],["45178.10","0"]],"u":20458942,"seq":114533091884},"cts":1704258145550}
{"topic":"orderbook.50.BTCUSDT","type":"delta","ts":1704258145571,"data":{"s":"BTCUSDT","b":[["45170.00","0.221"]],"a":[],"u":20458943,"seq":114533091939},"cts":1704258145570}
{"topic":"orderbook.50.BTCUSDT","type":"delta","ts":1704258145592,"data":{"s":"BTCUSDT","b":[["45164.10","0.018"]],"a":[["45176.10","0"],["45178.00","0.380"]],"u":20458944,"seq":114533092002},"cts":1704258145590}
{"topic":"orderbook.50.BTCUSDT","type":"delta","ts":1704258145612,"data":{"s":"BTCUSDT","b":[],"a":[["45173.70","0.011"],["45173.80","0.130"],["45178.00","0"]],"u":20458945,"seq":114533092054},"cts":1704258145610}
